RUNNING: "python -m dask_cuda.cli.dask_cuda_worker --rmm-pool-size=12G
             --local-directory=/tmp/
             --scheduler-file=/root/work/cugraph/mg_utils/dask-scheduler.json
             --memory-limit=auto
             --device-memory-limit=auto
            "
2023-06-22 22:09:08,611 - distributed.nanny - INFO -         Start Nanny at: 'tcp://10.33.227.169:39335'
2023-06-22 22:09:08,614 - distributed.nanny - INFO -         Start Nanny at: 'tcp://10.33.227.169:41251'
2023-06-22 22:09:08,618 - distributed.nanny - INFO -         Start Nanny at: 'tcp://10.33.227.169:35931'
2023-06-22 22:09:08,619 - distributed.nanny - INFO -         Start Nanny at: 'tcp://10.33.227.169:45453'
2023-06-22 22:09:08,621 - distributed.nanny - INFO -         Start Nanny at: 'tcp://10.33.227.169:39355'
2023-06-22 22:09:08,624 - distributed.nanny - INFO -         Start Nanny at: 'tcp://10.33.227.169:43471'
2023-06-22 22:09:08,627 - distributed.nanny - INFO -         Start Nanny at: 'tcp://10.33.227.169:41823'
2023-06-22 22:09:08,629 - distributed.nanny - INFO -         Start Nanny at: 'tcp://10.33.227.169:34067'
2023-06-22 22:09:10,018 - distributed.preloading - INFO - Creating preload: dask_cuda.initialize
2023-06-22 22:09:10,018 - distributed.preloading - INFO - Import preload module: dask_cuda.initialize
2023-06-22 22:09:10,153 - distributed.preloading - INFO - Creating preload: dask_cuda.initialize
2023-06-22 22:09:10,153 - distributed.preloading - INFO - Import preload module: dask_cuda.initialize
2023-06-22 22:09:10,162 - distributed.preloading - INFO - Creating preload: dask_cuda.initialize
2023-06-22 22:09:10,162 - distributed.preloading - INFO - Import preload module: dask_cuda.initialize
2023-06-22 22:09:10,164 - distributed.preloading - INFO - Creating preload: dask_cuda.initialize
2023-06-22 22:09:10,164 - distributed.preloading - INFO - Import preload module: dask_cuda.initialize
2023-06-22 22:09:10,164 - distributed.preloading - INFO - Creating preload: dask_cuda.initialize
2023-06-22 22:09:10,165 - distributed.preloading - INFO - Creating preload: dask_cuda.initialize
2023-06-22 22:09:10,165 - distributed.preloading - INFO - Import preload module: dask_cuda.initialize
2023-06-22 22:09:10,165 - distributed.preloading - INFO - Import preload module: dask_cuda.initialize
2023-06-22 22:09:10,165 - distributed.preloading - INFO - Creating preload: dask_cuda.initialize
2023-06-22 22:09:10,165 - distributed.preloading - INFO - Import preload module: dask_cuda.initialize
2023-06-22 22:09:10,174 - distributed.preloading - INFO - Creating preload: dask_cuda.initialize
2023-06-22 22:09:10,174 - distributed.preloading - INFO - Import preload module: dask_cuda.initialize
2023-06-22 22:09:10,431 - distributed.preloading - INFO - Run preload setup: dask_cuda.initialize
2023-06-22 22:09:10,599 - distributed.preloading - INFO - Run preload setup: dask_cuda.initialize
2023-06-22 22:09:10,609 - distributed.preloading - INFO - Run preload setup: dask_cuda.initialize
2023-06-22 22:09:10,615 - distributed.preloading - INFO - Run preload setup: dask_cuda.initialize
2023-06-22 22:09:10,616 - distributed.preloading - INFO - Run preload setup: dask_cuda.initialize
2023-06-22 22:09:10,617 - distributed.preloading - INFO - Run preload setup: dask_cuda.initialize
2023-06-22 22:09:10,627 - distributed.preloading - INFO - Run preload setup: dask_cuda.initialize
2023-06-22 22:09:10,628 - distributed.preloading - INFO - Run preload setup: dask_cuda.initialize
2023-06-22 22:09:12,959 - distributed.worker - INFO -       Start worker at:  tcp://10.33.227.169:35123
2023-06-22 22:09:12,960 - distributed.worker - INFO -          Listening to:  tcp://10.33.227.169:35123
2023-06-22 22:09:12,960 - distributed.worker - INFO -          dashboard at:        10.33.227.169:34163
2023-06-22 22:09:12,960 - distributed.worker - INFO - Waiting to connect to:   tcp://10.33.227.169:8786
2023-06-22 22:09:12,960 - distributed.worker - INFO - -------------------------------------------------
2023-06-22 22:09:12,960 - distributed.worker - INFO -               Threads:                          1
2023-06-22 22:09:12,960 - distributed.worker - INFO -                Memory:                  62.97 GiB
2023-06-22 22:09:12,960 - distributed.worker - INFO -       Local Directory: /tmp/dask-scratch-space/worker-5tym5nu6
2023-06-22 22:09:12,961 - distributed.worker - INFO - Starting Worker plugin RMMSetup-dbd3083e-9318-40c2-9f50-f5f7906859f7
2023-06-22 22:09:13,057 - distributed.worker - INFO -       Start worker at:  tcp://10.33.227.169:37101
2023-06-22 22:09:13,057 - distributed.worker - INFO -          Listening to:  tcp://10.33.227.169:37101
2023-06-22 22:09:13,057 - distributed.worker - INFO -          dashboard at:        10.33.227.169:36629
2023-06-22 22:09:13,057 - distributed.worker - INFO - Waiting to connect to:   tcp://10.33.227.169:8786
2023-06-22 22:09:13,057 - distributed.worker - INFO - -------------------------------------------------
2023-06-22 22:09:13,057 - distributed.worker - INFO -               Threads:                          1
2023-06-22 22:09:13,057 - distributed.worker - INFO -                Memory:                  62.97 GiB
2023-06-22 22:09:13,057 - distributed.worker - INFO -       Local Directory: /tmp/dask-scratch-space/worker-cpzf6iq8
2023-06-22 22:09:13,058 - distributed.worker - INFO - Starting Worker plugin RMMSetup-7f7929cf-4ff6-4017-8b6d-6c5cdef1ce54
2023-06-22 22:09:13,065 - distributed.worker - INFO -       Start worker at:  tcp://10.33.227.169:43727
2023-06-22 22:09:13,065 - distributed.worker - INFO -          Listening to:  tcp://10.33.227.169:43727
2023-06-22 22:09:13,065 - distributed.worker - INFO -          dashboard at:        10.33.227.169:43991
2023-06-22 22:09:13,065 - distributed.worker - INFO - Waiting to connect to:   tcp://10.33.227.169:8786
2023-06-22 22:09:13,065 - distributed.worker - INFO - -------------------------------------------------
2023-06-22 22:09:13,065 - distributed.worker - INFO -               Threads:                          1
2023-06-22 22:09:13,065 - distributed.worker - INFO -                Memory:                  62.97 GiB
2023-06-22 22:09:13,065 - distributed.worker - INFO -       Local Directory: /tmp/dask-scratch-space/worker-wb2c_1xm
2023-06-22 22:09:13,066 - distributed.worker - INFO - Starting Worker plugin PreImport-1d5c5530-0eea-4d64-9048-0fc785676b11
2023-06-22 22:09:13,066 - distributed.worker - INFO - Starting Worker plugin CPUAffinity-13cc8868-e60b-4ad2-b306-757fb8a17da6
2023-06-22 22:09:13,066 - distributed.worker - INFO - Starting Worker plugin RMMSetup-bdfa30a7-f627-4e34-aa57-b7cb9b64030f
2023-06-22 22:09:13,073 - distributed.worker - INFO -       Start worker at:  tcp://10.33.227.169:34817
2023-06-22 22:09:13,074 - distributed.worker - INFO -          Listening to:  tcp://10.33.227.169:34817
2023-06-22 22:09:13,074 - distributed.worker - INFO -          dashboard at:        10.33.227.169:44165
2023-06-22 22:09:13,074 - distributed.worker - INFO - Waiting to connect to:   tcp://10.33.227.169:8786
2023-06-22 22:09:13,074 - distributed.worker - INFO - -------------------------------------------------
2023-06-22 22:09:13,074 - distributed.worker - INFO -               Threads:                          1
2023-06-22 22:09:13,074 - distributed.worker - INFO -                Memory:                  62.97 GiB
2023-06-22 22:09:13,074 - distributed.worker - INFO -       Local Directory: /tmp/dask-scratch-space/worker-kvn65zjt
2023-06-22 22:09:13,074 - distributed.worker - INFO - Starting Worker plugin PreImport-b4550072-8bda-4c28-889c-ca095d2163cc
2023-06-22 22:09:13,074 - distributed.worker - INFO - Starting Worker plugin CPUAffinity-31050fc1-64f0-44dc-9700-dc84e66fe65b
2023-06-22 22:09:13,075 - distributed.worker - INFO - Starting Worker plugin RMMSetup-53cddab8-382e-4fc6-8568-2b295ea6a90f
2023-06-22 22:09:13,086 - distributed.worker - INFO - Starting Worker plugin CPUAffinity-6345ecf7-b319-46fd-897b-c87d23e8da8d
2023-06-22 22:09:13,087 - distributed.worker - INFO - Starting Worker plugin PreImport-d2c0cd83-5fa7-4fdb-a312-731a97ef63e3
2023-06-22 22:09:13,088 - distributed.worker - INFO - -------------------------------------------------
2023-06-22 22:09:13,088 - distributed.worker - INFO -       Start worker at:  tcp://10.33.227.169:46551
2023-06-22 22:09:13,088 - distributed.worker - INFO -          Listening to:  tcp://10.33.227.169:46551
2023-06-22 22:09:13,088 - distributed.worker - INFO -          dashboard at:        10.33.227.169:46501
2023-06-22 22:09:13,088 - distributed.worker - INFO - Waiting to connect to:   tcp://10.33.227.169:8786
2023-06-22 22:09:13,088 - distributed.worker - INFO - -------------------------------------------------
2023-06-22 22:09:13,088 - distributed.worker - INFO -               Threads:                          1
2023-06-22 22:09:13,088 - distributed.worker - INFO -                Memory:                  62.97 GiB
2023-06-22 22:09:13,088 - distributed.worker - INFO -       Local Directory: /tmp/dask-scratch-space/worker-5gu74rc4
2023-06-22 22:09:13,089 - distributed.worker - INFO - Starting Worker plugin PreImport-c9804ddc-4c0d-489d-a15b-73c7572e4c11
2023-06-22 22:09:13,089 - distributed.worker - INFO - Starting Worker plugin CPUAffinity-1f9fbb7a-cafe-4c78-9ae2-2954ab1e8caa
2023-06-22 22:09:13,090 - distributed.worker - INFO - Starting Worker plugin RMMSetup-4b7e0801-0366-4c64-8596-e90528cd165f
2023-06-22 22:09:13,105 - distributed.worker - INFO -         Registered to:   tcp://10.33.227.169:8786
2023-06-22 22:09:13,105 - distributed.worker - INFO - -------------------------------------------------
2023-06-22 22:09:13,106 - distributed.core - INFO - Starting established connection to tcp://10.33.227.169:8786
2023-06-22 22:09:13,108 - distributed.worker - INFO -       Start worker at:  tcp://10.33.227.169:43173
2023-06-22 22:09:13,109 - distributed.worker - INFO -          Listening to:  tcp://10.33.227.169:43173
2023-06-22 22:09:13,108 - distributed.worker - INFO -       Start worker at:  tcp://10.33.227.169:35351
2023-06-22 22:09:13,109 - distributed.worker - INFO -          dashboard at:        10.33.227.169:34615
2023-06-22 22:09:13,109 - distributed.worker - INFO -          Listening to:  tcp://10.33.227.169:35351
2023-06-22 22:09:13,109 - distributed.worker - INFO - Waiting to connect to:   tcp://10.33.227.169:8786
2023-06-22 22:09:13,109 - distributed.worker - INFO -          dashboard at:        10.33.227.169:42959
2023-06-22 22:09:13,109 - distributed.worker - INFO - -------------------------------------------------
2023-06-22 22:09:13,109 - distributed.worker - INFO - Waiting to connect to:   tcp://10.33.227.169:8786
2023-06-22 22:09:13,109 - distributed.worker - INFO -               Threads:                          1
2023-06-22 22:09:13,109 - distributed.worker - INFO - -------------------------------------------------
2023-06-22 22:09:13,109 - distributed.worker - INFO -                Memory:                  62.97 GiB
2023-06-22 22:09:13,109 - distributed.worker - INFO -               Threads:                          1
2023-06-22 22:09:13,109 - distributed.worker - INFO -       Local Directory: /tmp/dask-scratch-space/worker-w8658x_9
2023-06-22 22:09:13,109 - distributed.worker - INFO -                Memory:                  62.97 GiB
2023-06-22 22:09:13,109 - distributed.worker - INFO -       Local Directory: /tmp/dask-scratch-space/worker-4sj39czg
2023-06-22 22:09:13,109 - distributed.worker - INFO - Starting Worker plugin RMMSetup-733a89db-2b1d-471d-8604-8c0edf8f661f
2023-06-22 22:09:13,109 - distributed.worker - INFO - Starting Worker plugin PreImport-9e6b71bc-71b4-4071-a5c5-0462bc99f316
2023-06-22 22:09:13,109 - distributed.worker - INFO - Starting Worker plugin CPUAffinity-e480898d-5a29-4329-ab30-a22a6b72bebf
2023-06-22 22:09:13,109 - distributed.worker - INFO - Starting Worker plugin RMMSetup-77cef2d7-5729-40ba-aeab-f790e884ecf4
2023-06-22 22:09:13,113 - distributed.worker - INFO -       Start worker at:  tcp://10.33.227.169:39823
2023-06-22 22:09:13,113 - distributed.worker - INFO -          Listening to:  tcp://10.33.227.169:39823
2023-06-22 22:09:13,114 - distributed.worker - INFO -          dashboard at:        10.33.227.169:34191
2023-06-22 22:09:13,114 - distributed.worker - INFO - Waiting to connect to:   tcp://10.33.227.169:8786
2023-06-22 22:09:13,114 - distributed.worker - INFO - -------------------------------------------------
2023-06-22 22:09:13,114 - distributed.worker - INFO -               Threads:                          1
2023-06-22 22:09:13,114 - distributed.worker - INFO -                Memory:                  62.97 GiB
2023-06-22 22:09:13,114 - distributed.worker - INFO -       Local Directory: /tmp/dask-scratch-space/worker-9eakjdu_
2023-06-22 22:09:13,115 - distributed.worker - INFO - Starting Worker plugin PreImport-12979dd8-d324-4693-8322-84aa45eddd2f
2023-06-22 22:09:13,115 - distributed.worker - INFO - Starting Worker plugin CPUAffinity-1b40d332-58e1-4cd9-acf6-c4d72c467bbf
2023-06-22 22:09:13,115 - distributed.worker - INFO - Starting Worker plugin RMMSetup-6181fa58-5f66-4686-bc19-4a09d43d0201
2023-06-22 22:09:13,261 - distributed.worker - INFO - Starting Worker plugin PreImport-ed7c892c-23a6-4dd7-b9ae-96100c87ba01
2023-06-22 22:09:13,261 - distributed.worker - INFO - -------------------------------------------------
2023-06-22 22:09:13,261 - distributed.worker - INFO - Starting Worker plugin CPUAffinity-7e13a7d1-a1aa-48c6-ae7b-1d2316dee793
2023-06-22 22:09:13,262 - distributed.worker - INFO - -------------------------------------------------
2023-06-22 22:09:13,262 - distributed.worker - INFO - -------------------------------------------------
2023-06-22 22:09:13,263 - distributed.worker - INFO - -------------------------------------------------
2023-06-22 22:09:13,272 - distributed.worker - INFO -         Registered to:   tcp://10.33.227.169:8786
2023-06-22 22:09:13,272 - distributed.worker - INFO - -------------------------------------------------
2023-06-22 22:09:13,273 - distributed.core - INFO - Starting established connection to tcp://10.33.227.169:8786
2023-06-22 22:09:13,274 - distributed.worker - INFO -         Registered to:   tcp://10.33.227.169:8786
2023-06-22 22:09:13,274 - distributed.worker - INFO - -------------------------------------------------
2023-06-22 22:09:13,276 - distributed.core - INFO - Starting established connection to tcp://10.33.227.169:8786
2023-06-22 22:09:13,276 - distributed.worker - INFO -         Registered to:   tcp://10.33.227.169:8786
2023-06-22 22:09:13,277 - distributed.worker - INFO - -------------------------------------------------
2023-06-22 22:09:13,277 - distributed.worker - INFO -         Registered to:   tcp://10.33.227.169:8786
2023-06-22 22:09:13,277 - distributed.worker - INFO - -------------------------------------------------
2023-06-22 22:09:13,279 - distributed.core - INFO - Starting established connection to tcp://10.33.227.169:8786
2023-06-22 22:09:13,280 - distributed.core - INFO - Starting established connection to tcp://10.33.227.169:8786
2023-06-22 22:09:13,309 - distributed.worker - INFO - Starting Worker plugin PreImport-7e2c0121-085d-49a4-827e-09a6ade91f60
2023-06-22 22:09:13,309 - distributed.worker - INFO - Starting Worker plugin CPUAffinity-572d11b3-4464-4f4b-99c2-923819eebdd9
2023-06-22 22:09:13,309 - distributed.worker - INFO - -------------------------------------------------
2023-06-22 22:09:13,310 - distributed.worker - INFO - -------------------------------------------------
2023-06-22 22:09:13,310 - distributed.worker - INFO - -------------------------------------------------
2023-06-22 22:09:13,318 - distributed.worker - INFO -         Registered to:   tcp://10.33.227.169:8786
2023-06-22 22:09:13,319 - distributed.worker - INFO - -------------------------------------------------
2023-06-22 22:09:13,319 - distributed.worker - INFO -         Registered to:   tcp://10.33.227.169:8786
2023-06-22 22:09:13,320 - distributed.worker - INFO - -------------------------------------------------
2023-06-22 22:09:13,320 - distributed.core - INFO - Starting established connection to tcp://10.33.227.169:8786
2023-06-22 22:09:13,320 - distributed.worker - INFO -         Registered to:   tcp://10.33.227.169:8786
2023-06-22 22:09:13,320 - distributed.worker - INFO - -------------------------------------------------
2023-06-22 22:09:13,321 - distributed.core - INFO - Starting established connection to tcp://10.33.227.169:8786
2023-06-22 22:09:13,322 - distributed.core - INFO - Starting established connection to tcp://10.33.227.169:8786
2023-06-22 22:09:19,637 - distributed.worker - INFO - Run out-of-band function '_func_ucp_listener_port'
2023-06-22 22:09:19,637 - distributed.worker - INFO - Run out-of-band function '_func_ucp_listener_port'
2023-06-22 22:09:19,637 - distributed.worker - INFO - Run out-of-band function '_func_ucp_listener_port'
2023-06-22 22:09:19,637 - distributed.worker - INFO - Run out-of-band function '_func_ucp_listener_port'
2023-06-22 22:09:19,637 - distributed.worker - INFO - Run out-of-band function '_func_ucp_listener_port'
2023-06-22 22:09:19,637 - distributed.worker - INFO - Run out-of-band function '_func_ucp_listener_port'
2023-06-22 22:09:19,637 - distributed.worker - INFO - Run out-of-band function '_func_ucp_listener_port'
2023-06-22 22:09:19,640 - distributed.worker - INFO - Run out-of-band function '_func_ucp_listener_port'
2023-06-22 22:09:19,733 - distributed.worker - INFO - Run out-of-band function '_func_init_all'
2023-06-22 22:09:19,733 - distributed.worker - INFO - Run out-of-band function '_func_init_all'
2023-06-22 22:09:19,733 - distributed.worker - INFO - Run out-of-band function '_func_init_all'
2023-06-22 22:09:19,734 - distributed.worker - INFO - Run out-of-band function '_func_init_all'
2023-06-22 22:09:19,734 - distributed.worker - INFO - Run out-of-band function '_func_init_all'
2023-06-22 22:09:19,734 - distributed.worker - INFO - Run out-of-band function '_func_init_all'
2023-06-22 22:09:19,734 - distributed.worker - INFO - Run out-of-band function '_func_init_all'
2023-06-22 22:09:19,734 - distributed.worker - INFO - Run out-of-band function '_func_init_all'
2023-06-22 22:09:30,806 - distributed.worker - INFO - Run out-of-band function '_subcomm_init'
2023-06-22 22:09:30,814 - distributed.worker - INFO - Run out-of-band function '_subcomm_init'
2023-06-22 22:09:30,860 - distributed.worker - INFO - Run out-of-band function '_subcomm_init'
2023-06-22 22:09:30,875 - distributed.worker - INFO - Run out-of-band function '_subcomm_init'
2023-06-22 22:09:31,054 - distributed.worker - INFO - Run out-of-band function '_subcomm_init'
2023-06-22 22:09:31,064 - distributed.worker - INFO - Run out-of-band function '_subcomm_init'
2023-06-22 22:09:31,175 - distributed.worker - INFO - Run out-of-band function '_subcomm_init'
2023-06-22 22:09:31,304 - distributed.worker - INFO - Run out-of-band function '_subcomm_init'
2023-06-22 22:09:37,525 - distributed.core - INFO - Event loop was unresponsive in Worker for 16.26s.  This is often caused by long-running GIL-holding functions or moving large chunks of data. This can cause timeouts and instability.
2023-06-22 22:09:37,526 - distributed.core - INFO - Event loop was unresponsive in Worker for 16.27s.  This is often caused by long-running GIL-holding functions or moving large chunks of data. This can cause timeouts and instability.
2023-06-22 22:09:37,526 - distributed.core - INFO - Event loop was unresponsive in Worker for 16.25s.  This is often caused by long-running GIL-holding functions or moving large chunks of data. This can cause timeouts and instability.
2023-06-22 22:09:37,526 - distributed.core - INFO - Event loop was unresponsive in Worker for 16.27s.  This is often caused by long-running GIL-holding functions or moving large chunks of data. This can cause timeouts and instability.
2023-06-22 22:09:37,614 - distributed.core - INFO - Event loop was unresponsive in Worker for 16.35s.  This is often caused by long-running GIL-holding functions or moving large chunks of data. This can cause timeouts and instability.
2023-06-22 22:09:37,614 - distributed.core - INFO - Event loop was unresponsive in Worker for 16.34s.  This is often caused by long-running GIL-holding functions or moving large chunks of data. This can cause timeouts and instability.
2023-06-22 22:09:37,616 - distributed.core - INFO - Event loop was unresponsive in Worker for 16.36s.  This is often caused by long-running GIL-holding functions or moving large chunks of data. This can cause timeouts and instability.
2023-06-22 22:09:37,617 - distributed.core - INFO - Event loop was unresponsive in Worker for 16.35s.  This is often caused by long-running GIL-holding functions or moving large chunks of data. This can cause timeouts and instability.
2023-06-22 22:10:12,796 - distributed.worker - INFO - Run out-of-band function 'collect'
2023-06-22 22:10:12,796 - distributed.worker - INFO - Run out-of-band function 'collect'
2023-06-22 22:10:12,801 - distributed.worker - INFO - Run out-of-band function 'collect'
2023-06-22 22:10:12,801 - distributed.worker - INFO - Run out-of-band function 'collect'
2023-06-22 22:10:12,801 - distributed.worker - INFO - Run out-of-band function 'collect'
2023-06-22 22:10:12,801 - distributed.worker - INFO - Run out-of-band function 'collect'
2023-06-22 22:10:12,802 - distributed.worker - INFO - Run out-of-band function 'collect'
2023-06-22 22:10:12,802 - distributed.worker - INFO - Run out-of-band function 'collect'
2023-06-22 22:12:43,269 - distributed.worker - INFO - Stopping worker at tcp://10.33.227.169:35351. Reason: worker-close
2023-06-22 22:12:43,270 - distributed.worker - INFO - Stopping worker at tcp://10.33.227.169:37101. Reason: worker-handle-scheduler-connection-broken
2023-06-22 22:12:43,270 - distributed.worker - INFO - Stopping worker at tcp://10.33.227.169:39823. Reason: worker-close
2023-06-22 22:12:43,270 - distributed.worker - INFO - Stopping worker at tcp://10.33.227.169:43727. Reason: worker-handle-scheduler-connection-broken
2023-06-22 22:12:43,270 - distributed.worker - INFO - Stopping worker at tcp://10.33.227.169:35123. Reason: worker-handle-scheduler-connection-broken
2023-06-22 22:12:43,270 - distributed.worker - INFO - Stopping worker at tcp://10.33.227.169:34817. Reason: worker-close
2023-06-22 22:12:43,270 - distributed.worker - INFO - Stopping worker at tcp://10.33.227.169:43173. Reason: worker-handle-scheduler-connection-broken
2023-06-22 22:12:43,270 - distributed.worker - INFO - Stopping worker at tcp://10.33.227.169:46551. Reason: worker-close
2023-06-22 22:12:43,271 - distributed.nanny - INFO - Closing Nanny at 'tcp://10.33.227.169:39335'. Reason: nanny-close
2023-06-22 22:12:43,272 - distributed.batched - INFO - Batched Comm Closed <TCP (closed) Worker->Scheduler local=tcp://10.33.227.169:44622 remote=tcp://10.33.227.169:8786>
Traceback (most recent call last):
  File "/opt/conda/envs/rapids/lib/python3.10/asyncio/runners.py", line 44, in run
    return loop.run_until_complete(main)
  File "/opt/conda/envs/rapids/lib/python3.10/asyncio/base_events.py", line 636, in run_until_complete
    self.run_forever()
  File "/opt/conda/envs/rapids/lib/python3.10/asyncio/base_events.py", line 603, in run_forever
    self._run_once()
  File "/opt/conda/envs/rapids/lib/python3.10/asyncio/base_events.py", line 1871, in _run_once
    event_list = self._selector.select(timeout)
  File "/opt/conda/envs/rapids/lib/python3.10/selectors.py", line 469, in select
    fd_event_list = self._selector.poll(timeout, max_ev)
KeyboardInterrupt

During handling of the above exception, another exception occurred:

Traceback (most recent call last):
  File "/opt/conda/envs/rapids/lib/python3.10/site-packages/distributed/batched.py", line 115, in _background_send
    nbytes = yield coro
  File "/opt/conda/envs/rapids/lib/python3.10/site-packages/tornado/gen.py", line 767, in run
    value = future.result()
  File "/opt/conda/envs/rapids/lib/python3.10/site-packages/distributed/comm/tcp.py", line 269, in write
    raise CommClosedError()
distributed.comm.core.CommClosedError
2023-06-22 22:12:43,273 - distributed.nanny - INFO - Nanny asking worker to close. Reason: nanny-close
2023-06-22 22:12:43,272 - distributed.batched - INFO - Batched Comm Closed <TCP (closed) Worker->Scheduler local=tcp://10.33.227.169:44592 remote=tcp://10.33.227.169:8786>
Traceback (most recent call last):
  File "/opt/conda/envs/rapids/lib/python3.10/asyncio/runners.py", line 44, in run
    return loop.run_until_complete(main)
  File "/opt/conda/envs/rapids/lib/python3.10/asyncio/base_events.py", line 636, in run_until_complete
    self.run_forever()
  File "/opt/conda/envs/rapids/lib/python3.10/asyncio/base_events.py", line 603, in run_forever
    self._run_once()
  File "/opt/conda/envs/rapids/lib/python3.10/asyncio/base_events.py", line 1871, in _run_once
    event_list = self._selector.select(timeout)
  File "/opt/conda/envs/rapids/lib/python3.10/selectors.py", line 469, in select
    fd_event_list = self._selector.poll(timeout, max_ev)
KeyboardInterrupt

During handling of the above exception, another exception occurred:

Traceback (most recent call last):
  File "/opt/conda/envs/rapids/lib/python3.10/site-packages/distributed/batched.py", line 115, in _background_send
    nbytes = yield coro
  File "/opt/conda/envs/rapids/lib/python3.10/site-packages/tornado/gen.py", line 767, in run
    value = future.result()
  File "/opt/conda/envs/rapids/lib/python3.10/site-packages/distributed/comm/tcp.py", line 269, in write
    raise CommClosedError()
distributed.comm.core.CommClosedError
2023-06-22 22:12:43,275 - distributed.nanny - INFO - Closing Nanny at 'tcp://10.33.227.169:41251'. Reason: nanny-close
2023-06-22 22:12:43,273 - distributed.batched - INFO - Batched Comm Closed <TCP (closed) Worker->Scheduler local=tcp://10.33.227.169:44566 remote=tcp://10.33.227.169:8786>
Traceback (most recent call last):
  File "/opt/conda/envs/rapids/lib/python3.10/asyncio/runners.py", line 44, in run
    return loop.run_until_complete(main)
  File "/opt/conda/envs/rapids/lib/python3.10/asyncio/base_events.py", line 636, in run_until_complete
    self.run_forever()
  File "/opt/conda/envs/rapids/lib/python3.10/asyncio/base_events.py", line 603, in run_forever
    self._run_once()
  File "/opt/conda/envs/rapids/lib/python3.10/asyncio/base_events.py", line 1871, in _run_once
    event_list = self._selector.select(timeout)
  File "/opt/conda/envs/rapids/lib/python3.10/selectors.py", line 469, in select
    fd_event_list = self._selector.poll(timeout, max_ev)
KeyboardInterrupt

During handling of the above exception, another exception occurred:

Traceback (most recent call last):
  File "/opt/conda/envs/rapids/lib/python3.10/site-packages/distributed/batched.py", line 115, in _background_send
    nbytes = yield coro
  File "/opt/conda/envs/rapids/lib/python3.10/site-packages/tornado/gen.py", line 767, in run
    value = future.result()
  File "/opt/conda/envs/rapids/lib/python3.10/site-packages/distributed/comm/tcp.py", line 269, in write
    raise CommClosedError()
distributed.comm.core.CommClosedError
2023-06-22 22:12:43,276 - distributed.nanny - INFO - Nanny asking worker to close. Reason: nanny-close
2023-06-22 22:12:43,274 - distributed.batched - INFO - Batched Comm Closed <TCP (closed) Worker->Scheduler local=tcp://10.33.227.169:44564 remote=tcp://10.33.227.169:8786>
Traceback (most recent call last):
  File "/opt/conda/envs/rapids/lib/python3.10/asyncio/runners.py", line 44, in run
    return loop.run_until_complete(main)
  File "/opt/conda/envs/rapids/lib/python3.10/asyncio/base_events.py", line 636, in run_until_complete
    self.run_forever()
  File "/opt/conda/envs/rapids/lib/python3.10/asyncio/base_events.py", line 603, in run_forever
    self._run_once()
  File "/opt/conda/envs/rapids/lib/python3.10/asyncio/base_events.py", line 1871, in _run_once
    event_list = self._selector.select(timeout)
  File "/opt/conda/envs/rapids/lib/python3.10/selectors.py", line 469, in select
    fd_event_list = self._selector.poll(timeout, max_ev)
KeyboardInterrupt

During handling of the above exception, another exception occurred:

Traceback (most recent call last):
  File "/opt/conda/envs/rapids/lib/python3.10/site-packages/distributed/batched.py", line 115, in _background_send
    nbytes = yield coro
  File "/opt/conda/envs/rapids/lib/python3.10/site-packages/tornado/gen.py", line 767, in run
    value = future.result()
  File "/opt/conda/envs/rapids/lib/python3.10/site-packages/distributed/comm/tcp.py", line 269, in write
    raise CommClosedError()
distributed.comm.core.CommClosedError
2023-06-22 22:12:43,277 - distributed.nanny - INFO - Closing Nanny at 'tcp://10.33.227.169:39355'. Reason: nanny-close
2023-06-22 22:12:43,277 - distributed.nanny - INFO - Nanny asking worker to close. Reason: nanny-close
2023-06-22 22:12:43,277 - distributed.nanny - INFO - Closing Nanny at 'tcp://10.33.227.169:43471'. Reason: nanny-close
2023-06-22 22:12:43,278 - distributed.nanny - INFO - Nanny asking worker to close. Reason: nanny-close
2023-06-22 22:12:43,278 - distributed.nanny - INFO - Closing Nanny at 'tcp://10.33.227.169:35931'. Reason: nanny-close
2023-06-22 22:12:43,279 - distributed.nanny - INFO - Nanny asking worker to close. Reason: nanny-close
2023-06-22 22:12:43,279 - distributed.nanny - INFO - Closing Nanny at 'tcp://10.33.227.169:45453'. Reason: nanny-close
2023-06-22 22:12:43,280 - distributed.nanny - INFO - Nanny asking worker to close. Reason: nanny-close
2023-06-22 22:12:43,280 - distributed.nanny - INFO - Closing Nanny at 'tcp://10.33.227.169:41823'. Reason: nanny-close
2023-06-22 22:12:43,281 - distributed.nanny - INFO - Nanny asking worker to close. Reason: nanny-close
2023-06-22 22:12:43,282 - distributed.nanny - INFO - Closing Nanny at 'tcp://10.33.227.169:34067'. Reason: nanny-close
2023-06-22 22:12:43,282 - distributed.nanny - INFO - Nanny asking worker to close. Reason: nanny-close
2023-06-22 22:12:43,293 - distributed.core - ERROR - Timed out during handshake while connecting to tcp://10.33.227.169:39355 after 100 s
Traceback (most recent call last):
  File "/opt/conda/envs/rapids/lib/python3.10/asyncio/runners.py", line 44, in run
    return loop.run_until_complete(main)
  File "/opt/conda/envs/rapids/lib/python3.10/asyncio/base_events.py", line 636, in run_until_complete
    self.run_forever()
  File "/opt/conda/envs/rapids/lib/python3.10/asyncio/base_events.py", line 603, in run_forever
    self._run_once()
  File "/opt/conda/envs/rapids/lib/python3.10/asyncio/base_events.py", line 1871, in _run_once
    event_list = self._selector.select(timeout)
  File "/opt/conda/envs/rapids/lib/python3.10/selectors.py", line 469, in select
    fd_event_list = self._selector.poll(timeout, max_ev)
KeyboardInterrupt

During handling of the above exception, another exception occurred:

Traceback (most recent call last):
  File "/opt/conda/envs/rapids/lib/python3.10/site-packages/tornado/iostream.py", line 861, in _read_to_buffer
    bytes_read = self.read_from_fd(buf)
  File "/opt/conda/envs/rapids/lib/python3.10/site-packages/tornado/iostream.py", line 1116, in read_from_fd
    return self.socket.recv_into(buf, len(buf))
ConnectionResetError: [Errno 104] Connection reset by peer

The above exception was the direct cause of the following exception:

Traceback (most recent call last):
  File "/opt/conda/envs/rapids/lib/python3.10/site-packages/distributed/comm/core.py", line 373, in connect
    handshake = await wait_for(comm.read(), time_left())
  File "/opt/conda/envs/rapids/lib/python3.10/site-packages/distributed/utils.py", line 1878, in wait_for
    return await asyncio.wait_for(fut, timeout)
  File "/opt/conda/envs/rapids/lib/python3.10/asyncio/tasks.py", line 445, in wait_for
    return fut.result()
  File "/opt/conda/envs/rapids/lib/python3.10/site-packages/distributed/comm/tcp.py", line 241, in read
    convert_stream_closed_error(self, e)
  File "/opt/conda/envs/rapids/lib/python3.10/site-packages/distributed/comm/tcp.py", line 142, in convert_stream_closed_error
    raise CommClosedError(f"in {obj}: {exc.__class__.__name__}: {exc}") from exc
distributed.comm.core.CommClosedError: in <TCP (closed)  local=tcp://10.33.227.169:41084 remote=tcp://10.33.227.169:39355>: ConnectionResetError: [Errno 104] Connection reset by peer

The above exception was the direct cause of the following exception:

Traceback (most recent call last):
  File "/opt/conda/envs/rapids/lib/python3.10/site-packages/distributed/utils.py", line 754, in wrapper
    return await func(*args, **kwargs)
  File "/opt/conda/envs/rapids/lib/python3.10/site-packages/distributed/worker.py", line 1540, in close
    await r.close_gracefully(reason=reason)
  File "/opt/conda/envs/rapids/lib/python3.10/site-packages/distributed/core.py", line 1362, in send_recv_from_rpc
    comm = await self.pool.connect(self.addr)
  File "/opt/conda/envs/rapids/lib/python3.10/site-packages/distributed/core.py", line 1606, in connect
    return await connect_attempt
  File "/opt/conda/envs/rapids/lib/python3.10/site-packages/distributed/core.py", line 1527, in _connect
    comm = await connect(
  File "/opt/conda/envs/rapids/lib/python3.10/site-packages/distributed/comm/core.py", line 378, in connect
    raise OSError(
OSError: Timed out during handshake while connecting to tcp://10.33.227.169:39355 after 100 s
2023-06-22 22:12:43,294 - distributed.worker - ERROR - Timed out during handshake while connecting to tcp://10.33.227.169:39335 after 100 s
Traceback (most recent call last):
  File "/opt/conda/envs/rapids/lib/python3.10/asyncio/runners.py", line 44, in run
    return loop.run_until_complete(main)
  File "/opt/conda/envs/rapids/lib/python3.10/asyncio/base_events.py", line 636, in run_until_complete
    self.run_forever()
  File "/opt/conda/envs/rapids/lib/python3.10/asyncio/base_events.py", line 603, in run_forever
    self._run_once()
  File "/opt/conda/envs/rapids/lib/python3.10/asyncio/base_events.py", line 1871, in _run_once
    event_list = self._selector.select(timeout)
  File "/opt/conda/envs/rapids/lib/python3.10/selectors.py", line 469, in select
    fd_event_list = self._selector.poll(timeout, max_ev)
KeyboardInterrupt

During handling of the above exception, another exception occurred:

Traceback (most recent call last):
  File "/opt/conda/envs/rapids/lib/python3.10/site-packages/tornado/iostream.py", line 861, in _read_to_buffer
    bytes_read = self.read_from_fd(buf)
  File "/opt/conda/envs/rapids/lib/python3.10/site-packages/tornado/iostream.py", line 1116, in read_from_fd
    return self.socket.recv_into(buf, len(buf))
ConnectionResetError: [Errno 104] Connection reset by peer

The above exception was the direct cause of the following exception:

Traceback (most recent call last):
  File "/opt/conda/envs/rapids/lib/python3.10/site-packages/distributed/comm/core.py", line 373, in connect
    handshake = await wait_for(comm.read(), time_left())
  File "/opt/conda/envs/rapids/lib/python3.10/site-packages/distributed/utils.py", line 1878, in wait_for
    return await asyncio.wait_for(fut, timeout)
  File "/opt/conda/envs/rapids/lib/python3.10/asyncio/tasks.py", line 445, in wait_for
    return fut.result()
  File "/opt/conda/envs/rapids/lib/python3.10/site-packages/distributed/comm/tcp.py", line 241, in read
    convert_stream_closed_error(self, e)
  File "/opt/conda/envs/rapids/lib/python3.10/site-packages/distributed/comm/tcp.py", line 142, in convert_stream_closed_error
    raise CommClosedError(f"in {obj}: {exc.__class__.__name__}: {exc}") from exc
distributed.comm.core.CommClosedError: in <TCP (closed)  local=tcp://10.33.227.169:40530 remote=tcp://10.33.227.169:39335>: ConnectionResetError: [Errno 104] Connection reset by peer

The above exception was the direct cause of the following exception:

Traceback (most recent call last):
  File "/opt/conda/envs/rapids/lib/python3.10/site-packages/distributed/utils.py", line 754, in wrapper
    return await func(*args, **kwargs)
  File "/opt/conda/envs/rapids/lib/python3.10/site-packages/distributed/worker.py", line 1540, in close
    await r.close_gracefully(reason=reason)
  File "/opt/conda/envs/rapids/lib/python3.10/site-packages/distributed/core.py", line 1362, in send_recv_from_rpc
    comm = await self.pool.connect(self.addr)
  File "/opt/conda/envs/rapids/lib/python3.10/site-packages/distributed/core.py", line 1606, in connect
    return await connect_attempt
  File "/opt/conda/envs/rapids/lib/python3.10/site-packages/distributed/core.py", line 1527, in _connect
    comm = await connect(
  File "/opt/conda/envs/rapids/lib/python3.10/site-packages/distributed/comm/core.py", line 378, in connect
    raise OSError(
OSError: Timed out during handshake while connecting to tcp://10.33.227.169:39335 after 100 s
2023-06-22 22:12:43,294 - distributed.worker - ERROR - Timed out during handshake while connecting to tcp://10.33.227.169:41251 after 100 s
Traceback (most recent call last):
  File "/opt/conda/envs/rapids/lib/python3.10/asyncio/runners.py", line 44, in run
    return loop.run_until_complete(main)
  File "/opt/conda/envs/rapids/lib/python3.10/asyncio/base_events.py", line 636, in run_until_complete
    self.run_forever()
  File "/opt/conda/envs/rapids/lib/python3.10/asyncio/base_events.py", line 603, in run_forever
    self._run_once()
  File "/opt/conda/envs/rapids/lib/python3.10/asyncio/base_events.py", line 1871, in _run_once
    event_list = self._selector.select(timeout)
  File "/opt/conda/envs/rapids/lib/python3.10/selectors.py", line 469, in select
    fd_event_list = self._selector.poll(timeout, max_ev)
KeyboardInterrupt

During handling of the above exception, another exception occurred:

Traceback (most recent call last):
  File "/opt/conda/envs/rapids/lib/python3.10/site-packages/tornado/iostream.py", line 861, in _read_to_buffer
    bytes_read = self.read_from_fd(buf)
  File "/opt/conda/envs/rapids/lib/python3.10/site-packages/tornado/iostream.py", line 1116, in read_from_fd
    return self.socket.recv_into(buf, len(buf))
ConnectionResetError: [Errno 104] Connection reset by peer

The above exception was the direct cause of the following exception:

Traceback (most recent call last):
  File "/opt/conda/envs/rapids/lib/python3.10/site-packages/distributed/comm/core.py", line 373, in connect
    handshake = await wait_for(comm.read(), time_left())
  File "/opt/conda/envs/rapids/lib/python3.10/site-packages/distributed/utils.py", line 1878, in wait_for
    return await asyncio.wait_for(fut, timeout)
  File "/opt/conda/envs/rapids/lib/python3.10/asyncio/tasks.py", line 445, in wait_for
    return fut.result()
  File "/opt/conda/envs/rapids/lib/python3.10/site-packages/distributed/comm/tcp.py", line 241, in read
    convert_stream_closed_error(self, e)
  File "/opt/conda/envs/rapids/lib/python3.10/site-packages/distributed/comm/tcp.py", line 142, in convert_stream_closed_error
    raise CommClosedError(f"in {obj}: {exc.__class__.__name__}: {exc}") from exc
distributed.comm.core.CommClosedError: in <TCP (closed)  local=tcp://10.33.227.169:37480 remote=tcp://10.33.227.169:41251>: ConnectionResetError: [Errno 104] Connection reset by peer

The above exception was the direct cause of the following exception:

Traceback (most recent call last):
  File "/opt/conda/envs/rapids/lib/python3.10/site-packages/distributed/utils.py", line 754, in wrapper
    return await func(*args, **kwargs)
  File "/opt/conda/envs/rapids/lib/python3.10/site-packages/distributed/worker.py", line 1540, in close
    await r.close_gracefully(reason=reason)
  File "/opt/conda/envs/rapids/lib/python3.10/site-packages/distributed/core.py", line 1362, in send_recv_from_rpc
    comm = await self.pool.connect(self.addr)
  File "/opt/conda/envs/rapids/lib/python3.10/site-packages/distributed/core.py", line 1606, in connect
    return await connect_attempt
  File "/opt/conda/envs/rapids/lib/python3.10/site-packages/distributed/core.py", line 1527, in _connect
    comm = await connect(
  File "/opt/conda/envs/rapids/lib/python3.10/site-packages/distributed/comm/core.py", line 378, in connect
    raise OSError(
OSError: Timed out during handshake while connecting to tcp://10.33.227.169:41251 after 100 s
2023-06-22 22:12:43,296 - distributed.worker - ERROR - Timed out during handshake while connecting to tcp://10.33.227.169:45453 after 100 s
Traceback (most recent call last):
  File "/opt/conda/envs/rapids/lib/python3.10/asyncio/runners.py", line 44, in run
    return loop.run_until_complete(main)
  File "/opt/conda/envs/rapids/lib/python3.10/asyncio/base_events.py", line 636, in run_until_complete
    self.run_forever()
  File "/opt/conda/envs/rapids/lib/python3.10/asyncio/base_events.py", line 603, in run_forever
    self._run_once()
  File "/opt/conda/envs/rapids/lib/python3.10/asyncio/base_events.py", line 1871, in _run_once
    event_list = self._selector.select(timeout)
  File "/opt/conda/envs/rapids/lib/python3.10/selectors.py", line 469, in select
    fd_event_list = self._selector.poll(timeout, max_ev)
KeyboardInterrupt

During handling of the above exception, another exception occurred:

Traceback (most recent call last):
  File "/opt/conda/envs/rapids/lib/python3.10/site-packages/tornado/iostream.py", line 861, in _read_to_buffer
    bytes_read = self.read_from_fd(buf)
  File "/opt/conda/envs/rapids/lib/python3.10/site-packages/tornado/iostream.py", line 1116, in read_from_fd
    return self.socket.recv_into(buf, len(buf))
ConnectionResetError: [Errno 104] Connection reset by peer

The above exception was the direct cause of the following exception:

Traceback (most recent call last):
  File "/opt/conda/envs/rapids/lib/python3.10/site-packages/distributed/comm/core.py", line 373, in connect
    handshake = await wait_for(comm.read(), time_left())
  File "/opt/conda/envs/rapids/lib/python3.10/site-packages/distributed/utils.py", line 1878, in wait_for
    return await asyncio.wait_for(fut, timeout)
  File "/opt/conda/envs/rapids/lib/python3.10/asyncio/tasks.py", line 445, in wait_for
    return fut.result()
  File "/opt/conda/envs/rapids/lib/python3.10/site-packages/distributed/comm/tcp.py", line 241, in read
    convert_stream_closed_error(self, e)
  File "/opt/conda/envs/rapids/lib/python3.10/site-packages/distributed/comm/tcp.py", line 142, in convert_stream_closed_error
    raise CommClosedError(f"in {obj}: {exc.__class__.__name__}: {exc}") from exc
distributed.comm.core.CommClosedError: in <TCP (closed)  local=tcp://10.33.227.169:43152 remote=tcp://10.33.227.169:45453>: ConnectionResetError: [Errno 104] Connection reset by peer

The above exception was the direct cause of the following exception:

Traceback (most recent call last):
  File "/opt/conda/envs/rapids/lib/python3.10/site-packages/distributed/utils.py", line 754, in wrapper
    return await func(*args, **kwargs)
  File "/opt/conda/envs/rapids/lib/python3.10/site-packages/distributed/worker.py", line 1540, in close
    await r.close_gracefully(reason=reason)
  File "/opt/conda/envs/rapids/lib/python3.10/site-packages/distributed/core.py", line 1362, in send_recv_from_rpc
    comm = await self.pool.connect(self.addr)
  File "/opt/conda/envs/rapids/lib/python3.10/site-packages/distributed/core.py", line 1606, in connect
    return await connect_attempt
  File "/opt/conda/envs/rapids/lib/python3.10/site-packages/distributed/core.py", line 1527, in _connect
    comm = await connect(
  File "/opt/conda/envs/rapids/lib/python3.10/site-packages/distributed/comm/core.py", line 378, in connect
    raise OSError(
OSError: Timed out during handshake while connecting to tcp://10.33.227.169:45453 after 100 s
2023-06-22 22:12:43,298 - distributed.core - ERROR - Timed out during handshake while connecting to tcp://10.33.227.169:41823 after 100 s
Traceback (most recent call last):
  File "/opt/conda/envs/rapids/lib/python3.10/asyncio/runners.py", line 44, in run
    return loop.run_until_complete(main)
  File "/opt/conda/envs/rapids/lib/python3.10/asyncio/base_events.py", line 636, in run_until_complete
    self.run_forever()
  File "/opt/conda/envs/rapids/lib/python3.10/asyncio/base_events.py", line 603, in run_forever
    self._run_once()
  File "/opt/conda/envs/rapids/lib/python3.10/asyncio/base_events.py", line 1871, in _run_once
    event_list = self._selector.select(timeout)
  File "/opt/conda/envs/rapids/lib/python3.10/selectors.py", line 469, in select
    fd_event_list = self._selector.poll(timeout, max_ev)
KeyboardInterrupt

During handling of the above exception, another exception occurred:

Traceback (most recent call last):
  File "/opt/conda/envs/rapids/lib/python3.10/site-packages/tornado/iostream.py", line 861, in _read_to_buffer
    bytes_read = self.read_from_fd(buf)
  File "/opt/conda/envs/rapids/lib/python3.10/site-packages/tornado/iostream.py", line 1116, in read_from_fd
    return self.socket.recv_into(buf, len(buf))
ConnectionResetError: [Errno 104] Connection reset by peer

The above exception was the direct cause of the following exception:

Traceback (most recent call last):
  File "/opt/conda/envs/rapids/lib/python3.10/site-packages/distributed/comm/core.py", line 373, in connect
    handshake = await wait_for(comm.read(), time_left())
  File "/opt/conda/envs/rapids/lib/python3.10/site-packages/distributed/utils.py", line 1878, in wait_for
    return await asyncio.wait_for(fut, timeout)
  File "/opt/conda/envs/rapids/lib/python3.10/asyncio/tasks.py", line 445, in wait_for
    return fut.result()
  File "/opt/conda/envs/rapids/lib/python3.10/site-packages/distributed/comm/tcp.py", line 241, in read
    convert_stream_closed_error(self, e)
  File "/opt/conda/envs/rapids/lib/python3.10/site-packages/distributed/comm/tcp.py", line 142, in convert_stream_closed_error
    raise CommClosedError(f"in {obj}: {exc.__class__.__name__}: {exc}") from exc
distributed.comm.core.CommClosedError: in <TCP (closed)  local=tcp://10.33.227.169:34616 remote=tcp://10.33.227.169:41823>: ConnectionResetError: [Errno 104] Connection reset by peer

The above exception was the direct cause of the following exception:

Traceback (most recent call last):
  File "/opt/conda/envs/rapids/lib/python3.10/site-packages/distributed/utils.py", line 754, in wrapper
    return await func(*args, **kwargs)
  File "/opt/conda/envs/rapids/lib/python3.10/site-packages/distributed/worker.py", line 1540, in close
    await r.close_gracefully(reason=reason)
  File "/opt/conda/envs/rapids/lib/python3.10/site-packages/distributed/core.py", line 1362, in send_recv_from_rpc
    comm = await self.pool.connect(self.addr)
  File "/opt/conda/envs/rapids/lib/python3.10/site-packages/distributed/core.py", line 1606, in connect
    return await connect_attempt
  File "/opt/conda/envs/rapids/lib/python3.10/site-packages/distributed/core.py", line 1527, in _connect
    comm = await connect(
  File "/opt/conda/envs/rapids/lib/python3.10/site-packages/distributed/comm/core.py", line 378, in connect
    raise OSError(
OSError: Timed out during handshake while connecting to tcp://10.33.227.169:41823 after 100 s
2023-06-22 22:12:43,302 - distributed.core - ERROR - Timed out during handshake while connecting to tcp://10.33.227.169:35931 after 100 s
Traceback (most recent call last):
  File "/opt/conda/envs/rapids/lib/python3.10/asyncio/runners.py", line 44, in run
    return loop.run_until_complete(main)
  File "/opt/conda/envs/rapids/lib/python3.10/asyncio/base_events.py", line 636, in run_until_complete
    self.run_forever()
  File "/opt/conda/envs/rapids/lib/python3.10/asyncio/base_events.py", line 603, in run_forever
    self._run_once()
  File "/opt/conda/envs/rapids/lib/python3.10/asyncio/base_events.py", line 1871, in _run_once
    event_list = self._selector.select(timeout)
  File "/opt/conda/envs/rapids/lib/python3.10/selectors.py", line 469, in select
    fd_event_list = self._selector.poll(timeout, max_ev)
KeyboardInterrupt

During handling of the above exception, another exception occurred:

Traceback (most recent call last):
  File "/opt/conda/envs/rapids/lib/python3.10/site-packages/tornado/iostream.py", line 861, in _read_to_buffer
    bytes_read = self.read_from_fd(buf)
  File "/opt/conda/envs/rapids/lib/python3.10/site-packages/tornado/iostream.py", line 1116, in read_from_fd
    return self.socket.recv_into(buf, len(buf))
ConnectionResetError: [Errno 104] Connection reset by peer

The above exception was the direct cause of the following exception:

Traceback (most recent call last):
  File "/opt/conda/envs/rapids/lib/python3.10/site-packages/distributed/comm/core.py", line 373, in connect
    handshake = await wait_for(comm.read(), time_left())
  File "/opt/conda/envs/rapids/lib/python3.10/site-packages/distributed/utils.py", line 1878, in wait_for
    return await asyncio.wait_for(fut, timeout)
  File "/opt/conda/envs/rapids/lib/python3.10/asyncio/tasks.py", line 445, in wait_for
    return fut.result()
  File "/opt/conda/envs/rapids/lib/python3.10/site-packages/distributed/comm/tcp.py", line 241, in read
    convert_stream_closed_error(self, e)
  File "/opt/conda/envs/rapids/lib/python3.10/site-packages/distributed/comm/tcp.py", line 142, in convert_stream_closed_error
    raise CommClosedError(f"in {obj}: {exc.__class__.__name__}: {exc}") from exc
distributed.comm.core.CommClosedError: in <TCP (closed)  local=tcp://10.33.227.169:58768 remote=tcp://10.33.227.169:35931>: ConnectionResetError: [Errno 104] Connection reset by peer

The above exception was the direct cause of the following exception:

Traceback (most recent call last):
  File "/opt/conda/envs/rapids/lib/python3.10/site-packages/distributed/utils.py", line 754, in wrapper
    return await func(*args, **kwargs)
  File "/opt/conda/envs/rapids/lib/python3.10/site-packages/distributed/worker.py", line 1540, in close
    await r.close_gracefully(reason=reason)
  File "/opt/conda/envs/rapids/lib/python3.10/site-packages/distributed/core.py", line 1362, in send_recv_from_rpc
    comm = await self.pool.connect(self.addr)
  File "/opt/conda/envs/rapids/lib/python3.10/site-packages/distributed/core.py", line 1606, in connect
    return await connect_attempt
  File "/opt/conda/envs/rapids/lib/python3.10/site-packages/distributed/core.py", line 1527, in _connect
    comm = await connect(
  File "/opt/conda/envs/rapids/lib/python3.10/site-packages/distributed/comm/core.py", line 378, in connect
    raise OSError(
OSError: Timed out during handshake while connecting to tcp://10.33.227.169:35931 after 100 s
2023-06-22 22:12:43,304 - distributed.worker - ERROR - Timed out during handshake while connecting to tcp://10.33.227.169:43471 after 100 s
Traceback (most recent call last):
  File "/opt/conda/envs/rapids/lib/python3.10/asyncio/runners.py", line 44, in run
    return loop.run_until_complete(main)
  File "/opt/conda/envs/rapids/lib/python3.10/asyncio/base_events.py", line 636, in run_until_complete
    self.run_forever()
  File "/opt/conda/envs/rapids/lib/python3.10/asyncio/base_events.py", line 603, in run_forever
    self._run_once()
  File "/opt/conda/envs/rapids/lib/python3.10/asyncio/base_events.py", line 1871, in _run_once
    event_list = self._selector.select(timeout)
  File "/opt/conda/envs/rapids/lib/python3.10/selectors.py", line 469, in select
    fd_event_list = self._selector.poll(timeout, max_ev)
KeyboardInterrupt

During handling of the above exception, another exception occurred:

Traceback (most recent call last):
  File "/opt/conda/envs/rapids/lib/python3.10/site-packages/tornado/iostream.py", line 861, in _read_to_buffer
    bytes_read = self.read_from_fd(buf)
  File "/opt/conda/envs/rapids/lib/python3.10/site-packages/tornado/iostream.py", line 1116, in read_from_fd
    return self.socket.recv_into(buf, len(buf))
ConnectionResetError: [Errno 104] Connection reset by peer

The above exception was the direct cause of the following exception:

Traceback (most recent call last):
  File "/opt/conda/envs/rapids/lib/python3.10/site-packages/distributed/comm/core.py", line 373, in connect
    handshake = await wait_for(comm.read(), time_left())
  File "/opt/conda/envs/rapids/lib/python3.10/site-packages/distributed/utils.py", line 1878, in wait_for
    return await asyncio.wait_for(fut, timeout)
  File "/opt/conda/envs/rapids/lib/python3.10/asyncio/tasks.py", line 445, in wait_for
    return fut.result()
  File "/opt/conda/envs/rapids/lib/python3.10/site-packages/distributed/comm/tcp.py", line 241, in read
    convert_stream_closed_error(self, e)
  File "/opt/conda/envs/rapids/lib/python3.10/site-packages/distributed/comm/tcp.py", line 142, in convert_stream_closed_error
    raise CommClosedError(f"in {obj}: {exc.__class__.__name__}: {exc}") from exc
distributed.comm.core.CommClosedError: in <TCP (closed)  local=tcp://10.33.227.169:53732 remote=tcp://10.33.227.169:43471>: ConnectionResetError: [Errno 104] Connection reset by peer

The above exception was the direct cause of the following exception:

Traceback (most recent call last):
  File "/opt/conda/envs/rapids/lib/python3.10/site-packages/distributed/utils.py", line 754, in wrapper
    return await func(*args, **kwargs)
  File "/opt/conda/envs/rapids/lib/python3.10/site-packages/distributed/worker.py", line 1540, in close
    await r.close_gracefully(reason=reason)
  File "/opt/conda/envs/rapids/lib/python3.10/site-packages/distributed/core.py", line 1362, in send_recv_from_rpc
    comm = await self.pool.connect(self.addr)
  File "/opt/conda/envs/rapids/lib/python3.10/site-packages/distributed/core.py", line 1606, in connect
    return await connect_attempt
  File "/opt/conda/envs/rapids/lib/python3.10/site-packages/distributed/core.py", line 1527, in _connect
    comm = await connect(
  File "/opt/conda/envs/rapids/lib/python3.10/site-packages/distributed/comm/core.py", line 378, in connect
    raise OSError(
OSError: Timed out during handshake while connecting to tcp://10.33.227.169:43471 after 100 s
2023-06-22 22:12:43,307 - distributed.core - ERROR - Timed out during handshake while connecting to tcp://10.33.227.169:34067 after 100 s
Traceback (most recent call last):
  File "/opt/conda/envs/rapids/lib/python3.10/asyncio/runners.py", line 44, in run
    return loop.run_until_complete(main)
  File "/opt/conda/envs/rapids/lib/python3.10/asyncio/base_events.py", line 636, in run_until_complete
    self.run_forever()
  File "/opt/conda/envs/rapids/lib/python3.10/asyncio/base_events.py", line 603, in run_forever
    self._run_once()
  File "/opt/conda/envs/rapids/lib/python3.10/asyncio/base_events.py", line 1871, in _run_once
    event_list = self._selector.select(timeout)
  File "/opt/conda/envs/rapids/lib/python3.10/selectors.py", line 469, in select
    fd_event_list = self._selector.poll(timeout, max_ev)
KeyboardInterrupt

During handling of the above exception, another exception occurred:

Traceback (most recent call last):
  File "/opt/conda/envs/rapids/lib/python3.10/site-packages/tornado/iostream.py", line 861, in _read_to_buffer
    bytes_read = self.read_from_fd(buf)
  File "/opt/conda/envs/rapids/lib/python3.10/site-packages/tornado/iostream.py", line 1116, in read_from_fd
    return self.socket.recv_into(buf, len(buf))
ConnectionResetError: [Errno 104] Connection reset by peer

The above exception was the direct cause of the following exception:

Traceback (most recent call last):
  File "/opt/conda/envs/rapids/lib/python3.10/site-packages/distributed/comm/core.py", line 373, in connect
    handshake = await wait_for(comm.read(), time_left())
  File "/opt/conda/envs/rapids/lib/python3.10/site-packages/distributed/utils.py", line 1878, in wait_for
    return await asyncio.wait_for(fut, timeout)
  File "/opt/conda/envs/rapids/lib/python3.10/asyncio/tasks.py", line 445, in wait_for
    return fut.result()
  File "/opt/conda/envs/rapids/lib/python3.10/site-packages/distributed/comm/tcp.py", line 241, in read
    convert_stream_closed_error(self, e)
  File "/opt/conda/envs/rapids/lib/python3.10/site-packages/distributed/comm/tcp.py", line 142, in convert_stream_closed_error
    raise CommClosedError(f"in {obj}: {exc.__class__.__name__}: {exc}") from exc
distributed.comm.core.CommClosedError: in <TCP (closed)  local=tcp://10.33.227.169:47978 remote=tcp://10.33.227.169:34067>: ConnectionResetError: [Errno 104] Connection reset by peer

The above exception was the direct cause of the following exception:

Traceback (most recent call last):
  File "/opt/conda/envs/rapids/lib/python3.10/site-packages/distributed/utils.py", line 754, in wrapper
    return await func(*args, **kwargs)
  File "/opt/conda/envs/rapids/lib/python3.10/site-packages/distributed/worker.py", line 1540, in close
    await r.close_gracefully(reason=reason)
  File "/opt/conda/envs/rapids/lib/python3.10/site-packages/distributed/core.py", line 1362, in send_recv_from_rpc
    comm = await self.pool.connect(self.addr)
  File "/opt/conda/envs/rapids/lib/python3.10/site-packages/distributed/core.py", line 1606, in connect
    return await connect_attempt
  File "/opt/conda/envs/rapids/lib/python3.10/site-packages/distributed/core.py", line 1527, in _connect
    comm = await connect(
  File "/opt/conda/envs/rapids/lib/python3.10/site-packages/distributed/comm/core.py", line 378, in connect
    raise OSError(
OSError: Timed out during handshake while connecting to tcp://10.33.227.169:34067 after 100 s
2023-06-22 22:12:46,483 - distributed.nanny - WARNING - Worker process still alive after 3.1999839782714847 seconds, killing
2023-06-22 22:12:46,483 - distributed.nanny - WARNING - Worker process still alive after 3.1999990844726565 seconds, killing
2023-06-22 22:12:46,484 - distributed.nanny - WARNING - Worker process still alive after 3.1999992370605472 seconds, killing
2023-06-22 22:12:46,485 - distributed.nanny - WARNING - Worker process still alive after 3.1999992370605472 seconds, killing
2023-06-22 22:12:46,487 - distributed.nanny - WARNING - Worker process still alive after 3.1999992370605472 seconds, killing
2023-06-22 22:12:46,488 - distributed.nanny - WARNING - Worker process still alive after 3.1999990844726565 seconds, killing
2023-06-22 22:12:46,489 - distributed.nanny - WARNING - Worker process still alive after 3.199999389648438 seconds, killing
2023-06-22 22:12:46,489 - distributed.nanny - WARNING - Worker process still alive after 3.1999992370605472 seconds, killing
2023-06-22 22:12:47,274 - distributed.nanny - ERROR - Error in Nanny killing Worker subprocess
Traceback (most recent call last):
  File "/opt/conda/envs/rapids/lib/python3.10/asyncio/tasks.py", line 456, in wait_for
    return fut.result()
asyncio.exceptions.CancelledError

The above exception was the direct cause of the following exception:

Traceback (most recent call last):
  File "/opt/conda/envs/rapids/lib/python3.10/site-packages/distributed/nanny.py", line 597, in close
    await self.kill(timeout=timeout, reason=reason)
  File "/opt/conda/envs/rapids/lib/python3.10/site-packages/distributed/nanny.py", line 380, in kill
    await self.process.kill(reason=reason, timeout=0.8 * (deadline - time()))
  File "/opt/conda/envs/rapids/lib/python3.10/site-packages/distributed/nanny.py", line 853, in kill
    await process.join(max(0, deadline - time()))
  File "/opt/conda/envs/rapids/lib/python3.10/site-packages/distributed/process.py", line 330, in join
    await wait_for(asyncio.shield(self._exit_future), timeout)
  File "/opt/conda/envs/rapids/lib/python3.10/site-packages/distributed/utils.py", line 1878, in wait_for
    return await asyncio.wait_for(fut, timeout)
  File "/opt/conda/envs/rapids/lib/python3.10/asyncio/tasks.py", line 458, in wait_for
    raise exceptions.TimeoutError() from exc
asyncio.exceptions.TimeoutError
2023-06-22 22:12:47,277 - distributed.nanny - ERROR - Error in Nanny killing Worker subprocess
Traceback (most recent call last):
  File "/opt/conda/envs/rapids/lib/python3.10/asyncio/tasks.py", line 456, in wait_for
    return fut.result()
asyncio.exceptions.CancelledError

The above exception was the direct cause of the following exception:

Traceback (most recent call last):
  File "/opt/conda/envs/rapids/lib/python3.10/site-packages/distributed/nanny.py", line 597, in close
    await self.kill(timeout=timeout, reason=reason)
  File "/opt/conda/envs/rapids/lib/python3.10/site-packages/distributed/nanny.py", line 380, in kill
    await self.process.kill(reason=reason, timeout=0.8 * (deadline - time()))
  File "/opt/conda/envs/rapids/lib/python3.10/site-packages/distributed/nanny.py", line 853, in kill
    await process.join(max(0, deadline - time()))
  File "/opt/conda/envs/rapids/lib/python3.10/site-packages/distributed/process.py", line 330, in join
    await wait_for(asyncio.shield(self._exit_future), timeout)
  File "/opt/conda/envs/rapids/lib/python3.10/site-packages/distributed/utils.py", line 1878, in wait_for
    return await asyncio.wait_for(fut, timeout)
  File "/opt/conda/envs/rapids/lib/python3.10/asyncio/tasks.py", line 458, in wait_for
    raise exceptions.TimeoutError() from exc
asyncio.exceptions.TimeoutError
2023-06-22 22:12:47,277 - distributed.nanny - ERROR - Error in Nanny killing Worker subprocess
Traceback (most recent call last):
  File "/opt/conda/envs/rapids/lib/python3.10/asyncio/tasks.py", line 456, in wait_for
    return fut.result()
asyncio.exceptions.CancelledError

The above exception was the direct cause of the following exception:

Traceback (most recent call last):
  File "/opt/conda/envs/rapids/lib/python3.10/site-packages/distributed/nanny.py", line 597, in close
    await self.kill(timeout=timeout, reason=reason)
  File "/opt/conda/envs/rapids/lib/python3.10/site-packages/distributed/nanny.py", line 380, in kill
    await self.process.kill(reason=reason, timeout=0.8 * (deadline - time()))
  File "/opt/conda/envs/rapids/lib/python3.10/site-packages/distributed/nanny.py", line 853, in kill
    await process.join(max(0, deadline - time()))
  File "/opt/conda/envs/rapids/lib/python3.10/site-packages/distributed/process.py", line 330, in join
    await wait_for(asyncio.shield(self._exit_future), timeout)
  File "/opt/conda/envs/rapids/lib/python3.10/site-packages/distributed/utils.py", line 1878, in wait_for
    return await asyncio.wait_for(fut, timeout)
  File "/opt/conda/envs/rapids/lib/python3.10/asyncio/tasks.py", line 458, in wait_for
    raise exceptions.TimeoutError() from exc
asyncio.exceptions.TimeoutError
2023-06-22 22:12:47,289 - distributed.nanny - ERROR - Error in Nanny killing Worker subprocess
Traceback (most recent call last):
  File "/opt/conda/envs/rapids/lib/python3.10/asyncio/tasks.py", line 456, in wait_for
    return fut.result()
asyncio.exceptions.CancelledError

The above exception was the direct cause of the following exception:

Traceback (most recent call last):
  File "/opt/conda/envs/rapids/lib/python3.10/site-packages/distributed/nanny.py", line 597, in close
    await self.kill(timeout=timeout, reason=reason)
  File "/opt/conda/envs/rapids/lib/python3.10/site-packages/distributed/nanny.py", line 380, in kill
    await self.process.kill(reason=reason, timeout=0.8 * (deadline - time()))
  File "/opt/conda/envs/rapids/lib/python3.10/site-packages/distributed/nanny.py", line 853, in kill
    await process.join(max(0, deadline - time()))
  File "/opt/conda/envs/rapids/lib/python3.10/site-packages/distributed/process.py", line 330, in join
    await wait_for(asyncio.shield(self._exit_future), timeout)
  File "/opt/conda/envs/rapids/lib/python3.10/site-packages/distributed/utils.py", line 1878, in wait_for
    return await asyncio.wait_for(fut, timeout)
  File "/opt/conda/envs/rapids/lib/python3.10/asyncio/tasks.py", line 458, in wait_for
    raise exceptions.TimeoutError() from exc
asyncio.exceptions.TimeoutError
2023-06-22 22:12:47,290 - distributed.nanny - ERROR - Error in Nanny killing Worker subprocess
Traceback (most recent call last):
  File "/opt/conda/envs/rapids/lib/python3.10/asyncio/tasks.py", line 456, in wait_for
    return fut.result()
asyncio.exceptions.CancelledError

The above exception was the direct cause of the following exception:

Traceback (most recent call last):
  File "/opt/conda/envs/rapids/lib/python3.10/site-packages/distributed/nanny.py", line 597, in close
    await self.kill(timeout=timeout, reason=reason)
  File "/opt/conda/envs/rapids/lib/python3.10/site-packages/distributed/nanny.py", line 380, in kill
    await self.process.kill(reason=reason, timeout=0.8 * (deadline - time()))
  File "/opt/conda/envs/rapids/lib/python3.10/site-packages/distributed/nanny.py", line 853, in kill
    await process.join(max(0, deadline - time()))
  File "/opt/conda/envs/rapids/lib/python3.10/site-packages/distributed/process.py", line 330, in join
    await wait_for(asyncio.shield(self._exit_future), timeout)
  File "/opt/conda/envs/rapids/lib/python3.10/site-packages/distributed/utils.py", line 1878, in wait_for
    return await asyncio.wait_for(fut, timeout)
  File "/opt/conda/envs/rapids/lib/python3.10/asyncio/tasks.py", line 458, in wait_for
    raise exceptions.TimeoutError() from exc
asyncio.exceptions.TimeoutError
2023-06-22 22:12:47,290 - distributed.nanny - ERROR - Error in Nanny killing Worker subprocess
Traceback (most recent call last):
  File "/opt/conda/envs/rapids/lib/python3.10/asyncio/tasks.py", line 456, in wait_for
    return fut.result()
asyncio.exceptions.CancelledError

The above exception was the direct cause of the following exception:

Traceback (most recent call last):
  File "/opt/conda/envs/rapids/lib/python3.10/site-packages/distributed/nanny.py", line 597, in close
    await self.kill(timeout=timeout, reason=reason)
  File "/opt/conda/envs/rapids/lib/python3.10/site-packages/distributed/nanny.py", line 380, in kill
    await self.process.kill(reason=reason, timeout=0.8 * (deadline - time()))
  File "/opt/conda/envs/rapids/lib/python3.10/site-packages/distributed/nanny.py", line 853, in kill
    await process.join(max(0, deadline - time()))
  File "/opt/conda/envs/rapids/lib/python3.10/site-packages/distributed/process.py", line 330, in join
    await wait_for(asyncio.shield(self._exit_future), timeout)
  File "/opt/conda/envs/rapids/lib/python3.10/site-packages/distributed/utils.py", line 1878, in wait_for
    return await asyncio.wait_for(fut, timeout)
  File "/opt/conda/envs/rapids/lib/python3.10/asyncio/tasks.py", line 458, in wait_for
    raise exceptions.TimeoutError() from exc
asyncio.exceptions.TimeoutError
2023-06-22 22:12:47,290 - distributed.nanny - ERROR - Error in Nanny killing Worker subprocess
Traceback (most recent call last):
  File "/opt/conda/envs/rapids/lib/python3.10/asyncio/tasks.py", line 456, in wait_for
    return fut.result()
asyncio.exceptions.CancelledError

The above exception was the direct cause of the following exception:

Traceback (most recent call last):
  File "/opt/conda/envs/rapids/lib/python3.10/site-packages/distributed/nanny.py", line 597, in close
    await self.kill(timeout=timeout, reason=reason)
  File "/opt/conda/envs/rapids/lib/python3.10/site-packages/distributed/nanny.py", line 380, in kill
    await self.process.kill(reason=reason, timeout=0.8 * (deadline - time()))
  File "/opt/conda/envs/rapids/lib/python3.10/site-packages/distributed/nanny.py", line 853, in kill
    await process.join(max(0, deadline - time()))
  File "/opt/conda/envs/rapids/lib/python3.10/site-packages/distributed/process.py", line 330, in join
    await wait_for(asyncio.shield(self._exit_future), timeout)
  File "/opt/conda/envs/rapids/lib/python3.10/site-packages/distributed/utils.py", line 1878, in wait_for
    return await asyncio.wait_for(fut, timeout)
  File "/opt/conda/envs/rapids/lib/python3.10/asyncio/tasks.py", line 458, in wait_for
    raise exceptions.TimeoutError() from exc
asyncio.exceptions.TimeoutError
2023-06-22 22:12:47,290 - distributed.nanny - ERROR - Error in Nanny killing Worker subprocess
Traceback (most recent call last):
  File "/opt/conda/envs/rapids/lib/python3.10/asyncio/tasks.py", line 456, in wait_for
    return fut.result()
asyncio.exceptions.CancelledError

The above exception was the direct cause of the following exception:

Traceback (most recent call last):
  File "/opt/conda/envs/rapids/lib/python3.10/site-packages/distributed/nanny.py", line 597, in close
    await self.kill(timeout=timeout, reason=reason)
  File "/opt/conda/envs/rapids/lib/python3.10/site-packages/distributed/nanny.py", line 380, in kill
    await self.process.kill(reason=reason, timeout=0.8 * (deadline - time()))
  File "/opt/conda/envs/rapids/lib/python3.10/site-packages/distributed/nanny.py", line 853, in kill
    await process.join(max(0, deadline - time()))
  File "/opt/conda/envs/rapids/lib/python3.10/site-packages/distributed/process.py", line 330, in join
    await wait_for(asyncio.shield(self._exit_future), timeout)
  File "/opt/conda/envs/rapids/lib/python3.10/site-packages/distributed/utils.py", line 1878, in wait_for
    return await asyncio.wait_for(fut, timeout)
  File "/opt/conda/envs/rapids/lib/python3.10/asyncio/tasks.py", line 458, in wait_for
    raise exceptions.TimeoutError() from exc
asyncio.exceptions.TimeoutError
2023-06-22 22:12:47,292 - distributed.process - INFO - reaping stray process <SpawnProcess name='Dask Worker process (from Nanny)' pid=1453657 parent=1453609 started daemon>
2023-06-22 22:12:47,292 - distributed.process - INFO - reaping stray process <SpawnProcess name='Dask Worker process (from Nanny)' pid=1453654 parent=1453609 started daemon>
2023-06-22 22:12:47,293 - distributed.process - INFO - reaping stray process <SpawnProcess name='Dask Worker process (from Nanny)' pid=1453651 parent=1453609 started daemon>
2023-06-22 22:12:47,293 - distributed.process - INFO - reaping stray process <SpawnProcess name='Dask Worker process (from Nanny)' pid=1453648 parent=1453609 started daemon>
2023-06-22 22:12:47,293 - distributed.process - INFO - reaping stray process <SpawnProcess name='Dask Worker process (from Nanny)' pid=1453645 parent=1453609 started daemon>
2023-06-22 22:12:47,293 - distributed.process - INFO - reaping stray process <SpawnProcess name='Dask Worker process (from Nanny)' pid=1453642 parent=1453609 started daemon>
2023-06-22 22:12:47,293 - distributed.process - INFO - reaping stray process <SpawnProcess name='Dask Worker process (from Nanny)' pid=1453639 parent=1453609 started daemon>
2023-06-22 22:12:47,293 - distributed.process - INFO - reaping stray process <SpawnProcess name='Dask Worker process (from Nanny)' pid=1453636 parent=1453609 started daemon>
2023-06-22 22:12:47,797 - distributed.process - WARNING - [<AsyncProcess Dask Worker process (from Nanny)>] process 1453651 exit status was already read will report exitcode 255
2023-06-22 22:12:48,022 - distributed.process - WARNING - [<AsyncProcess Dask Worker process (from Nanny)>] process 1453639 exit status was already read will report exitcode 255
2023-06-22 22:12:48,342 - distributed.process - WARNING - [<AsyncProcess Dask Worker process (from Nanny)>] process 1453636 exit status was already read will report exitcode 255
