RUNNING: "python -m dask_cuda.cli.dask_cuda_worker --rmm-pool-size=12G
             --local-directory=/tmp/
             --scheduler-file=/root/work/cugraph/mg_utils/dask-scheduler.json
             --memory-limit=auto
             --device-memory-limit=auto
            "
2023-06-22 23:45:35,213 - distributed.nanny - INFO -         Start Nanny at: 'tcp://10.33.227.169:39309'
2023-06-22 23:45:35,218 - distributed.nanny - INFO -         Start Nanny at: 'tcp://10.33.227.169:34873'
2023-06-22 23:45:35,219 - distributed.nanny - INFO -         Start Nanny at: 'tcp://10.33.227.169:42441'
2023-06-22 23:45:35,221 - distributed.nanny - INFO -         Start Nanny at: 'tcp://10.33.227.169:42773'
2023-06-22 23:45:35,224 - distributed.nanny - INFO -         Start Nanny at: 'tcp://10.33.227.169:35755'
2023-06-22 23:45:35,226 - distributed.nanny - INFO -         Start Nanny at: 'tcp://10.33.227.169:34975'
2023-06-22 23:45:35,229 - distributed.nanny - INFO -         Start Nanny at: 'tcp://10.33.227.169:34759'
2023-06-22 23:45:35,231 - distributed.nanny - INFO -         Start Nanny at: 'tcp://10.33.227.169:33627'
2023-06-22 23:45:36,659 - distributed.diskutils - INFO - Found stale lock file and directory '/tmp/dask-scratch-space/worker-cyosacd8', purging
2023-06-22 23:45:36,659 - distributed.diskutils - INFO - Found stale lock file and directory '/tmp/dask-scratch-space/worker-_2y_ln2z', purging
2023-06-22 23:45:36,660 - distributed.diskutils - INFO - Found stale lock file and directory '/tmp/dask-scratch-space/worker-frq6ia3y', purging
2023-06-22 23:45:36,660 - distributed.diskutils - INFO - Found stale lock file and directory '/tmp/dask-scratch-space/worker-wp4s8i0s', purging
2023-06-22 23:45:36,660 - distributed.diskutils - INFO - Found stale lock file and directory '/tmp/dask-scratch-space/worker-ed7ivkb2', purging
2023-06-22 23:45:36,660 - distributed.diskutils - INFO - Found stale lock file and directory '/tmp/dask-scratch-space/worker-etrnenvb', purging
2023-06-22 23:45:36,661 - distributed.diskutils - INFO - Found stale lock file and directory '/tmp/dask-scratch-space/worker-iroz5_kc', purging
2023-06-22 23:45:36,670 - distributed.preloading - INFO - Creating preload: dask_cuda.initialize
2023-06-22 23:45:36,670 - distributed.preloading - INFO - Import preload module: dask_cuda.initialize
2023-06-22 23:45:36,765 - distributed.preloading - INFO - Creating preload: dask_cuda.initialize
2023-06-22 23:45:36,765 - distributed.preloading - INFO - Import preload module: dask_cuda.initialize
2023-06-22 23:45:36,765 - distributed.preloading - INFO - Creating preload: dask_cuda.initialize
2023-06-22 23:45:36,765 - distributed.preloading - INFO - Import preload module: dask_cuda.initialize
2023-06-22 23:45:36,775 - distributed.preloading - INFO - Creating preload: dask_cuda.initialize
2023-06-22 23:45:36,775 - distributed.preloading - INFO - Import preload module: dask_cuda.initialize
2023-06-22 23:45:36,776 - distributed.preloading - INFO - Creating preload: dask_cuda.initialize
2023-06-22 23:45:36,776 - distributed.preloading - INFO - Import preload module: dask_cuda.initialize
2023-06-22 23:45:36,776 - distributed.preloading - INFO - Creating preload: dask_cuda.initialize
2023-06-22 23:45:36,776 - distributed.preloading - INFO - Creating preload: dask_cuda.initialize
2023-06-22 23:45:36,776 - distributed.preloading - INFO - Import preload module: dask_cuda.initialize
2023-06-22 23:45:36,776 - distributed.preloading - INFO - Import preload module: dask_cuda.initialize
2023-06-22 23:45:36,842 - distributed.preloading - INFO - Creating preload: dask_cuda.initialize
2023-06-22 23:45:36,843 - distributed.preloading - INFO - Import preload module: dask_cuda.initialize
2023-06-22 23:45:37,101 - distributed.preloading - INFO - Run preload setup: dask_cuda.initialize
2023-06-22 23:45:37,212 - distributed.preloading - INFO - Run preload setup: dask_cuda.initialize
2023-06-22 23:45:37,215 - distributed.preloading - INFO - Run preload setup: dask_cuda.initialize
2023-06-22 23:45:37,217 - distributed.preloading - INFO - Run preload setup: dask_cuda.initialize
2023-06-22 23:45:37,218 - distributed.preloading - INFO - Run preload setup: dask_cuda.initialize
2023-06-22 23:45:37,222 - distributed.preloading - INFO - Run preload setup: dask_cuda.initialize
2023-06-22 23:45:37,225 - distributed.preloading - INFO - Run preload setup: dask_cuda.initialize
2023-06-22 23:45:37,298 - distributed.preloading - INFO - Run preload setup: dask_cuda.initialize
2023-06-22 23:45:38,741 - distributed.worker - INFO -       Start worker at:  tcp://10.33.227.169:41801
2023-06-22 23:45:38,741 - distributed.worker - INFO -          Listening to:  tcp://10.33.227.169:41801
2023-06-22 23:45:38,741 - distributed.worker - INFO -          dashboard at:        10.33.227.169:38091
2023-06-22 23:45:38,742 - distributed.worker - INFO - Waiting to connect to:   tcp://10.33.227.169:8786
2023-06-22 23:45:38,742 - distributed.worker - INFO - -------------------------------------------------
2023-06-22 23:45:38,742 - distributed.worker - INFO -               Threads:                          1
2023-06-22 23:45:38,742 - distributed.worker - INFO -                Memory:                  62.97 GiB
2023-06-22 23:45:38,742 - distributed.worker - INFO -       Local Directory: /tmp/dask-scratch-space/worker-pe2nt62a
2023-06-22 23:45:38,742 - distributed.worker - INFO - Starting Worker plugin RMMSetup-f75bbb22-9217-419b-ae00-93b684f81693
2023-06-22 23:45:38,941 - distributed.worker - INFO - Starting Worker plugin CPUAffinity-87641386-7079-4243-8c4b-3b1f0b47de03
2023-06-22 23:45:38,941 - distributed.worker - INFO - Starting Worker plugin PreImport-ab0d88bb-a7c3-4dc2-8f1d-9644f2b91607
2023-06-22 23:45:38,942 - distributed.worker - INFO - -------------------------------------------------
2023-06-22 23:45:38,956 - distributed.worker - INFO -         Registered to:   tcp://10.33.227.169:8786
2023-06-22 23:45:38,956 - distributed.worker - INFO - -------------------------------------------------
2023-06-22 23:45:38,957 - distributed.core - INFO - Starting established connection to tcp://10.33.227.169:8786
2023-06-22 23:45:39,668 - distributed.worker - INFO -       Start worker at:  tcp://10.33.227.169:39469
2023-06-22 23:45:39,668 - distributed.worker - INFO -          Listening to:  tcp://10.33.227.169:39469
2023-06-22 23:45:39,668 - distributed.worker - INFO -          dashboard at:        10.33.227.169:40401
2023-06-22 23:45:39,668 - distributed.worker - INFO - Waiting to connect to:   tcp://10.33.227.169:8786
2023-06-22 23:45:39,668 - distributed.worker - INFO - -------------------------------------------------
2023-06-22 23:45:39,669 - distributed.worker - INFO -               Threads:                          1
2023-06-22 23:45:39,669 - distributed.worker - INFO -                Memory:                  62.97 GiB
2023-06-22 23:45:39,669 - distributed.worker - INFO -       Local Directory: /tmp/dask-scratch-space/worker-ojurmaai
2023-06-22 23:45:39,669 - distributed.worker - INFO - Starting Worker plugin RMMSetup-bcbbfe2f-4ee7-4416-a1ab-b9bb8d3ae89c
2023-06-22 23:45:39,670 - distributed.worker - INFO -       Start worker at:  tcp://10.33.227.169:40299
2023-06-22 23:45:39,670 - distributed.worker - INFO -          Listening to:  tcp://10.33.227.169:40299
2023-06-22 23:45:39,670 - distributed.worker - INFO -          dashboard at:        10.33.227.169:44437
2023-06-22 23:45:39,670 - distributed.worker - INFO - Waiting to connect to:   tcp://10.33.227.169:8786
2023-06-22 23:45:39,670 - distributed.worker - INFO - -------------------------------------------------
2023-06-22 23:45:39,671 - distributed.worker - INFO -               Threads:                          1
2023-06-22 23:45:39,671 - distributed.worker - INFO -                Memory:                  62.97 GiB
2023-06-22 23:45:39,671 - distributed.worker - INFO -       Local Directory: /tmp/dask-scratch-space/worker-ufp1n5n2
2023-06-22 23:45:39,671 - distributed.worker - INFO - Starting Worker plugin PreImport-6c1cffa0-75f9-4a21-840d-b487c5d5e92c
2023-06-22 23:45:39,672 - distributed.worker - INFO - Starting Worker plugin CPUAffinity-d9ef99dc-ccd7-4e32-9a8d-feade2329c2b
2023-06-22 23:45:39,672 - distributed.worker - INFO - Starting Worker plugin RMMSetup-32d1ff83-d11e-43bc-99e7-d5fef6ed8502
2023-06-22 23:45:39,677 - distributed.worker - INFO -       Start worker at:  tcp://10.33.227.169:46407
2023-06-22 23:45:39,677 - distributed.worker - INFO -          Listening to:  tcp://10.33.227.169:46407
2023-06-22 23:45:39,677 - distributed.worker - INFO -          dashboard at:        10.33.227.169:35229
2023-06-22 23:45:39,677 - distributed.worker - INFO - Waiting to connect to:   tcp://10.33.227.169:8786
2023-06-22 23:45:39,677 - distributed.worker - INFO - -------------------------------------------------
2023-06-22 23:45:39,677 - distributed.worker - INFO -               Threads:                          1
2023-06-22 23:45:39,677 - distributed.worker - INFO -                Memory:                  62.97 GiB
2023-06-22 23:45:39,677 - distributed.worker - INFO -       Local Directory: /tmp/dask-scratch-space/worker-w7q9g_7a
2023-06-22 23:45:39,678 - distributed.worker - INFO - Starting Worker plugin CPUAffinity-b43193a0-9902-4ae5-a891-d94abb427391
2023-06-22 23:45:39,678 - distributed.worker - INFO - Starting Worker plugin PreImport-2fef0180-9c2d-48ae-9275-c58cf79606b8
2023-06-22 23:45:39,678 - distributed.worker - INFO - Starting Worker plugin RMMSetup-fbf6ca06-5154-4546-8150-18354e91d6d9
2023-06-22 23:45:39,685 - distributed.worker - INFO -       Start worker at:  tcp://10.33.227.169:43065
2023-06-22 23:45:39,686 - distributed.worker - INFO -          Listening to:  tcp://10.33.227.169:43065
2023-06-22 23:45:39,686 - distributed.worker - INFO -          dashboard at:        10.33.227.169:36503
2023-06-22 23:45:39,686 - distributed.worker - INFO - Waiting to connect to:   tcp://10.33.227.169:8786
2023-06-22 23:45:39,686 - distributed.worker - INFO - -------------------------------------------------
2023-06-22 23:45:39,686 - distributed.worker - INFO -               Threads:                          1
2023-06-22 23:45:39,686 - distributed.worker - INFO -                Memory:                  62.97 GiB
2023-06-22 23:45:39,686 - distributed.worker - INFO -       Local Directory: /tmp/dask-scratch-space/worker-lj9_fdh0
2023-06-22 23:45:39,686 - distributed.worker - INFO - Starting Worker plugin RMMSetup-018ce1a0-3a5f-424e-a132-fd5d7db111aa
2023-06-22 23:45:39,686 - distributed.worker - INFO -       Start worker at:  tcp://10.33.227.169:36967
2023-06-22 23:45:39,687 - distributed.worker - INFO -          Listening to:  tcp://10.33.227.169:36967
2023-06-22 23:45:39,687 - distributed.worker - INFO -          dashboard at:        10.33.227.169:45379
2023-06-22 23:45:39,687 - distributed.worker - INFO - Waiting to connect to:   tcp://10.33.227.169:8786
2023-06-22 23:45:39,687 - distributed.worker - INFO - -------------------------------------------------
2023-06-22 23:45:39,687 - distributed.worker - INFO -               Threads:                          1
2023-06-22 23:45:39,687 - distributed.worker - INFO -                Memory:                  62.97 GiB
2023-06-22 23:45:39,687 - distributed.worker - INFO -       Local Directory: /tmp/dask-scratch-space/worker-8k6ajuq3
2023-06-22 23:45:39,687 - distributed.worker - INFO - Starting Worker plugin PreImport-6195e0f5-2163-4968-a083-3ab69a557e6b
2023-06-22 23:45:39,688 - distributed.worker - INFO - Starting Worker plugin CPUAffinity-6c4ea42a-1d25-4ffa-ad61-7bb4d3ca1d3a
2023-06-22 23:45:39,688 - distributed.worker - INFO - Starting Worker plugin RMMSetup-5b8f2779-4bab-4c3d-9330-410e1b11e924
2023-06-22 23:45:39,688 - distributed.worker - INFO -       Start worker at:  tcp://10.33.227.169:36283
2023-06-22 23:45:39,689 - distributed.worker - INFO -          Listening to:  tcp://10.33.227.169:36283
2023-06-22 23:45:39,689 - distributed.worker - INFO -          dashboard at:        10.33.227.169:42645
2023-06-22 23:45:39,689 - distributed.worker - INFO - Waiting to connect to:   tcp://10.33.227.169:8786
2023-06-22 23:45:39,689 - distributed.worker - INFO - -------------------------------------------------
2023-06-22 23:45:39,689 - distributed.worker - INFO -               Threads:                          1
2023-06-22 23:45:39,689 - distributed.worker - INFO -                Memory:                  62.97 GiB
2023-06-22 23:45:39,689 - distributed.worker - INFO -       Local Directory: /tmp/dask-scratch-space/worker-f6ea_y1j
2023-06-22 23:45:39,689 - distributed.worker - INFO -       Start worker at:  tcp://10.33.227.169:41829
2023-06-22 23:45:39,690 - distributed.worker - INFO -          Listening to:  tcp://10.33.227.169:41829
2023-06-22 23:45:39,690 - distributed.worker - INFO -          dashboard at:        10.33.227.169:33907
2023-06-22 23:45:39,690 - distributed.worker - INFO - Waiting to connect to:   tcp://10.33.227.169:8786
2023-06-22 23:45:39,690 - distributed.worker - INFO - -------------------------------------------------
2023-06-22 23:45:39,690 - distributed.worker - INFO -               Threads:                          1
2023-06-22 23:45:39,690 - distributed.worker - INFO - Starting Worker plugin CPUAffinity-38685937-36e0-44bc-8116-4a63ade37089
2023-06-22 23:45:39,690 - distributed.worker - INFO -                Memory:                  62.97 GiB
2023-06-22 23:45:39,690 - distributed.worker - INFO - Starting Worker plugin PreImport-e4f51af3-3bc7-433e-adb3-6b2806dce3ef
2023-06-22 23:45:39,690 - distributed.worker - INFO -       Local Directory: /tmp/dask-scratch-space/worker-3li2n5s7
2023-06-22 23:45:39,690 - distributed.worker - INFO - Starting Worker plugin RMMSetup-9fcb4c88-1892-45ca-872e-1afc0a96b929
2023-06-22 23:45:39,691 - distributed.worker - INFO - Starting Worker plugin CPUAffinity-30b39055-bbbd-4c98-82f0-de9a4b64141d
2023-06-22 23:45:39,695 - distributed.worker - INFO - Starting Worker plugin PreImport-7dcbd5a6-4c97-4334-8210-8bae9d35f075
2023-06-22 23:45:39,695 - distributed.worker - INFO - Starting Worker plugin RMMSetup-61932357-f807-438a-b68b-a125d8b209c7
2023-06-22 23:45:39,851 - distributed.worker - INFO - Starting Worker plugin PreImport-ed0be15b-a98b-4243-b20d-071771a6565e
2023-06-22 23:45:39,852 - distributed.worker - INFO - Starting Worker plugin CPUAffinity-45401ca1-383d-4fc8-9b18-9f5cf53012ae
2023-06-22 23:45:39,852 - distributed.worker - INFO - -------------------------------------------------
2023-06-22 23:45:39,852 - distributed.worker - INFO - Starting Worker plugin CPUAffinity-49db7a30-8dd0-43ee-916f-1de5766be64c
2023-06-22 23:45:39,852 - distributed.worker - INFO - -------------------------------------------------
2023-06-22 23:45:39,853 - distributed.worker - INFO - -------------------------------------------------
2023-06-22 23:45:39,853 - distributed.worker - INFO - -------------------------------------------------
2023-06-22 23:45:39,853 - distributed.worker - INFO - Starting Worker plugin PreImport-8dc289d0-493f-4407-bb62-083b2068f60a
2023-06-22 23:45:39,855 - distributed.worker - INFO - -------------------------------------------------
2023-06-22 23:45:39,862 - distributed.worker - INFO -         Registered to:   tcp://10.33.227.169:8786
2023-06-22 23:45:39,862 - distributed.worker - INFO - -------------------------------------------------
2023-06-22 23:45:39,864 - distributed.core - INFO - Starting established connection to tcp://10.33.227.169:8786
2023-06-22 23:45:39,865 - distributed.worker - INFO -         Registered to:   tcp://10.33.227.169:8786
2023-06-22 23:45:39,865 - distributed.worker - INFO - -------------------------------------------------
2023-06-22 23:45:39,866 - distributed.worker - INFO -         Registered to:   tcp://10.33.227.169:8786
2023-06-22 23:45:39,867 - distributed.worker - INFO - -------------------------------------------------
2023-06-22 23:45:39,868 - distributed.core - INFO - Starting established connection to tcp://10.33.227.169:8786
2023-06-22 23:45:39,868 - distributed.worker - INFO -         Registered to:   tcp://10.33.227.169:8786
2023-06-22 23:45:39,868 - distributed.worker - INFO - -------------------------------------------------
2023-06-22 23:45:39,869 - distributed.core - INFO - Starting established connection to tcp://10.33.227.169:8786
2023-06-22 23:45:39,870 - distributed.worker - INFO -         Registered to:   tcp://10.33.227.169:8786
2023-06-22 23:45:39,870 - distributed.worker - INFO - -------------------------------------------------
2023-06-22 23:45:39,871 - distributed.core - INFO - Starting established connection to tcp://10.33.227.169:8786
2023-06-22 23:45:39,872 - distributed.core - INFO - Starting established connection to tcp://10.33.227.169:8786
2023-06-22 23:45:39,891 - distributed.worker - INFO - -------------------------------------------------
2023-06-22 23:45:39,892 - distributed.worker - INFO - -------------------------------------------------
2023-06-22 23:45:39,900 - distributed.worker - INFO -         Registered to:   tcp://10.33.227.169:8786
2023-06-22 23:45:39,900 - distributed.worker - INFO - -------------------------------------------------
2023-06-22 23:45:39,901 - distributed.worker - INFO -         Registered to:   tcp://10.33.227.169:8786
2023-06-22 23:45:39,901 - distributed.worker - INFO - -------------------------------------------------
2023-06-22 23:45:39,901 - distributed.core - INFO - Starting established connection to tcp://10.33.227.169:8786
2023-06-22 23:45:39,903 - distributed.core - INFO - Starting established connection to tcp://10.33.227.169:8786
2023-06-22 23:45:41,047 - distributed.worker - INFO - Run out-of-band function '_func_ucp_listener_port'
2023-06-22 23:45:41,047 - distributed.worker - INFO - Run out-of-band function '_func_ucp_listener_port'
2023-06-22 23:45:41,047 - distributed.worker - INFO - Run out-of-band function '_func_ucp_listener_port'
2023-06-22 23:45:41,048 - distributed.worker - INFO - Run out-of-band function '_func_ucp_listener_port'
2023-06-22 23:45:41,048 - distributed.worker - INFO - Run out-of-band function '_func_ucp_listener_port'
2023-06-22 23:45:41,048 - distributed.worker - INFO - Run out-of-band function '_func_ucp_listener_port'
2023-06-22 23:45:41,048 - distributed.worker - INFO - Run out-of-band function '_func_ucp_listener_port'
2023-06-22 23:45:41,049 - distributed.worker - INFO - Run out-of-band function '_func_ucp_listener_port'
2023-06-22 23:45:41,140 - distributed.worker - INFO - Run out-of-band function '_func_init_all'
2023-06-22 23:45:41,140 - distributed.worker - INFO - Run out-of-band function '_func_init_all'
2023-06-22 23:45:41,140 - distributed.worker - INFO - Run out-of-band function '_func_init_all'
2023-06-22 23:45:41,140 - distributed.worker - INFO - Run out-of-band function '_func_init_all'
2023-06-22 23:45:41,140 - distributed.worker - INFO - Run out-of-band function '_func_init_all'
2023-06-22 23:45:41,140 - distributed.worker - INFO - Run out-of-band function '_func_init_all'
2023-06-22 23:45:41,140 - distributed.worker - INFO - Run out-of-band function '_func_init_all'
2023-06-22 23:45:41,141 - distributed.worker - INFO - Run out-of-band function '_func_init_all'
2023-06-22 23:45:51,808 - distributed.worker - INFO - Run out-of-band function '_subcomm_init'
2023-06-22 23:45:51,954 - distributed.worker - INFO - Run out-of-band function '_subcomm_init'
2023-06-22 23:45:51,983 - distributed.worker - INFO - Run out-of-band function '_subcomm_init'
2023-06-22 23:45:51,998 - distributed.worker - INFO - Run out-of-band function '_subcomm_init'
2023-06-22 23:45:52,237 - distributed.worker - INFO - Run out-of-band function '_subcomm_init'
2023-06-22 23:45:52,239 - distributed.worker - INFO - Run out-of-band function '_subcomm_init'
2023-06-22 23:45:52,246 - distributed.worker - INFO - Run out-of-band function '_subcomm_init'
2023-06-22 23:45:52,260 - distributed.worker - INFO - Run out-of-band function '_subcomm_init'
2023-06-22 23:45:58,446 - distributed.core - INFO - Event loop was unresponsive in Worker for 15.82s.  This is often caused by long-running GIL-holding functions or moving large chunks of data. This can cause timeouts and instability.
2023-06-22 23:45:58,446 - distributed.core - INFO - Event loop was unresponsive in Worker for 15.82s.  This is often caused by long-running GIL-holding functions or moving large chunks of data. This can cause timeouts and instability.
2023-06-22 23:45:58,447 - distributed.core - INFO - Event loop was unresponsive in Worker for 15.82s.  This is often caused by long-running GIL-holding functions or moving large chunks of data. This can cause timeouts and instability.
2023-06-22 23:45:58,447 - distributed.core - INFO - Event loop was unresponsive in Worker for 15.83s.  This is often caused by long-running GIL-holding functions or moving large chunks of data. This can cause timeouts and instability.
2023-06-22 23:45:58,481 - distributed.core - INFO - Event loop was unresponsive in Worker for 15.85s.  This is often caused by long-running GIL-holding functions or moving large chunks of data. This can cause timeouts and instability.
2023-06-22 23:45:58,481 - distributed.core - INFO - Event loop was unresponsive in Worker for 15.86s.  This is often caused by long-running GIL-holding functions or moving large chunks of data. This can cause timeouts and instability.
2023-06-22 23:45:58,482 - distributed.core - INFO - Event loop was unresponsive in Worker for 15.86s.  This is often caused by long-running GIL-holding functions or moving large chunks of data. This can cause timeouts and instability.
2023-06-22 23:45:58,482 - distributed.core - INFO - Event loop was unresponsive in Worker for 15.86s.  This is often caused by long-running GIL-holding functions or moving large chunks of data. This can cause timeouts and instability.
2023-06-22 23:46:33,338 - distributed.worker - INFO - Run out-of-band function 'collect'
2023-06-22 23:46:33,338 - distributed.worker - INFO - Run out-of-band function 'collect'
2023-06-22 23:46:33,343 - distributed.worker - INFO - Run out-of-band function 'collect'
2023-06-22 23:46:33,343 - distributed.worker - INFO - Run out-of-band function 'collect'
2023-06-22 23:46:33,343 - distributed.worker - INFO - Run out-of-band function 'collect'
2023-06-22 23:46:33,343 - distributed.worker - INFO - Run out-of-band function 'collect'
2023-06-22 23:46:33,343 - distributed.worker - INFO - Run out-of-band function 'collect'
2023-06-22 23:46:33,343 - distributed.worker - INFO - Run out-of-band function 'collect'
2023-06-22 23:46:40,993 - distributed.worker - INFO - Run out-of-band function '_func_destroy_all'
2023-06-22 23:46:40,993 - distributed.worker - INFO - Run out-of-band function '_func_destroy_all'
2023-06-22 23:46:40,993 - distributed.worker - INFO - Run out-of-band function '_func_destroy_all'
2023-06-22 23:46:40,993 - distributed.worker - INFO - Run out-of-band function '_func_destroy_all'
2023-06-22 23:46:40,993 - distributed.worker - INFO - Run out-of-band function '_func_destroy_all'
2023-06-22 23:46:40,994 - distributed.worker - INFO - Run out-of-band function '_func_destroy_all'
2023-06-22 23:46:40,994 - distributed.worker - INFO - Run out-of-band function '_func_destroy_all'
2023-06-22 23:46:40,994 - distributed.worker - INFO - Run out-of-band function '_func_destroy_all'
2023-06-22 23:55:13,550 - distributed.worker - INFO - Stopping worker at tcp://10.33.227.169:41801. Reason: worker-handle-scheduler-connection-broken
2023-06-22 23:55:13,550 - distributed.worker - INFO - Stopping worker at tcp://10.33.227.169:36967. Reason: worker-handle-scheduler-connection-broken
2023-06-22 23:55:13,550 - distributed.worker - INFO - Stopping worker at tcp://10.33.227.169:36283. Reason: worker-close
2023-06-22 23:55:13,550 - distributed.worker - INFO - Stopping worker at tcp://10.33.227.169:41829. Reason: worker-handle-scheduler-connection-broken
2023-06-22 23:55:13,550 - distributed.worker - INFO - Stopping worker at tcp://10.33.227.169:43065. Reason: worker-handle-scheduler-connection-broken
2023-06-22 23:55:13,550 - distributed.worker - INFO - Stopping worker at tcp://10.33.227.169:40299. Reason: worker-handle-scheduler-connection-broken
2023-06-22 23:55:13,550 - distributed.worker - INFO - Stopping worker at tcp://10.33.227.169:46407. Reason: worker-close
2023-06-22 23:55:13,550 - distributed.worker - INFO - Stopping worker at tcp://10.33.227.169:39469. Reason: worker-close
2023-06-22 23:55:13,550 - distributed.nanny - INFO - Closing Nanny at 'tcp://10.33.227.169:39309'. Reason: nanny-close
2023-06-22 23:55:13,552 - distributed.nanny - INFO - Nanny asking worker to close. Reason: nanny-close
2023-06-22 23:55:13,553 - distributed.nanny - INFO - Closing Nanny at 'tcp://10.33.227.169:34873'. Reason: nanny-close
2023-06-22 23:55:13,554 - distributed.nanny - INFO - Nanny asking worker to close. Reason: nanny-close
2023-06-22 23:55:13,554 - distributed.nanny - INFO - Closing Nanny at 'tcp://10.33.227.169:42441'. Reason: nanny-close
2023-06-22 23:55:13,555 - distributed.nanny - INFO - Nanny asking worker to close. Reason: nanny-close
2023-06-22 23:55:13,555 - distributed.nanny - INFO - Closing Nanny at 'tcp://10.33.227.169:42773'. Reason: nanny-close
2023-06-22 23:55:13,555 - distributed.nanny - INFO - Nanny asking worker to close. Reason: nanny-close
2023-06-22 23:55:13,556 - distributed.nanny - INFO - Closing Nanny at 'tcp://10.33.227.169:35755'. Reason: nanny-close
2023-06-22 23:55:13,553 - distributed.batched - INFO - Batched Comm Closed <TCP (closed) Worker->Scheduler local=tcp://10.33.227.169:33478 remote=tcp://10.33.227.169:8786>
Traceback (most recent call last):
  File "/opt/conda/envs/rapids/lib/python3.10/asyncio/runners.py", line 44, in run
    return loop.run_until_complete(main)
  File "/opt/conda/envs/rapids/lib/python3.10/asyncio/base_events.py", line 636, in run_until_complete
    self.run_forever()
  File "/opt/conda/envs/rapids/lib/python3.10/asyncio/base_events.py", line 603, in run_forever
    self._run_once()
  File "/opt/conda/envs/rapids/lib/python3.10/asyncio/base_events.py", line 1871, in _run_once
    event_list = self._selector.select(timeout)
  File "/opt/conda/envs/rapids/lib/python3.10/selectors.py", line 469, in select
    fd_event_list = self._selector.poll(timeout, max_ev)
KeyboardInterrupt

During handling of the above exception, another exception occurred:

Traceback (most recent call last):
  File "/opt/conda/envs/rapids/lib/python3.10/site-packages/distributed/batched.py", line 115, in _background_send
    nbytes = yield coro
  File "/opt/conda/envs/rapids/lib/python3.10/site-packages/tornado/gen.py", line 767, in run
    value = future.result()
  File "/opt/conda/envs/rapids/lib/python3.10/site-packages/distributed/comm/tcp.py", line 269, in write
    raise CommClosedError()
distributed.comm.core.CommClosedError
2023-06-22 23:55:13,556 - distributed.nanny - INFO - Nanny asking worker to close. Reason: nanny-close
2023-06-22 23:55:13,556 - distributed.nanny - INFO - Closing Nanny at 'tcp://10.33.227.169:34975'. Reason: nanny-close
2023-06-22 23:55:13,557 - distributed.nanny - INFO - Nanny asking worker to close. Reason: nanny-close
2023-06-22 23:55:13,557 - distributed.nanny - INFO - Closing Nanny at 'tcp://10.33.227.169:34759'. Reason: nanny-close
2023-06-22 23:55:13,557 - distributed.nanny - INFO - Nanny asking worker to close. Reason: nanny-close
2023-06-22 23:55:13,554 - distributed.batched - INFO - Batched Comm Closed <TCP (closed) Worker->Scheduler local=tcp://10.33.227.169:33486 remote=tcp://10.33.227.169:8786>
Traceback (most recent call last):
  File "/opt/conda/envs/rapids/lib/python3.10/asyncio/runners.py", line 44, in run
    return loop.run_until_complete(main)
  File "/opt/conda/envs/rapids/lib/python3.10/asyncio/base_events.py", line 636, in run_until_complete
    self.run_forever()
  File "/opt/conda/envs/rapids/lib/python3.10/asyncio/base_events.py", line 603, in run_forever
    self._run_once()
  File "/opt/conda/envs/rapids/lib/python3.10/asyncio/base_events.py", line 1871, in _run_once
    event_list = self._selector.select(timeout)
  File "/opt/conda/envs/rapids/lib/python3.10/selectors.py", line 469, in select
    fd_event_list = self._selector.poll(timeout, max_ev)
KeyboardInterrupt

During handling of the above exception, another exception occurred:

Traceback (most recent call last):
  File "/opt/conda/envs/rapids/lib/python3.10/site-packages/distributed/batched.py", line 115, in _background_send
    nbytes = yield coro
  File "/opt/conda/envs/rapids/lib/python3.10/site-packages/tornado/gen.py", line 767, in run
    value = future.result()
  File "/opt/conda/envs/rapids/lib/python3.10/site-packages/distributed/comm/tcp.py", line 269, in write
    raise CommClosedError()
distributed.comm.core.CommClosedError
2023-06-22 23:55:13,554 - distributed.batched - INFO - Batched Comm Closed <TCP (closed) Worker->Scheduler local=tcp://10.33.227.169:33512 remote=tcp://10.33.227.169:8786>
Traceback (most recent call last):
  File "/opt/conda/envs/rapids/lib/python3.10/asyncio/runners.py", line 44, in run
    return loop.run_until_complete(main)
  File "/opt/conda/envs/rapids/lib/python3.10/asyncio/base_events.py", line 636, in run_until_complete
    self.run_forever()
  File "/opt/conda/envs/rapids/lib/python3.10/asyncio/base_events.py", line 603, in run_forever
    self._run_once()
  File "/opt/conda/envs/rapids/lib/python3.10/asyncio/base_events.py", line 1871, in _run_once
    event_list = self._selector.select(timeout)
  File "/opt/conda/envs/rapids/lib/python3.10/selectors.py", line 469, in select
    fd_event_list = self._selector.poll(timeout, max_ev)
KeyboardInterrupt

During handling of the above exception, another exception occurred:

Traceback (most recent call last):
  File "/opt/conda/envs/rapids/lib/python3.10/site-packages/distributed/batched.py", line 115, in _background_send
    nbytes = yield coro
  File "/opt/conda/envs/rapids/lib/python3.10/site-packages/tornado/gen.py", line 767, in run
    value = future.result()
  File "/opt/conda/envs/rapids/lib/python3.10/site-packages/distributed/comm/tcp.py", line 269, in write
    raise CommClosedError()
distributed.comm.core.CommClosedError
2023-06-22 23:55:13,558 - distributed.nanny - INFO - Closing Nanny at 'tcp://10.33.227.169:33627'. Reason: nanny-close
2023-06-22 23:55:13,558 - distributed.nanny - INFO - Nanny asking worker to close. Reason: nanny-close
2023-06-22 23:55:13,579 - distributed.worker - ERROR - Timed out during handshake while connecting to tcp://10.33.227.169:42773 after 100 s
Traceback (most recent call last):
  File "/opt/conda/envs/rapids/lib/python3.10/asyncio/runners.py", line 44, in run
    return loop.run_until_complete(main)
  File "/opt/conda/envs/rapids/lib/python3.10/asyncio/base_events.py", line 636, in run_until_complete
    self.run_forever()
  File "/opt/conda/envs/rapids/lib/python3.10/asyncio/base_events.py", line 603, in run_forever
    self._run_once()
  File "/opt/conda/envs/rapids/lib/python3.10/asyncio/base_events.py", line 1871, in _run_once
    event_list = self._selector.select(timeout)
  File "/opt/conda/envs/rapids/lib/python3.10/selectors.py", line 469, in select
    fd_event_list = self._selector.poll(timeout, max_ev)
KeyboardInterrupt

During handling of the above exception, another exception occurred:

Traceback (most recent call last):
  File "/opt/conda/envs/rapids/lib/python3.10/site-packages/tornado/iostream.py", line 861, in _read_to_buffer
    bytes_read = self.read_from_fd(buf)
  File "/opt/conda/envs/rapids/lib/python3.10/site-packages/tornado/iostream.py", line 1116, in read_from_fd
    return self.socket.recv_into(buf, len(buf))
ConnectionResetError: [Errno 104] Connection reset by peer

The above exception was the direct cause of the following exception:

Traceback (most recent call last):
  File "/opt/conda/envs/rapids/lib/python3.10/site-packages/distributed/comm/core.py", line 373, in connect
    handshake = await wait_for(comm.read(), time_left())
  File "/opt/conda/envs/rapids/lib/python3.10/site-packages/distributed/utils.py", line 1878, in wait_for
    return await asyncio.wait_for(fut, timeout)
  File "/opt/conda/envs/rapids/lib/python3.10/asyncio/tasks.py", line 445, in wait_for
    return fut.result()
  File "/opt/conda/envs/rapids/lib/python3.10/site-packages/distributed/comm/tcp.py", line 241, in read
    convert_stream_closed_error(self, e)
  File "/opt/conda/envs/rapids/lib/python3.10/site-packages/distributed/comm/tcp.py", line 142, in convert_stream_closed_error
    raise CommClosedError(f"in {obj}: {exc.__class__.__name__}: {exc}") from exc
distributed.comm.core.CommClosedError: in <TCP (closed)  local=tcp://10.33.227.169:33372 remote=tcp://10.33.227.169:42773>: ConnectionResetError: [Errno 104] Connection reset by peer

The above exception was the direct cause of the following exception:

Traceback (most recent call last):
  File "/opt/conda/envs/rapids/lib/python3.10/site-packages/distributed/utils.py", line 754, in wrapper
    return await func(*args, **kwargs)
  File "/opt/conda/envs/rapids/lib/python3.10/site-packages/distributed/worker.py", line 1540, in close
    await r.close_gracefully(reason=reason)
  File "/opt/conda/envs/rapids/lib/python3.10/site-packages/distributed/core.py", line 1362, in send_recv_from_rpc
    comm = await self.pool.connect(self.addr)
  File "/opt/conda/envs/rapids/lib/python3.10/site-packages/distributed/core.py", line 1606, in connect
    return await connect_attempt
  File "/opt/conda/envs/rapids/lib/python3.10/site-packages/distributed/core.py", line 1527, in _connect
    comm = await connect(
  File "/opt/conda/envs/rapids/lib/python3.10/site-packages/distributed/comm/core.py", line 378, in connect
    raise OSError(
OSError: Timed out during handshake while connecting to tcp://10.33.227.169:42773 after 100 s
2023-06-22 23:55:13,580 - distributed.worker - ERROR - Timed out during handshake while connecting to tcp://10.33.227.169:34759 after 100 s
Traceback (most recent call last):
  File "/opt/conda/envs/rapids/lib/python3.10/asyncio/runners.py", line 44, in run
    return loop.run_until_complete(main)
  File "/opt/conda/envs/rapids/lib/python3.10/asyncio/base_events.py", line 636, in run_until_complete
    self.run_forever()
  File "/opt/conda/envs/rapids/lib/python3.10/asyncio/base_events.py", line 603, in run_forever
    self._run_once()
  File "/opt/conda/envs/rapids/lib/python3.10/asyncio/base_events.py", line 1871, in _run_once
    event_list = self._selector.select(timeout)
  File "/opt/conda/envs/rapids/lib/python3.10/selectors.py", line 469, in select
    fd_event_list = self._selector.poll(timeout, max_ev)
KeyboardInterrupt

During handling of the above exception, another exception occurred:

Traceback (most recent call last):
  File "/opt/conda/envs/rapids/lib/python3.10/site-packages/tornado/iostream.py", line 861, in _read_to_buffer
    bytes_read = self.read_from_fd(buf)
  File "/opt/conda/envs/rapids/lib/python3.10/site-packages/tornado/iostream.py", line 1116, in read_from_fd
    return self.socket.recv_into(buf, len(buf))
ConnectionResetError: [Errno 104] Connection reset by peer

The above exception was the direct cause of the following exception:

Traceback (most recent call last):
  File "/opt/conda/envs/rapids/lib/python3.10/site-packages/distributed/comm/core.py", line 373, in connect
    handshake = await wait_for(comm.read(), time_left())
  File "/opt/conda/envs/rapids/lib/python3.10/site-packages/distributed/utils.py", line 1878, in wait_for
    return await asyncio.wait_for(fut, timeout)
  File "/opt/conda/envs/rapids/lib/python3.10/asyncio/tasks.py", line 445, in wait_for
    return fut.result()
  File "/opt/conda/envs/rapids/lib/python3.10/site-packages/distributed/comm/tcp.py", line 241, in read
    convert_stream_closed_error(self, e)
  File "/opt/conda/envs/rapids/lib/python3.10/site-packages/distributed/comm/tcp.py", line 142, in convert_stream_closed_error
    raise CommClosedError(f"in {obj}: {exc.__class__.__name__}: {exc}") from exc
distributed.comm.core.CommClosedError: in <TCP (closed)  local=tcp://10.33.227.169:49868 remote=tcp://10.33.227.169:34759>: ConnectionResetError: [Errno 104] Connection reset by peer

The above exception was the direct cause of the following exception:

Traceback (most recent call last):
  File "/opt/conda/envs/rapids/lib/python3.10/site-packages/distributed/utils.py", line 754, in wrapper
    return await func(*args, **kwargs)
  File "/opt/conda/envs/rapids/lib/python3.10/site-packages/distributed/worker.py", line 1540, in close
    await r.close_gracefully(reason=reason)
  File "/opt/conda/envs/rapids/lib/python3.10/site-packages/distributed/core.py", line 1362, in send_recv_from_rpc
    comm = await self.pool.connect(self.addr)
  File "/opt/conda/envs/rapids/lib/python3.10/site-packages/distributed/core.py", line 1606, in connect
    return await connect_attempt
  File "/opt/conda/envs/rapids/lib/python3.10/site-packages/distributed/core.py", line 1527, in _connect
    comm = await connect(
  File "/opt/conda/envs/rapids/lib/python3.10/site-packages/distributed/comm/core.py", line 378, in connect
    raise OSError(
OSError: Timed out during handshake while connecting to tcp://10.33.227.169:34759 after 100 s
2023-06-22 23:55:13,581 - distributed.worker - ERROR - Timed out during handshake while connecting to tcp://10.33.227.169:33627 after 100 s
Traceback (most recent call last):
  File "/opt/conda/envs/rapids/lib/python3.10/asyncio/runners.py", line 44, in run
    return loop.run_until_complete(main)
  File "/opt/conda/envs/rapids/lib/python3.10/asyncio/base_events.py", line 636, in run_until_complete
    self.run_forever()
  File "/opt/conda/envs/rapids/lib/python3.10/asyncio/base_events.py", line 603, in run_forever
    self._run_once()
  File "/opt/conda/envs/rapids/lib/python3.10/asyncio/base_events.py", line 1871, in _run_once
    event_list = self._selector.select(timeout)
  File "/opt/conda/envs/rapids/lib/python3.10/selectors.py", line 469, in select
    fd_event_list = self._selector.poll(timeout, max_ev)
KeyboardInterrupt

During handling of the above exception, another exception occurred:

Traceback (most recent call last):
  File "/opt/conda/envs/rapids/lib/python3.10/site-packages/tornado/iostream.py", line 861, in _read_to_buffer
    bytes_read = self.read_from_fd(buf)
  File "/opt/conda/envs/rapids/lib/python3.10/site-packages/tornado/iostream.py", line 1116, in read_from_fd
    return self.socket.recv_into(buf, len(buf))
ConnectionResetError: [Errno 104] Connection reset by peer

The above exception was the direct cause of the following exception:

Traceback (most recent call last):
  File "/opt/conda/envs/rapids/lib/python3.10/site-packages/distributed/comm/core.py", line 373, in connect
    handshake = await wait_for(comm.read(), time_left())
  File "/opt/conda/envs/rapids/lib/python3.10/site-packages/distributed/utils.py", line 1878, in wait_for
    return await asyncio.wait_for(fut, timeout)
  File "/opt/conda/envs/rapids/lib/python3.10/asyncio/tasks.py", line 445, in wait_for
    return fut.result()
  File "/opt/conda/envs/rapids/lib/python3.10/site-packages/distributed/comm/tcp.py", line 241, in read
    convert_stream_closed_error(self, e)
  File "/opt/conda/envs/rapids/lib/python3.10/site-packages/distributed/comm/tcp.py", line 142, in convert_stream_closed_error
    raise CommClosedError(f"in {obj}: {exc.__class__.__name__}: {exc}") from exc
distributed.comm.core.CommClosedError: in <TCP (closed)  local=tcp://10.33.227.169:39176 remote=tcp://10.33.227.169:33627>: ConnectionResetError: [Errno 104] Connection reset by peer

The above exception was the direct cause of the following exception:

Traceback (most recent call last):
  File "/opt/conda/envs/rapids/lib/python3.10/site-packages/distributed/utils.py", line 754, in wrapper
    return await func(*args, **kwargs)
  File "/opt/conda/envs/rapids/lib/python3.10/site-packages/distributed/worker.py", line 1540, in close
    await r.close_gracefully(reason=reason)
  File "/opt/conda/envs/rapids/lib/python3.10/site-packages/distributed/core.py", line 1362, in send_recv_from_rpc
    comm = await self.pool.connect(self.addr)
  File "/opt/conda/envs/rapids/lib/python3.10/site-packages/distributed/core.py", line 1606, in connect
    return await connect_attempt
  File "/opt/conda/envs/rapids/lib/python3.10/site-packages/distributed/core.py", line 1527, in _connect
    comm = await connect(
  File "/opt/conda/envs/rapids/lib/python3.10/site-packages/distributed/comm/core.py", line 378, in connect
    raise OSError(
OSError: Timed out during handshake while connecting to tcp://10.33.227.169:33627 after 100 s
2023-06-22 23:55:13,580 - distributed.worker - ERROR - Timed out during handshake while connecting to tcp://10.33.227.169:35755 after 100 s
Traceback (most recent call last):
  File "/opt/conda/envs/rapids/lib/python3.10/asyncio/runners.py", line 44, in run
    return loop.run_until_complete(main)
  File "/opt/conda/envs/rapids/lib/python3.10/asyncio/base_events.py", line 636, in run_until_complete
    self.run_forever()
  File "/opt/conda/envs/rapids/lib/python3.10/asyncio/base_events.py", line 603, in run_forever
    self._run_once()
  File "/opt/conda/envs/rapids/lib/python3.10/asyncio/base_events.py", line 1871, in _run_once
    event_list = self._selector.select(timeout)
  File "/opt/conda/envs/rapids/lib/python3.10/selectors.py", line 469, in select
    fd_event_list = self._selector.poll(timeout, max_ev)
KeyboardInterrupt

During handling of the above exception, another exception occurred:

Traceback (most recent call last):
  File "/opt/conda/envs/rapids/lib/python3.10/site-packages/tornado/iostream.py", line 861, in _read_to_buffer
    bytes_read = self.read_from_fd(buf)
  File "/opt/conda/envs/rapids/lib/python3.10/site-packages/tornado/iostream.py", line 1116, in read_from_fd
    return self.socket.recv_into(buf, len(buf))
ConnectionResetError: [Errno 104] Connection reset by peer

The above exception was the direct cause of the following exception:

Traceback (most recent call last):
  File "/opt/conda/envs/rapids/lib/python3.10/site-packages/distributed/comm/core.py", line 373, in connect
    handshake = await wait_for(comm.read(), time_left())
  File "/opt/conda/envs/rapids/lib/python3.10/site-packages/distributed/utils.py", line 1878, in wait_for
    return await asyncio.wait_for(fut, timeout)
  File "/opt/conda/envs/rapids/lib/python3.10/asyncio/tasks.py", line 445, in wait_for
    return fut.result()
  File "/opt/conda/envs/rapids/lib/python3.10/site-packages/distributed/comm/tcp.py", line 241, in read
    convert_stream_closed_error(self, e)
  File "/opt/conda/envs/rapids/lib/python3.10/site-packages/distributed/comm/tcp.py", line 142, in convert_stream_closed_error
    raise CommClosedError(f"in {obj}: {exc.__class__.__name__}: {exc}") from exc
distributed.comm.core.CommClosedError: in <TCP (closed)  local=tcp://10.33.227.169:40688 remote=tcp://10.33.227.169:35755>: ConnectionResetError: [Errno 104] Connection reset by peer

The above exception was the direct cause of the following exception:

Traceback (most recent call last):
  File "/opt/conda/envs/rapids/lib/python3.10/site-packages/distributed/utils.py", line 754, in wrapper
    return await func(*args, **kwargs)
  File "/opt/conda/envs/rapids/lib/python3.10/site-packages/distributed/worker.py", line 1540, in close
    await r.close_gracefully(reason=reason)
  File "/opt/conda/envs/rapids/lib/python3.10/site-packages/distributed/core.py", line 1362, in send_recv_from_rpc
    comm = await self.pool.connect(self.addr)
  File "/opt/conda/envs/rapids/lib/python3.10/site-packages/distributed/core.py", line 1606, in connect
    return await connect_attempt
  File "/opt/conda/envs/rapids/lib/python3.10/site-packages/distributed/core.py", line 1527, in _connect
    comm = await connect(
  File "/opt/conda/envs/rapids/lib/python3.10/site-packages/distributed/comm/core.py", line 378, in connect
    raise OSError(
OSError: Timed out during handshake while connecting to tcp://10.33.227.169:35755 after 100 s
2023-06-22 23:55:16,759 - distributed.nanny - WARNING - Worker process still alive after 3.199981384277344 seconds, killing
2023-06-22 23:55:16,760 - distributed.nanny - WARNING - Worker process still alive after 3.199999389648438 seconds, killing
2023-06-22 23:55:16,760 - distributed.nanny - WARNING - Worker process still alive after 3.1999992370605472 seconds, killing
2023-06-22 23:55:16,761 - distributed.nanny - WARNING - Worker process still alive after 3.1999992370605472 seconds, killing
2023-06-22 23:55:16,761 - distributed.nanny - WARNING - Worker process still alive after 3.1999992370605472 seconds, killing
2023-06-22 23:55:16,762 - distributed.nanny - WARNING - Worker process still alive after 3.1999995422363288 seconds, killing
2023-06-22 23:55:16,762 - distributed.nanny - WARNING - Worker process still alive after 3.199999389648438 seconds, killing
2023-06-22 23:55:16,763 - distributed.nanny - WARNING - Worker process still alive after 3.1999992370605472 seconds, killing
2023-06-22 23:55:17,553 - distributed.nanny - ERROR - Error in Nanny killing Worker subprocess
Traceback (most recent call last):
  File "/opt/conda/envs/rapids/lib/python3.10/asyncio/tasks.py", line 456, in wait_for
    return fut.result()
asyncio.exceptions.CancelledError

The above exception was the direct cause of the following exception:

Traceback (most recent call last):
  File "/opt/conda/envs/rapids/lib/python3.10/site-packages/distributed/nanny.py", line 597, in close
    await self.kill(timeout=timeout, reason=reason)
  File "/opt/conda/envs/rapids/lib/python3.10/site-packages/distributed/nanny.py", line 380, in kill
    await self.process.kill(reason=reason, timeout=0.8 * (deadline - time()))
  File "/opt/conda/envs/rapids/lib/python3.10/site-packages/distributed/nanny.py", line 853, in kill
    await process.join(max(0, deadline - time()))
  File "/opt/conda/envs/rapids/lib/python3.10/site-packages/distributed/process.py", line 330, in join
    await wait_for(asyncio.shield(self._exit_future), timeout)
  File "/opt/conda/envs/rapids/lib/python3.10/site-packages/distributed/utils.py", line 1878, in wait_for
    return await asyncio.wait_for(fut, timeout)
  File "/opt/conda/envs/rapids/lib/python3.10/asyncio/tasks.py", line 458, in wait_for
    raise exceptions.TimeoutError() from exc
asyncio.exceptions.TimeoutError
2023-06-22 23:55:17,555 - distributed.nanny - ERROR - Error in Nanny killing Worker subprocess
Traceback (most recent call last):
  File "/opt/conda/envs/rapids/lib/python3.10/asyncio/tasks.py", line 456, in wait_for
    return fut.result()
asyncio.exceptions.CancelledError

The above exception was the direct cause of the following exception:

Traceback (most recent call last):
  File "/opt/conda/envs/rapids/lib/python3.10/site-packages/distributed/nanny.py", line 597, in close
    await self.kill(timeout=timeout, reason=reason)
  File "/opt/conda/envs/rapids/lib/python3.10/site-packages/distributed/nanny.py", line 380, in kill
    await self.process.kill(reason=reason, timeout=0.8 * (deadline - time()))
  File "/opt/conda/envs/rapids/lib/python3.10/site-packages/distributed/nanny.py", line 853, in kill
    await process.join(max(0, deadline - time()))
  File "/opt/conda/envs/rapids/lib/python3.10/site-packages/distributed/process.py", line 330, in join
    await wait_for(asyncio.shield(self._exit_future), timeout)
  File "/opt/conda/envs/rapids/lib/python3.10/site-packages/distributed/utils.py", line 1878, in wait_for
    return await asyncio.wait_for(fut, timeout)
  File "/opt/conda/envs/rapids/lib/python3.10/asyncio/tasks.py", line 458, in wait_for
    raise exceptions.TimeoutError() from exc
asyncio.exceptions.TimeoutError
2023-06-22 23:55:17,556 - distributed.nanny - ERROR - Error in Nanny killing Worker subprocess
Traceback (most recent call last):
  File "/opt/conda/envs/rapids/lib/python3.10/asyncio/tasks.py", line 456, in wait_for
    return fut.result()
asyncio.exceptions.CancelledError

The above exception was the direct cause of the following exception:

Traceback (most recent call last):
  File "/opt/conda/envs/rapids/lib/python3.10/site-packages/distributed/nanny.py", line 597, in close
    await self.kill(timeout=timeout, reason=reason)
  File "/opt/conda/envs/rapids/lib/python3.10/site-packages/distributed/nanny.py", line 380, in kill
    await self.process.kill(reason=reason, timeout=0.8 * (deadline - time()))
  File "/opt/conda/envs/rapids/lib/python3.10/site-packages/distributed/nanny.py", line 853, in kill
    await process.join(max(0, deadline - time()))
  File "/opt/conda/envs/rapids/lib/python3.10/site-packages/distributed/process.py", line 330, in join
    await wait_for(asyncio.shield(self._exit_future), timeout)
  File "/opt/conda/envs/rapids/lib/python3.10/site-packages/distributed/utils.py", line 1878, in wait_for
    return await asyncio.wait_for(fut, timeout)
  File "/opt/conda/envs/rapids/lib/python3.10/asyncio/tasks.py", line 458, in wait_for
    raise exceptions.TimeoutError() from exc
asyncio.exceptions.TimeoutError
2023-06-22 23:55:17,556 - distributed.nanny - ERROR - Error in Nanny killing Worker subprocess
Traceback (most recent call last):
  File "/opt/conda/envs/rapids/lib/python3.10/asyncio/tasks.py", line 456, in wait_for
    return fut.result()
asyncio.exceptions.CancelledError

The above exception was the direct cause of the following exception:

Traceback (most recent call last):
  File "/opt/conda/envs/rapids/lib/python3.10/site-packages/distributed/nanny.py", line 597, in close
    await self.kill(timeout=timeout, reason=reason)
  File "/opt/conda/envs/rapids/lib/python3.10/site-packages/distributed/nanny.py", line 380, in kill
    await self.process.kill(reason=reason, timeout=0.8 * (deadline - time()))
  File "/opt/conda/envs/rapids/lib/python3.10/site-packages/distributed/nanny.py", line 853, in kill
    await process.join(max(0, deadline - time()))
  File "/opt/conda/envs/rapids/lib/python3.10/site-packages/distributed/process.py", line 330, in join
    await wait_for(asyncio.shield(self._exit_future), timeout)
  File "/opt/conda/envs/rapids/lib/python3.10/site-packages/distributed/utils.py", line 1878, in wait_for
    return await asyncio.wait_for(fut, timeout)
  File "/opt/conda/envs/rapids/lib/python3.10/asyncio/tasks.py", line 458, in wait_for
    raise exceptions.TimeoutError() from exc
asyncio.exceptions.TimeoutError
2023-06-22 23:55:17,556 - distributed.nanny - ERROR - Error in Nanny killing Worker subprocess
Traceback (most recent call last):
  File "/opt/conda/envs/rapids/lib/python3.10/asyncio/tasks.py", line 456, in wait_for
    return fut.result()
asyncio.exceptions.CancelledError

The above exception was the direct cause of the following exception:

Traceback (most recent call last):
  File "/opt/conda/envs/rapids/lib/python3.10/site-packages/distributed/nanny.py", line 597, in close
    await self.kill(timeout=timeout, reason=reason)
  File "/opt/conda/envs/rapids/lib/python3.10/site-packages/distributed/nanny.py", line 380, in kill
    await self.process.kill(reason=reason, timeout=0.8 * (deadline - time()))
  File "/opt/conda/envs/rapids/lib/python3.10/site-packages/distributed/nanny.py", line 853, in kill
    await process.join(max(0, deadline - time()))
  File "/opt/conda/envs/rapids/lib/python3.10/site-packages/distributed/process.py", line 330, in join
    await wait_for(asyncio.shield(self._exit_future), timeout)
  File "/opt/conda/envs/rapids/lib/python3.10/site-packages/distributed/utils.py", line 1878, in wait_for
    return await asyncio.wait_for(fut, timeout)
  File "/opt/conda/envs/rapids/lib/python3.10/asyncio/tasks.py", line 458, in wait_for
    raise exceptions.TimeoutError() from exc
asyncio.exceptions.TimeoutError
2023-06-22 23:55:17,557 - distributed.nanny - ERROR - Error in Nanny killing Worker subprocess
Traceback (most recent call last):
  File "/opt/conda/envs/rapids/lib/python3.10/asyncio/tasks.py", line 456, in wait_for
    return fut.result()
asyncio.exceptions.CancelledError

The above exception was the direct cause of the following exception:

Traceback (most recent call last):
  File "/opt/conda/envs/rapids/lib/python3.10/site-packages/distributed/nanny.py", line 597, in close
    await self.kill(timeout=timeout, reason=reason)
  File "/opt/conda/envs/rapids/lib/python3.10/site-packages/distributed/nanny.py", line 380, in kill
    await self.process.kill(reason=reason, timeout=0.8 * (deadline - time()))
  File "/opt/conda/envs/rapids/lib/python3.10/site-packages/distributed/nanny.py", line 853, in kill
    await process.join(max(0, deadline - time()))
  File "/opt/conda/envs/rapids/lib/python3.10/site-packages/distributed/process.py", line 330, in join
    await wait_for(asyncio.shield(self._exit_future), timeout)
  File "/opt/conda/envs/rapids/lib/python3.10/site-packages/distributed/utils.py", line 1878, in wait_for
    return await asyncio.wait_for(fut, timeout)
  File "/opt/conda/envs/rapids/lib/python3.10/asyncio/tasks.py", line 458, in wait_for
    raise exceptions.TimeoutError() from exc
asyncio.exceptions.TimeoutError
2023-06-22 23:55:17,557 - distributed.nanny - ERROR - Error in Nanny killing Worker subprocess
Traceback (most recent call last):
  File "/opt/conda/envs/rapids/lib/python3.10/asyncio/tasks.py", line 456, in wait_for
    return fut.result()
asyncio.exceptions.CancelledError

The above exception was the direct cause of the following exception:

Traceback (most recent call last):
  File "/opt/conda/envs/rapids/lib/python3.10/site-packages/distributed/nanny.py", line 597, in close
    await self.kill(timeout=timeout, reason=reason)
  File "/opt/conda/envs/rapids/lib/python3.10/site-packages/distributed/nanny.py", line 380, in kill
    await self.process.kill(reason=reason, timeout=0.8 * (deadline - time()))
  File "/opt/conda/envs/rapids/lib/python3.10/site-packages/distributed/nanny.py", line 853, in kill
    await process.join(max(0, deadline - time()))
  File "/opt/conda/envs/rapids/lib/python3.10/site-packages/distributed/process.py", line 330, in join
    await wait_for(asyncio.shield(self._exit_future), timeout)
  File "/opt/conda/envs/rapids/lib/python3.10/site-packages/distributed/utils.py", line 1878, in wait_for
    return await asyncio.wait_for(fut, timeout)
  File "/opt/conda/envs/rapids/lib/python3.10/asyncio/tasks.py", line 458, in wait_for
    raise exceptions.TimeoutError() from exc
asyncio.exceptions.TimeoutError
2023-06-22 23:55:17,559 - distributed.nanny - ERROR - Error in Nanny killing Worker subprocess
Traceback (most recent call last):
  File "/opt/conda/envs/rapids/lib/python3.10/asyncio/tasks.py", line 456, in wait_for
    return fut.result()
asyncio.exceptions.CancelledError

The above exception was the direct cause of the following exception:

Traceback (most recent call last):
  File "/opt/conda/envs/rapids/lib/python3.10/site-packages/distributed/nanny.py", line 597, in close
    await self.kill(timeout=timeout, reason=reason)
  File "/opt/conda/envs/rapids/lib/python3.10/site-packages/distributed/nanny.py", line 380, in kill
    await self.process.kill(reason=reason, timeout=0.8 * (deadline - time()))
  File "/opt/conda/envs/rapids/lib/python3.10/site-packages/distributed/nanny.py", line 853, in kill
    await process.join(max(0, deadline - time()))
  File "/opt/conda/envs/rapids/lib/python3.10/site-packages/distributed/process.py", line 330, in join
    await wait_for(asyncio.shield(self._exit_future), timeout)
  File "/opt/conda/envs/rapids/lib/python3.10/site-packages/distributed/utils.py", line 1878, in wait_for
    return await asyncio.wait_for(fut, timeout)
  File "/opt/conda/envs/rapids/lib/python3.10/asyncio/tasks.py", line 458, in wait_for
    raise exceptions.TimeoutError() from exc
asyncio.exceptions.TimeoutError
2023-06-22 23:55:17,560 - distributed.process - INFO - reaping stray process <SpawnProcess name='Dask Worker process (from Nanny)' pid=1528604 parent=1528565 started daemon>
2023-06-22 23:55:17,560 - distributed.process - INFO - reaping stray process <SpawnProcess name='Dask Worker process (from Nanny)' pid=1528601 parent=1528565 started daemon>
2023-06-22 23:55:17,560 - distributed.process - INFO - reaping stray process <SpawnProcess name='Dask Worker process (from Nanny)' pid=1528598 parent=1528565 started daemon>
2023-06-22 23:55:17,561 - distributed.process - INFO - reaping stray process <SpawnProcess name='Dask Worker process (from Nanny)' pid=1528595 parent=1528565 started daemon>
2023-06-22 23:55:17,561 - distributed.process - INFO - reaping stray process <SpawnProcess name='Dask Worker process (from Nanny)' pid=1528592 parent=1528565 started daemon>
2023-06-22 23:55:17,561 - distributed.process - INFO - reaping stray process <SpawnProcess name='Dask Worker process (from Nanny)' pid=1528589 parent=1528565 started daemon>
2023-06-22 23:55:17,561 - distributed.process - INFO - reaping stray process <SpawnProcess name='Dask Worker process (from Nanny)' pid=1528586 parent=1528565 started daemon>
2023-06-22 23:55:17,561 - distributed.process - INFO - reaping stray process <SpawnProcess name='Dask Worker process (from Nanny)' pid=1528583 parent=1528565 started daemon>
2023-06-22 23:55:17,890 - distributed.process - WARNING - [<AsyncProcess Dask Worker process (from Nanny)>] process 1528595 exit status was already read will report exitcode 255
2023-06-22 23:55:18,099 - distributed.process - WARNING - [<AsyncProcess Dask Worker process (from Nanny)>] process 1528586 exit status was already read will report exitcode 255
2023-06-22 23:55:18,214 - distributed.process - WARNING - [<AsyncProcess Dask Worker process (from Nanny)>] process 1528604 exit status was already read will report exitcode 255
2023-06-22 23:55:18,505 - distributed.process - WARNING - [<AsyncProcess Dask Worker process (from Nanny)>] process 1528583 exit status was already read will report exitcode 255
