RUNNING: "python -m dask_cuda.cli.dask_cuda_worker --rmm-pool-size=12G
             --local-directory=/tmp/
             --scheduler-file=/root/work/cugraph/mg_utils/dask-scheduler.json
             --memory-limit=auto
             --device-memory-limit=auto
            "
2023-06-22 23:24:47,674 - distributed.nanny - INFO -         Start Nanny at: 'tcp://10.33.227.169:45525'
2023-06-22 23:24:47,678 - distributed.nanny - INFO -         Start Nanny at: 'tcp://10.33.227.169:45527'
2023-06-22 23:24:47,679 - distributed.nanny - INFO -         Start Nanny at: 'tcp://10.33.227.169:36639'
2023-06-22 23:24:47,682 - distributed.nanny - INFO -         Start Nanny at: 'tcp://10.33.227.169:38355'
2023-06-22 23:24:47,684 - distributed.nanny - INFO -         Start Nanny at: 'tcp://10.33.227.169:46099'
2023-06-22 23:24:47,686 - distributed.nanny - INFO -         Start Nanny at: 'tcp://10.33.227.169:40239'
2023-06-22 23:24:47,689 - distributed.nanny - INFO -         Start Nanny at: 'tcp://10.33.227.169:46045'
2023-06-22 23:24:47,691 - distributed.nanny - INFO -         Start Nanny at: 'tcp://10.33.227.169:46067'
2023-06-22 23:24:49,180 - distributed.diskutils - INFO - Found stale lock file and directory '/tmp/dask-scratch-space/worker-qrvq4w3y', purging
2023-06-22 23:24:49,191 - distributed.preloading - INFO - Creating preload: dask_cuda.initialize
2023-06-22 23:24:49,191 - distributed.preloading - INFO - Import preload module: dask_cuda.initialize
2023-06-22 23:24:49,232 - distributed.preloading - INFO - Creating preload: dask_cuda.initialize
2023-06-22 23:24:49,232 - distributed.preloading - INFO - Import preload module: dask_cuda.initialize
2023-06-22 23:24:49,233 - distributed.preloading - INFO - Creating preload: dask_cuda.initialize
2023-06-22 23:24:49,233 - distributed.preloading - INFO - Import preload module: dask_cuda.initialize
2023-06-22 23:24:49,235 - distributed.preloading - INFO - Creating preload: dask_cuda.initialize
2023-06-22 23:24:49,235 - distributed.preloading - INFO - Import preload module: dask_cuda.initialize
2023-06-22 23:24:49,236 - distributed.preloading - INFO - Creating preload: dask_cuda.initialize
2023-06-22 23:24:49,236 - distributed.preloading - INFO - Import preload module: dask_cuda.initialize
2023-06-22 23:24:49,237 - distributed.preloading - INFO - Creating preload: dask_cuda.initialize
2023-06-22 23:24:49,237 - distributed.preloading - INFO - Import preload module: dask_cuda.initialize
2023-06-22 23:24:49,237 - distributed.preloading - INFO - Creating preload: dask_cuda.initialize
2023-06-22 23:24:49,238 - distributed.preloading - INFO - Import preload module: dask_cuda.initialize
2023-06-22 23:24:49,238 - distributed.preloading - INFO - Creating preload: dask_cuda.initialize
2023-06-22 23:24:49,238 - distributed.preloading - INFO - Import preload module: dask_cuda.initialize
2023-06-22 23:24:49,637 - distributed.preloading - INFO - Run preload setup: dask_cuda.initialize
2023-06-22 23:24:49,671 - distributed.preloading - INFO - Run preload setup: dask_cuda.initialize
2023-06-22 23:24:49,672 - distributed.preloading - INFO - Run preload setup: dask_cuda.initialize
2023-06-22 23:24:49,673 - distributed.preloading - INFO - Run preload setup: dask_cuda.initialize
2023-06-22 23:24:49,676 - distributed.preloading - INFO - Run preload setup: dask_cuda.initialize
2023-06-22 23:24:49,681 - distributed.preloading - INFO - Run preload setup: dask_cuda.initialize
2023-06-22 23:24:49,688 - distributed.preloading - INFO - Run preload setup: dask_cuda.initialize
2023-06-22 23:24:49,693 - distributed.preloading - INFO - Run preload setup: dask_cuda.initialize
2023-06-22 23:24:52,187 - distributed.worker - INFO -       Start worker at:  tcp://10.33.227.169:45977
2023-06-22 23:24:52,187 - distributed.worker - INFO -          Listening to:  tcp://10.33.227.169:45977
2023-06-22 23:24:52,187 - distributed.worker - INFO -          dashboard at:        10.33.227.169:41659
2023-06-22 23:24:52,187 - distributed.worker - INFO - Waiting to connect to:   tcp://10.33.227.169:8786
2023-06-22 23:24:52,187 - distributed.worker - INFO - -------------------------------------------------
2023-06-22 23:24:52,187 - distributed.worker - INFO -               Threads:                          1
2023-06-22 23:24:52,187 - distributed.worker - INFO -                Memory:                  62.97 GiB
2023-06-22 23:24:52,187 - distributed.worker - INFO -       Local Directory: /tmp/dask-scratch-space/worker-ybwaatb7
2023-06-22 23:24:52,187 - distributed.worker - INFO -       Start worker at:  tcp://10.33.227.169:33361
2023-06-22 23:24:52,188 - distributed.worker - INFO -          Listening to:  tcp://10.33.227.169:33361
2023-06-22 23:24:52,188 - distributed.worker - INFO -          dashboard at:        10.33.227.169:42411
2023-06-22 23:24:52,188 - distributed.worker - INFO - Waiting to connect to:   tcp://10.33.227.169:8786
2023-06-22 23:24:52,188 - distributed.worker - INFO - -------------------------------------------------
2023-06-22 23:24:52,188 - distributed.worker - INFO -               Threads:                          1
2023-06-22 23:24:52,188 - distributed.worker - INFO - Starting Worker plugin RMMSetup-d089837a-7343-4c6e-bc0b-07d5f311bb2c
2023-06-22 23:24:52,188 - distributed.worker - INFO -                Memory:                  62.97 GiB
2023-06-22 23:24:52,188 - distributed.worker - INFO -       Local Directory: /tmp/dask-scratch-space/worker-a_gb_d5l
2023-06-22 23:24:52,189 - distributed.worker - INFO - Starting Worker plugin RMMSetup-c3defd69-5fd4-4c99-9037-12a0659fb2e2
2023-06-22 23:24:52,304 - distributed.worker - INFO -       Start worker at:  tcp://10.33.227.169:40097
2023-06-22 23:24:52,304 - distributed.worker - INFO -          Listening to:  tcp://10.33.227.169:40097
2023-06-22 23:24:52,304 - distributed.worker - INFO -          dashboard at:        10.33.227.169:46745
2023-06-22 23:24:52,304 - distributed.worker - INFO - Waiting to connect to:   tcp://10.33.227.169:8786
2023-06-22 23:24:52,305 - distributed.worker - INFO - -------------------------------------------------
2023-06-22 23:24:52,305 - distributed.worker - INFO -               Threads:                          1
2023-06-22 23:24:52,305 - distributed.worker - INFO -                Memory:                  62.97 GiB
2023-06-22 23:24:52,305 - distributed.worker - INFO -       Local Directory: /tmp/dask-scratch-space/worker-qm3hzty8
2023-06-22 23:24:52,305 - distributed.worker - INFO - Starting Worker plugin RMMSetup-e009ced7-272e-445e-872b-0e28a49dcc2c
2023-06-22 23:24:52,334 - distributed.worker - INFO - Starting Worker plugin CPUAffinity-b70c014f-0573-4455-84e8-6abc2f9c9003
2023-06-22 23:24:52,334 - distributed.worker - INFO - Starting Worker plugin PreImport-55a82996-f76a-42ec-aa96-8a858fa725e2
2023-06-22 23:24:52,335 - distributed.worker - INFO - -------------------------------------------------
2023-06-22 23:24:52,335 - distributed.worker - INFO - Starting Worker plugin PreImport-58900f76-6a17-4d68-8193-cd3e7467a545
2023-06-22 23:24:52,335 - distributed.worker - INFO - Starting Worker plugin CPUAffinity-6ca42d84-d312-4b00-80d7-56d0e318fdf2
2023-06-22 23:24:52,337 - distributed.worker - INFO - -------------------------------------------------
2023-06-22 23:24:52,338 - distributed.worker - INFO -       Start worker at:  tcp://10.33.227.169:36011
2023-06-22 23:24:52,339 - distributed.worker - INFO -          Listening to:  tcp://10.33.227.169:36011
2023-06-22 23:24:52,339 - distributed.worker - INFO -          dashboard at:        10.33.227.169:43601
2023-06-22 23:24:52,339 - distributed.worker - INFO - Waiting to connect to:   tcp://10.33.227.169:8786
2023-06-22 23:24:52,339 - distributed.worker - INFO - -------------------------------------------------
2023-06-22 23:24:52,339 - distributed.worker - INFO -               Threads:                          1
2023-06-22 23:24:52,339 - distributed.worker - INFO -                Memory:                  62.97 GiB
2023-06-22 23:24:52,339 - distributed.worker - INFO -       Local Directory: /tmp/dask-scratch-space/worker-noeg7vn7
2023-06-22 23:24:52,340 - distributed.worker - INFO - Starting Worker plugin PreImport-c1cd8eb2-8933-4c18-b298-d530709a6aa6
2023-06-22 23:24:52,340 - distributed.worker - INFO - Starting Worker plugin CPUAffinity-2c883cfd-5885-4456-98df-f4e7fe933030
2023-06-22 23:24:52,340 - distributed.worker - INFO - Starting Worker plugin RMMSetup-d2d35c6f-ddb3-4779-a72a-9bc915ee6027
2023-06-22 23:24:52,342 - distributed.worker - INFO -       Start worker at:  tcp://10.33.227.169:44757
2023-06-22 23:24:52,342 - distributed.worker - INFO -          Listening to:  tcp://10.33.227.169:44757
2023-06-22 23:24:52,342 - distributed.worker - INFO -          dashboard at:        10.33.227.169:43065
2023-06-22 23:24:52,342 - distributed.worker - INFO - Waiting to connect to:   tcp://10.33.227.169:8786
2023-06-22 23:24:52,343 - distributed.worker - INFO - -------------------------------------------------
2023-06-22 23:24:52,343 - distributed.worker - INFO -               Threads:                          1
2023-06-22 23:24:52,343 - distributed.worker - INFO -                Memory:                  62.97 GiB
2023-06-22 23:24:52,343 - distributed.worker - INFO -       Local Directory: /tmp/dask-scratch-space/worker-d6ouan_x
2023-06-22 23:24:52,343 - distributed.worker - INFO - Starting Worker plugin PreImport-2244c1fd-c400-47ce-a542-fc56e4db3c31
2023-06-22 23:24:52,343 - distributed.worker - INFO - Starting Worker plugin CPUAffinity-795a974e-40da-4637-998f-98fa894b8c09
2023-06-22 23:24:52,343 - distributed.worker - INFO -       Start worker at:  tcp://10.33.227.169:38735
2023-06-22 23:24:52,343 - distributed.worker - INFO - Starting Worker plugin RMMSetup-a0723e80-11d2-4e1c-b5b8-a53f13f0744e
2023-06-22 23:24:52,343 - distributed.worker - INFO -          Listening to:  tcp://10.33.227.169:38735
2023-06-22 23:24:52,343 - distributed.worker - INFO -          dashboard at:        10.33.227.169:38099
2023-06-22 23:24:52,344 - distributed.worker - INFO - Waiting to connect to:   tcp://10.33.227.169:8786
2023-06-22 23:24:52,344 - distributed.worker - INFO - -------------------------------------------------
2023-06-22 23:24:52,344 - distributed.worker - INFO -               Threads:                          1
2023-06-22 23:24:52,344 - distributed.worker - INFO -                Memory:                  62.97 GiB
2023-06-22 23:24:52,344 - distributed.worker - INFO -       Local Directory: /tmp/dask-scratch-space/worker-khekh868
2023-06-22 23:24:52,344 - distributed.worker - INFO - Starting Worker plugin PreImport-0fbb7986-1c90-48fe-88d3-73fb39aaef71
2023-06-22 23:24:52,344 - distributed.worker - INFO - Starting Worker plugin CPUAffinity-6fab988e-97f9-416a-bd2d-70cd5d908273
2023-06-22 23:24:52,345 - distributed.worker - INFO - Starting Worker plugin RMMSetup-f5e3d71d-941c-4593-b0ad-08512d0d1cd3
2023-06-22 23:24:52,351 - distributed.worker - INFO -       Start worker at:  tcp://10.33.227.169:35579
2023-06-22 23:24:52,352 - distributed.worker - INFO -          Listening to:  tcp://10.33.227.169:35579
2023-06-22 23:24:52,352 - distributed.worker - INFO -          dashboard at:        10.33.227.169:33535
2023-06-22 23:24:52,352 - distributed.worker - INFO - Waiting to connect to:   tcp://10.33.227.169:8786
2023-06-22 23:24:52,352 - distributed.worker - INFO - -------------------------------------------------
2023-06-22 23:24:52,352 - distributed.worker - INFO -               Threads:                          1
2023-06-22 23:24:52,352 - distributed.worker - INFO -                Memory:                  62.97 GiB
2023-06-22 23:24:52,352 - distributed.worker - INFO -       Local Directory: /tmp/dask-scratch-space/worker-kav977lk
2023-06-22 23:24:52,352 - distributed.worker - INFO -       Start worker at:  tcp://10.33.227.169:41103
2023-06-22 23:24:52,352 - distributed.worker - INFO -          Listening to:  tcp://10.33.227.169:41103
2023-06-22 23:24:52,352 - distributed.worker - INFO -          dashboard at:        10.33.227.169:42653
2023-06-22 23:24:52,353 - distributed.worker - INFO - Waiting to connect to:   tcp://10.33.227.169:8786
2023-06-22 23:24:52,353 - distributed.worker - INFO - -------------------------------------------------
2023-06-22 23:24:52,353 - distributed.worker - INFO -               Threads:                          1
2023-06-22 23:24:52,353 - distributed.worker - INFO -                Memory:                  62.97 GiB
2023-06-22 23:24:52,353 - distributed.worker - INFO -       Local Directory: /tmp/dask-scratch-space/worker-o66kzbt5
2023-06-22 23:24:52,353 - distributed.worker - INFO - Starting Worker plugin PreImport-41d21448-c643-4258-9f57-690c948eca76
2023-06-22 23:24:52,353 - distributed.worker - INFO - Starting Worker plugin CPUAffinity-ddae455d-bdf4-4335-9a58-8895f30ed75a
2023-06-22 23:24:52,353 - distributed.worker - INFO - Starting Worker plugin RMMSetup-046cd7a7-4353-4c68-b1bd-655ce4464a7f
2023-06-22 23:24:52,354 - distributed.worker - INFO - Starting Worker plugin PreImport-bcb380f3-b126-4e44-a830-787bbb6b967b
2023-06-22 23:24:52,354 - distributed.worker - INFO - Starting Worker plugin CPUAffinity-5aaf9a73-48ce-4506-8da1-38969b6af98f
2023-06-22 23:24:52,355 - distributed.worker - INFO - Starting Worker plugin RMMSetup-50a01fdd-bd58-4717-b0ee-219ab24c60ee
2023-06-22 23:24:52,529 - distributed.worker - INFO - Starting Worker plugin PreImport-8a931107-3055-4212-87f9-48d4b3ebbdb9
2023-06-22 23:24:52,529 - distributed.worker - INFO - Starting Worker plugin CPUAffinity-5a71d52a-7e73-4312-99f6-e8dcd2f0e5c0
2023-06-22 23:24:52,530 - distributed.worker - INFO - -------------------------------------------------
2023-06-22 23:24:52,530 - distributed.worker - INFO - -------------------------------------------------
2023-06-22 23:24:52,530 - distributed.worker - INFO - -------------------------------------------------
2023-06-22 23:24:52,531 - distributed.worker - INFO - -------------------------------------------------
2023-06-22 23:24:52,531 - distributed.worker - INFO - -------------------------------------------------
2023-06-22 23:24:52,531 - distributed.worker - INFO - -------------------------------------------------
2023-06-22 23:24:52,611 - distributed.worker - INFO -         Registered to:   tcp://10.33.227.169:8786
2023-06-22 23:24:52,611 - distributed.worker - INFO - -------------------------------------------------
2023-06-22 23:24:52,613 - distributed.core - INFO - Starting established connection to tcp://10.33.227.169:8786
2023-06-22 23:24:52,613 - distributed.worker - INFO -         Registered to:   tcp://10.33.227.169:8786
2023-06-22 23:24:52,613 - distributed.worker - INFO - -------------------------------------------------
2023-06-22 23:24:52,616 - distributed.core - INFO - Starting established connection to tcp://10.33.227.169:8786
2023-06-22 23:24:52,621 - distributed.worker - INFO -         Registered to:   tcp://10.33.227.169:8786
2023-06-22 23:24:52,622 - distributed.worker - INFO - -------------------------------------------------
2023-06-22 23:24:52,622 - distributed.worker - INFO -         Registered to:   tcp://10.33.227.169:8786
2023-06-22 23:24:52,623 - distributed.worker - INFO - -------------------------------------------------
2023-06-22 23:24:52,623 - distributed.core - INFO - Starting established connection to tcp://10.33.227.169:8786
2023-06-22 23:24:52,624 - distributed.worker - INFO -         Registered to:   tcp://10.33.227.169:8786
2023-06-22 23:24:52,624 - distributed.worker - INFO - -------------------------------------------------
2023-06-22 23:24:52,624 - distributed.core - INFO - Starting established connection to tcp://10.33.227.169:8786
2023-06-22 23:24:52,625 - distributed.worker - INFO -         Registered to:   tcp://10.33.227.169:8786
2023-06-22 23:24:52,625 - distributed.worker - INFO - -------------------------------------------------
2023-06-22 23:24:52,625 - distributed.core - INFO - Starting established connection to tcp://10.33.227.169:8786
2023-06-22 23:24:52,626 - distributed.worker - INFO -         Registered to:   tcp://10.33.227.169:8786
2023-06-22 23:24:52,626 - distributed.worker - INFO - -------------------------------------------------
2023-06-22 23:24:52,626 - distributed.core - INFO - Starting established connection to tcp://10.33.227.169:8786
2023-06-22 23:24:52,627 - distributed.worker - INFO -         Registered to:   tcp://10.33.227.169:8786
2023-06-22 23:24:52,627 - distributed.worker - INFO - -------------------------------------------------
2023-06-22 23:24:52,628 - distributed.core - INFO - Starting established connection to tcp://10.33.227.169:8786
2023-06-22 23:24:52,629 - distributed.core - INFO - Starting established connection to tcp://10.33.227.169:8786
2023-06-22 23:24:58,048 - distributed.worker - INFO - Run out-of-band function '_func_ucp_listener_port'
2023-06-22 23:24:58,048 - distributed.worker - INFO - Run out-of-band function '_func_ucp_listener_port'
2023-06-22 23:24:58,048 - distributed.worker - INFO - Run out-of-band function '_func_ucp_listener_port'
2023-06-22 23:24:58,048 - distributed.worker - INFO - Run out-of-band function '_func_ucp_listener_port'
2023-06-22 23:24:58,049 - distributed.worker - INFO - Run out-of-band function '_func_ucp_listener_port'
2023-06-22 23:24:58,050 - distributed.worker - INFO - Run out-of-band function '_func_ucp_listener_port'
2023-06-22 23:24:58,050 - distributed.worker - INFO - Run out-of-band function '_func_ucp_listener_port'
2023-06-22 23:24:58,053 - distributed.worker - INFO - Run out-of-band function '_func_ucp_listener_port'
2023-06-22 23:24:58,123 - distributed.worker - INFO - Run out-of-band function '_func_init_all'
2023-06-22 23:24:58,123 - distributed.worker - INFO - Run out-of-band function '_func_init_all'
2023-06-22 23:24:58,123 - distributed.worker - INFO - Run out-of-band function '_func_init_all'
2023-06-22 23:24:58,124 - distributed.worker - INFO - Run out-of-band function '_func_init_all'
2023-06-22 23:24:58,124 - distributed.worker - INFO - Run out-of-band function '_func_init_all'
2023-06-22 23:24:58,124 - distributed.worker - INFO - Run out-of-band function '_func_init_all'
2023-06-22 23:24:58,124 - distributed.worker - INFO - Run out-of-band function '_func_init_all'
2023-06-22 23:24:58,125 - distributed.worker - INFO - Run out-of-band function '_func_init_all'
2023-06-22 23:25:08,920 - distributed.worker - INFO - Run out-of-band function '_subcomm_init'
2023-06-22 23:25:09,045 - distributed.worker - INFO - Run out-of-band function '_subcomm_init'
2023-06-22 23:25:09,051 - distributed.worker - INFO - Run out-of-band function '_subcomm_init'
2023-06-22 23:25:09,083 - distributed.worker - INFO - Run out-of-band function '_subcomm_init'
2023-06-22 23:25:09,094 - distributed.worker - INFO - Run out-of-band function '_subcomm_init'
2023-06-22 23:25:09,229 - distributed.worker - INFO - Run out-of-band function '_subcomm_init'
2023-06-22 23:25:09,265 - distributed.worker - INFO - Run out-of-band function '_subcomm_init'
2023-06-22 23:25:09,536 - distributed.worker - INFO - Run out-of-band function '_subcomm_init'
2023-06-22 23:25:15,668 - distributed.core - INFO - Event loop was unresponsive in Worker for 16.02s.  This is often caused by long-running GIL-holding functions or moving large chunks of data. This can cause timeouts and instability.
2023-06-22 23:25:15,669 - distributed.core - INFO - Event loop was unresponsive in Worker for 16.02s.  This is often caused by long-running GIL-holding functions or moving large chunks of data. This can cause timeouts and instability.
2023-06-22 23:25:15,669 - distributed.core - INFO - Event loop was unresponsive in Worker for 16.03s.  This is often caused by long-running GIL-holding functions or moving large chunks of data. This can cause timeouts and instability.
2023-06-22 23:25:15,670 - distributed.core - INFO - Event loop was unresponsive in Worker for 16.03s.  This is often caused by long-running GIL-holding functions or moving large chunks of data. This can cause timeouts and instability.
2023-06-22 23:25:15,673 - distributed.core - INFO - Event loop was unresponsive in Worker for 16.03s.  This is often caused by long-running GIL-holding functions or moving large chunks of data. This can cause timeouts and instability.
2023-06-22 23:25:15,673 - distributed.core - INFO - Event loop was unresponsive in Worker for 16.03s.  This is often caused by long-running GIL-holding functions or moving large chunks of data. This can cause timeouts and instability.
2023-06-22 23:25:15,673 - distributed.core - INFO - Event loop was unresponsive in Worker for 16.03s.  This is often caused by long-running GIL-holding functions or moving large chunks of data. This can cause timeouts and instability.
2023-06-22 23:25:15,674 - distributed.core - INFO - Event loop was unresponsive in Worker for 16.02s.  This is often caused by long-running GIL-holding functions or moving large chunks of data. This can cause timeouts and instability.
2023-06-22 23:25:51,779 - distributed.worker - INFO - Run out-of-band function 'collect'
2023-06-22 23:25:51,784 - distributed.worker - INFO - Run out-of-band function 'collect'
2023-06-22 23:25:51,784 - distributed.worker - INFO - Run out-of-band function 'collect'
2023-06-22 23:25:51,784 - distributed.worker - INFO - Run out-of-band function 'collect'
2023-06-22 23:25:51,784 - distributed.worker - INFO - Run out-of-band function 'collect'
2023-06-22 23:25:51,784 - distributed.worker - INFO - Run out-of-band function 'collect'
2023-06-22 23:25:51,784 - distributed.worker - INFO - Run out-of-band function 'collect'
2023-06-22 23:25:51,784 - distributed.worker - INFO - Run out-of-band function 'collect'
2023-06-22 23:25:56,056 - distributed.worker - INFO - Run out-of-band function 'collect'
2023-06-22 23:25:56,056 - distributed.worker - INFO - Run out-of-band function 'collect'
2023-06-22 23:25:56,056 - distributed.worker - INFO - Run out-of-band function 'collect'
2023-06-22 23:25:56,056 - distributed.worker - INFO - Run out-of-band function 'collect'
2023-06-22 23:25:56,056 - distributed.worker - INFO - Run out-of-band function 'collect'
2023-06-22 23:25:56,057 - distributed.worker - INFO - Run out-of-band function 'collect'
2023-06-22 23:25:56,057 - distributed.worker - INFO - Run out-of-band function 'collect'
2023-06-22 23:25:56,057 - distributed.worker - INFO - Run out-of-band function 'collect'
2023-06-22 23:25:56,512 - distributed.worker - INFO - Run out-of-band function 'collect'
2023-06-22 23:25:56,522 - distributed.worker - INFO - Run out-of-band function 'collect'
2023-06-22 23:25:56,522 - distributed.worker - INFO - Run out-of-band function 'collect'
2023-06-22 23:25:56,522 - distributed.worker - INFO - Run out-of-band function 'collect'
2023-06-22 23:25:56,522 - distributed.worker - INFO - Run out-of-band function 'collect'
2023-06-22 23:25:56,522 - distributed.worker - INFO - Run out-of-band function 'collect'
2023-06-22 23:25:56,523 - distributed.worker - INFO - Run out-of-band function 'collect'
2023-06-22 23:25:56,523 - distributed.worker - INFO - Run out-of-band function 'collect'
2023-06-22 23:25:56,997 - distributed.worker - INFO - Run out-of-band function 'collect'
2023-06-22 23:25:57,010 - distributed.worker - INFO - Run out-of-band function 'collect'
2023-06-22 23:25:57,010 - distributed.worker - INFO - Run out-of-band function 'collect'
2023-06-22 23:25:57,010 - distributed.worker - INFO - Run out-of-band function 'collect'
2023-06-22 23:25:57,010 - distributed.worker - INFO - Run out-of-band function 'collect'
2023-06-22 23:25:57,010 - distributed.worker - INFO - Run out-of-band function 'collect'
2023-06-22 23:25:57,010 - distributed.worker - INFO - Run out-of-band function 'collect'
2023-06-22 23:25:57,011 - distributed.worker - INFO - Run out-of-band function 'collect'
2023-06-22 23:25:57,497 - distributed.worker - INFO - Run out-of-band function 'collect'
2023-06-22 23:25:57,521 - distributed.worker - INFO - Run out-of-band function 'collect'
2023-06-22 23:25:57,521 - distributed.worker - INFO - Run out-of-band function 'collect'
2023-06-22 23:25:57,521 - distributed.worker - INFO - Run out-of-band function 'collect'
2023-06-22 23:25:57,521 - distributed.worker - INFO - Run out-of-band function 'collect'
2023-06-22 23:25:57,521 - distributed.worker - INFO - Run out-of-band function 'collect'
2023-06-22 23:25:57,521 - distributed.worker - INFO - Run out-of-band function 'collect'
2023-06-22 23:25:57,521 - distributed.worker - INFO - Run out-of-band function 'collect'
2023-06-22 23:25:58,025 - distributed.worker - INFO - Run out-of-band function 'collect'
2023-06-22 23:25:58,038 - distributed.worker - INFO - Run out-of-band function 'collect'
2023-06-22 23:25:58,038 - distributed.worker - INFO - Run out-of-band function 'collect'
2023-06-22 23:25:58,038 - distributed.worker - INFO - Run out-of-band function 'collect'
2023-06-22 23:25:58,038 - distributed.worker - INFO - Run out-of-band function 'collect'
2023-06-22 23:25:58,038 - distributed.worker - INFO - Run out-of-band function 'collect'
2023-06-22 23:25:58,038 - distributed.worker - INFO - Run out-of-band function 'collect'
2023-06-22 23:25:58,038 - distributed.worker - INFO - Run out-of-band function 'collect'
2023-06-22 23:25:58,554 - distributed.worker - INFO - Run out-of-band function 'collect'
2023-06-22 23:25:58,565 - distributed.worker - INFO - Run out-of-band function 'collect'
2023-06-22 23:25:58,565 - distributed.worker - INFO - Run out-of-band function 'collect'
2023-06-22 23:25:58,565 - distributed.worker - INFO - Run out-of-band function 'collect'
2023-06-22 23:25:58,565 - distributed.worker - INFO - Run out-of-band function 'collect'
2023-06-22 23:25:58,565 - distributed.worker - INFO - Run out-of-band function 'collect'
2023-06-22 23:25:58,565 - distributed.worker - INFO - Run out-of-band function 'collect'
2023-06-22 23:25:58,565 - distributed.worker - INFO - Run out-of-band function 'collect'
2023-06-22 23:25:59,103 - distributed.worker - INFO - Run out-of-band function 'collect'
2023-06-22 23:25:59,113 - distributed.worker - INFO - Run out-of-band function 'collect'
2023-06-22 23:25:59,113 - distributed.worker - INFO - Run out-of-band function 'collect'
2023-06-22 23:25:59,113 - distributed.worker - INFO - Run out-of-band function 'collect'
2023-06-22 23:25:59,113 - distributed.worker - INFO - Run out-of-band function 'collect'
2023-06-22 23:25:59,113 - distributed.worker - INFO - Run out-of-band function 'collect'
2023-06-22 23:25:59,113 - distributed.worker - INFO - Run out-of-band function 'collect'
2023-06-22 23:25:59,114 - distributed.worker - INFO - Run out-of-band function 'collect'
2023-06-22 23:25:59,668 - distributed.worker - INFO - Run out-of-band function 'collect'
2023-06-22 23:25:59,680 - distributed.worker - INFO - Run out-of-band function 'collect'
2023-06-22 23:25:59,680 - distributed.worker - INFO - Run out-of-band function 'collect'
2023-06-22 23:25:59,680 - distributed.worker - INFO - Run out-of-band function 'collect'
2023-06-22 23:25:59,680 - distributed.worker - INFO - Run out-of-band function 'collect'
2023-06-22 23:25:59,680 - distributed.worker - INFO - Run out-of-band function 'collect'
2023-06-22 23:25:59,680 - distributed.worker - INFO - Run out-of-band function 'collect'
2023-06-22 23:25:59,680 - distributed.worker - INFO - Run out-of-band function 'collect'
2023-06-22 23:26:00,247 - distributed.worker - INFO - Run out-of-band function 'collect'
2023-06-22 23:26:00,258 - distributed.worker - INFO - Run out-of-band function 'collect'
2023-06-22 23:26:00,258 - distributed.worker - INFO - Run out-of-band function 'collect'
2023-06-22 23:26:00,258 - distributed.worker - INFO - Run out-of-band function 'collect'
2023-06-22 23:26:00,258 - distributed.worker - INFO - Run out-of-band function 'collect'
2023-06-22 23:26:00,259 - distributed.worker - INFO - Run out-of-band function 'collect'
2023-06-22 23:26:00,259 - distributed.worker - INFO - Run out-of-band function 'collect'
2023-06-22 23:26:00,259 - distributed.worker - INFO - Run out-of-band function 'collect'
2023-06-22 23:26:00,832 - distributed.worker - INFO - Run out-of-band function 'collect'
2023-06-22 23:26:00,843 - distributed.worker - INFO - Run out-of-band function 'collect'
2023-06-22 23:26:00,843 - distributed.worker - INFO - Run out-of-band function 'collect'
2023-06-22 23:26:00,844 - distributed.worker - INFO - Run out-of-band function 'collect'
2023-06-22 23:26:00,844 - distributed.worker - INFO - Run out-of-band function 'collect'
2023-06-22 23:26:00,844 - distributed.worker - INFO - Run out-of-band function 'collect'
2023-06-22 23:26:00,844 - distributed.worker - INFO - Run out-of-band function 'collect'
2023-06-22 23:26:00,844 - distributed.worker - INFO - Run out-of-band function 'collect'
2023-06-22 23:26:02,027 - distributed.worker - INFO - Run out-of-band function '_func_destroy_all'
2023-06-22 23:26:02,027 - distributed.worker - INFO - Run out-of-band function '_func_destroy_all'
2023-06-22 23:26:02,027 - distributed.worker - INFO - Run out-of-band function '_func_destroy_all'
2023-06-22 23:26:02,028 - distributed.worker - INFO - Run out-of-band function '_func_destroy_all'
2023-06-22 23:26:02,028 - distributed.worker - INFO - Run out-of-band function '_func_destroy_all'
2023-06-22 23:26:02,028 - distributed.worker - INFO - Run out-of-band function '_func_destroy_all'
2023-06-22 23:26:02,028 - distributed.worker - INFO - Run out-of-band function '_func_destroy_all'
2023-06-22 23:26:02,028 - distributed.worker - INFO - Run out-of-band function '_func_destroy_all'
2023-06-22 23:28:37,841 - distributed.worker - INFO - Stopping worker at tcp://10.33.227.169:35579. Reason: worker-close
2023-06-22 23:28:37,841 - distributed.worker - INFO - Stopping worker at tcp://10.33.227.169:41103. Reason: worker-handle-scheduler-connection-broken
2023-06-22 23:28:37,842 - distributed.worker - INFO - Stopping worker at tcp://10.33.227.169:40097. Reason: worker-close
2023-06-22 23:28:37,842 - distributed.worker - INFO - Stopping worker at tcp://10.33.227.169:33361. Reason: worker-handle-scheduler-connection-broken
2023-06-22 23:28:37,842 - distributed.worker - INFO - Stopping worker at tcp://10.33.227.169:45977. Reason: worker-handle-scheduler-connection-broken
2023-06-22 23:28:37,842 - distributed.worker - INFO - Stopping worker at tcp://10.33.227.169:36011. Reason: worker-handle-scheduler-connection-broken
2023-06-22 23:28:37,842 - distributed.worker - INFO - Stopping worker at tcp://10.33.227.169:44757. Reason: worker-handle-scheduler-connection-broken
2023-06-22 23:28:37,842 - distributed.worker - INFO - Stopping worker at tcp://10.33.227.169:38735. Reason: worker-close
2023-06-22 23:28:37,843 - distributed.nanny - INFO - Closing Nanny at 'tcp://10.33.227.169:45525'. Reason: nanny-close
2023-06-22 23:28:37,844 - distributed.nanny - INFO - Nanny asking worker to close. Reason: nanny-close
2023-06-22 23:28:37,844 - distributed.batched - INFO - Batched Comm Closed <TCP (closed) Worker->Scheduler local=tcp://10.33.227.169:33536 remote=tcp://10.33.227.169:8786>
Traceback (most recent call last):
  File "/opt/conda/envs/rapids/lib/python3.10/asyncio/runners.py", line 44, in run
    return loop.run_until_complete(main)
  File "/opt/conda/envs/rapids/lib/python3.10/asyncio/base_events.py", line 636, in run_until_complete
    self.run_forever()
  File "/opt/conda/envs/rapids/lib/python3.10/asyncio/base_events.py", line 603, in run_forever
    self._run_once()
  File "/opt/conda/envs/rapids/lib/python3.10/asyncio/base_events.py", line 1871, in _run_once
    event_list = self._selector.select(timeout)
  File "/opt/conda/envs/rapids/lib/python3.10/selectors.py", line 469, in select
    fd_event_list = self._selector.poll(timeout, max_ev)
KeyboardInterrupt

During handling of the above exception, another exception occurred:

Traceback (most recent call last):
  File "/opt/conda/envs/rapids/lib/python3.10/site-packages/distributed/batched.py", line 115, in _background_send
    nbytes = yield coro
  File "/opt/conda/envs/rapids/lib/python3.10/site-packages/tornado/gen.py", line 767, in run
    value = future.result()
  File "/opt/conda/envs/rapids/lib/python3.10/site-packages/distributed/comm/tcp.py", line 269, in write
    raise CommClosedError()
distributed.comm.core.CommClosedError
2023-06-22 23:28:37,846 - distributed.nanny - INFO - Closing Nanny at 'tcp://10.33.227.169:45527'. Reason: nanny-close
2023-06-22 23:28:37,844 - distributed.batched - INFO - Batched Comm Closed <TCP (closed) Worker->Scheduler local=tcp://10.33.227.169:33576 remote=tcp://10.33.227.169:8786>
Traceback (most recent call last):
  File "/opt/conda/envs/rapids/lib/python3.10/asyncio/runners.py", line 44, in run
    return loop.run_until_complete(main)
  File "/opt/conda/envs/rapids/lib/python3.10/asyncio/base_events.py", line 636, in run_until_complete
    self.run_forever()
  File "/opt/conda/envs/rapids/lib/python3.10/asyncio/base_events.py", line 603, in run_forever
    self._run_once()
  File "/opt/conda/envs/rapids/lib/python3.10/asyncio/base_events.py", line 1871, in _run_once
    event_list = self._selector.select(timeout)
  File "/opt/conda/envs/rapids/lib/python3.10/selectors.py", line 469, in select
    fd_event_list = self._selector.poll(timeout, max_ev)
KeyboardInterrupt

During handling of the above exception, another exception occurred:

Traceback (most recent call last):
  File "/opt/conda/envs/rapids/lib/python3.10/site-packages/distributed/batched.py", line 115, in _background_send
    nbytes = yield coro
  File "/opt/conda/envs/rapids/lib/python3.10/site-packages/tornado/gen.py", line 767, in run
    value = future.result()
  File "/opt/conda/envs/rapids/lib/python3.10/site-packages/distributed/comm/tcp.py", line 269, in write
    raise CommClosedError()
distributed.comm.core.CommClosedError
2023-06-22 23:28:37,844 - distributed.batched - INFO - Batched Comm Closed <TCP (closed) Worker->Scheduler local=tcp://10.33.227.169:33564 remote=tcp://10.33.227.169:8786>
Traceback (most recent call last):
  File "/opt/conda/envs/rapids/lib/python3.10/asyncio/runners.py", line 44, in run
    return loop.run_until_complete(main)
  File "/opt/conda/envs/rapids/lib/python3.10/asyncio/base_events.py", line 636, in run_until_complete
    self.run_forever()
  File "/opt/conda/envs/rapids/lib/python3.10/asyncio/base_events.py", line 603, in run_forever
    self._run_once()
  File "/opt/conda/envs/rapids/lib/python3.10/asyncio/base_events.py", line 1871, in _run_once
    event_list = self._selector.select(timeout)
  File "/opt/conda/envs/rapids/lib/python3.10/selectors.py", line 469, in select
    fd_event_list = self._selector.poll(timeout, max_ev)
KeyboardInterrupt

During handling of the above exception, another exception occurred:

Traceback (most recent call last):
  File "/opt/conda/envs/rapids/lib/python3.10/site-packages/distributed/batched.py", line 115, in _background_send
    nbytes = yield coro
  File "/opt/conda/envs/rapids/lib/python3.10/site-packages/tornado/gen.py", line 767, in run
    value = future.result()
  File "/opt/conda/envs/rapids/lib/python3.10/site-packages/distributed/comm/tcp.py", line 269, in write
    raise CommClosedError()
distributed.comm.core.CommClosedError
2023-06-22 23:28:37,848 - distributed.nanny - INFO - Nanny asking worker to close. Reason: nanny-close
2023-06-22 23:28:37,848 - distributed.nanny - INFO - Closing Nanny at 'tcp://10.33.227.169:36639'. Reason: nanny-close
2023-06-22 23:28:37,848 - distributed.nanny - INFO - Nanny asking worker to close. Reason: nanny-close
2023-06-22 23:28:37,849 - distributed.nanny - INFO - Closing Nanny at 'tcp://10.33.227.169:38355'. Reason: nanny-close
2023-06-22 23:28:37,849 - distributed.nanny - INFO - Nanny asking worker to close. Reason: nanny-close
2023-06-22 23:28:37,849 - distributed.nanny - INFO - Closing Nanny at 'tcp://10.33.227.169:46099'. Reason: nanny-close
2023-06-22 23:28:37,850 - distributed.nanny - INFO - Nanny asking worker to close. Reason: nanny-close
2023-06-22 23:28:37,850 - distributed.nanny - INFO - Closing Nanny at 'tcp://10.33.227.169:40239'. Reason: nanny-close
2023-06-22 23:28:37,850 - distributed.nanny - INFO - Nanny asking worker to close. Reason: nanny-close
2023-06-22 23:28:37,851 - distributed.nanny - INFO - Closing Nanny at 'tcp://10.33.227.169:46045'. Reason: nanny-close
2023-06-22 23:28:37,851 - distributed.nanny - INFO - Nanny asking worker to close. Reason: nanny-close
2023-06-22 23:28:37,851 - distributed.nanny - INFO - Closing Nanny at 'tcp://10.33.227.169:46067'. Reason: nanny-close
2023-06-22 23:28:37,852 - distributed.nanny - INFO - Nanny asking worker to close. Reason: nanny-close
2023-06-22 23:28:37,860 - distributed.worker - ERROR - Timed out during handshake while connecting to tcp://10.33.227.169:45527 after 100 s
Traceback (most recent call last):
  File "/opt/conda/envs/rapids/lib/python3.10/asyncio/runners.py", line 44, in run
    return loop.run_until_complete(main)
  File "/opt/conda/envs/rapids/lib/python3.10/asyncio/base_events.py", line 636, in run_until_complete
    self.run_forever()
  File "/opt/conda/envs/rapids/lib/python3.10/asyncio/base_events.py", line 603, in run_forever
    self._run_once()
  File "/opt/conda/envs/rapids/lib/python3.10/asyncio/base_events.py", line 1871, in _run_once
    event_list = self._selector.select(timeout)
  File "/opt/conda/envs/rapids/lib/python3.10/selectors.py", line 469, in select
    fd_event_list = self._selector.poll(timeout, max_ev)
KeyboardInterrupt

During handling of the above exception, another exception occurred:

Traceback (most recent call last):
  File "/opt/conda/envs/rapids/lib/python3.10/site-packages/tornado/iostream.py", line 861, in _read_to_buffer
    bytes_read = self.read_from_fd(buf)
  File "/opt/conda/envs/rapids/lib/python3.10/site-packages/tornado/iostream.py", line 1116, in read_from_fd
    return self.socket.recv_into(buf, len(buf))
ConnectionResetError: [Errno 104] Connection reset by peer

The above exception was the direct cause of the following exception:

Traceback (most recent call last):
  File "/opt/conda/envs/rapids/lib/python3.10/site-packages/distributed/comm/core.py", line 373, in connect
    handshake = await wait_for(comm.read(), time_left())
  File "/opt/conda/envs/rapids/lib/python3.10/site-packages/distributed/utils.py", line 1878, in wait_for
    return await asyncio.wait_for(fut, timeout)
  File "/opt/conda/envs/rapids/lib/python3.10/asyncio/tasks.py", line 445, in wait_for
    return fut.result()
  File "/opt/conda/envs/rapids/lib/python3.10/site-packages/distributed/comm/tcp.py", line 241, in read
    convert_stream_closed_error(self, e)
  File "/opt/conda/envs/rapids/lib/python3.10/site-packages/distributed/comm/tcp.py", line 142, in convert_stream_closed_error
    raise CommClosedError(f"in {obj}: {exc.__class__.__name__}: {exc}") from exc
distributed.comm.core.CommClosedError: in <TCP (closed)  local=tcp://10.33.227.169:35962 remote=tcp://10.33.227.169:45527>: ConnectionResetError: [Errno 104] Connection reset by peer

The above exception was the direct cause of the following exception:

Traceback (most recent call last):
  File "/opt/conda/envs/rapids/lib/python3.10/site-packages/distributed/utils.py", line 754, in wrapper
    return await func(*args, **kwargs)
  File "/opt/conda/envs/rapids/lib/python3.10/site-packages/distributed/worker.py", line 1540, in close
    await r.close_gracefully(reason=reason)
  File "/opt/conda/envs/rapids/lib/python3.10/site-packages/distributed/core.py", line 1362, in send_recv_from_rpc
    comm = await self.pool.connect(self.addr)
  File "/opt/conda/envs/rapids/lib/python3.10/site-packages/distributed/core.py", line 1606, in connect
    return await connect_attempt
  File "/opt/conda/envs/rapids/lib/python3.10/site-packages/distributed/core.py", line 1527, in _connect
    comm = await connect(
  File "/opt/conda/envs/rapids/lib/python3.10/site-packages/distributed/comm/core.py", line 378, in connect
    raise OSError(
OSError: Timed out during handshake while connecting to tcp://10.33.227.169:45527 after 100 s
2023-06-22 23:28:37,864 - distributed.core - ERROR - Timed out during handshake while connecting to tcp://10.33.227.169:38355 after 100 s
Traceback (most recent call last):
  File "/opt/conda/envs/rapids/lib/python3.10/asyncio/runners.py", line 44, in run
    return loop.run_until_complete(main)
  File "/opt/conda/envs/rapids/lib/python3.10/asyncio/base_events.py", line 636, in run_until_complete
    self.run_forever()
  File "/opt/conda/envs/rapids/lib/python3.10/asyncio/base_events.py", line 603, in run_forever
    self._run_once()
  File "/opt/conda/envs/rapids/lib/python3.10/asyncio/base_events.py", line 1871, in _run_once
    event_list = self._selector.select(timeout)
  File "/opt/conda/envs/rapids/lib/python3.10/selectors.py", line 469, in select
    fd_event_list = self._selector.poll(timeout, max_ev)
KeyboardInterrupt

During handling of the above exception, another exception occurred:

Traceback (most recent call last):
  File "/opt/conda/envs/rapids/lib/python3.10/site-packages/tornado/iostream.py", line 861, in _read_to_buffer
    bytes_read = self.read_from_fd(buf)
  File "/opt/conda/envs/rapids/lib/python3.10/site-packages/tornado/iostream.py", line 1116, in read_from_fd
    return self.socket.recv_into(buf, len(buf))
ConnectionResetError: [Errno 104] Connection reset by peer

The above exception was the direct cause of the following exception:

Traceback (most recent call last):
  File "/opt/conda/envs/rapids/lib/python3.10/site-packages/distributed/comm/core.py", line 373, in connect
    handshake = await wait_for(comm.read(), time_left())
  File "/opt/conda/envs/rapids/lib/python3.10/site-packages/distributed/utils.py", line 1878, in wait_for
    return await asyncio.wait_for(fut, timeout)
  File "/opt/conda/envs/rapids/lib/python3.10/asyncio/tasks.py", line 445, in wait_for
    return fut.result()
  File "/opt/conda/envs/rapids/lib/python3.10/site-packages/distributed/comm/tcp.py", line 241, in read
    convert_stream_closed_error(self, e)
  File "/opt/conda/envs/rapids/lib/python3.10/site-packages/distributed/comm/tcp.py", line 142, in convert_stream_closed_error
    raise CommClosedError(f"in {obj}: {exc.__class__.__name__}: {exc}") from exc
distributed.comm.core.CommClosedError: in <TCP (closed)  local=tcp://10.33.227.169:35360 remote=tcp://10.33.227.169:38355>: ConnectionResetError: [Errno 104] Connection reset by peer

The above exception was the direct cause of the following exception:

Traceback (most recent call last):
  File "/opt/conda/envs/rapids/lib/python3.10/site-packages/distributed/utils.py", line 754, in wrapper
    return await func(*args, **kwargs)
  File "/opt/conda/envs/rapids/lib/python3.10/site-packages/distributed/worker.py", line 1540, in close
    await r.close_gracefully(reason=reason)
  File "/opt/conda/envs/rapids/lib/python3.10/site-packages/distributed/core.py", line 1362, in send_recv_from_rpc
    comm = await self.pool.connect(self.addr)
  File "/opt/conda/envs/rapids/lib/python3.10/site-packages/distributed/core.py", line 1606, in connect
    return await connect_attempt
  File "/opt/conda/envs/rapids/lib/python3.10/site-packages/distributed/core.py", line 1527, in _connect
    comm = await connect(
  File "/opt/conda/envs/rapids/lib/python3.10/site-packages/distributed/comm/core.py", line 378, in connect
    raise OSError(
OSError: Timed out during handshake while connecting to tcp://10.33.227.169:38355 after 100 s
2023-06-22 23:28:37,864 - distributed.worker - ERROR - Timed out during handshake while connecting to tcp://10.33.227.169:46045 after 100 s
Traceback (most recent call last):
  File "/opt/conda/envs/rapids/lib/python3.10/asyncio/runners.py", line 44, in run
    return loop.run_until_complete(main)
  File "/opt/conda/envs/rapids/lib/python3.10/asyncio/base_events.py", line 636, in run_until_complete
    self.run_forever()
  File "/opt/conda/envs/rapids/lib/python3.10/asyncio/base_events.py", line 603, in run_forever
    self._run_once()
  File "/opt/conda/envs/rapids/lib/python3.10/asyncio/base_events.py", line 1871, in _run_once
    event_list = self._selector.select(timeout)
  File "/opt/conda/envs/rapids/lib/python3.10/selectors.py", line 469, in select
    fd_event_list = self._selector.poll(timeout, max_ev)
KeyboardInterrupt

During handling of the above exception, another exception occurred:

Traceback (most recent call last):
  File "/opt/conda/envs/rapids/lib/python3.10/site-packages/tornado/iostream.py", line 861, in _read_to_buffer
    bytes_read = self.read_from_fd(buf)
  File "/opt/conda/envs/rapids/lib/python3.10/site-packages/tornado/iostream.py", line 1116, in read_from_fd
    return self.socket.recv_into(buf, len(buf))
ConnectionResetError: [Errno 104] Connection reset by peer

The above exception was the direct cause of the following exception:

Traceback (most recent call last):
  File "/opt/conda/envs/rapids/lib/python3.10/site-packages/distributed/comm/core.py", line 373, in connect
    handshake = await wait_for(comm.read(), time_left())
  File "/opt/conda/envs/rapids/lib/python3.10/site-packages/distributed/utils.py", line 1878, in wait_for
    return await asyncio.wait_for(fut, timeout)
  File "/opt/conda/envs/rapids/lib/python3.10/asyncio/tasks.py", line 445, in wait_for
    return fut.result()
  File "/opt/conda/envs/rapids/lib/python3.10/site-packages/distributed/comm/tcp.py", line 241, in read
    convert_stream_closed_error(self, e)
  File "/opt/conda/envs/rapids/lib/python3.10/site-packages/distributed/comm/tcp.py", line 142, in convert_stream_closed_error
    raise CommClosedError(f"in {obj}: {exc.__class__.__name__}: {exc}") from exc
distributed.comm.core.CommClosedError: in <TCP (closed)  local=tcp://10.33.227.169:35484 remote=tcp://10.33.227.169:46045>: ConnectionResetError: [Errno 104] Connection reset by peer

The above exception was the direct cause of the following exception:

Traceback (most recent call last):
  File "/opt/conda/envs/rapids/lib/python3.10/site-packages/distributed/utils.py", line 754, in wrapper
    return await func(*args, **kwargs)
  File "/opt/conda/envs/rapids/lib/python3.10/site-packages/distributed/worker.py", line 1540, in close
    await r.close_gracefully(reason=reason)
  File "/opt/conda/envs/rapids/lib/python3.10/site-packages/distributed/core.py", line 1362, in send_recv_from_rpc
    comm = await self.pool.connect(self.addr)
  File "/opt/conda/envs/rapids/lib/python3.10/site-packages/distributed/core.py", line 1606, in connect
    return await connect_attempt
  File "/opt/conda/envs/rapids/lib/python3.10/site-packages/distributed/core.py", line 1527, in _connect
    comm = await connect(
  File "/opt/conda/envs/rapids/lib/python3.10/site-packages/distributed/comm/core.py", line 378, in connect
    raise OSError(
OSError: Timed out during handshake while connecting to tcp://10.33.227.169:46045 after 100 s
2023-06-22 23:28:37,865 - distributed.core - ERROR - Timed out during handshake while connecting to tcp://10.33.227.169:36639 after 100 s
Traceback (most recent call last):
  File "/opt/conda/envs/rapids/lib/python3.10/asyncio/runners.py", line 44, in run
    return loop.run_until_complete(main)
  File "/opt/conda/envs/rapids/lib/python3.10/asyncio/base_events.py", line 636, in run_until_complete
    self.run_forever()
  File "/opt/conda/envs/rapids/lib/python3.10/asyncio/base_events.py", line 603, in run_forever
    self._run_once()
  File "/opt/conda/envs/rapids/lib/python3.10/asyncio/base_events.py", line 1871, in _run_once
    event_list = self._selector.select(timeout)
  File "/opt/conda/envs/rapids/lib/python3.10/selectors.py", line 469, in select
    fd_event_list = self._selector.poll(timeout, max_ev)
KeyboardInterrupt

During handling of the above exception, another exception occurred:

Traceback (most recent call last):
  File "/opt/conda/envs/rapids/lib/python3.10/site-packages/tornado/iostream.py", line 861, in _read_to_buffer
    bytes_read = self.read_from_fd(buf)
  File "/opt/conda/envs/rapids/lib/python3.10/site-packages/tornado/iostream.py", line 1116, in read_from_fd
    return self.socket.recv_into(buf, len(buf))
ConnectionResetError: [Errno 104] Connection reset by peer

The above exception was the direct cause of the following exception:

Traceback (most recent call last):
  File "/opt/conda/envs/rapids/lib/python3.10/site-packages/distributed/comm/core.py", line 373, in connect
    handshake = await wait_for(comm.read(), time_left())
  File "/opt/conda/envs/rapids/lib/python3.10/site-packages/distributed/utils.py", line 1878, in wait_for
    return await asyncio.wait_for(fut, timeout)
  File "/opt/conda/envs/rapids/lib/python3.10/asyncio/tasks.py", line 445, in wait_for
    return fut.result()
  File "/opt/conda/envs/rapids/lib/python3.10/site-packages/distributed/comm/tcp.py", line 241, in read
    convert_stream_closed_error(self, e)
  File "/opt/conda/envs/rapids/lib/python3.10/site-packages/distributed/comm/tcp.py", line 142, in convert_stream_closed_error
    raise CommClosedError(f"in {obj}: {exc.__class__.__name__}: {exc}") from exc
distributed.comm.core.CommClosedError: in <TCP (closed)  local=tcp://10.33.227.169:36300 remote=tcp://10.33.227.169:36639>: ConnectionResetError: [Errno 104] Connection reset by peer

The above exception was the direct cause of the following exception:

Traceback (most recent call last):
  File "/opt/conda/envs/rapids/lib/python3.10/site-packages/distributed/utils.py", line 754, in wrapper
    return await func(*args, **kwargs)
  File "/opt/conda/envs/rapids/lib/python3.10/site-packages/distributed/worker.py", line 1540, in close
    await r.close_gracefully(reason=reason)
  File "/opt/conda/envs/rapids/lib/python3.10/site-packages/distributed/core.py", line 1362, in send_recv_from_rpc
    comm = await self.pool.connect(self.addr)
  File "/opt/conda/envs/rapids/lib/python3.10/site-packages/distributed/core.py", line 1606, in connect
    return await connect_attempt
  File "/opt/conda/envs/rapids/lib/python3.10/site-packages/distributed/core.py", line 1527, in _connect
    comm = await connect(
  File "/opt/conda/envs/rapids/lib/python3.10/site-packages/distributed/comm/core.py", line 378, in connect
    raise OSError(
OSError: Timed out during handshake while connecting to tcp://10.33.227.169:36639 after 100 s
2023-06-22 23:28:37,865 - distributed.worker - ERROR - Timed out during handshake while connecting to tcp://10.33.227.169:46099 after 100 s
Traceback (most recent call last):
  File "/opt/conda/envs/rapids/lib/python3.10/asyncio/runners.py", line 44, in run
    return loop.run_until_complete(main)
  File "/opt/conda/envs/rapids/lib/python3.10/asyncio/base_events.py", line 636, in run_until_complete
    self.run_forever()
  File "/opt/conda/envs/rapids/lib/python3.10/asyncio/base_events.py", line 603, in run_forever
    self._run_once()
  File "/opt/conda/envs/rapids/lib/python3.10/asyncio/base_events.py", line 1871, in _run_once
    event_list = self._selector.select(timeout)
  File "/opt/conda/envs/rapids/lib/python3.10/selectors.py", line 469, in select
    fd_event_list = self._selector.poll(timeout, max_ev)
KeyboardInterrupt

During handling of the above exception, another exception occurred:

Traceback (most recent call last):
  File "/opt/conda/envs/rapids/lib/python3.10/site-packages/tornado/iostream.py", line 861, in _read_to_buffer
    bytes_read = self.read_from_fd(buf)
  File "/opt/conda/envs/rapids/lib/python3.10/site-packages/tornado/iostream.py", line 1116, in read_from_fd
    return self.socket.recv_into(buf, len(buf))
ConnectionResetError: [Errno 104] Connection reset by peer

The above exception was the direct cause of the following exception:

Traceback (most recent call last):
  File "/opt/conda/envs/rapids/lib/python3.10/site-packages/distributed/comm/core.py", line 373, in connect
    handshake = await wait_for(comm.read(), time_left())
  File "/opt/conda/envs/rapids/lib/python3.10/site-packages/distributed/utils.py", line 1878, in wait_for
    return await asyncio.wait_for(fut, timeout)
  File "/opt/conda/envs/rapids/lib/python3.10/asyncio/tasks.py", line 445, in wait_for
    return fut.result()
  File "/opt/conda/envs/rapids/lib/python3.10/site-packages/distributed/comm/tcp.py", line 241, in read
    convert_stream_closed_error(self, e)
  File "/opt/conda/envs/rapids/lib/python3.10/site-packages/distributed/comm/tcp.py", line 142, in convert_stream_closed_error
    raise CommClosedError(f"in {obj}: {exc.__class__.__name__}: {exc}") from exc
distributed.comm.core.CommClosedError: in <TCP (closed)  local=tcp://10.33.227.169:46246 remote=tcp://10.33.227.169:46099>: ConnectionResetError: [Errno 104] Connection reset by peer

The above exception was the direct cause of the following exception:

Traceback (most recent call last):
  File "/opt/conda/envs/rapids/lib/python3.10/site-packages/distributed/utils.py", line 754, in wrapper
    return await func(*args, **kwargs)
  File "/opt/conda/envs/rapids/lib/python3.10/site-packages/distributed/worker.py", line 1540, in close
    await r.close_gracefully(reason=reason)
  File "/opt/conda/envs/rapids/lib/python3.10/site-packages/distributed/core.py", line 1362, in send_recv_from_rpc
    comm = await self.pool.connect(self.addr)
  File "/opt/conda/envs/rapids/lib/python3.10/site-packages/distributed/core.py", line 1606, in connect
    return await connect_attempt
  File "/opt/conda/envs/rapids/lib/python3.10/site-packages/distributed/core.py", line 1527, in _connect
    comm = await connect(
  File "/opt/conda/envs/rapids/lib/python3.10/site-packages/distributed/comm/core.py", line 378, in connect
    raise OSError(
OSError: Timed out during handshake while connecting to tcp://10.33.227.169:46099 after 100 s
2023-06-22 23:28:37,867 - distributed.core - ERROR - Timed out during handshake while connecting to tcp://10.33.227.169:40239 after 100 s
Traceback (most recent call last):
  File "/opt/conda/envs/rapids/lib/python3.10/asyncio/runners.py", line 44, in run
    return loop.run_until_complete(main)
  File "/opt/conda/envs/rapids/lib/python3.10/asyncio/base_events.py", line 636, in run_until_complete
    self.run_forever()
  File "/opt/conda/envs/rapids/lib/python3.10/asyncio/base_events.py", line 603, in run_forever
    self._run_once()
  File "/opt/conda/envs/rapids/lib/python3.10/asyncio/base_events.py", line 1871, in _run_once
    event_list = self._selector.select(timeout)
  File "/opt/conda/envs/rapids/lib/python3.10/selectors.py", line 469, in select
    fd_event_list = self._selector.poll(timeout, max_ev)
KeyboardInterrupt

During handling of the above exception, another exception occurred:

Traceback (most recent call last):
  File "/opt/conda/envs/rapids/lib/python3.10/site-packages/tornado/iostream.py", line 861, in _read_to_buffer
    bytes_read = self.read_from_fd(buf)
  File "/opt/conda/envs/rapids/lib/python3.10/site-packages/tornado/iostream.py", line 1116, in read_from_fd
    return self.socket.recv_into(buf, len(buf))
ConnectionResetError: [Errno 104] Connection reset by peer

The above exception was the direct cause of the following exception:

Traceback (most recent call last):
  File "/opt/conda/envs/rapids/lib/python3.10/site-packages/distributed/comm/core.py", line 373, in connect
    handshake = await wait_for(comm.read(), time_left())
  File "/opt/conda/envs/rapids/lib/python3.10/site-packages/distributed/utils.py", line 1878, in wait_for
    return await asyncio.wait_for(fut, timeout)
  File "/opt/conda/envs/rapids/lib/python3.10/asyncio/tasks.py", line 445, in wait_for
    return fut.result()
  File "/opt/conda/envs/rapids/lib/python3.10/site-packages/distributed/comm/tcp.py", line 241, in read
    convert_stream_closed_error(self, e)
  File "/opt/conda/envs/rapids/lib/python3.10/site-packages/distributed/comm/tcp.py", line 142, in convert_stream_closed_error
    raise CommClosedError(f"in {obj}: {exc.__class__.__name__}: {exc}") from exc
distributed.comm.core.CommClosedError: in <TCP (closed)  local=tcp://10.33.227.169:40310 remote=tcp://10.33.227.169:40239>: ConnectionResetError: [Errno 104] Connection reset by peer

The above exception was the direct cause of the following exception:

Traceback (most recent call last):
  File "/opt/conda/envs/rapids/lib/python3.10/site-packages/distributed/utils.py", line 754, in wrapper
    return await func(*args, **kwargs)
  File "/opt/conda/envs/rapids/lib/python3.10/site-packages/distributed/worker.py", line 1540, in close
    await r.close_gracefully(reason=reason)
  File "/opt/conda/envs/rapids/lib/python3.10/site-packages/distributed/core.py", line 1362, in send_recv_from_rpc
    comm = await self.pool.connect(self.addr)
  File "/opt/conda/envs/rapids/lib/python3.10/site-packages/distributed/core.py", line 1606, in connect
    return await connect_attempt
  File "/opt/conda/envs/rapids/lib/python3.10/site-packages/distributed/core.py", line 1527, in _connect
    comm = await connect(
  File "/opt/conda/envs/rapids/lib/python3.10/site-packages/distributed/comm/core.py", line 378, in connect
    raise OSError(
OSError: Timed out during handshake while connecting to tcp://10.33.227.169:40239 after 100 s
2023-06-22 23:28:37,874 - distributed.worker - ERROR - Timed out during handshake while connecting to tcp://10.33.227.169:46067 after 100 s
Traceback (most recent call last):
  File "/opt/conda/envs/rapids/lib/python3.10/asyncio/runners.py", line 44, in run
    return loop.run_until_complete(main)
  File "/opt/conda/envs/rapids/lib/python3.10/asyncio/base_events.py", line 636, in run_until_complete
    self.run_forever()
  File "/opt/conda/envs/rapids/lib/python3.10/asyncio/base_events.py", line 603, in run_forever
    self._run_once()
  File "/opt/conda/envs/rapids/lib/python3.10/asyncio/base_events.py", line 1871, in _run_once
    event_list = self._selector.select(timeout)
  File "/opt/conda/envs/rapids/lib/python3.10/selectors.py", line 469, in select
    fd_event_list = self._selector.poll(timeout, max_ev)
KeyboardInterrupt

During handling of the above exception, another exception occurred:

Traceback (most recent call last):
  File "/opt/conda/envs/rapids/lib/python3.10/site-packages/tornado/iostream.py", line 861, in _read_to_buffer
    bytes_read = self.read_from_fd(buf)
  File "/opt/conda/envs/rapids/lib/python3.10/site-packages/tornado/iostream.py", line 1116, in read_from_fd
    return self.socket.recv_into(buf, len(buf))
ConnectionResetError: [Errno 104] Connection reset by peer

The above exception was the direct cause of the following exception:

Traceback (most recent call last):
  File "/opt/conda/envs/rapids/lib/python3.10/site-packages/distributed/comm/core.py", line 373, in connect
    handshake = await wait_for(comm.read(), time_left())
  File "/opt/conda/envs/rapids/lib/python3.10/site-packages/distributed/utils.py", line 1878, in wait_for
    return await asyncio.wait_for(fut, timeout)
  File "/opt/conda/envs/rapids/lib/python3.10/asyncio/tasks.py", line 445, in wait_for
    return fut.result()
  File "/opt/conda/envs/rapids/lib/python3.10/site-packages/distributed/comm/tcp.py", line 241, in read
    convert_stream_closed_error(self, e)
  File "/opt/conda/envs/rapids/lib/python3.10/site-packages/distributed/comm/tcp.py", line 142, in convert_stream_closed_error
    raise CommClosedError(f"in {obj}: {exc.__class__.__name__}: {exc}") from exc
distributed.comm.core.CommClosedError: in <TCP (closed)  local=tcp://10.33.227.169:41372 remote=tcp://10.33.227.169:46067>: ConnectionResetError: [Errno 104] Connection reset by peer

The above exception was the direct cause of the following exception:

Traceback (most recent call last):
  File "/opt/conda/envs/rapids/lib/python3.10/site-packages/distributed/utils.py", line 754, in wrapper
    return await func(*args, **kwargs)
  File "/opt/conda/envs/rapids/lib/python3.10/site-packages/distributed/worker.py", line 1540, in close
    await r.close_gracefully(reason=reason)
  File "/opt/conda/envs/rapids/lib/python3.10/site-packages/distributed/core.py", line 1362, in send_recv_from_rpc
    comm = await self.pool.connect(self.addr)
  File "/opt/conda/envs/rapids/lib/python3.10/site-packages/distributed/core.py", line 1606, in connect
    return await connect_attempt
  File "/opt/conda/envs/rapids/lib/python3.10/site-packages/distributed/core.py", line 1527, in _connect
    comm = await connect(
  File "/opt/conda/envs/rapids/lib/python3.10/site-packages/distributed/comm/core.py", line 378, in connect
    raise OSError(
OSError: Timed out during handshake while connecting to tcp://10.33.227.169:46067 after 100 s
2023-06-22 23:28:41,053 - distributed.nanny - WARNING - Worker process still alive after 3.199971618652344 seconds, killing
2023-06-22 23:28:41,054 - distributed.nanny - WARNING - Worker process still alive after 3.1999992370605472 seconds, killing
2023-06-22 23:28:41,055 - distributed.nanny - WARNING - Worker process still alive after 3.199999389648438 seconds, killing
2023-06-22 23:28:41,055 - distributed.nanny - WARNING - Worker process still alive after 3.199999389648438 seconds, killing
2023-06-22 23:28:41,056 - distributed.nanny - WARNING - Worker process still alive after 3.1999995422363288 seconds, killing
2023-06-22 23:28:41,057 - distributed.nanny - WARNING - Worker process still alive after 3.199999389648438 seconds, killing
2023-06-22 23:28:41,057 - distributed.nanny - WARNING - Worker process still alive after 3.199999389648438 seconds, killing
2023-06-22 23:28:41,057 - distributed.nanny - WARNING - Worker process still alive after 3.199999389648438 seconds, killing
2023-06-22 23:28:41,845 - distributed.nanny - ERROR - Error in Nanny killing Worker subprocess
Traceback (most recent call last):
  File "/opt/conda/envs/rapids/lib/python3.10/asyncio/tasks.py", line 456, in wait_for
    return fut.result()
asyncio.exceptions.CancelledError

The above exception was the direct cause of the following exception:

Traceback (most recent call last):
  File "/opt/conda/envs/rapids/lib/python3.10/site-packages/distributed/nanny.py", line 597, in close
    await self.kill(timeout=timeout, reason=reason)
  File "/opt/conda/envs/rapids/lib/python3.10/site-packages/distributed/nanny.py", line 380, in kill
    await self.process.kill(reason=reason, timeout=0.8 * (deadline - time()))
  File "/opt/conda/envs/rapids/lib/python3.10/site-packages/distributed/nanny.py", line 853, in kill
    await process.join(max(0, deadline - time()))
  File "/opt/conda/envs/rapids/lib/python3.10/site-packages/distributed/process.py", line 330, in join
    await wait_for(asyncio.shield(self._exit_future), timeout)
  File "/opt/conda/envs/rapids/lib/python3.10/site-packages/distributed/utils.py", line 1878, in wait_for
    return await asyncio.wait_for(fut, timeout)
  File "/opt/conda/envs/rapids/lib/python3.10/asyncio/tasks.py", line 458, in wait_for
    raise exceptions.TimeoutError() from exc
asyncio.exceptions.TimeoutError
2023-06-22 23:28:41,848 - distributed.nanny - ERROR - Error in Nanny killing Worker subprocess
Traceback (most recent call last):
  File "/opt/conda/envs/rapids/lib/python3.10/asyncio/tasks.py", line 456, in wait_for
    return fut.result()
asyncio.exceptions.CancelledError

The above exception was the direct cause of the following exception:

Traceback (most recent call last):
  File "/opt/conda/envs/rapids/lib/python3.10/site-packages/distributed/nanny.py", line 597, in close
    await self.kill(timeout=timeout, reason=reason)
  File "/opt/conda/envs/rapids/lib/python3.10/site-packages/distributed/nanny.py", line 380, in kill
    await self.process.kill(reason=reason, timeout=0.8 * (deadline - time()))
  File "/opt/conda/envs/rapids/lib/python3.10/site-packages/distributed/nanny.py", line 853, in kill
    await process.join(max(0, deadline - time()))
  File "/opt/conda/envs/rapids/lib/python3.10/site-packages/distributed/process.py", line 330, in join
    await wait_for(asyncio.shield(self._exit_future), timeout)
  File "/opt/conda/envs/rapids/lib/python3.10/site-packages/distributed/utils.py", line 1878, in wait_for
    return await asyncio.wait_for(fut, timeout)
  File "/opt/conda/envs/rapids/lib/python3.10/asyncio/tasks.py", line 458, in wait_for
    raise exceptions.TimeoutError() from exc
asyncio.exceptions.TimeoutError
2023-06-22 23:28:41,849 - distributed.nanny - ERROR - Error in Nanny killing Worker subprocess
Traceback (most recent call last):
  File "/opt/conda/envs/rapids/lib/python3.10/asyncio/tasks.py", line 456, in wait_for
    return fut.result()
asyncio.exceptions.CancelledError

The above exception was the direct cause of the following exception:

Traceback (most recent call last):
  File "/opt/conda/envs/rapids/lib/python3.10/site-packages/distributed/nanny.py", line 597, in close
    await self.kill(timeout=timeout, reason=reason)
  File "/opt/conda/envs/rapids/lib/python3.10/site-packages/distributed/nanny.py", line 380, in kill
    await self.process.kill(reason=reason, timeout=0.8 * (deadline - time()))
  File "/opt/conda/envs/rapids/lib/python3.10/site-packages/distributed/nanny.py", line 853, in kill
    await process.join(max(0, deadline - time()))
  File "/opt/conda/envs/rapids/lib/python3.10/site-packages/distributed/process.py", line 330, in join
    await wait_for(asyncio.shield(self._exit_future), timeout)
  File "/opt/conda/envs/rapids/lib/python3.10/site-packages/distributed/utils.py", line 1878, in wait_for
    return await asyncio.wait_for(fut, timeout)
  File "/opt/conda/envs/rapids/lib/python3.10/asyncio/tasks.py", line 458, in wait_for
    raise exceptions.TimeoutError() from exc
asyncio.exceptions.TimeoutError
2023-06-22 23:28:41,850 - distributed.nanny - ERROR - Error in Nanny killing Worker subprocess
Traceback (most recent call last):
  File "/opt/conda/envs/rapids/lib/python3.10/asyncio/tasks.py", line 456, in wait_for
    return fut.result()
asyncio.exceptions.CancelledError

The above exception was the direct cause of the following exception:

Traceback (most recent call last):
  File "/opt/conda/envs/rapids/lib/python3.10/site-packages/distributed/nanny.py", line 597, in close
    await self.kill(timeout=timeout, reason=reason)
  File "/opt/conda/envs/rapids/lib/python3.10/site-packages/distributed/nanny.py", line 380, in kill
    await self.process.kill(reason=reason, timeout=0.8 * (deadline - time()))
  File "/opt/conda/envs/rapids/lib/python3.10/site-packages/distributed/nanny.py", line 853, in kill
    await process.join(max(0, deadline - time()))
  File "/opt/conda/envs/rapids/lib/python3.10/site-packages/distributed/process.py", line 330, in join
    await wait_for(asyncio.shield(self._exit_future), timeout)
  File "/opt/conda/envs/rapids/lib/python3.10/site-packages/distributed/utils.py", line 1878, in wait_for
    return await asyncio.wait_for(fut, timeout)
  File "/opt/conda/envs/rapids/lib/python3.10/asyncio/tasks.py", line 458, in wait_for
    raise exceptions.TimeoutError() from exc
asyncio.exceptions.TimeoutError
2023-06-22 23:28:41,850 - distributed.nanny - ERROR - Error in Nanny killing Worker subprocess
Traceback (most recent call last):
  File "/opt/conda/envs/rapids/lib/python3.10/asyncio/tasks.py", line 456, in wait_for
    return fut.result()
asyncio.exceptions.CancelledError

The above exception was the direct cause of the following exception:

Traceback (most recent call last):
  File "/opt/conda/envs/rapids/lib/python3.10/site-packages/distributed/nanny.py", line 597, in close
    await self.kill(timeout=timeout, reason=reason)
  File "/opt/conda/envs/rapids/lib/python3.10/site-packages/distributed/nanny.py", line 380, in kill
    await self.process.kill(reason=reason, timeout=0.8 * (deadline - time()))
  File "/opt/conda/envs/rapids/lib/python3.10/site-packages/distributed/nanny.py", line 853, in kill
    await process.join(max(0, deadline - time()))
  File "/opt/conda/envs/rapids/lib/python3.10/site-packages/distributed/process.py", line 330, in join
    await wait_for(asyncio.shield(self._exit_future), timeout)
  File "/opt/conda/envs/rapids/lib/python3.10/site-packages/distributed/utils.py", line 1878, in wait_for
    return await asyncio.wait_for(fut, timeout)
  File "/opt/conda/envs/rapids/lib/python3.10/asyncio/tasks.py", line 458, in wait_for
    raise exceptions.TimeoutError() from exc
asyncio.exceptions.TimeoutError
2023-06-22 23:28:41,851 - distributed.nanny - ERROR - Error in Nanny killing Worker subprocess
Traceback (most recent call last):
  File "/opt/conda/envs/rapids/lib/python3.10/asyncio/tasks.py", line 456, in wait_for
    return fut.result()
asyncio.exceptions.CancelledError

The above exception was the direct cause of the following exception:

Traceback (most recent call last):
  File "/opt/conda/envs/rapids/lib/python3.10/site-packages/distributed/nanny.py", line 597, in close
    await self.kill(timeout=timeout, reason=reason)
  File "/opt/conda/envs/rapids/lib/python3.10/site-packages/distributed/nanny.py", line 380, in kill
    await self.process.kill(reason=reason, timeout=0.8 * (deadline - time()))
  File "/opt/conda/envs/rapids/lib/python3.10/site-packages/distributed/nanny.py", line 853, in kill
    await process.join(max(0, deadline - time()))
  File "/opt/conda/envs/rapids/lib/python3.10/site-packages/distributed/process.py", line 330, in join
    await wait_for(asyncio.shield(self._exit_future), timeout)
  File "/opt/conda/envs/rapids/lib/python3.10/site-packages/distributed/utils.py", line 1878, in wait_for
    return await asyncio.wait_for(fut, timeout)
  File "/opt/conda/envs/rapids/lib/python3.10/asyncio/tasks.py", line 458, in wait_for
    raise exceptions.TimeoutError() from exc
asyncio.exceptions.TimeoutError
2023-06-22 23:28:41,852 - distributed.nanny - ERROR - Error in Nanny killing Worker subprocess
Traceback (most recent call last):
  File "/opt/conda/envs/rapids/lib/python3.10/asyncio/tasks.py", line 456, in wait_for
    return fut.result()
asyncio.exceptions.CancelledError

The above exception was the direct cause of the following exception:

Traceback (most recent call last):
  File "/opt/conda/envs/rapids/lib/python3.10/site-packages/distributed/nanny.py", line 597, in close
    await self.kill(timeout=timeout, reason=reason)
  File "/opt/conda/envs/rapids/lib/python3.10/site-packages/distributed/nanny.py", line 380, in kill
    await self.process.kill(reason=reason, timeout=0.8 * (deadline - time()))
  File "/opt/conda/envs/rapids/lib/python3.10/site-packages/distributed/nanny.py", line 853, in kill
    await process.join(max(0, deadline - time()))
  File "/opt/conda/envs/rapids/lib/python3.10/site-packages/distributed/process.py", line 330, in join
    await wait_for(asyncio.shield(self._exit_future), timeout)
  File "/opt/conda/envs/rapids/lib/python3.10/site-packages/distributed/utils.py", line 1878, in wait_for
    return await asyncio.wait_for(fut, timeout)
  File "/opt/conda/envs/rapids/lib/python3.10/asyncio/tasks.py", line 458, in wait_for
    raise exceptions.TimeoutError() from exc
asyncio.exceptions.TimeoutError
2023-06-22 23:28:41,852 - distributed.nanny - ERROR - Error in Nanny killing Worker subprocess
Traceback (most recent call last):
  File "/opt/conda/envs/rapids/lib/python3.10/asyncio/tasks.py", line 456, in wait_for
    return fut.result()
asyncio.exceptions.CancelledError

The above exception was the direct cause of the following exception:

Traceback (most recent call last):
  File "/opt/conda/envs/rapids/lib/python3.10/site-packages/distributed/nanny.py", line 597, in close
    await self.kill(timeout=timeout, reason=reason)
  File "/opt/conda/envs/rapids/lib/python3.10/site-packages/distributed/nanny.py", line 380, in kill
    await self.process.kill(reason=reason, timeout=0.8 * (deadline - time()))
  File "/opt/conda/envs/rapids/lib/python3.10/site-packages/distributed/nanny.py", line 853, in kill
    await process.join(max(0, deadline - time()))
  File "/opt/conda/envs/rapids/lib/python3.10/site-packages/distributed/process.py", line 330, in join
    await wait_for(asyncio.shield(self._exit_future), timeout)
  File "/opt/conda/envs/rapids/lib/python3.10/site-packages/distributed/utils.py", line 1878, in wait_for
    return await asyncio.wait_for(fut, timeout)
  File "/opt/conda/envs/rapids/lib/python3.10/asyncio/tasks.py", line 458, in wait_for
    raise exceptions.TimeoutError() from exc
asyncio.exceptions.TimeoutError
2023-06-22 23:28:41,854 - distributed.process - INFO - reaping stray process <SpawnProcess name='Dask Worker process (from Nanny)' pid=1513557 parent=1513521 started daemon>
2023-06-22 23:28:41,854 - distributed.process - INFO - reaping stray process <SpawnProcess name='Dask Worker process (from Nanny)' pid=1513554 parent=1513521 started daemon>
2023-06-22 23:28:41,854 - distributed.process - INFO - reaping stray process <SpawnProcess name='Dask Worker process (from Nanny)' pid=1513551 parent=1513521 started daemon>
2023-06-22 23:28:41,854 - distributed.process - INFO - reaping stray process <SpawnProcess name='Dask Worker process (from Nanny)' pid=1513548 parent=1513521 started daemon>
2023-06-22 23:28:41,854 - distributed.process - INFO - reaping stray process <SpawnProcess name='Dask Worker process (from Nanny)' pid=1513545 parent=1513521 started daemon>
2023-06-22 23:28:41,854 - distributed.process - INFO - reaping stray process <SpawnProcess name='Dask Worker process (from Nanny)' pid=1513542 parent=1513521 started daemon>
2023-06-22 23:28:41,855 - distributed.process - INFO - reaping stray process <SpawnProcess name='Dask Worker process (from Nanny)' pid=1513539 parent=1513521 started daemon>
2023-06-22 23:28:41,855 - distributed.process - INFO - reaping stray process <SpawnProcess name='Dask Worker process (from Nanny)' pid=1513536 parent=1513521 started daemon>
2023-06-22 23:28:42,073 - distributed.process - WARNING - [<AsyncProcess Dask Worker process (from Nanny)>] process 1513539 exit status was already read will report exitcode 255
2023-06-22 23:28:42,174 - distributed.process - WARNING - [<AsyncProcess Dask Worker process (from Nanny)>] process 1513542 exit status was already read will report exitcode 255
2023-06-22 23:28:42,749 - distributed.process - WARNING - [<AsyncProcess Dask Worker process (from Nanny)>] process 1513545 exit status was already read will report exitcode 255
