RUNNING: "python -m dask_cuda.cli.dask_cuda_worker --rmm-pool-size=12G
             --local-directory=/tmp/
             --scheduler-file=/root/work/cugraph/mg_utils/dask-scheduler.json
             --memory-limit=auto
             --device-memory-limit=auto
            "
2023-06-22 21:28:05,145 - distributed.nanny - INFO -         Start Nanny at: 'tcp://10.33.227.169:35101'
2023-06-22 21:28:05,149 - distributed.nanny - INFO -         Start Nanny at: 'tcp://10.33.227.169:34527'
2023-06-22 21:28:05,150 - distributed.nanny - INFO -         Start Nanny at: 'tcp://10.33.227.169:34385'
2023-06-22 21:28:05,153 - distributed.nanny - INFO -         Start Nanny at: 'tcp://10.33.227.169:38535'
2023-06-22 21:28:05,155 - distributed.nanny - INFO -         Start Nanny at: 'tcp://10.33.227.169:34113'
2023-06-22 21:28:05,158 - distributed.nanny - INFO -         Start Nanny at: 'tcp://10.33.227.169:34197'
2023-06-22 21:28:05,160 - distributed.nanny - INFO -         Start Nanny at: 'tcp://10.33.227.169:42269'
2023-06-22 21:28:05,163 - distributed.nanny - INFO -         Start Nanny at: 'tcp://10.33.227.169:43597'
2023-06-22 21:28:06,605 - distributed.diskutils - INFO - Found stale lock file and directory '/tmp/dask-scratch-space/worker-qrjl0ka4', purging
2023-06-22 21:28:06,606 - distributed.diskutils - INFO - Found stale lock file and directory '/tmp/dask-scratch-space/worker-6tut9t0e', purging
2023-06-22 21:28:06,606 - distributed.diskutils - INFO - Found stale lock file and directory '/tmp/dask-scratch-space/worker-182oplzg', purging
2023-06-22 21:28:06,606 - distributed.diskutils - INFO - Found stale lock file and directory '/tmp/dask-scratch-space/worker-u3qxx481', purging
2023-06-22 21:28:06,606 - distributed.diskutils - INFO - Found stale lock file and directory '/tmp/dask-scratch-space/worker-q0k244ur', purging
2023-06-22 21:28:06,607 - distributed.diskutils - INFO - Found stale lock file and directory '/tmp/dask-scratch-space/worker-bfpz592y', purging
2023-06-22 21:28:06,617 - distributed.preloading - INFO - Creating preload: dask_cuda.initialize
2023-06-22 21:28:06,617 - distributed.preloading - INFO - Import preload module: dask_cuda.initialize
2023-06-22 21:28:06,704 - distributed.preloading - INFO - Creating preload: dask_cuda.initialize
2023-06-22 21:28:06,704 - distributed.preloading - INFO - Import preload module: dask_cuda.initialize
2023-06-22 21:28:06,707 - distributed.preloading - INFO - Creating preload: dask_cuda.initialize
2023-06-22 21:28:06,707 - distributed.preloading - INFO - Import preload module: dask_cuda.initialize
2023-06-22 21:28:06,708 - distributed.preloading - INFO - Creating preload: dask_cuda.initialize
2023-06-22 21:28:06,708 - distributed.preloading - INFO - Creating preload: dask_cuda.initialize
2023-06-22 21:28:06,708 - distributed.preloading - INFO - Import preload module: dask_cuda.initialize
2023-06-22 21:28:06,708 - distributed.preloading - INFO - Import preload module: dask_cuda.initialize
2023-06-22 21:28:06,715 - distributed.preloading - INFO - Creating preload: dask_cuda.initialize
2023-06-22 21:28:06,715 - distributed.preloading - INFO - Import preload module: dask_cuda.initialize
2023-06-22 21:28:06,721 - distributed.preloading - INFO - Creating preload: dask_cuda.initialize
2023-06-22 21:28:06,721 - distributed.preloading - INFO - Import preload module: dask_cuda.initialize
2023-06-22 21:28:06,722 - distributed.preloading - INFO - Creating preload: dask_cuda.initialize
2023-06-22 21:28:06,723 - distributed.preloading - INFO - Import preload module: dask_cuda.initialize
2023-06-22 21:28:07,029 - distributed.preloading - INFO - Run preload setup: dask_cuda.initialize
2023-06-22 21:28:07,132 - distributed.preloading - INFO - Run preload setup: dask_cuda.initialize
2023-06-22 21:28:07,154 - distributed.preloading - INFO - Run preload setup: dask_cuda.initialize
2023-06-22 21:28:07,154 - distributed.preloading - INFO - Run preload setup: dask_cuda.initialize
2023-06-22 21:28:07,154 - distributed.preloading - INFO - Run preload setup: dask_cuda.initialize
2023-06-22 21:28:07,173 - distributed.preloading - INFO - Run preload setup: dask_cuda.initialize
2023-06-22 21:28:07,177 - distributed.preloading - INFO - Run preload setup: dask_cuda.initialize
2023-06-22 21:28:07,179 - distributed.preloading - INFO - Run preload setup: dask_cuda.initialize
2023-06-22 21:28:09,598 - distributed.worker - INFO -       Start worker at:  tcp://10.33.227.169:39247
2023-06-22 21:28:09,598 - distributed.worker - INFO -          Listening to:  tcp://10.33.227.169:39247
2023-06-22 21:28:09,599 - distributed.worker - INFO -          dashboard at:        10.33.227.169:46011
2023-06-22 21:28:09,599 - distributed.worker - INFO - Waiting to connect to:   tcp://10.33.227.169:8786
2023-06-22 21:28:09,599 - distributed.worker - INFO - -------------------------------------------------
2023-06-22 21:28:09,599 - distributed.worker - INFO -               Threads:                          1
2023-06-22 21:28:09,599 - distributed.worker - INFO -                Memory:                  62.97 GiB
2023-06-22 21:28:09,599 - distributed.worker - INFO -       Local Directory: /tmp/dask-scratch-space/worker-ouhmj9b9
2023-06-22 21:28:09,599 - distributed.worker - INFO - Starting Worker plugin PreImport-2edb8069-7268-4267-890a-551865865edb
2023-06-22 21:28:09,600 - distributed.worker - INFO - Starting Worker plugin CPUAffinity-1ccde4f2-32ef-457b-aa1a-5afad3eef547
2023-06-22 21:28:09,600 - distributed.worker - INFO - Starting Worker plugin RMMSetup-384667ba-ae0a-430f-97d4-5987814d5b14
2023-06-22 21:28:09,642 - distributed.worker - INFO -       Start worker at:  tcp://10.33.227.169:35787
2023-06-22 21:28:09,642 - distributed.worker - INFO -          Listening to:  tcp://10.33.227.169:35787
2023-06-22 21:28:09,642 - distributed.worker - INFO -          dashboard at:        10.33.227.169:42211
2023-06-22 21:28:09,642 - distributed.worker - INFO - Waiting to connect to:   tcp://10.33.227.169:8786
2023-06-22 21:28:09,642 - distributed.worker - INFO - -------------------------------------------------
2023-06-22 21:28:09,642 - distributed.worker - INFO -               Threads:                          1
2023-06-22 21:28:09,642 - distributed.worker - INFO -                Memory:                  62.97 GiB
2023-06-22 21:28:09,642 - distributed.worker - INFO -       Local Directory: /tmp/dask-scratch-space/worker-q0z6irjx
2023-06-22 21:28:09,643 - distributed.worker - INFO - Starting Worker plugin PreImport-99f783a8-c442-4347-99d1-ef3f3ebd470d
2023-06-22 21:28:09,643 - distributed.worker - INFO - Starting Worker plugin CPUAffinity-51da9194-2fb8-4566-8e99-4ba9ea32444d
2023-06-22 21:28:09,643 - distributed.worker - INFO - Starting Worker plugin RMMSetup-f57c03b9-0b8f-450b-a474-b18ae6e91bef
2023-06-22 21:28:09,659 - distributed.worker - INFO -       Start worker at:  tcp://10.33.227.169:41823
2023-06-22 21:28:09,659 - distributed.worker - INFO -          Listening to:  tcp://10.33.227.169:41823
2023-06-22 21:28:09,659 - distributed.worker - INFO -          dashboard at:        10.33.227.169:46261
2023-06-22 21:28:09,659 - distributed.worker - INFO - Waiting to connect to:   tcp://10.33.227.169:8786
2023-06-22 21:28:09,659 - distributed.worker - INFO - -------------------------------------------------
2023-06-22 21:28:09,659 - distributed.worker - INFO -               Threads:                          1
2023-06-22 21:28:09,659 - distributed.worker - INFO -                Memory:                  62.97 GiB
2023-06-22 21:28:09,659 - distributed.worker - INFO -       Local Directory: /tmp/dask-scratch-space/worker-r3bt28xw
2023-06-22 21:28:09,660 - distributed.worker - INFO - Starting Worker plugin RMMSetup-169cae54-0c21-47cf-8aea-44ddc5755b3e
2023-06-22 21:28:09,665 - distributed.worker - INFO -       Start worker at:  tcp://10.33.227.169:43565
2023-06-22 21:28:09,665 - distributed.worker - INFO -          Listening to:  tcp://10.33.227.169:43565
2023-06-22 21:28:09,665 - distributed.worker - INFO -          dashboard at:        10.33.227.169:46279
2023-06-22 21:28:09,666 - distributed.worker - INFO - Waiting to connect to:   tcp://10.33.227.169:8786
2023-06-22 21:28:09,666 - distributed.worker - INFO - -------------------------------------------------
2023-06-22 21:28:09,666 - distributed.worker - INFO -               Threads:                          1
2023-06-22 21:28:09,666 - distributed.worker - INFO -                Memory:                  62.97 GiB
2023-06-22 21:28:09,666 - distributed.worker - INFO -       Local Directory: /tmp/dask-scratch-space/worker-7hnj6ew5
2023-06-22 21:28:09,666 - distributed.worker - INFO - Starting Worker plugin PreImport-63d0a1cb-625e-4b58-98e0-3e21480524f9
2023-06-22 21:28:09,666 - distributed.worker - INFO - Starting Worker plugin CPUAffinity-2bb29180-f8e5-4ac3-8d99-5e9203c17e83
2023-06-22 21:28:09,667 - distributed.worker - INFO - Starting Worker plugin RMMSetup-2ab579a9-cb94-481f-a509-23c48e9b0707
2023-06-22 21:28:09,671 - distributed.worker - INFO -       Start worker at:  tcp://10.33.227.169:39523
2023-06-22 21:28:09,672 - distributed.worker - INFO -          Listening to:  tcp://10.33.227.169:39523
2023-06-22 21:28:09,672 - distributed.worker - INFO -          dashboard at:        10.33.227.169:41011
2023-06-22 21:28:09,672 - distributed.worker - INFO - Waiting to connect to:   tcp://10.33.227.169:8786
2023-06-22 21:28:09,672 - distributed.worker - INFO - -------------------------------------------------
2023-06-22 21:28:09,672 - distributed.worker - INFO -               Threads:                          1
2023-06-22 21:28:09,672 - distributed.worker - INFO -                Memory:                  62.97 GiB
2023-06-22 21:28:09,672 - distributed.worker - INFO -       Local Directory: /tmp/dask-scratch-space/worker-vwh_irom
2023-06-22 21:28:09,673 - distributed.worker - INFO - Starting Worker plugin RMMSetup-9c1bf17a-9841-4943-97b6-c9e5b4fe3172
2023-06-22 21:28:09,675 - distributed.worker - INFO -       Start worker at:  tcp://10.33.227.169:41457
2023-06-22 21:28:09,675 - distributed.worker - INFO -          Listening to:  tcp://10.33.227.169:41457
2023-06-22 21:28:09,675 - distributed.worker - INFO -          dashboard at:        10.33.227.169:42985
2023-06-22 21:28:09,675 - distributed.worker - INFO - Waiting to connect to:   tcp://10.33.227.169:8786
2023-06-22 21:28:09,675 - distributed.worker - INFO - -------------------------------------------------
2023-06-22 21:28:09,675 - distributed.worker - INFO -               Threads:                          1
2023-06-22 21:28:09,676 - distributed.worker - INFO -                Memory:                  62.97 GiB
2023-06-22 21:28:09,676 - distributed.worker - INFO -       Local Directory: /tmp/dask-scratch-space/worker-0yt_cx2x
2023-06-22 21:28:09,676 - distributed.worker - INFO - Starting Worker plugin PreImport-da7f456d-ba6f-435e-8cf2-5833b3812302
2023-06-22 21:28:09,676 - distributed.worker - INFO - Starting Worker plugin CPUAffinity-f9e671ea-3ca3-4062-af83-ee909dbefc33
2023-06-22 21:28:09,676 - distributed.worker - INFO - Starting Worker plugin RMMSetup-6710971b-9b6a-4efa-aa28-e05f8b54670c
2023-06-22 21:28:09,678 - distributed.worker - INFO -       Start worker at:  tcp://10.33.227.169:36481
2023-06-22 21:28:09,678 - distributed.worker - INFO -          Listening to:  tcp://10.33.227.169:36481
2023-06-22 21:28:09,678 - distributed.worker - INFO -          dashboard at:        10.33.227.169:40413
2023-06-22 21:28:09,678 - distributed.worker - INFO - Waiting to connect to:   tcp://10.33.227.169:8786
2023-06-22 21:28:09,678 - distributed.worker - INFO - -------------------------------------------------
2023-06-22 21:28:09,678 - distributed.worker - INFO -               Threads:                          1
2023-06-22 21:28:09,678 - distributed.worker - INFO -                Memory:                  62.97 GiB
2023-06-22 21:28:09,678 - distributed.worker - INFO -       Local Directory: /tmp/dask-scratch-space/worker-lslqeeid
2023-06-22 21:28:09,679 - distributed.worker - INFO - Starting Worker plugin RMMSetup-ac25f9b2-00e5-4d60-b5c3-4411a2d3ff82
2023-06-22 21:28:09,684 - distributed.worker - INFO -       Start worker at:  tcp://10.33.227.169:46613
2023-06-22 21:28:09,684 - distributed.worker - INFO -          Listening to:  tcp://10.33.227.169:46613
2023-06-22 21:28:09,684 - distributed.worker - INFO -          dashboard at:        10.33.227.169:40251
2023-06-22 21:28:09,684 - distributed.worker - INFO - Waiting to connect to:   tcp://10.33.227.169:8786
2023-06-22 21:28:09,684 - distributed.worker - INFO - -------------------------------------------------
2023-06-22 21:28:09,684 - distributed.worker - INFO -               Threads:                          1
2023-06-22 21:28:09,684 - distributed.worker - INFO -                Memory:                  62.97 GiB
2023-06-22 21:28:09,684 - distributed.worker - INFO -       Local Directory: /tmp/dask-scratch-space/worker-t_gpm9dk
2023-06-22 21:28:09,685 - distributed.worker - INFO - Starting Worker plugin PreImport-07e5f2f6-9db5-4ee0-9c7a-a0f2b7d8871a
2023-06-22 21:28:09,685 - distributed.worker - INFO - Starting Worker plugin CPUAffinity-ef8cbb91-5a04-42e8-a008-e4396dd92c85
2023-06-22 21:28:09,685 - distributed.worker - INFO - Starting Worker plugin RMMSetup-e7ab466c-6bbf-4dab-9429-fc6c3a721cf8
2023-06-22 21:28:09,787 - distributed.worker - INFO - -------------------------------------------------
2023-06-22 21:28:09,883 - distributed.worker - INFO - Starting Worker plugin CPUAffinity-e2bb0cea-1541-4106-b42e-56bd66ff8631
2023-06-22 21:28:09,884 - distributed.worker - INFO - -------------------------------------------------
2023-06-22 21:28:09,883 - distributed.worker - INFO - Starting Worker plugin PreImport-fa12b508-eb26-48a8-8bbf-2ac58e283dec
2023-06-22 21:28:09,884 - distributed.worker - INFO - Starting Worker plugin PreImport-953252d4-8064-49f5-9e31-ab001ea294c9
2023-06-22 21:28:09,884 - distributed.worker - INFO - Starting Worker plugin CPUAffinity-1502287e-edc0-433a-ad73-432ee157669d
2023-06-22 21:28:09,884 - distributed.worker - INFO - -------------------------------------------------
2023-06-22 21:28:09,884 - distributed.worker - INFO - Starting Worker plugin PreImport-11426d6c-e04f-4e8c-aec9-02f4fa6a4d52
2023-06-22 21:28:09,885 - distributed.worker - INFO - Starting Worker plugin CPUAffinity-aebbceb1-7ff2-48c6-8865-ab8601b2f9e8
2023-06-22 21:28:09,885 - distributed.worker - INFO - -------------------------------------------------
2023-06-22 21:28:09,885 - distributed.worker - INFO - -------------------------------------------------
2023-06-22 21:28:09,885 - distributed.worker - INFO - -------------------------------------------------
2023-06-22 21:28:09,885 - distributed.worker - INFO - -------------------------------------------------
2023-06-22 21:28:09,886 - distributed.worker - INFO - -------------------------------------------------
2023-06-22 21:28:10,046 - distributed.worker - INFO -         Registered to:   tcp://10.33.227.169:8786
2023-06-22 21:28:10,046 - distributed.worker - INFO - -------------------------------------------------
2023-06-22 21:28:10,048 - distributed.core - INFO - Starting established connection to tcp://10.33.227.169:8786
2023-06-22 21:28:10,056 - distributed.worker - INFO -         Registered to:   tcp://10.33.227.169:8786
2023-06-22 21:28:10,056 - distributed.worker - INFO - -------------------------------------------------
2023-06-22 21:28:10,057 - distributed.worker - INFO -         Registered to:   tcp://10.33.227.169:8786
2023-06-22 21:28:10,057 - distributed.worker - INFO - -------------------------------------------------
2023-06-22 21:28:10,057 - distributed.core - INFO - Starting established connection to tcp://10.33.227.169:8786
2023-06-22 21:28:10,058 - distributed.worker - INFO -         Registered to:   tcp://10.33.227.169:8786
2023-06-22 21:28:10,058 - distributed.worker - INFO - -------------------------------------------------
2023-06-22 21:28:10,058 - distributed.core - INFO - Starting established connection to tcp://10.33.227.169:8786
2023-06-22 21:28:10,059 - distributed.core - INFO - Starting established connection to tcp://10.33.227.169:8786
2023-06-22 21:28:10,060 - distributed.worker - INFO -         Registered to:   tcp://10.33.227.169:8786
2023-06-22 21:28:10,060 - distributed.worker - INFO - -------------------------------------------------
2023-06-22 21:28:10,061 - distributed.worker - INFO -         Registered to:   tcp://10.33.227.169:8786
2023-06-22 21:28:10,061 - distributed.worker - INFO - -------------------------------------------------
2023-06-22 21:28:10,061 - distributed.worker - INFO -         Registered to:   tcp://10.33.227.169:8786
2023-06-22 21:28:10,062 - distributed.worker - INFO - -------------------------------------------------
2023-06-22 21:28:10,062 - distributed.core - INFO - Starting established connection to tcp://10.33.227.169:8786
2023-06-22 21:28:10,062 - distributed.worker - INFO -         Registered to:   tcp://10.33.227.169:8786
2023-06-22 21:28:10,062 - distributed.worker - INFO - -------------------------------------------------
2023-06-22 21:28:10,063 - distributed.core - INFO - Starting established connection to tcp://10.33.227.169:8786
2023-06-22 21:28:10,064 - distributed.core - INFO - Starting established connection to tcp://10.33.227.169:8786
2023-06-22 21:28:10,065 - distributed.core - INFO - Starting established connection to tcp://10.33.227.169:8786
2023-06-22 21:29:01,675 - distributed.worker - INFO - Run out-of-band function '_func_ucp_listener_port'
2023-06-22 21:29:01,675 - distributed.worker - INFO - Run out-of-band function '_func_ucp_listener_port'
2023-06-22 21:29:01,676 - distributed.worker - INFO - Run out-of-band function '_func_ucp_listener_port'
2023-06-22 21:29:01,681 - distributed.worker - INFO - Run out-of-band function '_func_ucp_listener_port'
2023-06-22 21:29:01,681 - distributed.worker - INFO - Run out-of-band function '_func_ucp_listener_port'
2023-06-22 21:29:01,682 - distributed.worker - INFO - Run out-of-band function '_func_ucp_listener_port'
2023-06-22 21:29:01,683 - distributed.worker - INFO - Run out-of-band function '_func_ucp_listener_port'
2023-06-22 21:29:01,683 - distributed.worker - INFO - Run out-of-band function '_func_ucp_listener_port'
2023-06-22 21:29:01,777 - distributed.worker - INFO - Run out-of-band function '_func_init_all'
2023-06-22 21:29:01,777 - distributed.worker - INFO - Run out-of-band function '_func_init_all'
2023-06-22 21:29:01,777 - distributed.worker - INFO - Run out-of-band function '_func_init_all'
2023-06-22 21:29:01,778 - distributed.worker - INFO - Run out-of-band function '_func_init_all'
2023-06-22 21:29:01,778 - distributed.worker - INFO - Run out-of-band function '_func_init_all'
2023-06-22 21:29:01,778 - distributed.worker - INFO - Run out-of-band function '_func_init_all'
2023-06-22 21:29:01,778 - distributed.worker - INFO - Run out-of-band function '_func_init_all'
2023-06-22 21:29:01,778 - distributed.worker - INFO - Run out-of-band function '_func_init_all'
2023-06-22 21:29:12,676 - distributed.worker - INFO - Run out-of-band function '_subcomm_init'
2023-06-22 21:29:12,908 - distributed.worker - INFO - Run out-of-band function '_subcomm_init'
2023-06-22 21:29:12,919 - distributed.worker - INFO - Run out-of-band function '_subcomm_init'
2023-06-22 21:29:12,930 - distributed.worker - INFO - Run out-of-band function '_subcomm_init'
2023-06-22 21:29:13,024 - distributed.worker - INFO - Run out-of-band function '_subcomm_init'
2023-06-22 21:29:13,111 - distributed.worker - INFO - Run out-of-band function '_subcomm_init'
2023-06-22 21:29:13,114 - distributed.worker - INFO - Run out-of-band function '_subcomm_init'
2023-06-22 21:29:13,191 - distributed.worker - INFO - Run out-of-band function '_subcomm_init'
2023-06-22 21:29:19,173 - distributed.core - INFO - Event loop was unresponsive in Worker for 15.79s.  This is often caused by long-running GIL-holding functions or moving large chunks of data. This can cause timeouts and instability.
2023-06-22 21:29:19,213 - distributed.core - INFO - Event loop was unresponsive in Worker for 15.83s.  This is often caused by long-running GIL-holding functions or moving large chunks of data. This can cause timeouts and instability.
2023-06-22 21:29:19,213 - distributed.core - INFO - Event loop was unresponsive in Worker for 15.83s.  This is often caused by long-running GIL-holding functions or moving large chunks of data. This can cause timeouts and instability.
2023-06-22 21:29:19,213 - distributed.core - INFO - Event loop was unresponsive in Worker for 15.83s.  This is often caused by long-running GIL-holding functions or moving large chunks of data. This can cause timeouts and instability.
2023-06-22 21:29:19,258 - distributed.core - INFO - Event loop was unresponsive in Worker for 15.87s.  This is often caused by long-running GIL-holding functions or moving large chunks of data. This can cause timeouts and instability.
2023-06-22 21:29:19,258 - distributed.core - INFO - Event loop was unresponsive in Worker for 15.88s.  This is often caused by long-running GIL-holding functions or moving large chunks of data. This can cause timeouts and instability.
2023-06-22 21:29:19,259 - distributed.core - INFO - Event loop was unresponsive in Worker for 15.88s.  This is often caused by long-running GIL-holding functions or moving large chunks of data. This can cause timeouts and instability.
2023-06-22 21:29:19,259 - distributed.core - INFO - Event loop was unresponsive in Worker for 15.88s.  This is often caused by long-running GIL-holding functions or moving large chunks of data. This can cause timeouts and instability.
2023-06-22 21:29:41,678 - distributed.worker - INFO - Stopping worker at tcp://10.33.227.169:39523. Reason: worker-close
2023-06-22 21:29:41,678 - distributed.worker - INFO - Stopping worker at tcp://10.33.227.169:39247. Reason: worker-handle-scheduler-connection-broken
2023-06-22 21:29:41,678 - distributed.worker - INFO - Stopping worker at tcp://10.33.227.169:41823. Reason: worker-handle-scheduler-connection-broken
2023-06-22 21:29:41,678 - distributed.worker - INFO - Stopping worker at tcp://10.33.227.169:41457. Reason: worker-close
2023-06-22 21:29:41,678 - distributed.worker - INFO - Stopping worker at tcp://10.33.227.169:43565. Reason: worker-close
2023-06-22 21:29:41,678 - distributed.worker - INFO - Stopping worker at tcp://10.33.227.169:46613. Reason: worker-close
2023-06-22 21:29:41,678 - distributed.worker - INFO - Stopping worker at tcp://10.33.227.169:35787. Reason: worker-close
2023-06-22 21:29:41,678 - distributed.worker - INFO - Stopping worker at tcp://10.33.227.169:36481. Reason: worker-close
2023-06-22 21:29:41,680 - distributed.nanny - INFO - Closing Nanny at 'tcp://10.33.227.169:38535'. Reason: nanny-close
2023-06-22 21:29:41,680 - distributed.batched - INFO - Batched Comm Closed <TCP (closed) Worker->Scheduler local=tcp://10.33.227.169:42938 remote=tcp://10.33.227.169:8786>
Traceback (most recent call last):
  File "/opt/conda/envs/rapids/lib/python3.10/asyncio/runners.py", line 44, in run
    return loop.run_until_complete(main)
  File "/opt/conda/envs/rapids/lib/python3.10/asyncio/base_events.py", line 636, in run_until_complete
    self.run_forever()
  File "/opt/conda/envs/rapids/lib/python3.10/asyncio/base_events.py", line 603, in run_forever
    self._run_once()
  File "/opt/conda/envs/rapids/lib/python3.10/asyncio/base_events.py", line 1871, in _run_once
    event_list = self._selector.select(timeout)
  File "/opt/conda/envs/rapids/lib/python3.10/selectors.py", line 469, in select
    fd_event_list = self._selector.poll(timeout, max_ev)
KeyboardInterrupt

During handling of the above exception, another exception occurred:

Traceback (most recent call last):
  File "/opt/conda/envs/rapids/lib/python3.10/site-packages/distributed/batched.py", line 115, in _background_send
    nbytes = yield coro
  File "/opt/conda/envs/rapids/lib/python3.10/site-packages/tornado/gen.py", line 767, in run
    value = future.result()
  File "/opt/conda/envs/rapids/lib/python3.10/site-packages/distributed/comm/tcp.py", line 269, in write
    raise CommClosedError()
distributed.comm.core.CommClosedError
2023-06-22 21:29:41,680 - distributed.batched - INFO - Batched Comm Closed <TCP (closed) Worker->Scheduler local=tcp://10.33.227.169:42982 remote=tcp://10.33.227.169:8786>
Traceback (most recent call last):
  File "/opt/conda/envs/rapids/lib/python3.10/asyncio/runners.py", line 44, in run
    return loop.run_until_complete(main)
  File "/opt/conda/envs/rapids/lib/python3.10/asyncio/base_events.py", line 636, in run_until_complete
    self.run_forever()
  File "/opt/conda/envs/rapids/lib/python3.10/asyncio/base_events.py", line 603, in run_forever
    self._run_once()
  File "/opt/conda/envs/rapids/lib/python3.10/asyncio/base_events.py", line 1871, in _run_once
    event_list = self._selector.select(timeout)
  File "/opt/conda/envs/rapids/lib/python3.10/selectors.py", line 469, in select
    fd_event_list = self._selector.poll(timeout, max_ev)
KeyboardInterrupt

During handling of the above exception, another exception occurred:

Traceback (most recent call last):
  File "/opt/conda/envs/rapids/lib/python3.10/site-packages/distributed/batched.py", line 115, in _background_send
    nbytes = yield coro
  File "/opt/conda/envs/rapids/lib/python3.10/site-packages/tornado/gen.py", line 767, in run
    value = future.result()
  File "/opt/conda/envs/rapids/lib/python3.10/site-packages/distributed/comm/tcp.py", line 269, in write
    raise CommClosedError()
distributed.comm.core.CommClosedError
2023-06-22 21:29:41,682 - distributed.nanny - INFO - Nanny asking worker to close. Reason: nanny-close
2023-06-22 21:29:41,680 - distributed.batched - INFO - Batched Comm Closed <TCP (closed) Worker->Scheduler local=tcp://10.33.227.169:42926 remote=tcp://10.33.227.169:8786>
Traceback (most recent call last):
  File "/opt/conda/envs/rapids/lib/python3.10/asyncio/runners.py", line 44, in run
    return loop.run_until_complete(main)
  File "/opt/conda/envs/rapids/lib/python3.10/asyncio/base_events.py", line 636, in run_until_complete
    self.run_forever()
  File "/opt/conda/envs/rapids/lib/python3.10/asyncio/base_events.py", line 603, in run_forever
    self._run_once()
  File "/opt/conda/envs/rapids/lib/python3.10/asyncio/base_events.py", line 1871, in _run_once
    event_list = self._selector.select(timeout)
  File "/opt/conda/envs/rapids/lib/python3.10/selectors.py", line 469, in select
    fd_event_list = self._selector.poll(timeout, max_ev)
KeyboardInterrupt

During handling of the above exception, another exception occurred:

Traceback (most recent call last):
  File "/opt/conda/envs/rapids/lib/python3.10/site-packages/distributed/batched.py", line 115, in _background_send
    nbytes = yield coro
  File "/opt/conda/envs/rapids/lib/python3.10/site-packages/tornado/gen.py", line 767, in run
    value = future.result()
  File "/opt/conda/envs/rapids/lib/python3.10/site-packages/distributed/comm/tcp.py", line 269, in write
    raise CommClosedError()
distributed.comm.core.CommClosedError
2023-06-22 21:29:41,680 - distributed.batched - INFO - Batched Comm Closed <TCP (closed) Worker->Scheduler local=tcp://10.33.227.169:42952 remote=tcp://10.33.227.169:8786>
Traceback (most recent call last):
  File "/opt/conda/envs/rapids/lib/python3.10/asyncio/runners.py", line 44, in run
    return loop.run_until_complete(main)
  File "/opt/conda/envs/rapids/lib/python3.10/asyncio/base_events.py", line 636, in run_until_complete
    self.run_forever()
  File "/opt/conda/envs/rapids/lib/python3.10/asyncio/base_events.py", line 603, in run_forever
    self._run_once()
  File "/opt/conda/envs/rapids/lib/python3.10/asyncio/base_events.py", line 1871, in _run_once
    event_list = self._selector.select(timeout)
  File "/opt/conda/envs/rapids/lib/python3.10/selectors.py", line 469, in select
    fd_event_list = self._selector.poll(timeout, max_ev)
KeyboardInterrupt

During handling of the above exception, another exception occurred:

Traceback (most recent call last):
  File "/opt/conda/envs/rapids/lib/python3.10/site-packages/distributed/batched.py", line 115, in _background_send
    nbytes = yield coro
  File "/opt/conda/envs/rapids/lib/python3.10/site-packages/tornado/gen.py", line 767, in run
    value = future.result()
  File "/opt/conda/envs/rapids/lib/python3.10/site-packages/distributed/comm/tcp.py", line 269, in write
    raise CommClosedError()
distributed.comm.core.CommClosedError
2023-06-22 21:29:41,680 - distributed.batched - INFO - Batched Comm Closed <TCP (closed) Worker->Scheduler local=tcp://10.33.227.169:42910 remote=tcp://10.33.227.169:8786>
Traceback (most recent call last):
  File "/opt/conda/envs/rapids/lib/python3.10/asyncio/runners.py", line 44, in run
    return loop.run_until_complete(main)
  File "/opt/conda/envs/rapids/lib/python3.10/asyncio/base_events.py", line 636, in run_until_complete
    self.run_forever()
  File "/opt/conda/envs/rapids/lib/python3.10/asyncio/base_events.py", line 603, in run_forever
    self._run_once()
  File "/opt/conda/envs/rapids/lib/python3.10/asyncio/base_events.py", line 1909, in _run_once
    handle._run()
  File "/opt/conda/envs/rapids/lib/python3.10/asyncio/events.py", line 80, in _run
    self._context.run(self._callback, *self._args)
  File "/opt/conda/envs/rapids/lib/python3.10/site-packages/tornado/ioloop.py", line 740, in _run_callback
    from tornado import gen
  File "<frozen importlib._bootstrap>", line 1064, in _handle_fromlist
KeyboardInterrupt

During handling of the above exception, another exception occurred:

Traceback (most recent call last):
  File "/opt/conda/envs/rapids/lib/python3.10/site-packages/distributed/batched.py", line 115, in _background_send
    nbytes = yield coro
  File "/opt/conda/envs/rapids/lib/python3.10/site-packages/tornado/gen.py", line 767, in run
    value = future.result()
  File "/opt/conda/envs/rapids/lib/python3.10/site-packages/distributed/comm/tcp.py", line 269, in write
    raise CommClosedError()
distributed.comm.core.CommClosedError
2023-06-22 21:29:41,680 - distributed.batched - INFO - Batched Comm Closed <TCP (closed) Worker->Scheduler local=tcp://10.33.227.169:42962 remote=tcp://10.33.227.169:8786>
Traceback (most recent call last):
  File "/opt/conda/envs/rapids/lib/python3.10/asyncio/runners.py", line 44, in run
    return loop.run_until_complete(main)
  File "/opt/conda/envs/rapids/lib/python3.10/asyncio/base_events.py", line 636, in run_until_complete
    self.run_forever()
  File "/opt/conda/envs/rapids/lib/python3.10/asyncio/base_events.py", line 603, in run_forever
    self._run_once()
  File "/opt/conda/envs/rapids/lib/python3.10/asyncio/base_events.py", line 1871, in _run_once
    event_list = self._selector.select(timeout)
  File "/opt/conda/envs/rapids/lib/python3.10/selectors.py", line 469, in select
    fd_event_list = self._selector.poll(timeout, max_ev)
KeyboardInterrupt

During handling of the above exception, another exception occurred:

Traceback (most recent call last):
  File "/opt/conda/envs/rapids/lib/python3.10/site-packages/distributed/batched.py", line 115, in _background_send
    nbytes = yield coro
  File "/opt/conda/envs/rapids/lib/python3.10/site-packages/tornado/gen.py", line 767, in run
    value = future.result()
  File "/opt/conda/envs/rapids/lib/python3.10/site-packages/distributed/comm/tcp.py", line 269, in write
    raise CommClosedError()
distributed.comm.core.CommClosedError
2023-06-22 21:29:41,684 - distributed.nanny - INFO - Closing Nanny at 'tcp://10.33.227.169:35101'. Reason: nanny-close
2023-06-22 21:29:41,686 - distributed.nanny - INFO - Nanny asking worker to close. Reason: nanny-close
2023-06-22 21:29:41,686 - distributed.nanny - INFO - Closing Nanny at 'tcp://10.33.227.169:34527'. Reason: nanny-close
2023-06-22 21:29:41,687 - distributed.nanny - INFO - Nanny asking worker to close. Reason: nanny-close
2023-06-22 21:29:41,687 - distributed.nanny - INFO - Closing Nanny at 'tcp://10.33.227.169:34385'. Reason: nanny-close
2023-06-22 21:29:41,688 - distributed.nanny - INFO - Nanny asking worker to close. Reason: nanny-close
2023-06-22 21:29:41,688 - distributed.nanny - INFO - Closing Nanny at 'tcp://10.33.227.169:34113'. Reason: nanny-close
2023-06-22 21:29:41,688 - distributed.nanny - INFO - Nanny asking worker to close. Reason: nanny-close
2023-06-22 21:29:41,689 - distributed.nanny - INFO - Closing Nanny at 'tcp://10.33.227.169:34197'. Reason: nanny-close
2023-06-22 21:29:41,689 - distributed.nanny - INFO - Nanny asking worker to close. Reason: nanny-close
2023-06-22 21:29:41,689 - distributed.nanny - INFO - Closing Nanny at 'tcp://10.33.227.169:42269'. Reason: nanny-close
2023-06-22 21:29:41,690 - distributed.nanny - INFO - Nanny asking worker to close. Reason: nanny-close
2023-06-22 21:29:41,690 - distributed.nanny - INFO - Closing Nanny at 'tcp://10.33.227.169:43597'. Reason: nanny-close
2023-06-22 21:29:41,690 - distributed.nanny - INFO - Nanny asking worker to close. Reason: nanny-close
2023-06-22 21:29:41,702 - distributed.worker - ERROR - Timed out during handshake while connecting to tcp://10.33.227.169:38535 after 100 s
Traceback (most recent call last):
  File "/opt/conda/envs/rapids/lib/python3.10/asyncio/runners.py", line 44, in run
    return loop.run_until_complete(main)
  File "/opt/conda/envs/rapids/lib/python3.10/asyncio/base_events.py", line 636, in run_until_complete
    self.run_forever()
  File "/opt/conda/envs/rapids/lib/python3.10/asyncio/base_events.py", line 603, in run_forever
    self._run_once()
  File "/opt/conda/envs/rapids/lib/python3.10/asyncio/base_events.py", line 1871, in _run_once
    event_list = self._selector.select(timeout)
  File "/opt/conda/envs/rapids/lib/python3.10/selectors.py", line 469, in select
    fd_event_list = self._selector.poll(timeout, max_ev)
KeyboardInterrupt

During handling of the above exception, another exception occurred:

Traceback (most recent call last):
  File "/opt/conda/envs/rapids/lib/python3.10/site-packages/tornado/iostream.py", line 861, in _read_to_buffer
    bytes_read = self.read_from_fd(buf)
  File "/opt/conda/envs/rapids/lib/python3.10/site-packages/tornado/iostream.py", line 1116, in read_from_fd
    return self.socket.recv_into(buf, len(buf))
ConnectionResetError: [Errno 104] Connection reset by peer

The above exception was the direct cause of the following exception:

Traceback (most recent call last):
  File "/opt/conda/envs/rapids/lib/python3.10/site-packages/distributed/comm/core.py", line 373, in connect
    handshake = await wait_for(comm.read(), time_left())
  File "/opt/conda/envs/rapids/lib/python3.10/site-packages/distributed/utils.py", line 1878, in wait_for
    return await asyncio.wait_for(fut, timeout)
  File "/opt/conda/envs/rapids/lib/python3.10/asyncio/tasks.py", line 445, in wait_for
    return fut.result()
  File "/opt/conda/envs/rapids/lib/python3.10/site-packages/distributed/comm/tcp.py", line 241, in read
    convert_stream_closed_error(self, e)
  File "/opt/conda/envs/rapids/lib/python3.10/site-packages/distributed/comm/tcp.py", line 142, in convert_stream_closed_error
    raise CommClosedError(f"in {obj}: {exc.__class__.__name__}: {exc}") from exc
distributed.comm.core.CommClosedError: in <TCP (closed)  local=tcp://10.33.227.169:43616 remote=tcp://10.33.227.169:38535>: ConnectionResetError: [Errno 104] Connection reset by peer

The above exception was the direct cause of the following exception:

Traceback (most recent call last):
  File "/opt/conda/envs/rapids/lib/python3.10/site-packages/distributed/utils.py", line 754, in wrapper
    return await func(*args, **kwargs)
  File "/opt/conda/envs/rapids/lib/python3.10/site-packages/distributed/worker.py", line 1540, in close
    await r.close_gracefully(reason=reason)
  File "/opt/conda/envs/rapids/lib/python3.10/site-packages/distributed/core.py", line 1362, in send_recv_from_rpc
    comm = await self.pool.connect(self.addr)
  File "/opt/conda/envs/rapids/lib/python3.10/site-packages/distributed/core.py", line 1606, in connect
    return await connect_attempt
  File "/opt/conda/envs/rapids/lib/python3.10/site-packages/distributed/core.py", line 1527, in _connect
    comm = await connect(
  File "/opt/conda/envs/rapids/lib/python3.10/site-packages/distributed/comm/core.py", line 378, in connect
    raise OSError(
OSError: Timed out during handshake while connecting to tcp://10.33.227.169:38535 after 100 s
2023-06-22 21:29:41,704 - distributed.core - ERROR - Timed out during handshake while connecting to tcp://10.33.227.169:35101 after 100 s
Traceback (most recent call last):
  File "/opt/conda/envs/rapids/lib/python3.10/asyncio/runners.py", line 44, in run
    return loop.run_until_complete(main)
  File "/opt/conda/envs/rapids/lib/python3.10/asyncio/base_events.py", line 636, in run_until_complete
    self.run_forever()
  File "/opt/conda/envs/rapids/lib/python3.10/asyncio/base_events.py", line 603, in run_forever
    self._run_once()
  File "/opt/conda/envs/rapids/lib/python3.10/asyncio/base_events.py", line 1871, in _run_once
    event_list = self._selector.select(timeout)
  File "/opt/conda/envs/rapids/lib/python3.10/selectors.py", line 469, in select
    fd_event_list = self._selector.poll(timeout, max_ev)
KeyboardInterrupt

During handling of the above exception, another exception occurred:

Traceback (most recent call last):
  File "/opt/conda/envs/rapids/lib/python3.10/site-packages/tornado/iostream.py", line 861, in _read_to_buffer
    bytes_read = self.read_from_fd(buf)
  File "/opt/conda/envs/rapids/lib/python3.10/site-packages/tornado/iostream.py", line 1116, in read_from_fd
    return self.socket.recv_into(buf, len(buf))
ConnectionResetError: [Errno 104] Connection reset by peer

The above exception was the direct cause of the following exception:

Traceback (most recent call last):
  File "/opt/conda/envs/rapids/lib/python3.10/site-packages/distributed/comm/core.py", line 373, in connect
    handshake = await wait_for(comm.read(), time_left())
  File "/opt/conda/envs/rapids/lib/python3.10/site-packages/distributed/utils.py", line 1878, in wait_for
    return await asyncio.wait_for(fut, timeout)
  File "/opt/conda/envs/rapids/lib/python3.10/asyncio/tasks.py", line 445, in wait_for
    return fut.result()
  File "/opt/conda/envs/rapids/lib/python3.10/site-packages/distributed/comm/tcp.py", line 241, in read
    convert_stream_closed_error(self, e)
  File "/opt/conda/envs/rapids/lib/python3.10/site-packages/distributed/comm/tcp.py", line 142, in convert_stream_closed_error
    raise CommClosedError(f"in {obj}: {exc.__class__.__name__}: {exc}") from exc
distributed.comm.core.CommClosedError: in <TCP (closed)  local=tcp://10.33.227.169:54802 remote=tcp://10.33.227.169:35101>: ConnectionResetError: [Errno 104] Connection reset by peer

The above exception was the direct cause of the following exception:

Traceback (most recent call last):
  File "/opt/conda/envs/rapids/lib/python3.10/site-packages/distributed/utils.py", line 754, in wrapper
    return await func(*args, **kwargs)
  File "/opt/conda/envs/rapids/lib/python3.10/site-packages/distributed/worker.py", line 1540, in close
    await r.close_gracefully(reason=reason)
  File "/opt/conda/envs/rapids/lib/python3.10/site-packages/distributed/core.py", line 1362, in send_recv_from_rpc
    comm = await self.pool.connect(self.addr)
  File "/opt/conda/envs/rapids/lib/python3.10/site-packages/distributed/core.py", line 1606, in connect
    return await connect_attempt
  File "/opt/conda/envs/rapids/lib/python3.10/site-packages/distributed/core.py", line 1527, in _connect
    comm = await connect(
  File "/opt/conda/envs/rapids/lib/python3.10/site-packages/distributed/comm/core.py", line 378, in connect
    raise OSError(
OSError: Timed out during handshake while connecting to tcp://10.33.227.169:35101 after 100 s
2023-06-22 21:29:41,704 - distributed.core - ERROR - Timed out during handshake while connecting to tcp://10.33.227.169:34385 after 100 s
Traceback (most recent call last):
  File "/opt/conda/envs/rapids/lib/python3.10/asyncio/runners.py", line 44, in run
    return loop.run_until_complete(main)
  File "/opt/conda/envs/rapids/lib/python3.10/asyncio/base_events.py", line 636, in run_until_complete
    self.run_forever()
  File "/opt/conda/envs/rapids/lib/python3.10/asyncio/base_events.py", line 603, in run_forever
    self._run_once()
  File "/opt/conda/envs/rapids/lib/python3.10/asyncio/base_events.py", line 1871, in _run_once
    event_list = self._selector.select(timeout)
  File "/opt/conda/envs/rapids/lib/python3.10/selectors.py", line 469, in select
    fd_event_list = self._selector.poll(timeout, max_ev)
KeyboardInterrupt

During handling of the above exception, another exception occurred:

Traceback (most recent call last):
  File "/opt/conda/envs/rapids/lib/python3.10/site-packages/tornado/iostream.py", line 861, in _read_to_buffer
    bytes_read = self.read_from_fd(buf)
  File "/opt/conda/envs/rapids/lib/python3.10/site-packages/tornado/iostream.py", line 1116, in read_from_fd
    return self.socket.recv_into(buf, len(buf))
ConnectionResetError: [Errno 104] Connection reset by peer

The above exception was the direct cause of the following exception:

Traceback (most recent call last):
  File "/opt/conda/envs/rapids/lib/python3.10/site-packages/distributed/comm/core.py", line 373, in connect
    handshake = await wait_for(comm.read(), time_left())
  File "/opt/conda/envs/rapids/lib/python3.10/site-packages/distributed/utils.py", line 1878, in wait_for
    return await asyncio.wait_for(fut, timeout)
  File "/opt/conda/envs/rapids/lib/python3.10/asyncio/tasks.py", line 445, in wait_for
    return fut.result()
  File "/opt/conda/envs/rapids/lib/python3.10/site-packages/distributed/comm/tcp.py", line 241, in read
    convert_stream_closed_error(self, e)
  File "/opt/conda/envs/rapids/lib/python3.10/site-packages/distributed/comm/tcp.py", line 142, in convert_stream_closed_error
    raise CommClosedError(f"in {obj}: {exc.__class__.__name__}: {exc}") from exc
distributed.comm.core.CommClosedError: in <TCP (closed)  local=tcp://10.33.227.169:40004 remote=tcp://10.33.227.169:34385>: ConnectionResetError: [Errno 104] Connection reset by peer

The above exception was the direct cause of the following exception:

Traceback (most recent call last):
  File "/opt/conda/envs/rapids/lib/python3.10/site-packages/distributed/utils.py", line 754, in wrapper
    return await func(*args, **kwargs)
  File "/opt/conda/envs/rapids/lib/python3.10/site-packages/distributed/worker.py", line 1540, in close
    await r.close_gracefully(reason=reason)
  File "/opt/conda/envs/rapids/lib/python3.10/site-packages/distributed/core.py", line 1362, in send_recv_from_rpc
    comm = await self.pool.connect(self.addr)
  File "/opt/conda/envs/rapids/lib/python3.10/site-packages/distributed/core.py", line 1606, in connect
    return await connect_attempt
  File "/opt/conda/envs/rapids/lib/python3.10/site-packages/distributed/core.py", line 1527, in _connect
    comm = await connect(
  File "/opt/conda/envs/rapids/lib/python3.10/site-packages/distributed/comm/core.py", line 378, in connect
    raise OSError(
OSError: Timed out during handshake while connecting to tcp://10.33.227.169:34385 after 100 s
2023-06-22 21:29:41,707 - distributed.core - ERROR - Timed out during handshake while connecting to tcp://10.33.227.169:42269 after 100 s
Traceback (most recent call last):
  File "/opt/conda/envs/rapids/lib/python3.10/asyncio/runners.py", line 44, in run
    return loop.run_until_complete(main)
  File "/opt/conda/envs/rapids/lib/python3.10/asyncio/base_events.py", line 636, in run_until_complete
    self.run_forever()
  File "/opt/conda/envs/rapids/lib/python3.10/asyncio/base_events.py", line 603, in run_forever
    self._run_once()
  File "/opt/conda/envs/rapids/lib/python3.10/asyncio/base_events.py", line 1871, in _run_once
    event_list = self._selector.select(timeout)
  File "/opt/conda/envs/rapids/lib/python3.10/selectors.py", line 469, in select
    fd_event_list = self._selector.poll(timeout, max_ev)
KeyboardInterrupt

During handling of the above exception, another exception occurred:

Traceback (most recent call last):
  File "/opt/conda/envs/rapids/lib/python3.10/site-packages/tornado/iostream.py", line 861, in _read_to_buffer
    bytes_read = self.read_from_fd(buf)
  File "/opt/conda/envs/rapids/lib/python3.10/site-packages/tornado/iostream.py", line 1116, in read_from_fd
    return self.socket.recv_into(buf, len(buf))
ConnectionResetError: [Errno 104] Connection reset by peer

The above exception was the direct cause of the following exception:

Traceback (most recent call last):
  File "/opt/conda/envs/rapids/lib/python3.10/site-packages/distributed/comm/core.py", line 373, in connect
    handshake = await wait_for(comm.read(), time_left())
  File "/opt/conda/envs/rapids/lib/python3.10/site-packages/distributed/utils.py", line 1878, in wait_for
    return await asyncio.wait_for(fut, timeout)
  File "/opt/conda/envs/rapids/lib/python3.10/asyncio/tasks.py", line 445, in wait_for
    return fut.result()
  File "/opt/conda/envs/rapids/lib/python3.10/site-packages/distributed/comm/tcp.py", line 241, in read
    convert_stream_closed_error(self, e)
  File "/opt/conda/envs/rapids/lib/python3.10/site-packages/distributed/comm/tcp.py", line 142, in convert_stream_closed_error
    raise CommClosedError(f"in {obj}: {exc.__class__.__name__}: {exc}") from exc
distributed.comm.core.CommClosedError: in <TCP (closed)  local=tcp://10.33.227.169:48642 remote=tcp://10.33.227.169:42269>: ConnectionResetError: [Errno 104] Connection reset by peer

The above exception was the direct cause of the following exception:

Traceback (most recent call last):
  File "/opt/conda/envs/rapids/lib/python3.10/site-packages/distributed/utils.py", line 754, in wrapper
    return await func(*args, **kwargs)
  File "/opt/conda/envs/rapids/lib/python3.10/site-packages/distributed/worker.py", line 1540, in close
    await r.close_gracefully(reason=reason)
  File "/opt/conda/envs/rapids/lib/python3.10/site-packages/distributed/core.py", line 1362, in send_recv_from_rpc
    comm = await self.pool.connect(self.addr)
  File "/opt/conda/envs/rapids/lib/python3.10/site-packages/distributed/core.py", line 1606, in connect
    return await connect_attempt
  File "/opt/conda/envs/rapids/lib/python3.10/site-packages/distributed/core.py", line 1527, in _connect
    comm = await connect(
  File "/opt/conda/envs/rapids/lib/python3.10/site-packages/distributed/comm/core.py", line 378, in connect
    raise OSError(
OSError: Timed out during handshake while connecting to tcp://10.33.227.169:42269 after 100 s
2023-06-22 21:29:41,706 - distributed.worker - ERROR - Timed out during handshake while connecting to tcp://10.33.227.169:43597 after 100 s
Traceback (most recent call last):
  File "/opt/conda/envs/rapids/lib/python3.10/asyncio/runners.py", line 44, in run
    return loop.run_until_complete(main)
  File "/opt/conda/envs/rapids/lib/python3.10/asyncio/base_events.py", line 636, in run_until_complete
    self.run_forever()
  File "/opt/conda/envs/rapids/lib/python3.10/asyncio/base_events.py", line 603, in run_forever
    self._run_once()
  File "/opt/conda/envs/rapids/lib/python3.10/asyncio/base_events.py", line 1871, in _run_once
    event_list = self._selector.select(timeout)
  File "/opt/conda/envs/rapids/lib/python3.10/selectors.py", line 469, in select
    fd_event_list = self._selector.poll(timeout, max_ev)
KeyboardInterrupt

During handling of the above exception, another exception occurred:

Traceback (most recent call last):
  File "/opt/conda/envs/rapids/lib/python3.10/site-packages/tornado/iostream.py", line 861, in _read_to_buffer
    bytes_read = self.read_from_fd(buf)
  File "/opt/conda/envs/rapids/lib/python3.10/site-packages/tornado/iostream.py", line 1116, in read_from_fd
    return self.socket.recv_into(buf, len(buf))
ConnectionResetError: [Errno 104] Connection reset by peer

The above exception was the direct cause of the following exception:

Traceback (most recent call last):
  File "/opt/conda/envs/rapids/lib/python3.10/site-packages/distributed/comm/core.py", line 373, in connect
    handshake = await wait_for(comm.read(), time_left())
  File "/opt/conda/envs/rapids/lib/python3.10/site-packages/distributed/utils.py", line 1878, in wait_for
    return await asyncio.wait_for(fut, timeout)
  File "/opt/conda/envs/rapids/lib/python3.10/asyncio/tasks.py", line 445, in wait_for
    return fut.result()
  File "/opt/conda/envs/rapids/lib/python3.10/site-packages/distributed/comm/tcp.py", line 241, in read
    convert_stream_closed_error(self, e)
  File "/opt/conda/envs/rapids/lib/python3.10/site-packages/distributed/comm/tcp.py", line 142, in convert_stream_closed_error
    raise CommClosedError(f"in {obj}: {exc.__class__.__name__}: {exc}") from exc
distributed.comm.core.CommClosedError: in <TCP (closed)  local=tcp://10.33.227.169:35282 remote=tcp://10.33.227.169:43597>: ConnectionResetError: [Errno 104] Connection reset by peer

The above exception was the direct cause of the following exception:

Traceback (most recent call last):
  File "/opt/conda/envs/rapids/lib/python3.10/site-packages/distributed/utils.py", line 754, in wrapper
    return await func(*args, **kwargs)
  File "/opt/conda/envs/rapids/lib/python3.10/site-packages/distributed/worker.py", line 1540, in close
    await r.close_gracefully(reason=reason)
  File "/opt/conda/envs/rapids/lib/python3.10/site-packages/distributed/core.py", line 1362, in send_recv_from_rpc
    comm = await self.pool.connect(self.addr)
  File "/opt/conda/envs/rapids/lib/python3.10/site-packages/distributed/core.py", line 1606, in connect
    return await connect_attempt
  File "/opt/conda/envs/rapids/lib/python3.10/site-packages/distributed/core.py", line 1527, in _connect
    comm = await connect(
  File "/opt/conda/envs/rapids/lib/python3.10/site-packages/distributed/comm/core.py", line 378, in connect
    raise OSError(
OSError: Timed out during handshake while connecting to tcp://10.33.227.169:43597 after 100 s
2023-06-22 21:29:41,710 - distributed.core - ERROR - Timed out during handshake while connecting to tcp://10.33.227.169:34113 after 100 s
Traceback (most recent call last):
  File "/opt/conda/envs/rapids/lib/python3.10/asyncio/runners.py", line 44, in run
    return loop.run_until_complete(main)
  File "/opt/conda/envs/rapids/lib/python3.10/asyncio/base_events.py", line 636, in run_until_complete
    self.run_forever()
  File "/opt/conda/envs/rapids/lib/python3.10/asyncio/base_events.py", line 603, in run_forever
    self._run_once()
  File "/opt/conda/envs/rapids/lib/python3.10/asyncio/base_events.py", line 1871, in _run_once
    event_list = self._selector.select(timeout)
  File "/opt/conda/envs/rapids/lib/python3.10/selectors.py", line 469, in select
    fd_event_list = self._selector.poll(timeout, max_ev)
KeyboardInterrupt

During handling of the above exception, another exception occurred:

Traceback (most recent call last):
  File "/opt/conda/envs/rapids/lib/python3.10/site-packages/tornado/iostream.py", line 861, in _read_to_buffer
    bytes_read = self.read_from_fd(buf)
  File "/opt/conda/envs/rapids/lib/python3.10/site-packages/tornado/iostream.py", line 1116, in read_from_fd
    return self.socket.recv_into(buf, len(buf))
ConnectionResetError: [Errno 104] Connection reset by peer

The above exception was the direct cause of the following exception:

Traceback (most recent call last):
  File "/opt/conda/envs/rapids/lib/python3.10/site-packages/distributed/comm/core.py", line 373, in connect
    handshake = await wait_for(comm.read(), time_left())
  File "/opt/conda/envs/rapids/lib/python3.10/site-packages/distributed/utils.py", line 1878, in wait_for
    return await asyncio.wait_for(fut, timeout)
  File "/opt/conda/envs/rapids/lib/python3.10/asyncio/tasks.py", line 445, in wait_for
    return fut.result()
  File "/opt/conda/envs/rapids/lib/python3.10/site-packages/distributed/comm/tcp.py", line 241, in read
    convert_stream_closed_error(self, e)
  File "/opt/conda/envs/rapids/lib/python3.10/site-packages/distributed/comm/tcp.py", line 142, in convert_stream_closed_error
    raise CommClosedError(f"in {obj}: {exc.__class__.__name__}: {exc}") from exc
distributed.comm.core.CommClosedError: in <TCP (closed)  local=tcp://10.33.227.169:44880 remote=tcp://10.33.227.169:34113>: ConnectionResetError: [Errno 104] Connection reset by peer

The above exception was the direct cause of the following exception:

Traceback (most recent call last):
  File "/opt/conda/envs/rapids/lib/python3.10/site-packages/distributed/utils.py", line 754, in wrapper
    return await func(*args, **kwargs)
  File "/opt/conda/envs/rapids/lib/python3.10/site-packages/distributed/worker.py", line 1540, in close
    await r.close_gracefully(reason=reason)
  File "/opt/conda/envs/rapids/lib/python3.10/site-packages/distributed/core.py", line 1362, in send_recv_from_rpc
    comm = await self.pool.connect(self.addr)
  File "/opt/conda/envs/rapids/lib/python3.10/site-packages/distributed/core.py", line 1606, in connect
    return await connect_attempt
  File "/opt/conda/envs/rapids/lib/python3.10/site-packages/distributed/core.py", line 1527, in _connect
    comm = await connect(
  File "/opt/conda/envs/rapids/lib/python3.10/site-packages/distributed/comm/core.py", line 378, in connect
    raise OSError(
OSError: Timed out during handshake while connecting to tcp://10.33.227.169:34113 after 100 s
2023-06-22 21:29:41,710 - distributed.core - ERROR - Timed out during handshake while connecting to tcp://10.33.227.169:34527 after 100 s
Traceback (most recent call last):
  File "/opt/conda/envs/rapids/lib/python3.10/asyncio/runners.py", line 44, in run
    return loop.run_until_complete(main)
  File "/opt/conda/envs/rapids/lib/python3.10/asyncio/base_events.py", line 636, in run_until_complete
    self.run_forever()
  File "/opt/conda/envs/rapids/lib/python3.10/asyncio/base_events.py", line 603, in run_forever
    self._run_once()
  File "/opt/conda/envs/rapids/lib/python3.10/asyncio/base_events.py", line 1909, in _run_once
    handle._run()
  File "/opt/conda/envs/rapids/lib/python3.10/asyncio/events.py", line 80, in _run
    self._context.run(self._callback, *self._args)
  File "/opt/conda/envs/rapids/lib/python3.10/site-packages/tornado/ioloop.py", line 740, in _run_callback
    from tornado import gen
  File "<frozen importlib._bootstrap>", line 1064, in _handle_fromlist
KeyboardInterrupt

During handling of the above exception, another exception occurred:

Traceback (most recent call last):
  File "/opt/conda/envs/rapids/lib/python3.10/site-packages/tornado/iostream.py", line 861, in _read_to_buffer
    bytes_read = self.read_from_fd(buf)
  File "/opt/conda/envs/rapids/lib/python3.10/site-packages/tornado/iostream.py", line 1116, in read_from_fd
    return self.socket.recv_into(buf, len(buf))
ConnectionResetError: [Errno 104] Connection reset by peer

The above exception was the direct cause of the following exception:

Traceback (most recent call last):
  File "/opt/conda/envs/rapids/lib/python3.10/site-packages/distributed/comm/core.py", line 373, in connect
    handshake = await wait_for(comm.read(), time_left())
  File "/opt/conda/envs/rapids/lib/python3.10/site-packages/distributed/utils.py", line 1878, in wait_for
    return await asyncio.wait_for(fut, timeout)
  File "/opt/conda/envs/rapids/lib/python3.10/asyncio/tasks.py", line 445, in wait_for
    return fut.result()
  File "/opt/conda/envs/rapids/lib/python3.10/site-packages/distributed/comm/tcp.py", line 241, in read
    convert_stream_closed_error(self, e)
  File "/opt/conda/envs/rapids/lib/python3.10/site-packages/distributed/comm/tcp.py", line 142, in convert_stream_closed_error
    raise CommClosedError(f"in {obj}: {exc.__class__.__name__}: {exc}") from exc
distributed.comm.core.CommClosedError: in <TCP (closed)  local=tcp://10.33.227.169:59718 remote=tcp://10.33.227.169:34527>: ConnectionResetError: [Errno 104] Connection reset by peer

The above exception was the direct cause of the following exception:

Traceback (most recent call last):
  File "/opt/conda/envs/rapids/lib/python3.10/site-packages/distributed/utils.py", line 754, in wrapper
    return await func(*args, **kwargs)
  File "/opt/conda/envs/rapids/lib/python3.10/site-packages/distributed/worker.py", line 1540, in close
    await r.close_gracefully(reason=reason)
  File "/opt/conda/envs/rapids/lib/python3.10/site-packages/distributed/core.py", line 1362, in send_recv_from_rpc
    comm = await self.pool.connect(self.addr)
  File "/opt/conda/envs/rapids/lib/python3.10/site-packages/distributed/core.py", line 1606, in connect
    return await connect_attempt
  File "/opt/conda/envs/rapids/lib/python3.10/site-packages/distributed/core.py", line 1527, in _connect
    comm = await connect(
  File "/opt/conda/envs/rapids/lib/python3.10/site-packages/distributed/comm/core.py", line 378, in connect
    raise OSError(
OSError: Timed out during handshake while connecting to tcp://10.33.227.169:34527 after 100 s
2023-06-22 21:29:41,711 - distributed.core - ERROR - Timed out during handshake while connecting to tcp://10.33.227.169:34197 after 100 s
Traceback (most recent call last):
  File "/opt/conda/envs/rapids/lib/python3.10/asyncio/runners.py", line 44, in run
    return loop.run_until_complete(main)
  File "/opt/conda/envs/rapids/lib/python3.10/asyncio/base_events.py", line 636, in run_until_complete
    self.run_forever()
  File "/opt/conda/envs/rapids/lib/python3.10/asyncio/base_events.py", line 603, in run_forever
    self._run_once()
  File "/opt/conda/envs/rapids/lib/python3.10/asyncio/base_events.py", line 1871, in _run_once
    event_list = self._selector.select(timeout)
  File "/opt/conda/envs/rapids/lib/python3.10/selectors.py", line 469, in select
    fd_event_list = self._selector.poll(timeout, max_ev)
KeyboardInterrupt

During handling of the above exception, another exception occurred:

Traceback (most recent call last):
  File "/opt/conda/envs/rapids/lib/python3.10/site-packages/tornado/iostream.py", line 861, in _read_to_buffer
    bytes_read = self.read_from_fd(buf)
  File "/opt/conda/envs/rapids/lib/python3.10/site-packages/tornado/iostream.py", line 1116, in read_from_fd
    return self.socket.recv_into(buf, len(buf))
ConnectionResetError: [Errno 104] Connection reset by peer

The above exception was the direct cause of the following exception:

Traceback (most recent call last):
  File "/opt/conda/envs/rapids/lib/python3.10/site-packages/distributed/comm/core.py", line 373, in connect
    handshake = await wait_for(comm.read(), time_left())
  File "/opt/conda/envs/rapids/lib/python3.10/site-packages/distributed/utils.py", line 1878, in wait_for
    return await asyncio.wait_for(fut, timeout)
  File "/opt/conda/envs/rapids/lib/python3.10/asyncio/tasks.py", line 445, in wait_for
    return fut.result()
  File "/opt/conda/envs/rapids/lib/python3.10/site-packages/distributed/comm/tcp.py", line 241, in read
    convert_stream_closed_error(self, e)
  File "/opt/conda/envs/rapids/lib/python3.10/site-packages/distributed/comm/tcp.py", line 142, in convert_stream_closed_error
    raise CommClosedError(f"in {obj}: {exc.__class__.__name__}: {exc}") from exc
distributed.comm.core.CommClosedError: in <TCP (closed)  local=tcp://10.33.227.169:32864 remote=tcp://10.33.227.169:34197>: ConnectionResetError: [Errno 104] Connection reset by peer

The above exception was the direct cause of the following exception:

Traceback (most recent call last):
  File "/opt/conda/envs/rapids/lib/python3.10/site-packages/distributed/utils.py", line 754, in wrapper
    return await func(*args, **kwargs)
  File "/opt/conda/envs/rapids/lib/python3.10/site-packages/distributed/worker.py", line 1540, in close
    await r.close_gracefully(reason=reason)
  File "/opt/conda/envs/rapids/lib/python3.10/site-packages/distributed/core.py", line 1362, in send_recv_from_rpc
    comm = await self.pool.connect(self.addr)
  File "/opt/conda/envs/rapids/lib/python3.10/site-packages/distributed/core.py", line 1606, in connect
    return await connect_attempt
  File "/opt/conda/envs/rapids/lib/python3.10/site-packages/distributed/core.py", line 1527, in _connect
    comm = await connect(
  File "/opt/conda/envs/rapids/lib/python3.10/site-packages/distributed/comm/core.py", line 378, in connect
    raise OSError(
OSError: Timed out during handshake while connecting to tcp://10.33.227.169:34197 after 100 s
2023-06-22 21:29:44,892 - distributed.nanny - WARNING - Worker process still alive after 3.199983367919922 seconds, killing
2023-06-22 21:29:44,893 - distributed.nanny - WARNING - Worker process still alive after 3.1999990844726565 seconds, killing
2023-06-22 21:29:44,894 - distributed.nanny - WARNING - Worker process still alive after 3.1999990844726565 seconds, killing
2023-06-22 21:29:44,894 - distributed.nanny - WARNING - Worker process still alive after 3.199999389648438 seconds, killing
2023-06-22 21:29:44,895 - distributed.nanny - WARNING - Worker process still alive after 3.1999992370605472 seconds, killing
2023-06-22 21:29:44,895 - distributed.nanny - WARNING - Worker process still alive after 3.1999992370605472 seconds, killing
2023-06-22 21:29:44,896 - distributed.nanny - WARNING - Worker process still alive after 3.1999992370605472 seconds, killing
2023-06-22 21:29:44,896 - distributed.nanny - WARNING - Worker process still alive after 3.199999389648438 seconds, killing
2023-06-22 21:29:45,683 - distributed.nanny - ERROR - Error in Nanny killing Worker subprocess
Traceback (most recent call last):
  File "/opt/conda/envs/rapids/lib/python3.10/asyncio/tasks.py", line 456, in wait_for
    return fut.result()
asyncio.exceptions.CancelledError

The above exception was the direct cause of the following exception:

Traceback (most recent call last):
  File "/opt/conda/envs/rapids/lib/python3.10/site-packages/distributed/nanny.py", line 597, in close
    await self.kill(timeout=timeout, reason=reason)
  File "/opt/conda/envs/rapids/lib/python3.10/site-packages/distributed/nanny.py", line 380, in kill
    await self.process.kill(reason=reason, timeout=0.8 * (deadline - time()))
  File "/opt/conda/envs/rapids/lib/python3.10/site-packages/distributed/nanny.py", line 853, in kill
    await process.join(max(0, deadline - time()))
  File "/opt/conda/envs/rapids/lib/python3.10/site-packages/distributed/process.py", line 330, in join
    await wait_for(asyncio.shield(self._exit_future), timeout)
  File "/opt/conda/envs/rapids/lib/python3.10/site-packages/distributed/utils.py", line 1878, in wait_for
    return await asyncio.wait_for(fut, timeout)
  File "/opt/conda/envs/rapids/lib/python3.10/asyncio/tasks.py", line 458, in wait_for
    raise exceptions.TimeoutError() from exc
asyncio.exceptions.TimeoutError
2023-06-22 21:29:45,686 - distributed.nanny - ERROR - Error in Nanny killing Worker subprocess
Traceback (most recent call last):
  File "/opt/conda/envs/rapids/lib/python3.10/asyncio/tasks.py", line 456, in wait_for
    return fut.result()
asyncio.exceptions.CancelledError

The above exception was the direct cause of the following exception:

Traceback (most recent call last):
  File "/opt/conda/envs/rapids/lib/python3.10/site-packages/distributed/nanny.py", line 597, in close
    await self.kill(timeout=timeout, reason=reason)
  File "/opt/conda/envs/rapids/lib/python3.10/site-packages/distributed/nanny.py", line 380, in kill
    await self.process.kill(reason=reason, timeout=0.8 * (deadline - time()))
  File "/opt/conda/envs/rapids/lib/python3.10/site-packages/distributed/nanny.py", line 853, in kill
    await process.join(max(0, deadline - time()))
  File "/opt/conda/envs/rapids/lib/python3.10/site-packages/distributed/process.py", line 330, in join
    await wait_for(asyncio.shield(self._exit_future), timeout)
  File "/opt/conda/envs/rapids/lib/python3.10/site-packages/distributed/utils.py", line 1878, in wait_for
    return await asyncio.wait_for(fut, timeout)
  File "/opt/conda/envs/rapids/lib/python3.10/asyncio/tasks.py", line 458, in wait_for
    raise exceptions.TimeoutError() from exc
asyncio.exceptions.TimeoutError
2023-06-22 21:29:45,687 - distributed.nanny - ERROR - Error in Nanny killing Worker subprocess
Traceback (most recent call last):
  File "/opt/conda/envs/rapids/lib/python3.10/asyncio/tasks.py", line 456, in wait_for
    return fut.result()
asyncio.exceptions.CancelledError

The above exception was the direct cause of the following exception:

Traceback (most recent call last):
  File "/opt/conda/envs/rapids/lib/python3.10/site-packages/distributed/nanny.py", line 597, in close
    await self.kill(timeout=timeout, reason=reason)
  File "/opt/conda/envs/rapids/lib/python3.10/site-packages/distributed/nanny.py", line 380, in kill
    await self.process.kill(reason=reason, timeout=0.8 * (deadline - time()))
  File "/opt/conda/envs/rapids/lib/python3.10/site-packages/distributed/nanny.py", line 853, in kill
    await process.join(max(0, deadline - time()))
  File "/opt/conda/envs/rapids/lib/python3.10/site-packages/distributed/process.py", line 330, in join
    await wait_for(asyncio.shield(self._exit_future), timeout)
  File "/opt/conda/envs/rapids/lib/python3.10/site-packages/distributed/utils.py", line 1878, in wait_for
    return await asyncio.wait_for(fut, timeout)
  File "/opt/conda/envs/rapids/lib/python3.10/asyncio/tasks.py", line 458, in wait_for
    raise exceptions.TimeoutError() from exc
asyncio.exceptions.TimeoutError
2023-06-22 21:29:45,688 - distributed.nanny - ERROR - Error in Nanny killing Worker subprocess
Traceback (most recent call last):
  File "/opt/conda/envs/rapids/lib/python3.10/asyncio/tasks.py", line 456, in wait_for
    return fut.result()
asyncio.exceptions.CancelledError

The above exception was the direct cause of the following exception:

Traceback (most recent call last):
  File "/opt/conda/envs/rapids/lib/python3.10/site-packages/distributed/nanny.py", line 597, in close
    await self.kill(timeout=timeout, reason=reason)
  File "/opt/conda/envs/rapids/lib/python3.10/site-packages/distributed/nanny.py", line 380, in kill
    await self.process.kill(reason=reason, timeout=0.8 * (deadline - time()))
  File "/opt/conda/envs/rapids/lib/python3.10/site-packages/distributed/nanny.py", line 853, in kill
    await process.join(max(0, deadline - time()))
  File "/opt/conda/envs/rapids/lib/python3.10/site-packages/distributed/process.py", line 330, in join
    await wait_for(asyncio.shield(self._exit_future), timeout)
  File "/opt/conda/envs/rapids/lib/python3.10/site-packages/distributed/utils.py", line 1878, in wait_for
    return await asyncio.wait_for(fut, timeout)
  File "/opt/conda/envs/rapids/lib/python3.10/asyncio/tasks.py", line 458, in wait_for
    raise exceptions.TimeoutError() from exc
asyncio.exceptions.TimeoutError
2023-06-22 21:29:45,689 - distributed.nanny - ERROR - Error in Nanny killing Worker subprocess
Traceback (most recent call last):
  File "/opt/conda/envs/rapids/lib/python3.10/asyncio/tasks.py", line 456, in wait_for
    return fut.result()
asyncio.exceptions.CancelledError

The above exception was the direct cause of the following exception:

Traceback (most recent call last):
  File "/opt/conda/envs/rapids/lib/python3.10/site-packages/distributed/nanny.py", line 597, in close
    await self.kill(timeout=timeout, reason=reason)
  File "/opt/conda/envs/rapids/lib/python3.10/site-packages/distributed/nanny.py", line 380, in kill
    await self.process.kill(reason=reason, timeout=0.8 * (deadline - time()))
  File "/opt/conda/envs/rapids/lib/python3.10/site-packages/distributed/nanny.py", line 853, in kill
    await process.join(max(0, deadline - time()))
  File "/opt/conda/envs/rapids/lib/python3.10/site-packages/distributed/process.py", line 330, in join
    await wait_for(asyncio.shield(self._exit_future), timeout)
  File "/opt/conda/envs/rapids/lib/python3.10/site-packages/distributed/utils.py", line 1878, in wait_for
    return await asyncio.wait_for(fut, timeout)
  File "/opt/conda/envs/rapids/lib/python3.10/asyncio/tasks.py", line 458, in wait_for
    raise exceptions.TimeoutError() from exc
asyncio.exceptions.TimeoutError
2023-06-22 21:29:45,689 - distributed.nanny - ERROR - Error in Nanny killing Worker subprocess
Traceback (most recent call last):
  File "/opt/conda/envs/rapids/lib/python3.10/asyncio/tasks.py", line 456, in wait_for
    return fut.result()
asyncio.exceptions.CancelledError

The above exception was the direct cause of the following exception:

Traceback (most recent call last):
  File "/opt/conda/envs/rapids/lib/python3.10/site-packages/distributed/nanny.py", line 597, in close
    await self.kill(timeout=timeout, reason=reason)
  File "/opt/conda/envs/rapids/lib/python3.10/site-packages/distributed/nanny.py", line 380, in kill
    await self.process.kill(reason=reason, timeout=0.8 * (deadline - time()))
  File "/opt/conda/envs/rapids/lib/python3.10/site-packages/distributed/nanny.py", line 853, in kill
    await process.join(max(0, deadline - time()))
  File "/opt/conda/envs/rapids/lib/python3.10/site-packages/distributed/process.py", line 330, in join
    await wait_for(asyncio.shield(self._exit_future), timeout)
  File "/opt/conda/envs/rapids/lib/python3.10/site-packages/distributed/utils.py", line 1878, in wait_for
    return await asyncio.wait_for(fut, timeout)
  File "/opt/conda/envs/rapids/lib/python3.10/asyncio/tasks.py", line 458, in wait_for
    raise exceptions.TimeoutError() from exc
asyncio.exceptions.TimeoutError
2023-06-22 21:29:45,691 - distributed.nanny - ERROR - Error in Nanny killing Worker subprocess
Traceback (most recent call last):
  File "/opt/conda/envs/rapids/lib/python3.10/asyncio/tasks.py", line 456, in wait_for
    return fut.result()
asyncio.exceptions.CancelledError

The above exception was the direct cause of the following exception:

Traceback (most recent call last):
  File "/opt/conda/envs/rapids/lib/python3.10/site-packages/distributed/nanny.py", line 597, in close
    await self.kill(timeout=timeout, reason=reason)
  File "/opt/conda/envs/rapids/lib/python3.10/site-packages/distributed/nanny.py", line 380, in kill
    await self.process.kill(reason=reason, timeout=0.8 * (deadline - time()))
  File "/opt/conda/envs/rapids/lib/python3.10/site-packages/distributed/nanny.py", line 853, in kill
    await process.join(max(0, deadline - time()))
  File "/opt/conda/envs/rapids/lib/python3.10/site-packages/distributed/process.py", line 330, in join
    await wait_for(asyncio.shield(self._exit_future), timeout)
  File "/opt/conda/envs/rapids/lib/python3.10/site-packages/distributed/utils.py", line 1878, in wait_for
    return await asyncio.wait_for(fut, timeout)
  File "/opt/conda/envs/rapids/lib/python3.10/asyncio/tasks.py", line 458, in wait_for
    raise exceptions.TimeoutError() from exc
asyncio.exceptions.TimeoutError
2023-06-22 21:29:45,691 - distributed.nanny - ERROR - Error in Nanny killing Worker subprocess
Traceback (most recent call last):
  File "/opt/conda/envs/rapids/lib/python3.10/asyncio/tasks.py", line 456, in wait_for
    return fut.result()
asyncio.exceptions.CancelledError

The above exception was the direct cause of the following exception:

Traceback (most recent call last):
  File "/opt/conda/envs/rapids/lib/python3.10/site-packages/distributed/nanny.py", line 597, in close
    await self.kill(timeout=timeout, reason=reason)
  File "/opt/conda/envs/rapids/lib/python3.10/site-packages/distributed/nanny.py", line 380, in kill
    await self.process.kill(reason=reason, timeout=0.8 * (deadline - time()))
  File "/opt/conda/envs/rapids/lib/python3.10/site-packages/distributed/nanny.py", line 853, in kill
    await process.join(max(0, deadline - time()))
  File "/opt/conda/envs/rapids/lib/python3.10/site-packages/distributed/process.py", line 330, in join
    await wait_for(asyncio.shield(self._exit_future), timeout)
  File "/opt/conda/envs/rapids/lib/python3.10/site-packages/distributed/utils.py", line 1878, in wait_for
    return await asyncio.wait_for(fut, timeout)
  File "/opt/conda/envs/rapids/lib/python3.10/asyncio/tasks.py", line 458, in wait_for
    raise exceptions.TimeoutError() from exc
asyncio.exceptions.TimeoutError
2023-06-22 21:29:45,693 - distributed.process - INFO - reaping stray process <SpawnProcess name='Dask Worker process (from Nanny)' pid=1422843 parent=1422800 started daemon>
2023-06-22 21:29:45,693 - distributed.process - INFO - reaping stray process <SpawnProcess name='Dask Worker process (from Nanny)' pid=1422840 parent=1422800 started daemon>
2023-06-22 21:29:45,693 - distributed.process - INFO - reaping stray process <SpawnProcess name='Dask Worker process (from Nanny)' pid=1422837 parent=1422800 started daemon>
2023-06-22 21:29:45,693 - distributed.process - INFO - reaping stray process <SpawnProcess name='Dask Worker process (from Nanny)' pid=1422834 parent=1422800 started daemon>
2023-06-22 21:29:45,693 - distributed.process - INFO - reaping stray process <SpawnProcess name='Dask Worker process (from Nanny)' pid=1422831 parent=1422800 started daemon>
2023-06-22 21:29:45,693 - distributed.process - INFO - reaping stray process <SpawnProcess name='Dask Worker process (from Nanny)' pid=1422828 parent=1422800 started daemon>
2023-06-22 21:29:45,693 - distributed.process - INFO - reaping stray process <SpawnProcess name='Dask Worker process (from Nanny)' pid=1422825 parent=1422800 started daemon>
2023-06-22 21:29:45,693 - distributed.process - INFO - reaping stray process <SpawnProcess name='Dask Worker process (from Nanny)' pid=1422822 parent=1422800 started daemon>
2023-06-22 21:29:45,813 - distributed.process - WARNING - [<AsyncProcess Dask Worker process (from Nanny)>] process 1422825 exit status was already read will report exitcode 255
2023-06-22 21:29:46,567 - distributed.process - WARNING - [<AsyncProcess Dask Worker process (from Nanny)>] process 1422822 exit status was already read will report exitcode 255
