RUNNING: "python -m dask_cuda.cli.dask_cuda_worker --rmm-pool-size=28G
             --rmm-async
             --local-directory=/tmp/
             --scheduler-file=/root/cugraph/mg_utils/dask-scheduler.json
             --memory-limit=auto
             --device-memory-limit=auto
            "
2023-06-26 18:17:24,554 - distributed.nanny - INFO -         Start Nanny at: 'tcp://10.120.104.11:43887'
2023-06-26 18:17:24,557 - distributed.nanny - INFO -         Start Nanny at: 'tcp://10.120.104.11:39859'
2023-06-26 18:17:24,559 - distributed.nanny - INFO -         Start Nanny at: 'tcp://10.120.104.11:35553'
2023-06-26 18:17:24,561 - distributed.nanny - INFO -         Start Nanny at: 'tcp://10.120.104.11:36393'
2023-06-26 18:17:24,564 - distributed.nanny - INFO -         Start Nanny at: 'tcp://10.120.104.11:44959'
2023-06-26 18:17:24,565 - distributed.nanny - INFO -         Start Nanny at: 'tcp://10.120.104.11:38169'
2023-06-26 18:17:24,567 - distributed.nanny - INFO -         Start Nanny at: 'tcp://10.120.104.11:44155'
2023-06-26 18:17:24,569 - distributed.nanny - INFO -         Start Nanny at: 'tcp://10.120.104.11:45397'
2023-06-26 18:17:24,571 - distributed.nanny - INFO -         Start Nanny at: 'tcp://10.120.104.11:33985'
2023-06-26 18:17:24,574 - distributed.nanny - INFO -         Start Nanny at: 'tcp://10.120.104.11:37381'
2023-06-26 18:17:24,576 - distributed.nanny - INFO -         Start Nanny at: 'tcp://10.120.104.11:42109'
2023-06-26 18:17:24,578 - distributed.nanny - INFO -         Start Nanny at: 'tcp://10.120.104.11:36583'
2023-06-26 18:17:24,582 - distributed.nanny - INFO -         Start Nanny at: 'tcp://10.120.104.11:41217'
2023-06-26 18:17:24,585 - distributed.nanny - INFO -         Start Nanny at: 'tcp://10.120.104.11:44453'
2023-06-26 18:17:24,587 - distributed.nanny - INFO -         Start Nanny at: 'tcp://10.120.104.11:37963'
2023-06-26 18:17:24,593 - distributed.nanny - INFO -         Start Nanny at: 'tcp://10.120.104.11:37069'
2023-06-26 18:17:26,163 - distributed.preloading - INFO - Creating preload: dask_cuda.initialize
2023-06-26 18:17:26,163 - distributed.preloading - INFO - Import preload module: dask_cuda.initialize
2023-06-26 18:17:26,220 - distributed.preloading - INFO - Creating preload: dask_cuda.initialize
2023-06-26 18:17:26,220 - distributed.preloading - INFO - Import preload module: dask_cuda.initialize
2023-06-26 18:17:26,222 - distributed.preloading - INFO - Creating preload: dask_cuda.initialize
2023-06-26 18:17:26,222 - distributed.preloading - INFO - Import preload module: dask_cuda.initialize
2023-06-26 18:17:26,223 - distributed.preloading - INFO - Creating preload: dask_cuda.initialize
2023-06-26 18:17:26,223 - distributed.preloading - INFO - Import preload module: dask_cuda.initialize
2023-06-26 18:17:26,243 - distributed.preloading - INFO - Creating preload: dask_cuda.initialize
2023-06-26 18:17:26,243 - distributed.preloading - INFO - Import preload module: dask_cuda.initialize
2023-06-26 18:17:26,244 - distributed.preloading - INFO - Creating preload: dask_cuda.initialize
2023-06-26 18:17:26,244 - distributed.preloading - INFO - Import preload module: dask_cuda.initialize
2023-06-26 18:17:26,257 - distributed.preloading - INFO - Creating preload: dask_cuda.initialize
2023-06-26 18:17:26,258 - distributed.preloading - INFO - Import preload module: dask_cuda.initialize
2023-06-26 18:17:26,274 - distributed.preloading - INFO - Creating preload: dask_cuda.initialize
2023-06-26 18:17:26,274 - distributed.preloading - INFO - Import preload module: dask_cuda.initialize
2023-06-26 18:17:26,288 - distributed.preloading - INFO - Creating preload: dask_cuda.initialize
2023-06-26 18:17:26,288 - distributed.preloading - INFO - Import preload module: dask_cuda.initialize
2023-06-26 18:17:26,293 - distributed.preloading - INFO - Creating preload: dask_cuda.initialize
2023-06-26 18:17:26,293 - distributed.preloading - INFO - Import preload module: dask_cuda.initialize
2023-06-26 18:17:26,304 - distributed.preloading - INFO - Creating preload: dask_cuda.initialize
2023-06-26 18:17:26,304 - distributed.preloading - INFO - Import preload module: dask_cuda.initialize
2023-06-26 18:17:26,307 - distributed.preloading - INFO - Creating preload: dask_cuda.initialize
2023-06-26 18:17:26,307 - distributed.preloading - INFO - Import preload module: dask_cuda.initialize
2023-06-26 18:17:26,307 - distributed.preloading - INFO - Creating preload: dask_cuda.initialize
2023-06-26 18:17:26,307 - distributed.preloading - INFO - Import preload module: dask_cuda.initialize
2023-06-26 18:17:26,308 - distributed.preloading - INFO - Creating preload: dask_cuda.initialize
2023-06-26 18:17:26,308 - distributed.preloading - INFO - Import preload module: dask_cuda.initialize
2023-06-26 18:17:26,308 - distributed.preloading - INFO - Creating preload: dask_cuda.initialize
2023-06-26 18:17:26,308 - distributed.preloading - INFO - Import preload module: dask_cuda.initialize
2023-06-26 18:17:26,317 - distributed.preloading - INFO - Creating preload: dask_cuda.initialize
2023-06-26 18:17:26,317 - distributed.preloading - INFO - Import preload module: dask_cuda.initialize
2023-06-26 18:17:26,338 - distributed.preloading - INFO - Run preload setup: dask_cuda.initialize
2023-06-26 18:17:26,399 - distributed.preloading - INFO - Run preload setup: dask_cuda.initialize
2023-06-26 18:17:26,400 - distributed.preloading - INFO - Run preload setup: dask_cuda.initialize
2023-06-26 18:17:26,403 - distributed.preloading - INFO - Run preload setup: dask_cuda.initialize
2023-06-26 18:17:26,437 - distributed.preloading - INFO - Run preload setup: dask_cuda.initialize
2023-06-26 18:17:26,468 - distributed.preloading - INFO - Run preload setup: dask_cuda.initialize
2023-06-26 18:17:26,469 - distributed.preloading - INFO - Run preload setup: dask_cuda.initialize
2023-06-26 18:17:26,472 - distributed.preloading - INFO - Run preload setup: dask_cuda.initialize
2023-06-26 18:17:26,479 - distributed.preloading - INFO - Run preload setup: dask_cuda.initialize
2023-06-26 18:17:26,482 - distributed.preloading - INFO - Run preload setup: dask_cuda.initialize
2023-06-26 18:17:26,483 - distributed.preloading - INFO - Run preload setup: dask_cuda.initialize
2023-06-26 18:17:26,484 - distributed.preloading - INFO - Run preload setup: dask_cuda.initialize
2023-06-26 18:17:26,485 - distributed.preloading - INFO - Run preload setup: dask_cuda.initialize
2023-06-26 18:17:26,485 - distributed.preloading - INFO - Run preload setup: dask_cuda.initialize
2023-06-26 18:17:26,487 - distributed.preloading - INFO - Run preload setup: dask_cuda.initialize
2023-06-26 18:17:26,494 - distributed.preloading - INFO - Run preload setup: dask_cuda.initialize
2023-06-26 18:17:32,911 - distributed.worker - INFO -       Start worker at:  tcp://10.120.104.11:46155
2023-06-26 18:17:32,911 - distributed.worker - INFO -          Listening to:  tcp://10.120.104.11:46155
2023-06-26 18:17:32,911 - distributed.worker - INFO -          dashboard at:        10.120.104.11:43053
2023-06-26 18:17:32,911 - distributed.worker - INFO - Waiting to connect to:   tcp://10.120.104.11:8786
2023-06-26 18:17:32,911 - distributed.worker - INFO - -------------------------------------------------
2023-06-26 18:17:32,911 - distributed.worker - INFO -               Threads:                          1
2023-06-26 18:17:32,911 - distributed.worker - INFO -                Memory:                  94.41 GiB
2023-06-26 18:17:32,911 - distributed.worker - INFO -       Local Directory: /tmp/dask-scratch-space/worker-dcsq6p9a
2023-06-26 18:17:32,912 - distributed.worker - INFO - Starting Worker plugin RMMSetup-60045d9c-c069-495b-9dbd-25a368f7e808
2023-06-26 18:17:32,930 - distributed.worker - INFO -       Start worker at:  tcp://10.120.104.11:46209
2023-06-26 18:17:32,930 - distributed.worker - INFO -          Listening to:  tcp://10.120.104.11:46209
2023-06-26 18:17:32,930 - distributed.worker - INFO -          dashboard at:        10.120.104.11:33847
2023-06-26 18:17:32,930 - distributed.worker - INFO - Waiting to connect to:   tcp://10.120.104.11:8786
2023-06-26 18:17:32,930 - distributed.worker - INFO - -------------------------------------------------
2023-06-26 18:17:32,930 - distributed.worker - INFO -               Threads:                          1
2023-06-26 18:17:32,930 - distributed.worker - INFO -                Memory:                  94.41 GiB
2023-06-26 18:17:32,931 - distributed.worker - INFO -       Local Directory: /tmp/dask-scratch-space/worker-0w5rq7_6
2023-06-26 18:17:32,931 - distributed.worker - INFO -       Start worker at:  tcp://10.120.104.11:39311
2023-06-26 18:17:32,931 - distributed.worker - INFO -          Listening to:  tcp://10.120.104.11:39311
2023-06-26 18:17:32,931 - distributed.worker - INFO -          dashboard at:        10.120.104.11:41663
2023-06-26 18:17:32,931 - distributed.worker - INFO - Waiting to connect to:   tcp://10.120.104.11:8786
2023-06-26 18:17:32,931 - distributed.worker - INFO - -------------------------------------------------
2023-06-26 18:17:32,931 - distributed.worker - INFO -               Threads:                          1
2023-06-26 18:17:32,931 - distributed.worker - INFO -                Memory:                  94.41 GiB
2023-06-26 18:17:32,931 - distributed.worker - INFO -       Local Directory: /tmp/dask-scratch-space/worker-jy7suzf6
2023-06-26 18:17:32,932 - distributed.worker - INFO - Starting Worker plugin RMMSetup-80b2d2be-0ab1-48ba-af0a-8a68d7955dfc
2023-06-26 18:17:32,932 - distributed.worker - INFO - Starting Worker plugin RMMSetup-84b00129-5b22-4d63-aae9-81812f76c86b
2023-06-26 18:17:32,958 - distributed.worker - INFO -       Start worker at:  tcp://10.120.104.11:36093
2023-06-26 18:17:32,958 - distributed.worker - INFO -          Listening to:  tcp://10.120.104.11:36093
2023-06-26 18:17:32,958 - distributed.worker - INFO -          dashboard at:        10.120.104.11:35883
2023-06-26 18:17:32,958 - distributed.worker - INFO - Waiting to connect to:   tcp://10.120.104.11:8786
2023-06-26 18:17:32,958 - distributed.worker - INFO - -------------------------------------------------
2023-06-26 18:17:32,958 - distributed.worker - INFO -               Threads:                          1
2023-06-26 18:17:32,958 - distributed.worker - INFO -                Memory:                  94.41 GiB
2023-06-26 18:17:32,958 - distributed.worker - INFO -       Local Directory: /tmp/dask-scratch-space/worker-4j_6h30n
2023-06-26 18:17:32,958 - distributed.worker - INFO - Starting Worker plugin RMMSetup-7fc6a8d0-b1b9-4dfe-8eaa-9f0af032a18c
2023-06-26 18:17:32,960 - distributed.worker - INFO -       Start worker at:  tcp://10.120.104.11:41597
2023-06-26 18:17:32,960 - distributed.worker - INFO -          Listening to:  tcp://10.120.104.11:41597
2023-06-26 18:17:32,960 - distributed.worker - INFO -          dashboard at:        10.120.104.11:37805
2023-06-26 18:17:32,960 - distributed.worker - INFO - Waiting to connect to:   tcp://10.120.104.11:8786
2023-06-26 18:17:32,960 - distributed.worker - INFO - -------------------------------------------------
2023-06-26 18:17:32,960 - distributed.worker - INFO -               Threads:                          1
2023-06-26 18:17:32,960 - distributed.worker - INFO -                Memory:                  94.41 GiB
2023-06-26 18:17:32,960 - distributed.worker - INFO -       Local Directory: /tmp/dask-scratch-space/worker-js0jhzke
2023-06-26 18:17:32,961 - distributed.worker - INFO - Starting Worker plugin PreImport-bb122b13-be08-4636-af20-5331ed834554
2023-06-26 18:17:32,961 - distributed.worker - INFO - Starting Worker plugin RMMSetup-f12e564d-88af-4058-8eb8-89b997c57f3b
2023-06-26 18:17:33,017 - distributed.worker - INFO -       Start worker at:  tcp://10.120.104.11:36759
2023-06-26 18:17:33,017 - distributed.worker - INFO -          Listening to:  tcp://10.120.104.11:36759
2023-06-26 18:17:33,017 - distributed.worker - INFO -          dashboard at:        10.120.104.11:38463
2023-06-26 18:17:33,017 - distributed.worker - INFO - Waiting to connect to:   tcp://10.120.104.11:8786
2023-06-26 18:17:33,017 - distributed.worker - INFO - -------------------------------------------------
2023-06-26 18:17:33,017 - distributed.worker - INFO -               Threads:                          1
2023-06-26 18:17:33,018 - distributed.worker - INFO -                Memory:                  94.41 GiB
2023-06-26 18:17:33,018 - distributed.worker - INFO -       Local Directory: /tmp/dask-scratch-space/worker-sa69qw1s
2023-06-26 18:17:33,018 - distributed.worker - INFO - Starting Worker plugin RMMSetup-9b29413a-9a0e-4991-9e24-37b009a29101
2023-06-26 18:17:33,058 - distributed.worker - INFO -       Start worker at:  tcp://10.120.104.11:41775
2023-06-26 18:17:33,058 - distributed.worker - INFO -          Listening to:  tcp://10.120.104.11:41775
2023-06-26 18:17:33,059 - distributed.worker - INFO -          dashboard at:        10.120.104.11:36739
2023-06-26 18:17:33,059 - distributed.worker - INFO - Waiting to connect to:   tcp://10.120.104.11:8786
2023-06-26 18:17:33,059 - distributed.worker - INFO - -------------------------------------------------
2023-06-26 18:17:33,059 - distributed.worker - INFO -               Threads:                          1
2023-06-26 18:17:33,059 - distributed.worker - INFO -                Memory:                  94.41 GiB
2023-06-26 18:17:33,059 - distributed.worker - INFO -       Local Directory: /tmp/dask-scratch-space/worker-o7tkv763
2023-06-26 18:17:33,060 - distributed.worker - INFO - Starting Worker plugin RMMSetup-c815df4e-278b-4eaf-b7a0-92cfeea59369
2023-06-26 18:17:33,172 - distributed.worker - INFO -       Start worker at:  tcp://10.120.104.11:37137
2023-06-26 18:17:33,173 - distributed.worker - INFO -          Listening to:  tcp://10.120.104.11:37137
2023-06-26 18:17:33,173 - distributed.worker - INFO -          dashboard at:        10.120.104.11:41323
2023-06-26 18:17:33,173 - distributed.worker - INFO - Waiting to connect to:   tcp://10.120.104.11:8786
2023-06-26 18:17:33,173 - distributed.worker - INFO - -------------------------------------------------
2023-06-26 18:17:33,173 - distributed.worker - INFO -               Threads:                          1
2023-06-26 18:17:33,173 - distributed.worker - INFO -                Memory:                  94.41 GiB
2023-06-26 18:17:33,173 - distributed.worker - INFO -       Local Directory: /tmp/dask-scratch-space/worker-u0_co017
2023-06-26 18:17:33,174 - distributed.worker - INFO - Starting Worker plugin RMMSetup-a5d66876-a183-460f-88b5-5e9650c59ee7
2023-06-26 18:17:33,211 - distributed.worker - INFO -       Start worker at:  tcp://10.120.104.11:46135
2023-06-26 18:17:33,211 - distributed.worker - INFO -          Listening to:  tcp://10.120.104.11:46135
2023-06-26 18:17:33,211 - distributed.worker - INFO -          dashboard at:        10.120.104.11:45881
2023-06-26 18:17:33,211 - distributed.worker - INFO - Waiting to connect to:   tcp://10.120.104.11:8786
2023-06-26 18:17:33,211 - distributed.worker - INFO - -------------------------------------------------
2023-06-26 18:17:33,211 - distributed.worker - INFO -               Threads:                          1
2023-06-26 18:17:33,211 - distributed.worker - INFO -                Memory:                  94.41 GiB
2023-06-26 18:17:33,211 - distributed.worker - INFO -       Local Directory: /tmp/dask-scratch-space/worker-me2_6q6o
2023-06-26 18:17:33,212 - distributed.worker - INFO - Starting Worker plugin PreImport-ae051d20-0a92-4200-8007-f8a4ffeb39d0
2023-06-26 18:17:33,212 - distributed.worker - INFO - Starting Worker plugin RMMSetup-2f08f346-d400-4612-a45c-16d3430fb923
2023-06-26 18:17:33,212 - distributed.worker - INFO -       Start worker at:  tcp://10.120.104.11:46591
2023-06-26 18:17:33,212 - distributed.worker - INFO -          Listening to:  tcp://10.120.104.11:46591
2023-06-26 18:17:33,212 - distributed.worker - INFO -          dashboard at:        10.120.104.11:44893
2023-06-26 18:17:33,212 - distributed.worker - INFO - Waiting to connect to:   tcp://10.120.104.11:8786
2023-06-26 18:17:33,212 - distributed.worker - INFO - -------------------------------------------------
2023-06-26 18:17:33,212 - distributed.worker - INFO -               Threads:                          1
2023-06-26 18:17:33,213 - distributed.worker - INFO -                Memory:                  94.41 GiB
2023-06-26 18:17:33,213 - distributed.worker - INFO -       Local Directory: /tmp/dask-scratch-space/worker-8cnf6rlj
2023-06-26 18:17:33,213 - distributed.worker - INFO - Starting Worker plugin CPUAffinity-9e2fb2d9-7ce5-4f31-8066-581a1d30ab11
2023-06-26 18:17:33,213 - distributed.worker - INFO - Starting Worker plugin RMMSetup-f910cd27-c68e-42b6-a081-ea30a7d8ff62
2023-06-26 18:17:33,228 - distributed.worker - INFO -       Start worker at:  tcp://10.120.104.11:39335
2023-06-26 18:17:33,228 - distributed.worker - INFO -          Listening to:  tcp://10.120.104.11:39335
2023-06-26 18:17:33,228 - distributed.worker - INFO -          dashboard at:        10.120.104.11:37547
2023-06-26 18:17:33,228 - distributed.worker - INFO - Waiting to connect to:   tcp://10.120.104.11:8786
2023-06-26 18:17:33,228 - distributed.worker - INFO - -------------------------------------------------
2023-06-26 18:17:33,228 - distributed.worker - INFO -               Threads:                          1
2023-06-26 18:17:33,228 - distributed.worker - INFO -                Memory:                  94.41 GiB
2023-06-26 18:17:33,228 - distributed.worker - INFO -       Local Directory: /tmp/dask-scratch-space/worker-gz2ts65w
2023-06-26 18:17:33,229 - distributed.worker - INFO - Starting Worker plugin PreImport-b05d1542-6a4f-4513-b395-cee3f65cb4de
2023-06-26 18:17:33,229 - distributed.worker - INFO - Starting Worker plugin RMMSetup-b2652e91-126c-41c8-90f1-f65bbdfb5fbc
2023-06-26 18:17:33,478 - distributed.worker - INFO -       Start worker at:  tcp://10.120.104.11:41345
2023-06-26 18:17:33,479 - distributed.worker - INFO -          Listening to:  tcp://10.120.104.11:41345
2023-06-26 18:17:33,479 - distributed.worker - INFO -          dashboard at:        10.120.104.11:39315
2023-06-26 18:17:33,479 - distributed.worker - INFO - Waiting to connect to:   tcp://10.120.104.11:8786
2023-06-26 18:17:33,479 - distributed.worker - INFO - -------------------------------------------------
2023-06-26 18:17:33,479 - distributed.worker - INFO -               Threads:                          1
2023-06-26 18:17:33,479 - distributed.worker - INFO -                Memory:                  94.41 GiB
2023-06-26 18:17:33,479 - distributed.worker - INFO -       Local Directory: /tmp/dask-scratch-space/worker-8a5b2gde
2023-06-26 18:17:33,479 - distributed.worker - INFO - Starting Worker plugin RMMSetup-b22bdae9-0528-48ae-b0a6-b5e3dc7168cd
2023-06-26 18:17:33,550 - distributed.worker - INFO -       Start worker at:  tcp://10.120.104.11:36151
2023-06-26 18:17:33,550 - distributed.worker - INFO -          Listening to:  tcp://10.120.104.11:36151
2023-06-26 18:17:33,550 - distributed.worker - INFO -          dashboard at:        10.120.104.11:40065
2023-06-26 18:17:33,550 - distributed.worker - INFO - Waiting to connect to:   tcp://10.120.104.11:8786
2023-06-26 18:17:33,550 - distributed.worker - INFO - -------------------------------------------------
2023-06-26 18:17:33,550 - distributed.worker - INFO -               Threads:                          1
2023-06-26 18:17:33,550 - distributed.worker - INFO -                Memory:                  94.41 GiB
2023-06-26 18:17:33,550 - distributed.worker - INFO -       Local Directory: /tmp/dask-scratch-space/worker-hylzwfc1
2023-06-26 18:17:33,551 - distributed.worker - INFO - Starting Worker plugin RMMSetup-6bde461d-fe1a-47f7-94d1-9ad1f7b3a47d
2023-06-26 18:17:33,569 - distributed.worker - INFO -       Start worker at:  tcp://10.120.104.11:43507
2023-06-26 18:17:33,569 - distributed.worker - INFO -          Listening to:  tcp://10.120.104.11:43507
2023-06-26 18:17:33,569 - distributed.worker - INFO -          dashboard at:        10.120.104.11:44969
2023-06-26 18:17:33,569 - distributed.worker - INFO - Waiting to connect to:   tcp://10.120.104.11:8786
2023-06-26 18:17:33,569 - distributed.worker - INFO - -------------------------------------------------
2023-06-26 18:17:33,569 - distributed.worker - INFO -               Threads:                          1
2023-06-26 18:17:33,569 - distributed.worker - INFO -                Memory:                  94.41 GiB
2023-06-26 18:17:33,570 - distributed.worker - INFO -       Local Directory: /tmp/dask-scratch-space/worker-kyq9kxrc
2023-06-26 18:17:33,570 - distributed.worker - INFO - Starting Worker plugin CPUAffinity-14f503c1-15c1-486a-b328-fa41f2e15035
2023-06-26 18:17:33,570 - distributed.worker - INFO - Starting Worker plugin RMMSetup-fb5065ad-b3dc-40f3-87de-014ad3fdd6e4
2023-06-26 18:17:33,577 - distributed.worker - INFO -       Start worker at:  tcp://10.120.104.11:41221
2023-06-26 18:17:33,577 - distributed.worker - INFO -          Listening to:  tcp://10.120.104.11:41221
2023-06-26 18:17:33,577 - distributed.worker - INFO -          dashboard at:        10.120.104.11:46389
2023-06-26 18:17:33,577 - distributed.worker - INFO - Waiting to connect to:   tcp://10.120.104.11:8786
2023-06-26 18:17:33,577 - distributed.worker - INFO - -------------------------------------------------
2023-06-26 18:17:33,577 - distributed.worker - INFO -               Threads:                          1
2023-06-26 18:17:33,577 - distributed.worker - INFO -                Memory:                  94.41 GiB
2023-06-26 18:17:33,577 - distributed.worker - INFO -       Local Directory: /tmp/dask-scratch-space/worker-iapw1d50
2023-06-26 18:17:33,577 - distributed.worker - INFO -       Start worker at:  tcp://10.120.104.11:41121
2023-06-26 18:17:33,578 - distributed.worker - INFO -          Listening to:  tcp://10.120.104.11:41121
2023-06-26 18:17:33,578 - distributed.worker - INFO -          dashboard at:        10.120.104.11:44725
2023-06-26 18:17:33,578 - distributed.worker - INFO - Starting Worker plugin CPUAffinity-3c1043f4-af54-4c06-9896-4c4d3c99c060
2023-06-26 18:17:33,578 - distributed.worker - INFO - Waiting to connect to:   tcp://10.120.104.11:8786
2023-06-26 18:17:33,578 - distributed.worker - INFO - -------------------------------------------------
2023-06-26 18:17:33,578 - distributed.worker - INFO -               Threads:                          1
2023-06-26 18:17:33,578 - distributed.worker - INFO -                Memory:                  94.41 GiB
2023-06-26 18:17:33,578 - distributed.worker - INFO -       Local Directory: /tmp/dask-scratch-space/worker-w79vsmno
2023-06-26 18:17:33,578 - distributed.worker - INFO - Starting Worker plugin RMMSetup-d39d194e-634c-4ce2-8bcb-a5f91e68eaa7
2023-06-26 18:17:33,579 - distributed.worker - INFO - Starting Worker plugin RMMSetup-3c468e10-39ae-4d00-9d19-fa492342d056
2023-06-26 18:17:36,638 - distributed.worker - INFO - Starting Worker plugin CPUAffinity-b5eb37e5-21d8-42e9-b4c4-5284346acf0f
2023-06-26 18:17:36,639 - distributed.worker - INFO - Starting Worker plugin PreImport-3b297149-b508-492d-8330-ecfe3fd616f9
2023-06-26 18:17:36,639 - distributed.worker - INFO - -------------------------------------------------
2023-06-26 18:17:36,660 - distributed.worker - INFO -         Registered to:   tcp://10.120.104.11:8786
2023-06-26 18:17:36,660 - distributed.worker - INFO - -------------------------------------------------
2023-06-26 18:17:36,661 - distributed.core - INFO - Starting established connection to tcp://10.120.104.11:8786
2023-06-26 18:17:36,865 - distributed.worker - INFO - Starting Worker plugin CPUAffinity-65c561bc-d690-4a2a-98aa-f1b6155fd2d5
2023-06-26 18:17:36,865 - distributed.worker - INFO - Starting Worker plugin PreImport-f86c251e-9ffb-423a-b54b-0043e5b79c17
2023-06-26 18:17:36,867 - distributed.worker - INFO - -------------------------------------------------
2023-06-26 18:17:36,898 - distributed.worker - INFO - Starting Worker plugin CPUAffinity-8bf9c3c1-6403-4cf7-9d79-f0f5c21a5c8e
2023-06-26 18:17:36,899 - distributed.worker - INFO - -------------------------------------------------
2023-06-26 18:17:36,900 - distributed.worker - INFO -         Registered to:   tcp://10.120.104.11:8786
2023-06-26 18:17:36,900 - distributed.worker - INFO - -------------------------------------------------
2023-06-26 18:17:36,903 - distributed.core - INFO - Starting established connection to tcp://10.120.104.11:8786
2023-06-26 18:17:36,921 - distributed.worker - INFO - Starting Worker plugin CPUAffinity-cc0f9eae-e916-4d0b-90c1-55de9b2e3b94
2023-06-26 18:17:36,922 - distributed.worker - INFO - Starting Worker plugin PreImport-23aec6a7-3171-459b-872e-c18753c0ef5f
2023-06-26 18:17:36,922 - distributed.worker - INFO -         Registered to:   tcp://10.120.104.11:8786
2023-06-26 18:17:36,922 - distributed.worker - INFO - -------------------------------------------------
2023-06-26 18:17:36,923 - distributed.worker - INFO - -------------------------------------------------
2023-06-26 18:17:36,925 - distributed.core - INFO - Starting established connection to tcp://10.120.104.11:8786
2023-06-26 18:17:36,951 - distributed.worker - INFO -         Registered to:   tcp://10.120.104.11:8786
2023-06-26 18:17:36,951 - distributed.worker - INFO - -------------------------------------------------
2023-06-26 18:17:36,953 - distributed.core - INFO - Starting established connection to tcp://10.120.104.11:8786
2023-06-26 18:17:36,970 - distributed.worker - INFO - Starting Worker plugin CPUAffinity-0820b8b3-71da-4bf6-8b73-f50c532add42
2023-06-26 18:17:36,971 - distributed.worker - INFO - Starting Worker plugin PreImport-f42c1039-eb8a-4319-a980-49e65d98e6a0
2023-06-26 18:17:36,971 - distributed.worker - INFO - -------------------------------------------------
2023-06-26 18:17:36,988 - distributed.worker - INFO -         Registered to:   tcp://10.120.104.11:8786
2023-06-26 18:17:36,988 - distributed.worker - INFO - -------------------------------------------------
2023-06-26 18:17:36,989 - distributed.core - INFO - Starting established connection to tcp://10.120.104.11:8786
2023-06-26 18:17:36,989 - distributed.worker - INFO - Starting Worker plugin PreImport-6da6084d-c65e-49a2-a142-1bdc42230350
2023-06-26 18:17:36,990 - distributed.worker - INFO - -------------------------------------------------
2023-06-26 18:17:37,007 - distributed.worker - INFO - Starting Worker plugin CPUAffinity-f6ae4781-5fa3-4427-9929-7edea1402a05
2023-06-26 18:17:37,008 - distributed.worker - INFO - Starting Worker plugin PreImport-76b89ca4-4db9-4034-8cab-3654f19ab458
2023-06-26 18:17:37,009 - distributed.worker - INFO - -------------------------------------------------
2023-06-26 18:17:37,009 - distributed.worker - INFO - Starting Worker plugin CPUAffinity-d0f4337c-d910-4cd6-86d0-76909f447379
2023-06-26 18:17:37,009 - distributed.worker - INFO - Starting Worker plugin PreImport-1b14d0e7-afbb-4296-ac4b-aee576337a6a
2023-06-26 18:17:37,010 - distributed.worker - INFO - -------------------------------------------------
2023-06-26 18:17:37,018 - distributed.worker - INFO -         Registered to:   tcp://10.120.104.11:8786
2023-06-26 18:17:37,018 - distributed.worker - INFO - -------------------------------------------------
2023-06-26 18:17:37,019 - distributed.core - INFO - Starting established connection to tcp://10.120.104.11:8786
2023-06-26 18:17:37,024 - distributed.worker - INFO - Starting Worker plugin CPUAffinity-54417c4e-eed5-4404-ac2e-b51e9cc9ffb7
2023-06-26 18:17:37,024 - distributed.worker - INFO - Starting Worker plugin PreImport-c764ea10-d87d-429f-8f82-54604973618b
2023-06-26 18:17:37,025 - distributed.worker - INFO - -------------------------------------------------
2023-06-26 18:17:37,025 - distributed.worker - INFO -         Registered to:   tcp://10.120.104.11:8786
2023-06-26 18:17:37,025 - distributed.worker - INFO - -------------------------------------------------
2023-06-26 18:17:37,026 - distributed.core - INFO - Starting established connection to tcp://10.120.104.11:8786
2023-06-26 18:17:37,026 - distributed.worker - INFO -         Registered to:   tcp://10.120.104.11:8786
2023-06-26 18:17:37,027 - distributed.worker - INFO - -------------------------------------------------
2023-06-26 18:17:37,028 - distributed.core - INFO - Starting established connection to tcp://10.120.104.11:8786
2023-06-26 18:17:37,039 - distributed.worker - INFO -         Registered to:   tcp://10.120.104.11:8786
2023-06-26 18:17:37,039 - distributed.worker - INFO - -------------------------------------------------
2023-06-26 18:17:37,040 - distributed.core - INFO - Starting established connection to tcp://10.120.104.11:8786
2023-06-26 18:17:37,072 - distributed.worker - INFO - Starting Worker plugin CPUAffinity-1c7d98b8-2bab-4169-b19f-7abf31711841
2023-06-26 18:17:37,073 - distributed.worker - INFO - -------------------------------------------------
2023-06-26 18:17:37,087 - distributed.worker - INFO -         Registered to:   tcp://10.120.104.11:8786
2023-06-26 18:17:37,087 - distributed.worker - INFO - -------------------------------------------------
2023-06-26 18:17:37,088 - distributed.core - INFO - Starting established connection to tcp://10.120.104.11:8786
2023-06-26 18:17:37,092 - distributed.worker - INFO - Starting Worker plugin CPUAffinity-bf3c81d8-5fea-413e-bb25-d0d25e574e75
2023-06-26 18:17:37,092 - distributed.worker - INFO - Starting Worker plugin PreImport-c9077894-a999-47eb-b48a-1b1b46e32449
2023-06-26 18:17:37,093 - distributed.worker - INFO - -------------------------------------------------
2023-06-26 18:17:37,110 - distributed.worker - INFO -         Registered to:   tcp://10.120.104.11:8786
2023-06-26 18:17:37,110 - distributed.worker - INFO - -------------------------------------------------
2023-06-26 18:17:37,112 - distributed.core - INFO - Starting established connection to tcp://10.120.104.11:8786
2023-06-26 18:17:37,116 - distributed.worker - INFO - Starting Worker plugin CPUAffinity-b16d98df-2681-4cd3-8801-b22eca6fe93b
2023-06-26 18:17:37,118 - distributed.worker - INFO - -------------------------------------------------
2023-06-26 18:17:37,132 - distributed.worker - INFO -         Registered to:   tcp://10.120.104.11:8786
2023-06-26 18:17:37,132 - distributed.worker - INFO - -------------------------------------------------
2023-06-26 18:17:37,133 - distributed.core - INFO - Starting established connection to tcp://10.120.104.11:8786
2023-06-26 18:17:37,134 - distributed.worker - INFO - Starting Worker plugin CPUAffinity-89a9f667-4092-4264-9fb1-2d398bfe4efa
2023-06-26 18:17:37,135 - distributed.worker - INFO - Starting Worker plugin PreImport-1e6f0565-1ede-42c3-b4d4-8a8b58db9642
2023-06-26 18:17:37,136 - distributed.worker - INFO - -------------------------------------------------
2023-06-26 18:17:37,157 - distributed.worker - INFO -         Registered to:   tcp://10.120.104.11:8786
2023-06-26 18:17:37,157 - distributed.worker - INFO - -------------------------------------------------
2023-06-26 18:17:37,159 - distributed.core - INFO - Starting established connection to tcp://10.120.104.11:8786
2023-06-26 18:17:37,187 - distributed.worker - INFO - Starting Worker plugin CPUAffinity-61c2d098-b38e-4636-9f01-cae95cc45b2f
2023-06-26 18:17:37,187 - distributed.worker - INFO - Starting Worker plugin PreImport-05f3953b-b3c3-44cd-980e-229b8a45cff8
2023-06-26 18:17:37,188 - distributed.worker - INFO - Starting Worker plugin PreImport-b1f3c781-dc35-4d6f-892a-3110a6b22d70
2023-06-26 18:17:37,189 - distributed.worker - INFO - -------------------------------------------------
2023-06-26 18:17:37,189 - distributed.worker - INFO - -------------------------------------------------
2023-06-26 18:17:37,192 - distributed.worker - INFO - Starting Worker plugin PreImport-04b3bb65-22f7-418f-b797-e545e52db969
2023-06-26 18:17:37,193 - distributed.worker - INFO - -------------------------------------------------
2023-06-26 18:17:37,207 - distributed.worker - INFO -         Registered to:   tcp://10.120.104.11:8786
2023-06-26 18:17:37,207 - distributed.worker - INFO - -------------------------------------------------
2023-06-26 18:17:37,208 - distributed.worker - INFO -         Registered to:   tcp://10.120.104.11:8786
2023-06-26 18:17:37,208 - distributed.worker - INFO - -------------------------------------------------
2023-06-26 18:17:37,210 - distributed.core - INFO - Starting established connection to tcp://10.120.104.11:8786
2023-06-26 18:17:37,210 - distributed.core - INFO - Starting established connection to tcp://10.120.104.11:8786
2023-06-26 18:17:37,210 - distributed.worker - INFO -         Registered to:   tcp://10.120.104.11:8786
2023-06-26 18:17:37,210 - distributed.worker - INFO - -------------------------------------------------
2023-06-26 18:17:37,212 - distributed.core - INFO - Starting established connection to tcp://10.120.104.11:8786
2023-06-26 18:18:04,144 - distributed.worker - INFO - Stopping worker at tcp://10.120.104.11:39335. Reason: worker-close
2023-06-26 18:18:04,144 - distributed.worker - INFO - Stopping worker at tcp://10.120.104.11:37137. Reason: worker-close
2023-06-26 18:18:04,144 - distributed.worker - INFO - Stopping worker at tcp://10.120.104.11:46591. Reason: worker-close
2023-06-26 18:18:04,144 - distributed.worker - INFO - Stopping worker at tcp://10.120.104.11:36093. Reason: worker-close
2023-06-26 18:18:04,144 - distributed.worker - INFO - Stopping worker at tcp://10.120.104.11:41345. Reason: worker-close
2023-06-26 18:18:04,144 - distributed.worker - INFO - Stopping worker at tcp://10.120.104.11:36759. Reason: worker-close
2023-06-26 18:18:04,144 - distributed.worker - INFO - Stopping worker at tcp://10.120.104.11:46135. Reason: worker-close
2023-06-26 18:18:04,144 - distributed.worker - INFO - Stopping worker at tcp://10.120.104.11:41597. Reason: worker-close
2023-06-26 18:18:04,145 - distributed.worker - INFO - Stopping worker at tcp://10.120.104.11:39311. Reason: worker-close
2023-06-26 18:18:04,145 - distributed.worker - INFO - Stopping worker at tcp://10.120.104.11:41221. Reason: worker-handle-scheduler-connection-broken
2023-06-26 18:18:04,145 - distributed.worker - INFO - Stopping worker at tcp://10.120.104.11:41775. Reason: worker-handle-scheduler-connection-broken
2023-06-26 18:18:04,145 - distributed.worker - INFO - Stopping worker at tcp://10.120.104.11:41121. Reason: worker-close
2023-06-26 18:18:04,145 - distributed.worker - INFO - Stopping worker at tcp://10.120.104.11:46209. Reason: worker-handle-scheduler-connection-broken
2023-06-26 18:18:04,145 - distributed.worker - INFO - Stopping worker at tcp://10.120.104.11:36151. Reason: worker-close
2023-06-26 18:18:04,145 - distributed.worker - INFO - Stopping worker at tcp://10.120.104.11:46155. Reason: worker-handle-scheduler-connection-broken
2023-06-26 18:18:04,145 - distributed.worker - INFO - Stopping worker at tcp://10.120.104.11:43507. Reason: worker-close
2023-06-26 18:18:04,146 - distributed.nanny - INFO - Closing Nanny at 'tcp://10.120.104.11:43887'. Reason: nanny-close
2023-06-26 18:18:04,146 - distributed.batched - INFO - Batched Comm Closed <TCP (closed) Worker->Scheduler local=tcp://10.120.104.11:46098 remote=tcp://10.120.104.11:8786>
Traceback (most recent call last):
  File "/opt/conda/envs/rapids/lib/python3.10/asyncio/runners.py", line 44, in run
    return loop.run_until_complete(main)
  File "/opt/conda/envs/rapids/lib/python3.10/asyncio/base_events.py", line 636, in run_until_complete
    self.run_forever()
  File "/opt/conda/envs/rapids/lib/python3.10/asyncio/base_events.py", line 603, in run_forever
    self._run_once()
  File "/opt/conda/envs/rapids/lib/python3.10/asyncio/base_events.py", line 1871, in _run_once
    event_list = self._selector.select(timeout)
  File "/opt/conda/envs/rapids/lib/python3.10/selectors.py", line 469, in select
    fd_event_list = self._selector.poll(timeout, max_ev)
KeyboardInterrupt

During handling of the above exception, another exception occurred:

Traceback (most recent call last):
  File "/opt/conda/envs/rapids/lib/python3.10/site-packages/distributed/batched.py", line 115, in _background_send
    nbytes = yield coro
  File "/opt/conda/envs/rapids/lib/python3.10/site-packages/tornado/gen.py", line 767, in run
    value = future.result()
  File "/opt/conda/envs/rapids/lib/python3.10/site-packages/distributed/comm/tcp.py", line 269, in write
    raise CommClosedError()
distributed.comm.core.CommClosedError
2023-06-26 18:18:04,146 - distributed.batched - INFO - Batched Comm Closed <TCP (closed) Worker->Scheduler local=tcp://10.120.104.11:46158 remote=tcp://10.120.104.11:8786>
Traceback (most recent call last):
  File "/opt/conda/envs/rapids/lib/python3.10/asyncio/runners.py", line 44, in run
    return loop.run_until_complete(main)
  File "/opt/conda/envs/rapids/lib/python3.10/asyncio/base_events.py", line 636, in run_until_complete
    self.run_forever()
  File "/opt/conda/envs/rapids/lib/python3.10/asyncio/base_events.py", line 603, in run_forever
    self._run_once()
  File "/opt/conda/envs/rapids/lib/python3.10/asyncio/base_events.py", line 1871, in _run_once
    event_list = self._selector.select(timeout)
  File "/opt/conda/envs/rapids/lib/python3.10/selectors.py", line 469, in select
    fd_event_list = self._selector.poll(timeout, max_ev)
KeyboardInterrupt

During handling of the above exception, another exception occurred:

Traceback (most recent call last):
  File "/opt/conda/envs/rapids/lib/python3.10/site-packages/distributed/batched.py", line 115, in _background_send
    nbytes = yield coro
  File "/opt/conda/envs/rapids/lib/python3.10/site-packages/tornado/gen.py", line 767, in run
    value = future.result()
  File "/opt/conda/envs/rapids/lib/python3.10/site-packages/distributed/comm/tcp.py", line 269, in write
    raise CommClosedError()
distributed.comm.core.CommClosedError
2023-06-26 18:18:04,146 - distributed.batched - INFO - Batched Comm Closed <TCP (closed) Worker->Scheduler local=tcp://10.120.104.11:46128 remote=tcp://10.120.104.11:8786>
Traceback (most recent call last):
  File "/opt/conda/envs/rapids/lib/python3.10/asyncio/runners.py", line 44, in run
    return loop.run_until_complete(main)
  File "/opt/conda/envs/rapids/lib/python3.10/asyncio/base_events.py", line 636, in run_until_complete
    self.run_forever()
  File "/opt/conda/envs/rapids/lib/python3.10/asyncio/base_events.py", line 603, in run_forever
    self._run_once()
  File "/opt/conda/envs/rapids/lib/python3.10/asyncio/base_events.py", line 1871, in _run_once
    event_list = self._selector.select(timeout)
  File "/opt/conda/envs/rapids/lib/python3.10/selectors.py", line 469, in select
    fd_event_list = self._selector.poll(timeout, max_ev)
KeyboardInterrupt

During handling of the above exception, another exception occurred:

Traceback (most recent call last):
  File "/opt/conda/envs/rapids/lib/python3.10/site-packages/distributed/batched.py", line 115, in _background_send
    nbytes = yield coro
  File "/opt/conda/envs/rapids/lib/python3.10/site-packages/tornado/gen.py", line 767, in run
    value = future.result()
  File "/opt/conda/envs/rapids/lib/python3.10/site-packages/distributed/comm/tcp.py", line 269, in write
    raise CommClosedError()
distributed.comm.core.CommClosedError
2023-06-26 18:18:04,146 - distributed.batched - INFO - Batched Comm Closed <TCP (closed) Worker->Scheduler local=tcp://10.120.104.11:46138 remote=tcp://10.120.104.11:8786>
Traceback (most recent call last):
  File "/opt/conda/envs/rapids/lib/python3.10/asyncio/runners.py", line 44, in run
    return loop.run_until_complete(main)
  File "/opt/conda/envs/rapids/lib/python3.10/asyncio/base_events.py", line 636, in run_until_complete
    self.run_forever()
  File "/opt/conda/envs/rapids/lib/python3.10/asyncio/base_events.py", line 603, in run_forever
    self._run_once()
  File "/opt/conda/envs/rapids/lib/python3.10/asyncio/base_events.py", line 1871, in _run_once
    event_list = self._selector.select(timeout)
  File "/opt/conda/envs/rapids/lib/python3.10/selectors.py", line 469, in select
    fd_event_list = self._selector.poll(timeout, max_ev)
KeyboardInterrupt

During handling of the above exception, another exception occurred:

Traceback (most recent call last):
  File "/opt/conda/envs/rapids/lib/python3.10/site-packages/distributed/batched.py", line 115, in _background_send
    nbytes = yield coro
  File "/opt/conda/envs/rapids/lib/python3.10/site-packages/tornado/gen.py", line 767, in run
    value = future.result()
  File "/opt/conda/envs/rapids/lib/python3.10/site-packages/distributed/comm/tcp.py", line 269, in write
    raise CommClosedError()
distributed.comm.core.CommClosedError
2023-06-26 18:18:04,146 - distributed.batched - INFO - Batched Comm Closed <TCP (closed) Worker->Scheduler local=tcp://10.120.104.11:46092 remote=tcp://10.120.104.11:8786>
Traceback (most recent call last):
  File "/opt/conda/envs/rapids/lib/python3.10/asyncio/runners.py", line 44, in run
    return loop.run_until_complete(main)
  File "/opt/conda/envs/rapids/lib/python3.10/asyncio/base_events.py", line 636, in run_until_complete
    self.run_forever()
  File "/opt/conda/envs/rapids/lib/python3.10/asyncio/base_events.py", line 603, in run_forever
    self._run_once()
  File "/opt/conda/envs/rapids/lib/python3.10/asyncio/base_events.py", line 1871, in _run_once
    event_list = self._selector.select(timeout)
  File "/opt/conda/envs/rapids/lib/python3.10/selectors.py", line 469, in select
    fd_event_list = self._selector.poll(timeout, max_ev)
KeyboardInterrupt

During handling of the above exception, another exception occurred:

Traceback (most recent call last):
  File "/opt/conda/envs/rapids/lib/python3.10/site-packages/distributed/batched.py", line 115, in _background_send
    nbytes = yield coro
  File "/opt/conda/envs/rapids/lib/python3.10/site-packages/tornado/gen.py", line 767, in run
    value = future.result()
  File "/opt/conda/envs/rapids/lib/python3.10/site-packages/distributed/comm/tcp.py", line 269, in write
    raise CommClosedError()
distributed.comm.core.CommClosedError
2023-06-26 18:18:04,146 - distributed.batched - INFO - Batched Comm Closed <TCP (closed) Worker->Scheduler local=tcp://10.120.104.11:46112 remote=tcp://10.120.104.11:8786>
Traceback (most recent call last):
  File "/opt/conda/envs/rapids/lib/python3.10/asyncio/runners.py", line 44, in run
    return loop.run_until_complete(main)
  File "/opt/conda/envs/rapids/lib/python3.10/asyncio/base_events.py", line 636, in run_until_complete
    self.run_forever()
  File "/opt/conda/envs/rapids/lib/python3.10/asyncio/base_events.py", line 603, in run_forever
    self._run_once()
  File "/opt/conda/envs/rapids/lib/python3.10/asyncio/base_events.py", line 1871, in _run_once
    event_list = self._selector.select(timeout)
  File "/opt/conda/envs/rapids/lib/python3.10/selectors.py", line 469, in select
    fd_event_list = self._selector.poll(timeout, max_ev)
KeyboardInterrupt

During handling of the above exception, another exception occurred:

Traceback (most recent call last):
  File "/opt/conda/envs/rapids/lib/python3.10/site-packages/distributed/batched.py", line 115, in _background_send
    nbytes = yield coro
  File "/opt/conda/envs/rapids/lib/python3.10/site-packages/tornado/gen.py", line 767, in run
    value = future.result()
  File "/opt/conda/envs/rapids/lib/python3.10/site-packages/distributed/comm/tcp.py", line 269, in write
    raise CommClosedError()
distributed.comm.core.CommClosedError
2023-06-26 18:18:04,146 - distributed.batched - INFO - Batched Comm Closed <TCP (closed) Worker->Scheduler local=tcp://10.120.104.11:46048 remote=tcp://10.120.104.11:8786>
Traceback (most recent call last):
  File "/opt/conda/envs/rapids/lib/python3.10/asyncio/runners.py", line 44, in run
    return loop.run_until_complete(main)
  File "/opt/conda/envs/rapids/lib/python3.10/asyncio/base_events.py", line 636, in run_until_complete
    self.run_forever()
  File "/opt/conda/envs/rapids/lib/python3.10/asyncio/base_events.py", line 603, in run_forever
    self._run_once()
  File "/opt/conda/envs/rapids/lib/python3.10/asyncio/base_events.py", line 1871, in _run_once
    event_list = self._selector.select(timeout)
  File "/opt/conda/envs/rapids/lib/python3.10/selectors.py", line 469, in select
    fd_event_list = self._selector.poll(timeout, max_ev)
KeyboardInterrupt

During handling of the above exception, another exception occurred:

Traceback (most recent call last):
  File "/opt/conda/envs/rapids/lib/python3.10/site-packages/distributed/batched.py", line 115, in _background_send
    nbytes = yield coro
  File "/opt/conda/envs/rapids/lib/python3.10/site-packages/tornado/gen.py", line 767, in run
    value = future.result()
  File "/opt/conda/envs/rapids/lib/python3.10/site-packages/distributed/comm/tcp.py", line 269, in write
    raise CommClosedError()
distributed.comm.core.CommClosedError
2023-06-26 18:18:04,146 - distributed.batched - INFO - Batched Comm Closed <TCP (closed) Worker->Scheduler local=tcp://10.120.104.11:46146 remote=tcp://10.120.104.11:8786>
Traceback (most recent call last):
  File "/opt/conda/envs/rapids/lib/python3.10/asyncio/runners.py", line 44, in run
    return loop.run_until_complete(main)
  File "/opt/conda/envs/rapids/lib/python3.10/asyncio/base_events.py", line 636, in run_until_complete
    self.run_forever()
  File "/opt/conda/envs/rapids/lib/python3.10/asyncio/base_events.py", line 603, in run_forever
    self._run_once()
  File "/opt/conda/envs/rapids/lib/python3.10/asyncio/base_events.py", line 1871, in _run_once
    event_list = self._selector.select(timeout)
  File "/opt/conda/envs/rapids/lib/python3.10/selectors.py", line 469, in select
    fd_event_list = self._selector.poll(timeout, max_ev)
KeyboardInterrupt

During handling of the above exception, another exception occurred:

Traceback (most recent call last):
  File "/opt/conda/envs/rapids/lib/python3.10/site-packages/distributed/batched.py", line 115, in _background_send
    nbytes = yield coro
  File "/opt/conda/envs/rapids/lib/python3.10/site-packages/tornado/gen.py", line 767, in run
    value = future.result()
  File "/opt/conda/envs/rapids/lib/python3.10/site-packages/distributed/comm/tcp.py", line 269, in write
    raise CommClosedError()
distributed.comm.core.CommClosedError
2023-06-26 18:18:04,146 - distributed.batched - INFO - Batched Comm Closed <TCP (closed) Worker->Scheduler local=tcp://10.120.104.11:46068 remote=tcp://10.120.104.11:8786>
Traceback (most recent call last):
  File "/opt/conda/envs/rapids/lib/python3.10/asyncio/runners.py", line 44, in run
    return loop.run_until_complete(main)
  File "/opt/conda/envs/rapids/lib/python3.10/asyncio/base_events.py", line 636, in run_until_complete
    self.run_forever()
  File "/opt/conda/envs/rapids/lib/python3.10/asyncio/base_events.py", line 603, in run_forever
    self._run_once()
  File "/opt/conda/envs/rapids/lib/python3.10/asyncio/base_events.py", line 1871, in _run_once
    event_list = self._selector.select(timeout)
  File "/opt/conda/envs/rapids/lib/python3.10/selectors.py", line 469, in select
    fd_event_list = self._selector.poll(timeout, max_ev)
KeyboardInterrupt

During handling of the above exception, another exception occurred:

Traceback (most recent call last):
  File "/opt/conda/envs/rapids/lib/python3.10/site-packages/distributed/batched.py", line 115, in _background_send
    nbytes = yield coro
  File "/opt/conda/envs/rapids/lib/python3.10/site-packages/tornado/gen.py", line 767, in run
    value = future.result()
  File "/opt/conda/envs/rapids/lib/python3.10/site-packages/distributed/comm/tcp.py", line 269, in write
    raise CommClosedError()
distributed.comm.core.CommClosedError
2023-06-26 18:18:04,148 - distributed.nanny - INFO - Nanny asking worker to close. Reason: nanny-close
2023-06-26 18:18:04,147 - distributed.batched - INFO - Batched Comm Closed <TCP (closed) Worker->Scheduler local=tcp://10.120.104.11:46184 remote=tcp://10.120.104.11:8786>
Traceback (most recent call last):
  File "/opt/conda/envs/rapids/lib/python3.10/asyncio/runners.py", line 44, in run
    return loop.run_until_complete(main)
  File "/opt/conda/envs/rapids/lib/python3.10/asyncio/base_events.py", line 636, in run_until_complete
    self.run_forever()
  File "/opt/conda/envs/rapids/lib/python3.10/asyncio/base_events.py", line 603, in run_forever
    self._run_once()
  File "/opt/conda/envs/rapids/lib/python3.10/asyncio/base_events.py", line 1871, in _run_once
    event_list = self._selector.select(timeout)
  File "/opt/conda/envs/rapids/lib/python3.10/selectors.py", line 469, in select
    fd_event_list = self._selector.poll(timeout, max_ev)
KeyboardInterrupt

During handling of the above exception, another exception occurred:

Traceback (most recent call last):
  File "/opt/conda/envs/rapids/lib/python3.10/site-packages/distributed/batched.py", line 115, in _background_send
    nbytes = yield coro
  File "/opt/conda/envs/rapids/lib/python3.10/site-packages/tornado/gen.py", line 767, in run
    value = future.result()
  File "/opt/conda/envs/rapids/lib/python3.10/site-packages/distributed/comm/tcp.py", line 269, in write
    raise CommClosedError()
distributed.comm.core.CommClosedError
2023-06-26 18:18:04,149 - distributed.nanny - INFO - Closing Nanny at 'tcp://10.120.104.11:39859'. Reason: nanny-close
2023-06-26 18:18:04,147 - distributed.batched - INFO - Batched Comm Closed <TCP (closed) Worker->Scheduler local=tcp://10.120.104.11:46172 remote=tcp://10.120.104.11:8786>
Traceback (most recent call last):
  File "/opt/conda/envs/rapids/lib/python3.10/asyncio/runners.py", line 44, in run
    return loop.run_until_complete(main)
  File "/opt/conda/envs/rapids/lib/python3.10/asyncio/base_events.py", line 636, in run_until_complete
    self.run_forever()
  File "/opt/conda/envs/rapids/lib/python3.10/asyncio/base_events.py", line 603, in run_forever
    self._run_once()
  File "/opt/conda/envs/rapids/lib/python3.10/asyncio/base_events.py", line 1871, in _run_once
    event_list = self._selector.select(timeout)
  File "/opt/conda/envs/rapids/lib/python3.10/selectors.py", line 469, in select
    fd_event_list = self._selector.poll(timeout, max_ev)
KeyboardInterrupt

During handling of the above exception, another exception occurred:

Traceback (most recent call last):
  File "/opt/conda/envs/rapids/lib/python3.10/site-packages/distributed/batched.py", line 115, in _background_send
    nbytes = yield coro
  File "/opt/conda/envs/rapids/lib/python3.10/site-packages/tornado/gen.py", line 767, in run
    value = future.result()
  File "/opt/conda/envs/rapids/lib/python3.10/site-packages/distributed/comm/tcp.py", line 269, in write
    raise CommClosedError()
distributed.comm.core.CommClosedError
2023-06-26 18:18:04,148 - distributed.batched - INFO - Batched Comm Closed <TCP (closed) Worker->Scheduler local=tcp://10.120.104.11:46190 remote=tcp://10.120.104.11:8786>
Traceback (most recent call last):
  File "/opt/conda/envs/rapids/lib/python3.10/asyncio/runners.py", line 44, in run
    return loop.run_until_complete(main)
  File "/opt/conda/envs/rapids/lib/python3.10/asyncio/base_events.py", line 636, in run_until_complete
    self.run_forever()
  File "/opt/conda/envs/rapids/lib/python3.10/asyncio/base_events.py", line 603, in run_forever
    self._run_once()
  File "/opt/conda/envs/rapids/lib/python3.10/asyncio/base_events.py", line 1871, in _run_once
    event_list = self._selector.select(timeout)
  File "/opt/conda/envs/rapids/lib/python3.10/selectors.py", line 469, in select
    fd_event_list = self._selector.poll(timeout, max_ev)
KeyboardInterrupt

During handling of the above exception, another exception occurred:

Traceback (most recent call last):
  File "/opt/conda/envs/rapids/lib/python3.10/site-packages/distributed/batched.py", line 115, in _background_send
    nbytes = yield coro
  File "/opt/conda/envs/rapids/lib/python3.10/site-packages/tornado/gen.py", line 767, in run
    value = future.result()
  File "/opt/conda/envs/rapids/lib/python3.10/site-packages/distributed/comm/tcp.py", line 269, in write
    raise CommClosedError()
distributed.comm.core.CommClosedError
2023-06-26 18:18:04,151 - distributed.nanny - INFO - Nanny asking worker to close. Reason: nanny-close
2023-06-26 18:18:04,151 - distributed.nanny - INFO - Closing Nanny at 'tcp://10.120.104.11:35553'. Reason: nanny-close
2023-06-26 18:18:04,152 - distributed.nanny - INFO - Nanny asking worker to close. Reason: nanny-close
2023-06-26 18:18:04,152 - distributed.nanny - INFO - Closing Nanny at 'tcp://10.120.104.11:36393'. Reason: nanny-close
2023-06-26 18:18:04,152 - distributed.nanny - INFO - Nanny asking worker to close. Reason: nanny-close
2023-06-26 18:18:04,152 - distributed.nanny - INFO - Closing Nanny at 'tcp://10.120.104.11:44959'. Reason: nanny-close
2023-06-26 18:18:04,153 - distributed.nanny - INFO - Nanny asking worker to close. Reason: nanny-close
2023-06-26 18:18:04,153 - distributed.nanny - INFO - Closing Nanny at 'tcp://10.120.104.11:38169'. Reason: nanny-close
2023-06-26 18:18:04,153 - distributed.nanny - INFO - Nanny asking worker to close. Reason: nanny-close
2023-06-26 18:18:04,153 - distributed.nanny - INFO - Closing Nanny at 'tcp://10.120.104.11:44155'. Reason: nanny-close
2023-06-26 18:18:04,154 - distributed.nanny - INFO - Nanny asking worker to close. Reason: nanny-close
2023-06-26 18:18:04,154 - distributed.nanny - INFO - Closing Nanny at 'tcp://10.120.104.11:45397'. Reason: nanny-close
2023-06-26 18:18:04,154 - distributed.nanny - INFO - Nanny asking worker to close. Reason: nanny-close
2023-06-26 18:18:04,154 - distributed.nanny - INFO - Closing Nanny at 'tcp://10.120.104.11:33985'. Reason: nanny-close
2023-06-26 18:18:04,154 - distributed.nanny - INFO - Nanny asking worker to close. Reason: nanny-close
2023-06-26 18:18:04,155 - distributed.nanny - INFO - Closing Nanny at 'tcp://10.120.104.11:37381'. Reason: nanny-close
2023-06-26 18:18:04,155 - distributed.nanny - INFO - Nanny asking worker to close. Reason: nanny-close
2023-06-26 18:18:04,157 - distributed.nanny - INFO - Closing Nanny at 'tcp://10.120.104.11:42109'. Reason: nanny-close
2023-06-26 18:18:04,157 - distributed.nanny - INFO - Nanny asking worker to close. Reason: nanny-close
2023-06-26 18:18:04,158 - distributed.nanny - INFO - Closing Nanny at 'tcp://10.120.104.11:36583'. Reason: nanny-close
2023-06-26 18:18:04,158 - distributed.nanny - INFO - Nanny asking worker to close. Reason: nanny-close
2023-06-26 18:18:04,158 - distributed.nanny - INFO - Closing Nanny at 'tcp://10.120.104.11:41217'. Reason: nanny-close
2023-06-26 18:18:04,158 - distributed.nanny - INFO - Nanny asking worker to close. Reason: nanny-close
2023-06-26 18:18:04,159 - distributed.nanny - INFO - Closing Nanny at 'tcp://10.120.104.11:44453'. Reason: nanny-close
2023-06-26 18:18:04,159 - distributed.nanny - INFO - Nanny asking worker to close. Reason: nanny-close
2023-06-26 18:18:04,159 - distributed.nanny - INFO - Closing Nanny at 'tcp://10.120.104.11:37963'. Reason: nanny-close
2023-06-26 18:18:04,159 - distributed.nanny - INFO - Nanny asking worker to close. Reason: nanny-close
2023-06-26 18:18:04,160 - distributed.nanny - INFO - Closing Nanny at 'tcp://10.120.104.11:37069'. Reason: nanny-close
2023-06-26 18:18:04,160 - distributed.nanny - INFO - Nanny asking worker to close. Reason: nanny-close
2023-06-26 18:18:04,520 - distributed.core - ERROR - Timed out during handshake while connecting to tcp://10.120.104.11:35553 after 100 s
Traceback (most recent call last):
  File "/opt/conda/envs/rapids/lib/python3.10/asyncio/runners.py", line 44, in run
    return loop.run_until_complete(main)
  File "/opt/conda/envs/rapids/lib/python3.10/asyncio/base_events.py", line 636, in run_until_complete
    self.run_forever()
  File "/opt/conda/envs/rapids/lib/python3.10/asyncio/base_events.py", line 603, in run_forever
    self._run_once()
  File "/opt/conda/envs/rapids/lib/python3.10/asyncio/base_events.py", line 1871, in _run_once
    event_list = self._selector.select(timeout)
  File "/opt/conda/envs/rapids/lib/python3.10/selectors.py", line 469, in select
    fd_event_list = self._selector.poll(timeout, max_ev)
KeyboardInterrupt

During handling of the above exception, another exception occurred:

Traceback (most recent call last):
  File "/opt/conda/envs/rapids/lib/python3.10/site-packages/tornado/iostream.py", line 861, in _read_to_buffer
    bytes_read = self.read_from_fd(buf)
  File "/opt/conda/envs/rapids/lib/python3.10/site-packages/tornado/iostream.py", line 1116, in read_from_fd
    return self.socket.recv_into(buf, len(buf))
ConnectionResetError: [Errno 104] Connection reset by peer

The above exception was the direct cause of the following exception:

Traceback (most recent call last):
  File "/opt/conda/envs/rapids/lib/python3.10/site-packages/distributed/comm/core.py", line 392, in connect
    handshake = await wait_for(comm.read(), time_left())
  File "/opt/conda/envs/rapids/lib/python3.10/site-packages/distributed/utils.py", line 1919, in wait_for
    return await asyncio.wait_for(fut, timeout)
  File "/opt/conda/envs/rapids/lib/python3.10/asyncio/tasks.py", line 445, in wait_for
    return fut.result()
  File "/opt/conda/envs/rapids/lib/python3.10/site-packages/distributed/comm/tcp.py", line 241, in read
    convert_stream_closed_error(self, e)
  File "/opt/conda/envs/rapids/lib/python3.10/site-packages/distributed/comm/tcp.py", line 142, in convert_stream_closed_error
    raise CommClosedError(f"in {obj}: {exc.__class__.__name__}: {exc}") from exc
distributed.comm.core.CommClosedError: in <TCP (closed)  local=tcp://10.120.104.11:33134 remote=tcp://10.120.104.11:35553>: ConnectionResetError: [Errno 104] Connection reset by peer

The above exception was the direct cause of the following exception:

Traceback (most recent call last):
  File "/opt/conda/envs/rapids/lib/python3.10/site-packages/distributed/utils.py", line 795, in wrapper
    return await func(*args, **kwargs)
  File "/opt/conda/envs/rapids/lib/python3.10/site-packages/distributed/worker.py", line 1558, in close
    await r.close_gracefully(reason=reason)
  File "/opt/conda/envs/rapids/lib/python3.10/site-packages/distributed/core.py", line 1374, in send_recv_from_rpc
    comm = await self.pool.connect(self.addr)
  File "/opt/conda/envs/rapids/lib/python3.10/site-packages/distributed/core.py", line 1620, in connect
    return await connect_attempt
  File "/opt/conda/envs/rapids/lib/python3.10/site-packages/distributed/core.py", line 1539, in _connect
    comm = await connect(
  File "/opt/conda/envs/rapids/lib/python3.10/site-packages/distributed/comm/core.py", line 397, in connect
    raise OSError(
OSError: Timed out during handshake while connecting to tcp://10.120.104.11:35553 after 100 s
2023-06-26 18:18:04,521 - distributed.worker - ERROR - Timed out during handshake while connecting to tcp://10.120.104.11:39859 after 100 s
Traceback (most recent call last):
  File "/opt/conda/envs/rapids/lib/python3.10/asyncio/runners.py", line 44, in run
    return loop.run_until_complete(main)
  File "/opt/conda/envs/rapids/lib/python3.10/asyncio/base_events.py", line 636, in run_until_complete
    self.run_forever()
  File "/opt/conda/envs/rapids/lib/python3.10/asyncio/base_events.py", line 603, in run_forever
    self._run_once()
  File "/opt/conda/envs/rapids/lib/python3.10/asyncio/base_events.py", line 1871, in _run_once
    event_list = self._selector.select(timeout)
  File "/opt/conda/envs/rapids/lib/python3.10/selectors.py", line 469, in select
    fd_event_list = self._selector.poll(timeout, max_ev)
KeyboardInterrupt

During handling of the above exception, another exception occurred:

Traceback (most recent call last):
  File "/opt/conda/envs/rapids/lib/python3.10/site-packages/tornado/iostream.py", line 861, in _read_to_buffer
    bytes_read = self.read_from_fd(buf)
  File "/opt/conda/envs/rapids/lib/python3.10/site-packages/tornado/iostream.py", line 1116, in read_from_fd
    return self.socket.recv_into(buf, len(buf))
ConnectionResetError: [Errno 104] Connection reset by peer

The above exception was the direct cause of the following exception:

Traceback (most recent call last):
  File "/opt/conda/envs/rapids/lib/python3.10/site-packages/distributed/comm/core.py", line 392, in connect
    handshake = await wait_for(comm.read(), time_left())
  File "/opt/conda/envs/rapids/lib/python3.10/site-packages/distributed/utils.py", line 1919, in wait_for
    return await asyncio.wait_for(fut, timeout)
  File "/opt/conda/envs/rapids/lib/python3.10/asyncio/tasks.py", line 445, in wait_for
    return fut.result()
  File "/opt/conda/envs/rapids/lib/python3.10/site-packages/distributed/comm/tcp.py", line 241, in read
    convert_stream_closed_error(self, e)
  File "/opt/conda/envs/rapids/lib/python3.10/site-packages/distributed/comm/tcp.py", line 142, in convert_stream_closed_error
    raise CommClosedError(f"in {obj}: {exc.__class__.__name__}: {exc}") from exc
distributed.comm.core.CommClosedError: in <TCP (closed)  local=tcp://10.120.104.11:58370 remote=tcp://10.120.104.11:39859>: ConnectionResetError: [Errno 104] Connection reset by peer

The above exception was the direct cause of the following exception:

Traceback (most recent call last):
  File "/opt/conda/envs/rapids/lib/python3.10/site-packages/distributed/utils.py", line 795, in wrapper
    return await func(*args, **kwargs)
  File "/opt/conda/envs/rapids/lib/python3.10/site-packages/distributed/worker.py", line 1558, in close
    await r.close_gracefully(reason=reason)
  File "/opt/conda/envs/rapids/lib/python3.10/site-packages/distributed/core.py", line 1374, in send_recv_from_rpc
    comm = await self.pool.connect(self.addr)
  File "/opt/conda/envs/rapids/lib/python3.10/site-packages/distributed/core.py", line 1620, in connect
    return await connect_attempt
  File "/opt/conda/envs/rapids/lib/python3.10/site-packages/distributed/core.py", line 1539, in _connect
    comm = await connect(
  File "/opt/conda/envs/rapids/lib/python3.10/site-packages/distributed/comm/core.py", line 397, in connect
    raise OSError(
OSError: Timed out during handshake while connecting to tcp://10.120.104.11:39859 after 100 s
2023-06-26 18:18:04,522 - distributed.worker - ERROR - Timed out during handshake while connecting to tcp://10.120.104.11:36393 after 100 s
Traceback (most recent call last):
  File "/opt/conda/envs/rapids/lib/python3.10/asyncio/runners.py", line 44, in run
    return loop.run_until_complete(main)
  File "/opt/conda/envs/rapids/lib/python3.10/asyncio/base_events.py", line 636, in run_until_complete
    self.run_forever()
  File "/opt/conda/envs/rapids/lib/python3.10/asyncio/base_events.py", line 603, in run_forever
    self._run_once()
  File "/opt/conda/envs/rapids/lib/python3.10/asyncio/base_events.py", line 1871, in _run_once
    event_list = self._selector.select(timeout)
  File "/opt/conda/envs/rapids/lib/python3.10/selectors.py", line 469, in select
    fd_event_list = self._selector.poll(timeout, max_ev)
KeyboardInterrupt

During handling of the above exception, another exception occurred:

Traceback (most recent call last):
  File "/opt/conda/envs/rapids/lib/python3.10/site-packages/tornado/iostream.py", line 861, in _read_to_buffer
    bytes_read = self.read_from_fd(buf)
  File "/opt/conda/envs/rapids/lib/python3.10/site-packages/tornado/iostream.py", line 1116, in read_from_fd
    return self.socket.recv_into(buf, len(buf))
ConnectionResetError: [Errno 104] Connection reset by peer

The above exception was the direct cause of the following exception:

Traceback (most recent call last):
  File "/opt/conda/envs/rapids/lib/python3.10/site-packages/distributed/comm/core.py", line 392, in connect
    handshake = await wait_for(comm.read(), time_left())
  File "/opt/conda/envs/rapids/lib/python3.10/site-packages/distributed/utils.py", line 1919, in wait_for
    return await asyncio.wait_for(fut, timeout)
  File "/opt/conda/envs/rapids/lib/python3.10/asyncio/tasks.py", line 445, in wait_for
    return fut.result()
  File "/opt/conda/envs/rapids/lib/python3.10/site-packages/distributed/comm/tcp.py", line 241, in read
    convert_stream_closed_error(self, e)
  File "/opt/conda/envs/rapids/lib/python3.10/site-packages/distributed/comm/tcp.py", line 142, in convert_stream_closed_error
    raise CommClosedError(f"in {obj}: {exc.__class__.__name__}: {exc}") from exc
distributed.comm.core.CommClosedError: in <TCP (closed)  local=tcp://10.120.104.11:46874 remote=tcp://10.120.104.11:36393>: ConnectionResetError: [Errno 104] Connection reset by peer

The above exception was the direct cause of the following exception:

Traceback (most recent call last):
  File "/opt/conda/envs/rapids/lib/python3.10/site-packages/distributed/utils.py", line 795, in wrapper
    return await func(*args, **kwargs)
  File "/opt/conda/envs/rapids/lib/python3.10/site-packages/distributed/worker.py", line 1558, in close
    await r.close_gracefully(reason=reason)
  File "/opt/conda/envs/rapids/lib/python3.10/site-packages/distributed/core.py", line 1374, in send_recv_from_rpc
    comm = await self.pool.connect(self.addr)
  File "/opt/conda/envs/rapids/lib/python3.10/site-packages/distributed/core.py", line 1620, in connect
    return await connect_attempt
  File "/opt/conda/envs/rapids/lib/python3.10/site-packages/distributed/core.py", line 1539, in _connect
    comm = await connect(
  File "/opt/conda/envs/rapids/lib/python3.10/site-packages/distributed/comm/core.py", line 397, in connect
    raise OSError(
OSError: Timed out during handshake while connecting to tcp://10.120.104.11:36393 after 100 s
2023-06-26 18:18:04,523 - distributed.core - ERROR - Timed out during handshake while connecting to tcp://10.120.104.11:38169 after 100 s
Traceback (most recent call last):
  File "/opt/conda/envs/rapids/lib/python3.10/asyncio/runners.py", line 44, in run
    return loop.run_until_complete(main)
  File "/opt/conda/envs/rapids/lib/python3.10/asyncio/base_events.py", line 636, in run_until_complete
    self.run_forever()
  File "/opt/conda/envs/rapids/lib/python3.10/asyncio/base_events.py", line 603, in run_forever
    self._run_once()
  File "/opt/conda/envs/rapids/lib/python3.10/asyncio/base_events.py", line 1871, in _run_once
    event_list = self._selector.select(timeout)
  File "/opt/conda/envs/rapids/lib/python3.10/selectors.py", line 469, in select
    fd_event_list = self._selector.poll(timeout, max_ev)
KeyboardInterrupt

During handling of the above exception, another exception occurred:

Traceback (most recent call last):
  File "/opt/conda/envs/rapids/lib/python3.10/site-packages/tornado/iostream.py", line 861, in _read_to_buffer
    bytes_read = self.read_from_fd(buf)
  File "/opt/conda/envs/rapids/lib/python3.10/site-packages/tornado/iostream.py", line 1116, in read_from_fd
    return self.socket.recv_into(buf, len(buf))
ConnectionResetError: [Errno 104] Connection reset by peer

The above exception was the direct cause of the following exception:

Traceback (most recent call last):
  File "/opt/conda/envs/rapids/lib/python3.10/site-packages/distributed/comm/core.py", line 392, in connect
    handshake = await wait_for(comm.read(), time_left())
  File "/opt/conda/envs/rapids/lib/python3.10/site-packages/distributed/utils.py", line 1919, in wait_for
    return await asyncio.wait_for(fut, timeout)
  File "/opt/conda/envs/rapids/lib/python3.10/asyncio/tasks.py", line 445, in wait_for
    return fut.result()
  File "/opt/conda/envs/rapids/lib/python3.10/site-packages/distributed/comm/tcp.py", line 241, in read
    convert_stream_closed_error(self, e)
  File "/opt/conda/envs/rapids/lib/python3.10/site-packages/distributed/comm/tcp.py", line 142, in convert_stream_closed_error
    raise CommClosedError(f"in {obj}: {exc.__class__.__name__}: {exc}") from exc
distributed.comm.core.CommClosedError: in <TCP (closed)  local=tcp://10.120.104.11:48724 remote=tcp://10.120.104.11:38169>: ConnectionResetError: [Errno 104] Connection reset by peer

The above exception was the direct cause of the following exception:

Traceback (most recent call last):
  File "/opt/conda/envs/rapids/lib/python3.10/site-packages/distributed/utils.py", line 795, in wrapper
    return await func(*args, **kwargs)
  File "/opt/conda/envs/rapids/lib/python3.10/site-packages/distributed/worker.py", line 1558, in close
    await r.close_gracefully(reason=reason)
  File "/opt/conda/envs/rapids/lib/python3.10/site-packages/distributed/core.py", line 1374, in send_recv_from_rpc
    comm = await self.pool.connect(self.addr)
  File "/opt/conda/envs/rapids/lib/python3.10/site-packages/distributed/core.py", line 1620, in connect
    return await connect_attempt
  File "/opt/conda/envs/rapids/lib/python3.10/site-packages/distributed/core.py", line 1539, in _connect
    comm = await connect(
  File "/opt/conda/envs/rapids/lib/python3.10/site-packages/distributed/comm/core.py", line 397, in connect
    raise OSError(
OSError: Timed out during handshake while connecting to tcp://10.120.104.11:38169 after 100 s
2023-06-26 18:18:04,523 - distributed.core - ERROR - Timed out during handshake while connecting to tcp://10.120.104.11:37963 after 100 s
Traceback (most recent call last):
  File "/opt/conda/envs/rapids/lib/python3.10/asyncio/runners.py", line 44, in run
    return loop.run_until_complete(main)
  File "/opt/conda/envs/rapids/lib/python3.10/asyncio/base_events.py", line 636, in run_until_complete
    self.run_forever()
  File "/opt/conda/envs/rapids/lib/python3.10/asyncio/base_events.py", line 603, in run_forever
    self._run_once()
  File "/opt/conda/envs/rapids/lib/python3.10/asyncio/base_events.py", line 1871, in _run_once
    event_list = self._selector.select(timeout)
  File "/opt/conda/envs/rapids/lib/python3.10/selectors.py", line 469, in select
    fd_event_list = self._selector.poll(timeout, max_ev)
KeyboardInterrupt

During handling of the above exception, another exception occurred:

Traceback (most recent call last):
  File "/opt/conda/envs/rapids/lib/python3.10/site-packages/tornado/iostream.py", line 861, in _read_to_buffer
    bytes_read = self.read_from_fd(buf)
  File "/opt/conda/envs/rapids/lib/python3.10/site-packages/tornado/iostream.py", line 1116, in read_from_fd
    return self.socket.recv_into(buf, len(buf))
ConnectionResetError: [Errno 104] Connection reset by peer

The above exception was the direct cause of the following exception:

Traceback (most recent call last):
  File "/opt/conda/envs/rapids/lib/python3.10/site-packages/distributed/comm/core.py", line 392, in connect
    handshake = await wait_for(comm.read(), time_left())
  File "/opt/conda/envs/rapids/lib/python3.10/site-packages/distributed/utils.py", line 1919, in wait_for
    return await asyncio.wait_for(fut, timeout)
  File "/opt/conda/envs/rapids/lib/python3.10/asyncio/tasks.py", line 445, in wait_for
    return fut.result()
  File "/opt/conda/envs/rapids/lib/python3.10/site-packages/distributed/comm/tcp.py", line 241, in read
    convert_stream_closed_error(self, e)
  File "/opt/conda/envs/rapids/lib/python3.10/site-packages/distributed/comm/tcp.py", line 142, in convert_stream_closed_error
    raise CommClosedError(f"in {obj}: {exc.__class__.__name__}: {exc}") from exc
distributed.comm.core.CommClosedError: in <TCP (closed)  local=tcp://10.120.104.11:59232 remote=tcp://10.120.104.11:37963>: ConnectionResetError: [Errno 104] Connection reset by peer

The above exception was the direct cause of the following exception:

Traceback (most recent call last):
  File "/opt/conda/envs/rapids/lib/python3.10/site-packages/distributed/utils.py", line 795, in wrapper
    return await func(*args, **kwargs)
  File "/opt/conda/envs/rapids/lib/python3.10/site-packages/distributed/worker.py", line 1558, in close
    await r.close_gracefully(reason=reason)
  File "/opt/conda/envs/rapids/lib/python3.10/site-packages/distributed/core.py", line 1374, in send_recv_from_rpc
    comm = await self.pool.connect(self.addr)
  File "/opt/conda/envs/rapids/lib/python3.10/site-packages/distributed/core.py", line 1620, in connect
    return await connect_attempt
  File "/opt/conda/envs/rapids/lib/python3.10/site-packages/distributed/core.py", line 1539, in _connect
    comm = await connect(
  File "/opt/conda/envs/rapids/lib/python3.10/site-packages/distributed/comm/core.py", line 397, in connect
    raise OSError(
OSError: Timed out during handshake while connecting to tcp://10.120.104.11:37963 after 100 s
2023-06-26 18:18:04,525 - distributed.core - ERROR - Timed out during handshake while connecting to tcp://10.120.104.11:44959 after 100 s
Traceback (most recent call last):
  File "/opt/conda/envs/rapids/lib/python3.10/asyncio/runners.py", line 44, in run
    return loop.run_until_complete(main)
  File "/opt/conda/envs/rapids/lib/python3.10/asyncio/base_events.py", line 636, in run_until_complete
    self.run_forever()
  File "/opt/conda/envs/rapids/lib/python3.10/asyncio/base_events.py", line 603, in run_forever
    self._run_once()
  File "/opt/conda/envs/rapids/lib/python3.10/asyncio/base_events.py", line 1871, in _run_once
    event_list = self._selector.select(timeout)
  File "/opt/conda/envs/rapids/lib/python3.10/selectors.py", line 469, in select
    fd_event_list = self._selector.poll(timeout, max_ev)
KeyboardInterrupt

During handling of the above exception, another exception occurred:

Traceback (most recent call last):
  File "/opt/conda/envs/rapids/lib/python3.10/site-packages/tornado/iostream.py", line 861, in _read_to_buffer
    bytes_read = self.read_from_fd(buf)
  File "/opt/conda/envs/rapids/lib/python3.10/site-packages/tornado/iostream.py", line 1116, in read_from_fd
    return self.socket.recv_into(buf, len(buf))
ConnectionResetError: [Errno 104] Connection reset by peer

The above exception was the direct cause of the following exception:

Traceback (most recent call last):
  File "/opt/conda/envs/rapids/lib/python3.10/site-packages/distributed/comm/core.py", line 392, in connect
    handshake = await wait_for(comm.read(), time_left())
  File "/opt/conda/envs/rapids/lib/python3.10/site-packages/distributed/utils.py", line 1919, in wait_for
    return await asyncio.wait_for(fut, timeout)
  File "/opt/conda/envs/rapids/lib/python3.10/asyncio/tasks.py", line 445, in wait_for
    return fut.result()
  File "/opt/conda/envs/rapids/lib/python3.10/site-packages/distributed/comm/tcp.py", line 241, in read
    convert_stream_closed_error(self, e)
  File "/opt/conda/envs/rapids/lib/python3.10/site-packages/distributed/comm/tcp.py", line 142, in convert_stream_closed_error
    raise CommClosedError(f"in {obj}: {exc.__class__.__name__}: {exc}") from exc
distributed.comm.core.CommClosedError: in <TCP (closed)  local=tcp://10.120.104.11:43246 remote=tcp://10.120.104.11:44959>: ConnectionResetError: [Errno 104] Connection reset by peer

The above exception was the direct cause of the following exception:

Traceback (most recent call last):
  File "/opt/conda/envs/rapids/lib/python3.10/site-packages/distributed/utils.py", line 795, in wrapper
    return await func(*args, **kwargs)
  File "/opt/conda/envs/rapids/lib/python3.10/site-packages/distributed/worker.py", line 1558, in close
    await r.close_gracefully(reason=reason)
  File "/opt/conda/envs/rapids/lib/python3.10/site-packages/distributed/core.py", line 1374, in send_recv_from_rpc
    comm = await self.pool.connect(self.addr)
  File "/opt/conda/envs/rapids/lib/python3.10/site-packages/distributed/core.py", line 1620, in connect
    return await connect_attempt
  File "/opt/conda/envs/rapids/lib/python3.10/site-packages/distributed/core.py", line 1539, in _connect
    comm = await connect(
  File "/opt/conda/envs/rapids/lib/python3.10/site-packages/distributed/comm/core.py", line 397, in connect
    raise OSError(
OSError: Timed out during handshake while connecting to tcp://10.120.104.11:44959 after 100 s
2023-06-26 18:18:04,526 - distributed.core - ERROR - Timed out during handshake while connecting to tcp://10.120.104.11:41217 after 100 s
Traceback (most recent call last):
  File "/opt/conda/envs/rapids/lib/python3.10/asyncio/runners.py", line 44, in run
    return loop.run_until_complete(main)
  File "/opt/conda/envs/rapids/lib/python3.10/asyncio/base_events.py", line 636, in run_until_complete
    self.run_forever()
  File "/opt/conda/envs/rapids/lib/python3.10/asyncio/base_events.py", line 603, in run_forever
    self._run_once()
  File "/opt/conda/envs/rapids/lib/python3.10/asyncio/base_events.py", line 1871, in _run_once
    event_list = self._selector.select(timeout)
  File "/opt/conda/envs/rapids/lib/python3.10/selectors.py", line 469, in select
    fd_event_list = self._selector.poll(timeout, max_ev)
KeyboardInterrupt

During handling of the above exception, another exception occurred:

Traceback (most recent call last):
  File "/opt/conda/envs/rapids/lib/python3.10/site-packages/tornado/iostream.py", line 861, in _read_to_buffer
    bytes_read = self.read_from_fd(buf)
  File "/opt/conda/envs/rapids/lib/python3.10/site-packages/tornado/iostream.py", line 1116, in read_from_fd
    return self.socket.recv_into(buf, len(buf))
ConnectionResetError: [Errno 104] Connection reset by peer

The above exception was the direct cause of the following exception:

Traceback (most recent call last):
  File "/opt/conda/envs/rapids/lib/python3.10/site-packages/distributed/comm/core.py", line 392, in connect
    handshake = await wait_for(comm.read(), time_left())
  File "/opt/conda/envs/rapids/lib/python3.10/site-packages/distributed/utils.py", line 1919, in wait_for
    return await asyncio.wait_for(fut, timeout)
  File "/opt/conda/envs/rapids/lib/python3.10/asyncio/tasks.py", line 445, in wait_for
    return fut.result()
  File "/opt/conda/envs/rapids/lib/python3.10/site-packages/distributed/comm/tcp.py", line 241, in read
    convert_stream_closed_error(self, e)
  File "/opt/conda/envs/rapids/lib/python3.10/site-packages/distributed/comm/tcp.py", line 142, in convert_stream_closed_error
    raise CommClosedError(f"in {obj}: {exc.__class__.__name__}: {exc}") from exc
distributed.comm.core.CommClosedError: in <TCP (closed)  local=tcp://10.120.104.11:47040 remote=tcp://10.120.104.11:41217>: ConnectionResetError: [Errno 104] Connection reset by peer

The above exception was the direct cause of the following exception:

Traceback (most recent call last):
  File "/opt/conda/envs/rapids/lib/python3.10/site-packages/distributed/utils.py", line 795, in wrapper
    return await func(*args, **kwargs)
  File "/opt/conda/envs/rapids/lib/python3.10/site-packages/distributed/worker.py", line 1558, in close
    await r.close_gracefully(reason=reason)
  File "/opt/conda/envs/rapids/lib/python3.10/site-packages/distributed/core.py", line 1374, in send_recv_from_rpc
    comm = await self.pool.connect(self.addr)
  File "/opt/conda/envs/rapids/lib/python3.10/site-packages/distributed/core.py", line 1620, in connect
    return await connect_attempt
  File "/opt/conda/envs/rapids/lib/python3.10/site-packages/distributed/core.py", line 1539, in _connect
    comm = await connect(
  File "/opt/conda/envs/rapids/lib/python3.10/site-packages/distributed/comm/core.py", line 397, in connect
    raise OSError(
OSError: Timed out during handshake while connecting to tcp://10.120.104.11:41217 after 100 s
2023-06-26 18:18:04,526 - distributed.core - ERROR - Timed out during handshake while connecting to tcp://10.120.104.11:44155 after 100 s
Traceback (most recent call last):
  File "/opt/conda/envs/rapids/lib/python3.10/asyncio/runners.py", line 44, in run
    return loop.run_until_complete(main)
  File "/opt/conda/envs/rapids/lib/python3.10/asyncio/base_events.py", line 636, in run_until_complete
    self.run_forever()
  File "/opt/conda/envs/rapids/lib/python3.10/asyncio/base_events.py", line 603, in run_forever
    self._run_once()
  File "/opt/conda/envs/rapids/lib/python3.10/asyncio/base_events.py", line 1871, in _run_once
    event_list = self._selector.select(timeout)
  File "/opt/conda/envs/rapids/lib/python3.10/selectors.py", line 469, in select
    fd_event_list = self._selector.poll(timeout, max_ev)
KeyboardInterrupt

During handling of the above exception, another exception occurred:

Traceback (most recent call last):
  File "/opt/conda/envs/rapids/lib/python3.10/site-packages/tornado/iostream.py", line 861, in _read_to_buffer
    bytes_read = self.read_from_fd(buf)
  File "/opt/conda/envs/rapids/lib/python3.10/site-packages/tornado/iostream.py", line 1116, in read_from_fd
    return self.socket.recv_into(buf, len(buf))
ConnectionResetError: [Errno 104] Connection reset by peer

The above exception was the direct cause of the following exception:

Traceback (most recent call last):
  File "/opt/conda/envs/rapids/lib/python3.10/site-packages/distributed/comm/core.py", line 392, in connect
    handshake = await wait_for(comm.read(), time_left())
  File "/opt/conda/envs/rapids/lib/python3.10/site-packages/distributed/utils.py", line 1919, in wait_for
    return await asyncio.wait_for(fut, timeout)
  File "/opt/conda/envs/rapids/lib/python3.10/asyncio/tasks.py", line 445, in wait_for
    return fut.result()
  File "/opt/conda/envs/rapids/lib/python3.10/site-packages/distributed/comm/tcp.py", line 241, in read
    convert_stream_closed_error(self, e)
  File "/opt/conda/envs/rapids/lib/python3.10/site-packages/distributed/comm/tcp.py", line 142, in convert_stream_closed_error
    raise CommClosedError(f"in {obj}: {exc.__class__.__name__}: {exc}") from exc
distributed.comm.core.CommClosedError: in <TCP (closed)  local=tcp://10.120.104.11:41276 remote=tcp://10.120.104.11:44155>: ConnectionResetError: [Errno 104] Connection reset by peer

The above exception was the direct cause of the following exception:

Traceback (most recent call last):
  File "/opt/conda/envs/rapids/lib/python3.10/site-packages/distributed/utils.py", line 795, in wrapper
    return await func(*args, **kwargs)
  File "/opt/conda/envs/rapids/lib/python3.10/site-packages/distributed/worker.py", line 1558, in close
    await r.close_gracefully(reason=reason)
  File "/opt/conda/envs/rapids/lib/python3.10/site-packages/distributed/core.py", line 1374, in send_recv_from_rpc
    comm = await self.pool.connect(self.addr)
  File "/opt/conda/envs/rapids/lib/python3.10/site-packages/distributed/core.py", line 1620, in connect
    return await connect_attempt
  File "/opt/conda/envs/rapids/lib/python3.10/site-packages/distributed/core.py", line 1539, in _connect
    comm = await connect(
  File "/opt/conda/envs/rapids/lib/python3.10/site-packages/distributed/comm/core.py", line 397, in connect
    raise OSError(
OSError: Timed out during handshake while connecting to tcp://10.120.104.11:44155 after 100 s
2023-06-26 18:18:04,527 - distributed.core - ERROR - Timed out during handshake while connecting to tcp://10.120.104.11:37069 after 100 s
Traceback (most recent call last):
  File "/opt/conda/envs/rapids/lib/python3.10/asyncio/runners.py", line 44, in run
    return loop.run_until_complete(main)
  File "/opt/conda/envs/rapids/lib/python3.10/asyncio/base_events.py", line 636, in run_until_complete
    self.run_forever()
  File "/opt/conda/envs/rapids/lib/python3.10/asyncio/base_events.py", line 603, in run_forever
    self._run_once()
  File "/opt/conda/envs/rapids/lib/python3.10/asyncio/base_events.py", line 1871, in _run_once
    event_list = self._selector.select(timeout)
  File "/opt/conda/envs/rapids/lib/python3.10/selectors.py", line 469, in select
    fd_event_list = self._selector.poll(timeout, max_ev)
KeyboardInterrupt

During handling of the above exception, another exception occurred:

Traceback (most recent call last):
  File "/opt/conda/envs/rapids/lib/python3.10/site-packages/tornado/iostream.py", line 861, in _read_to_buffer
    bytes_read = self.read_from_fd(buf)
  File "/opt/conda/envs/rapids/lib/python3.10/site-packages/tornado/iostream.py", line 1116, in read_from_fd
    return self.socket.recv_into(buf, len(buf))
ConnectionResetError: [Errno 104] Connection reset by peer

The above exception was the direct cause of the following exception:

Traceback (most recent call last):
  File "/opt/conda/envs/rapids/lib/python3.10/site-packages/distributed/comm/core.py", line 392, in connect
    handshake = await wait_for(comm.read(), time_left())
  File "/opt/conda/envs/rapids/lib/python3.10/site-packages/distributed/utils.py", line 1919, in wait_for
    return await asyncio.wait_for(fut, timeout)
  File "/opt/conda/envs/rapids/lib/python3.10/asyncio/tasks.py", line 445, in wait_for
    return fut.result()
  File "/opt/conda/envs/rapids/lib/python3.10/site-packages/distributed/comm/tcp.py", line 241, in read
    convert_stream_closed_error(self, e)
  File "/opt/conda/envs/rapids/lib/python3.10/site-packages/distributed/comm/tcp.py", line 142, in convert_stream_closed_error
    raise CommClosedError(f"in {obj}: {exc.__class__.__name__}: {exc}") from exc
distributed.comm.core.CommClosedError: in <TCP (closed)  local=tcp://10.120.104.11:33380 remote=tcp://10.120.104.11:37069>: ConnectionResetError: [Errno 104] Connection reset by peer

The above exception was the direct cause of the following exception:

Traceback (most recent call last):
  File "/opt/conda/envs/rapids/lib/python3.10/site-packages/distributed/utils.py", line 795, in wrapper
    return await func(*args, **kwargs)
  File "/opt/conda/envs/rapids/lib/python3.10/site-packages/distributed/worker.py", line 1558, in close
    await r.close_gracefully(reason=reason)
  File "/opt/conda/envs/rapids/lib/python3.10/site-packages/distributed/core.py", line 1374, in send_recv_from_rpc
    comm = await self.pool.connect(self.addr)
  File "/opt/conda/envs/rapids/lib/python3.10/site-packages/distributed/core.py", line 1620, in connect
    return await connect_attempt
  File "/opt/conda/envs/rapids/lib/python3.10/site-packages/distributed/core.py", line 1539, in _connect
    comm = await connect(
  File "/opt/conda/envs/rapids/lib/python3.10/site-packages/distributed/comm/core.py", line 397, in connect
    raise OSError(
OSError: Timed out during handshake while connecting to tcp://10.120.104.11:37069 after 100 s
2023-06-26 18:18:04,527 - distributed.core - ERROR - Timed out during handshake while connecting to tcp://10.120.104.11:37381 after 100 s
Traceback (most recent call last):
  File "/opt/conda/envs/rapids/lib/python3.10/asyncio/runners.py", line 44, in run
    return loop.run_until_complete(main)
  File "/opt/conda/envs/rapids/lib/python3.10/asyncio/base_events.py", line 636, in run_until_complete
    self.run_forever()
  File "/opt/conda/envs/rapids/lib/python3.10/asyncio/base_events.py", line 603, in run_forever
    self._run_once()
  File "/opt/conda/envs/rapids/lib/python3.10/asyncio/base_events.py", line 1871, in _run_once
    event_list = self._selector.select(timeout)
  File "/opt/conda/envs/rapids/lib/python3.10/selectors.py", line 469, in select
    fd_event_list = self._selector.poll(timeout, max_ev)
KeyboardInterrupt

During handling of the above exception, another exception occurred:

Traceback (most recent call last):
  File "/opt/conda/envs/rapids/lib/python3.10/site-packages/tornado/iostream.py", line 861, in _read_to_buffer
    bytes_read = self.read_from_fd(buf)
  File "/opt/conda/envs/rapids/lib/python3.10/site-packages/tornado/iostream.py", line 1116, in read_from_fd
    return self.socket.recv_into(buf, len(buf))
ConnectionResetError: [Errno 104] Connection reset by peer

The above exception was the direct cause of the following exception:

Traceback (most recent call last):
  File "/opt/conda/envs/rapids/lib/python3.10/site-packages/distributed/comm/core.py", line 392, in connect
    handshake = await wait_for(comm.read(), time_left())
  File "/opt/conda/envs/rapids/lib/python3.10/site-packages/distributed/utils.py", line 1919, in wait_for
    return await asyncio.wait_for(fut, timeout)
  File "/opt/conda/envs/rapids/lib/python3.10/asyncio/tasks.py", line 445, in wait_for
    return fut.result()
  File "/opt/conda/envs/rapids/lib/python3.10/site-packages/distributed/comm/tcp.py", line 241, in read
    convert_stream_closed_error(self, e)
  File "/opt/conda/envs/rapids/lib/python3.10/site-packages/distributed/comm/tcp.py", line 142, in convert_stream_closed_error
    raise CommClosedError(f"in {obj}: {exc.__class__.__name__}: {exc}") from exc
distributed.comm.core.CommClosedError: in <TCP (closed)  local=tcp://10.120.104.11:37314 remote=tcp://10.120.104.11:37381>: ConnectionResetError: [Errno 104] Connection reset by peer

The above exception was the direct cause of the following exception:

Traceback (most recent call last):
  File "/opt/conda/envs/rapids/lib/python3.10/site-packages/distributed/utils.py", line 795, in wrapper
    return await func(*args, **kwargs)
  File "/opt/conda/envs/rapids/lib/python3.10/site-packages/distributed/worker.py", line 1558, in close
    await r.close_gracefully(reason=reason)
  File "/opt/conda/envs/rapids/lib/python3.10/site-packages/distributed/core.py", line 1374, in send_recv_from_rpc
    comm = await self.pool.connect(self.addr)
  File "/opt/conda/envs/rapids/lib/python3.10/site-packages/distributed/core.py", line 1620, in connect
    return await connect_attempt
  File "/opt/conda/envs/rapids/lib/python3.10/site-packages/distributed/core.py", line 1539, in _connect
    comm = await connect(
  File "/opt/conda/envs/rapids/lib/python3.10/site-packages/distributed/comm/core.py", line 397, in connect
    raise OSError(
OSError: Timed out during handshake while connecting to tcp://10.120.104.11:37381 after 100 s
2023-06-26 18:18:04,527 - distributed.worker - ERROR - Timed out during handshake while connecting to tcp://10.120.104.11:45397 after 100 s
Traceback (most recent call last):
  File "/opt/conda/envs/rapids/lib/python3.10/asyncio/runners.py", line 44, in run
    return loop.run_until_complete(main)
  File "/opt/conda/envs/rapids/lib/python3.10/asyncio/base_events.py", line 636, in run_until_complete
    self.run_forever()
  File "/opt/conda/envs/rapids/lib/python3.10/asyncio/base_events.py", line 603, in run_forever
    self._run_once()
  File "/opt/conda/envs/rapids/lib/python3.10/asyncio/base_events.py", line 1871, in _run_once
    event_list = self._selector.select(timeout)
  File "/opt/conda/envs/rapids/lib/python3.10/selectors.py", line 469, in select
    fd_event_list = self._selector.poll(timeout, max_ev)
KeyboardInterrupt

During handling of the above exception, another exception occurred:

Traceback (most recent call last):
  File "/opt/conda/envs/rapids/lib/python3.10/site-packages/tornado/iostream.py", line 861, in _read_to_buffer
    bytes_read = self.read_from_fd(buf)
  File "/opt/conda/envs/rapids/lib/python3.10/site-packages/tornado/iostream.py", line 1116, in read_from_fd
    return self.socket.recv_into(buf, len(buf))
ConnectionResetError: [Errno 104] Connection reset by peer

The above exception was the direct cause of the following exception:

Traceback (most recent call last):
  File "/opt/conda/envs/rapids/lib/python3.10/site-packages/distributed/comm/core.py", line 392, in connect
    handshake = await wait_for(comm.read(), time_left())
  File "/opt/conda/envs/rapids/lib/python3.10/site-packages/distributed/utils.py", line 1919, in wait_for
    return await asyncio.wait_for(fut, timeout)
  File "/opt/conda/envs/rapids/lib/python3.10/asyncio/tasks.py", line 445, in wait_for
    return fut.result()
  File "/opt/conda/envs/rapids/lib/python3.10/site-packages/distributed/comm/tcp.py", line 241, in read
    convert_stream_closed_error(self, e)
  File "/opt/conda/envs/rapids/lib/python3.10/site-packages/distributed/comm/tcp.py", line 142, in convert_stream_closed_error
    raise CommClosedError(f"in {obj}: {exc.__class__.__name__}: {exc}") from exc
distributed.comm.core.CommClosedError: in <TCP (closed)  local=tcp://10.120.104.11:34350 remote=tcp://10.120.104.11:45397>: ConnectionResetError: [Errno 104] Connection reset by peer

The above exception was the direct cause of the following exception:

Traceback (most recent call last):
  File "/opt/conda/envs/rapids/lib/python3.10/site-packages/distributed/utils.py", line 795, in wrapper
    return await func(*args, **kwargs)
  File "/opt/conda/envs/rapids/lib/python3.10/site-packages/distributed/worker.py", line 1558, in close
    await r.close_gracefully(reason=reason)
  File "/opt/conda/envs/rapids/lib/python3.10/site-packages/distributed/core.py", line 1374, in send_recv_from_rpc
    comm = await self.pool.connect(self.addr)
  File "/opt/conda/envs/rapids/lib/python3.10/site-packages/distributed/core.py", line 1620, in connect
    return await connect_attempt
  File "/opt/conda/envs/rapids/lib/python3.10/site-packages/distributed/core.py", line 1539, in _connect
    comm = await connect(
  File "/opt/conda/envs/rapids/lib/python3.10/site-packages/distributed/comm/core.py", line 397, in connect
    raise OSError(
OSError: Timed out during handshake while connecting to tcp://10.120.104.11:45397 after 100 s
2023-06-26 18:18:04,528 - distributed.core - ERROR - Timed out during handshake while connecting to tcp://10.120.104.11:44453 after 100 s
Traceback (most recent call last):
  File "/opt/conda/envs/rapids/lib/python3.10/asyncio/runners.py", line 44, in run
    return loop.run_until_complete(main)
  File "/opt/conda/envs/rapids/lib/python3.10/asyncio/base_events.py", line 636, in run_until_complete
    self.run_forever()
  File "/opt/conda/envs/rapids/lib/python3.10/asyncio/base_events.py", line 603, in run_forever
    self._run_once()
  File "/opt/conda/envs/rapids/lib/python3.10/asyncio/base_events.py", line 1871, in _run_once
    event_list = self._selector.select(timeout)
  File "/opt/conda/envs/rapids/lib/python3.10/selectors.py", line 469, in select
    fd_event_list = self._selector.poll(timeout, max_ev)
KeyboardInterrupt

During handling of the above exception, another exception occurred:

Traceback (most recent call last):
  File "/opt/conda/envs/rapids/lib/python3.10/site-packages/tornado/iostream.py", line 861, in _read_to_buffer
    bytes_read = self.read_from_fd(buf)
  File "/opt/conda/envs/rapids/lib/python3.10/site-packages/tornado/iostream.py", line 1116, in read_from_fd
    return self.socket.recv_into(buf, len(buf))
ConnectionResetError: [Errno 104] Connection reset by peer

The above exception was the direct cause of the following exception:

Traceback (most recent call last):
  File "/opt/conda/envs/rapids/lib/python3.10/site-packages/distributed/comm/core.py", line 392, in connect
    handshake = await wait_for(comm.read(), time_left())
  File "/opt/conda/envs/rapids/lib/python3.10/site-packages/distributed/utils.py", line 1919, in wait_for
    return await asyncio.wait_for(fut, timeout)
  File "/opt/conda/envs/rapids/lib/python3.10/asyncio/tasks.py", line 445, in wait_for
    return fut.result()
  File "/opt/conda/envs/rapids/lib/python3.10/site-packages/distributed/comm/tcp.py", line 241, in read
    convert_stream_closed_error(self, e)
  File "/opt/conda/envs/rapids/lib/python3.10/site-packages/distributed/comm/tcp.py", line 142, in convert_stream_closed_error
    raise CommClosedError(f"in {obj}: {exc.__class__.__name__}: {exc}") from exc
distributed.comm.core.CommClosedError: in <TCP (closed)  local=tcp://10.120.104.11:41960 remote=tcp://10.120.104.11:44453>: ConnectionResetError: [Errno 104] Connection reset by peer

The above exception was the direct cause of the following exception:

Traceback (most recent call last):
  File "/opt/conda/envs/rapids/lib/python3.10/site-packages/distributed/utils.py", line 795, in wrapper
    return await func(*args, **kwargs)
  File "/opt/conda/envs/rapids/lib/python3.10/site-packages/distributed/worker.py", line 1558, in close
    await r.close_gracefully(reason=reason)
  File "/opt/conda/envs/rapids/lib/python3.10/site-packages/distributed/core.py", line 1374, in send_recv_from_rpc
    comm = await self.pool.connect(self.addr)
  File "/opt/conda/envs/rapids/lib/python3.10/site-packages/distributed/core.py", line 1620, in connect
    return await connect_attempt
  File "/opt/conda/envs/rapids/lib/python3.10/site-packages/distributed/core.py", line 1539, in _connect
    comm = await connect(
  File "/opt/conda/envs/rapids/lib/python3.10/site-packages/distributed/comm/core.py", line 397, in connect
    raise OSError(
OSError: Timed out during handshake while connecting to tcp://10.120.104.11:44453 after 100 s
2023-06-26 18:18:04,528 - distributed.core - ERROR - Timed out during handshake while connecting to tcp://10.120.104.11:33985 after 100 s
Traceback (most recent call last):
  File "/opt/conda/envs/rapids/lib/python3.10/asyncio/runners.py", line 44, in run
    return loop.run_until_complete(main)
  File "/opt/conda/envs/rapids/lib/python3.10/asyncio/base_events.py", line 636, in run_until_complete
    self.run_forever()
  File "/opt/conda/envs/rapids/lib/python3.10/asyncio/base_events.py", line 603, in run_forever
    self._run_once()
  File "/opt/conda/envs/rapids/lib/python3.10/asyncio/base_events.py", line 1871, in _run_once
    event_list = self._selector.select(timeout)
  File "/opt/conda/envs/rapids/lib/python3.10/selectors.py", line 469, in select
    fd_event_list = self._selector.poll(timeout, max_ev)
KeyboardInterrupt

During handling of the above exception, another exception occurred:

Traceback (most recent call last):
  File "/opt/conda/envs/rapids/lib/python3.10/site-packages/tornado/iostream.py", line 861, in _read_to_buffer
    bytes_read = self.read_from_fd(buf)
  File "/opt/conda/envs/rapids/lib/python3.10/site-packages/tornado/iostream.py", line 1116, in read_from_fd
    return self.socket.recv_into(buf, len(buf))
ConnectionResetError: [Errno 104] Connection reset by peer

The above exception was the direct cause of the following exception:

Traceback (most recent call last):
  File "/opt/conda/envs/rapids/lib/python3.10/site-packages/distributed/comm/core.py", line 392, in connect
    handshake = await wait_for(comm.read(), time_left())
  File "/opt/conda/envs/rapids/lib/python3.10/site-packages/distributed/utils.py", line 1919, in wait_for
    return await asyncio.wait_for(fut, timeout)
  File "/opt/conda/envs/rapids/lib/python3.10/asyncio/tasks.py", line 445, in wait_for
    return fut.result()
  File "/opt/conda/envs/rapids/lib/python3.10/site-packages/distributed/comm/tcp.py", line 241, in read
    convert_stream_closed_error(self, e)
  File "/opt/conda/envs/rapids/lib/python3.10/site-packages/distributed/comm/tcp.py", line 142, in convert_stream_closed_error
    raise CommClosedError(f"in {obj}: {exc.__class__.__name__}: {exc}") from exc
distributed.comm.core.CommClosedError: in <TCP (closed)  local=tcp://10.120.104.11:53008 remote=tcp://10.120.104.11:33985>: ConnectionResetError: [Errno 104] Connection reset by peer

The above exception was the direct cause of the following exception:

Traceback (most recent call last):
  File "/opt/conda/envs/rapids/lib/python3.10/site-packages/distributed/utils.py", line 795, in wrapper
    return await func(*args, **kwargs)
  File "/opt/conda/envs/rapids/lib/python3.10/site-packages/distributed/worker.py", line 1558, in close
    await r.close_gracefully(reason=reason)
  File "/opt/conda/envs/rapids/lib/python3.10/site-packages/distributed/core.py", line 1374, in send_recv_from_rpc
    comm = await self.pool.connect(self.addr)
  File "/opt/conda/envs/rapids/lib/python3.10/site-packages/distributed/core.py", line 1620, in connect
    return await connect_attempt
  File "/opt/conda/envs/rapids/lib/python3.10/site-packages/distributed/core.py", line 1539, in _connect
    comm = await connect(
  File "/opt/conda/envs/rapids/lib/python3.10/site-packages/distributed/comm/core.py", line 397, in connect
    raise OSError(
OSError: Timed out during handshake while connecting to tcp://10.120.104.11:33985 after 100 s
2023-06-26 18:18:04,536 - distributed.core - ERROR - Timed out during handshake while connecting to tcp://10.120.104.11:36583 after 100 s
Traceback (most recent call last):
  File "/opt/conda/envs/rapids/lib/python3.10/asyncio/runners.py", line 44, in run
    return loop.run_until_complete(main)
  File "/opt/conda/envs/rapids/lib/python3.10/asyncio/base_events.py", line 636, in run_until_complete
    self.run_forever()
  File "/opt/conda/envs/rapids/lib/python3.10/asyncio/base_events.py", line 603, in run_forever
    self._run_once()
  File "/opt/conda/envs/rapids/lib/python3.10/asyncio/base_events.py", line 1871, in _run_once
    event_list = self._selector.select(timeout)
  File "/opt/conda/envs/rapids/lib/python3.10/selectors.py", line 469, in select
    fd_event_list = self._selector.poll(timeout, max_ev)
KeyboardInterrupt

During handling of the above exception, another exception occurred:

Traceback (most recent call last):
  File "/opt/conda/envs/rapids/lib/python3.10/site-packages/tornado/iostream.py", line 861, in _read_to_buffer
    bytes_read = self.read_from_fd(buf)
  File "/opt/conda/envs/rapids/lib/python3.10/site-packages/tornado/iostream.py", line 1116, in read_from_fd
    return self.socket.recv_into(buf, len(buf))
ConnectionResetError: [Errno 104] Connection reset by peer

The above exception was the direct cause of the following exception:

Traceback (most recent call last):
  File "/opt/conda/envs/rapids/lib/python3.10/site-packages/distributed/comm/core.py", line 392, in connect
    handshake = await wait_for(comm.read(), time_left())
  File "/opt/conda/envs/rapids/lib/python3.10/site-packages/distributed/utils.py", line 1919, in wait_for
    return await asyncio.wait_for(fut, timeout)
  File "/opt/conda/envs/rapids/lib/python3.10/asyncio/tasks.py", line 445, in wait_for
    return fut.result()
  File "/opt/conda/envs/rapids/lib/python3.10/site-packages/distributed/comm/tcp.py", line 241, in read
    convert_stream_closed_error(self, e)
  File "/opt/conda/envs/rapids/lib/python3.10/site-packages/distributed/comm/tcp.py", line 142, in convert_stream_closed_error
    raise CommClosedError(f"in {obj}: {exc.__class__.__name__}: {exc}") from exc
distributed.comm.core.CommClosedError: in <TCP (closed)  local=tcp://10.120.104.11:47486 remote=tcp://10.120.104.11:36583>: ConnectionResetError: [Errno 104] Connection reset by peer

The above exception was the direct cause of the following exception:

Traceback (most recent call last):
  File "/opt/conda/envs/rapids/lib/python3.10/site-packages/distributed/utils.py", line 795, in wrapper
    return await func(*args, **kwargs)
  File "/opt/conda/envs/rapids/lib/python3.10/site-packages/distributed/worker.py", line 1558, in close
    await r.close_gracefully(reason=reason)
  File "/opt/conda/envs/rapids/lib/python3.10/site-packages/distributed/core.py", line 1374, in send_recv_from_rpc
    comm = await self.pool.connect(self.addr)
  File "/opt/conda/envs/rapids/lib/python3.10/site-packages/distributed/core.py", line 1620, in connect
    return await connect_attempt
  File "/opt/conda/envs/rapids/lib/python3.10/site-packages/distributed/core.py", line 1539, in _connect
    comm = await connect(
  File "/opt/conda/envs/rapids/lib/python3.10/site-packages/distributed/comm/core.py", line 397, in connect
    raise OSError(
OSError: Timed out during handshake while connecting to tcp://10.120.104.11:36583 after 100 s
2023-06-26 18:18:04,536 - distributed.worker - ERROR - Timed out during handshake while connecting to tcp://10.120.104.11:42109 after 100 s
Traceback (most recent call last):
  File "/opt/conda/envs/rapids/lib/python3.10/asyncio/runners.py", line 44, in run
    return loop.run_until_complete(main)
  File "/opt/conda/envs/rapids/lib/python3.10/asyncio/base_events.py", line 636, in run_until_complete
    self.run_forever()
  File "/opt/conda/envs/rapids/lib/python3.10/asyncio/base_events.py", line 603, in run_forever
    self._run_once()
  File "/opt/conda/envs/rapids/lib/python3.10/asyncio/base_events.py", line 1871, in _run_once
    event_list = self._selector.select(timeout)
  File "/opt/conda/envs/rapids/lib/python3.10/selectors.py", line 469, in select
    fd_event_list = self._selector.poll(timeout, max_ev)
KeyboardInterrupt

During handling of the above exception, another exception occurred:

Traceback (most recent call last):
  File "/opt/conda/envs/rapids/lib/python3.10/site-packages/tornado/iostream.py", line 861, in _read_to_buffer
    bytes_read = self.read_from_fd(buf)
  File "/opt/conda/envs/rapids/lib/python3.10/site-packages/tornado/iostream.py", line 1116, in read_from_fd
    return self.socket.recv_into(buf, len(buf))
ConnectionResetError: [Errno 104] Connection reset by peer

The above exception was the direct cause of the following exception:

Traceback (most recent call last):
  File "/opt/conda/envs/rapids/lib/python3.10/site-packages/distributed/comm/core.py", line 392, in connect
    handshake = await wait_for(comm.read(), time_left())
  File "/opt/conda/envs/rapids/lib/python3.10/site-packages/distributed/utils.py", line 1919, in wait_for
    return await asyncio.wait_for(fut, timeout)
  File "/opt/conda/envs/rapids/lib/python3.10/asyncio/tasks.py", line 445, in wait_for
    return fut.result()
  File "/opt/conda/envs/rapids/lib/python3.10/site-packages/distributed/comm/tcp.py", line 241, in read
    convert_stream_closed_error(self, e)
  File "/opt/conda/envs/rapids/lib/python3.10/site-packages/distributed/comm/tcp.py", line 142, in convert_stream_closed_error
    raise CommClosedError(f"in {obj}: {exc.__class__.__name__}: {exc}") from exc
distributed.comm.core.CommClosedError: in <TCP (closed)  local=tcp://10.120.104.11:47062 remote=tcp://10.120.104.11:42109>: ConnectionResetError: [Errno 104] Connection reset by peer

The above exception was the direct cause of the following exception:

Traceback (most recent call last):
  File "/opt/conda/envs/rapids/lib/python3.10/site-packages/distributed/utils.py", line 795, in wrapper
    return await func(*args, **kwargs)
  File "/opt/conda/envs/rapids/lib/python3.10/site-packages/distributed/worker.py", line 1558, in close
    await r.close_gracefully(reason=reason)
  File "/opt/conda/envs/rapids/lib/python3.10/site-packages/distributed/core.py", line 1374, in send_recv_from_rpc
    comm = await self.pool.connect(self.addr)
  File "/opt/conda/envs/rapids/lib/python3.10/site-packages/distributed/core.py", line 1620, in connect
    return await connect_attempt
  File "/opt/conda/envs/rapids/lib/python3.10/site-packages/distributed/core.py", line 1539, in _connect
    comm = await connect(
  File "/opt/conda/envs/rapids/lib/python3.10/site-packages/distributed/comm/core.py", line 397, in connect
    raise OSError(
OSError: Timed out during handshake while connecting to tcp://10.120.104.11:42109 after 100 s
2023-06-26 18:18:07,361 - distributed.nanny - WARNING - Worker process still alive after 3.1999841308593755 seconds, killing
2023-06-26 18:18:07,361 - distributed.nanny - WARNING - Worker process still alive after 3.1999992370605472 seconds, killing
2023-06-26 18:18:07,362 - distributed.nanny - WARNING - Worker process still alive after 3.1999995422363288 seconds, killing
2023-06-26 18:18:07,362 - distributed.nanny - WARNING - Worker process still alive after 3.199999694824219 seconds, killing
2023-06-26 18:18:07,362 - distributed.nanny - WARNING - Worker process still alive after 3.199999694824219 seconds, killing
2023-06-26 18:18:07,363 - distributed.nanny - WARNING - Worker process still alive after 3.199999694824219 seconds, killing
2023-06-26 18:18:07,363 - distributed.nanny - WARNING - Worker process still alive after 3.199999694824219 seconds, killing
2023-06-26 18:18:07,363 - distributed.nanny - WARNING - Worker process still alive after 3.199999694824219 seconds, killing
2023-06-26 18:18:07,364 - distributed.nanny - WARNING - Worker process still alive after 3.199999694824219 seconds, killing
2023-06-26 18:18:07,364 - distributed.nanny - WARNING - Worker process still alive after 3.19999984741211 seconds, killing
2023-06-26 18:18:07,364 - distributed.nanny - WARNING - Worker process still alive after 3.1999995422363288 seconds, killing
2023-06-26 18:18:07,364 - distributed.nanny - WARNING - Worker process still alive after 3.19999984741211 seconds, killing
2023-06-26 18:18:07,365 - distributed.nanny - WARNING - Worker process still alive after 3.199999694824219 seconds, killing
2023-06-26 18:18:07,365 - distributed.nanny - WARNING - Worker process still alive after 3.199999694824219 seconds, killing
2023-06-26 18:18:07,365 - distributed.nanny - WARNING - Worker process still alive after 3.19999984741211 seconds, killing
2023-06-26 18:18:07,366 - distributed.nanny - WARNING - Worker process still alive after 3.1999995422363288 seconds, killing
2023-06-26 18:18:08,164 - distributed.nanny - ERROR - Error in Nanny killing Worker subprocess
Traceback (most recent call last):
  File "/opt/conda/envs/rapids/lib/python3.10/asyncio/tasks.py", line 456, in wait_for
    return fut.result()
asyncio.exceptions.CancelledError

The above exception was the direct cause of the following exception:

Traceback (most recent call last):
  File "/opt/conda/envs/rapids/lib/python3.10/site-packages/distributed/nanny.py", line 597, in close
    await self.kill(timeout=timeout, reason=reason)
  File "/opt/conda/envs/rapids/lib/python3.10/site-packages/distributed/nanny.py", line 380, in kill
    await self.process.kill(reason=reason, timeout=0.8 * (deadline - time()))
  File "/opt/conda/envs/rapids/lib/python3.10/site-packages/distributed/nanny.py", line 853, in kill
    await process.join(max(0, deadline - time()))
  File "/opt/conda/envs/rapids/lib/python3.10/site-packages/distributed/process.py", line 330, in join
    await wait_for(asyncio.shield(self._exit_future), timeout)
  File "/opt/conda/envs/rapids/lib/python3.10/site-packages/distributed/utils.py", line 1919, in wait_for
    return await asyncio.wait_for(fut, timeout)
  File "/opt/conda/envs/rapids/lib/python3.10/asyncio/tasks.py", line 458, in wait_for
    raise exceptions.TimeoutError() from exc
asyncio.exceptions.TimeoutError
2023-06-26 18:18:08,165 - distributed.nanny - ERROR - Error in Nanny killing Worker subprocess
Traceback (most recent call last):
  File "/opt/conda/envs/rapids/lib/python3.10/asyncio/tasks.py", line 456, in wait_for
    return fut.result()
asyncio.exceptions.CancelledError

The above exception was the direct cause of the following exception:

Traceback (most recent call last):
  File "/opt/conda/envs/rapids/lib/python3.10/site-packages/distributed/nanny.py", line 597, in close
    await self.kill(timeout=timeout, reason=reason)
  File "/opt/conda/envs/rapids/lib/python3.10/site-packages/distributed/nanny.py", line 380, in kill
    await self.process.kill(reason=reason, timeout=0.8 * (deadline - time()))
  File "/opt/conda/envs/rapids/lib/python3.10/site-packages/distributed/nanny.py", line 853, in kill
    await process.join(max(0, deadline - time()))
  File "/opt/conda/envs/rapids/lib/python3.10/site-packages/distributed/process.py", line 330, in join
    await wait_for(asyncio.shield(self._exit_future), timeout)
  File "/opt/conda/envs/rapids/lib/python3.10/site-packages/distributed/utils.py", line 1919, in wait_for
    return await asyncio.wait_for(fut, timeout)
  File "/opt/conda/envs/rapids/lib/python3.10/asyncio/tasks.py", line 458, in wait_for
    raise exceptions.TimeoutError() from exc
asyncio.exceptions.TimeoutError
2023-06-26 18:18:08,165 - distributed.nanny - ERROR - Error in Nanny killing Worker subprocess
Traceback (most recent call last):
  File "/opt/conda/envs/rapids/lib/python3.10/asyncio/tasks.py", line 456, in wait_for
    return fut.result()
asyncio.exceptions.CancelledError

The above exception was the direct cause of the following exception:

Traceback (most recent call last):
  File "/opt/conda/envs/rapids/lib/python3.10/site-packages/distributed/nanny.py", line 597, in close
    await self.kill(timeout=timeout, reason=reason)
  File "/opt/conda/envs/rapids/lib/python3.10/site-packages/distributed/nanny.py", line 380, in kill
    await self.process.kill(reason=reason, timeout=0.8 * (deadline - time()))
  File "/opt/conda/envs/rapids/lib/python3.10/site-packages/distributed/nanny.py", line 853, in kill
    await process.join(max(0, deadline - time()))
  File "/opt/conda/envs/rapids/lib/python3.10/site-packages/distributed/process.py", line 330, in join
    await wait_for(asyncio.shield(self._exit_future), timeout)
  File "/opt/conda/envs/rapids/lib/python3.10/site-packages/distributed/utils.py", line 1919, in wait_for
    return await asyncio.wait_for(fut, timeout)
  File "/opt/conda/envs/rapids/lib/python3.10/asyncio/tasks.py", line 458, in wait_for
    raise exceptions.TimeoutError() from exc
asyncio.exceptions.TimeoutError
2023-06-26 18:18:08,166 - distributed.nanny - ERROR - Error in Nanny killing Worker subprocess
Traceback (most recent call last):
  File "/opt/conda/envs/rapids/lib/python3.10/asyncio/tasks.py", line 456, in wait_for
    return fut.result()
asyncio.exceptions.CancelledError

The above exception was the direct cause of the following exception:

Traceback (most recent call last):
  File "/opt/conda/envs/rapids/lib/python3.10/site-packages/distributed/nanny.py", line 597, in close
    await self.kill(timeout=timeout, reason=reason)
  File "/opt/conda/envs/rapids/lib/python3.10/site-packages/distributed/nanny.py", line 380, in kill
    await self.process.kill(reason=reason, timeout=0.8 * (deadline - time()))
  File "/opt/conda/envs/rapids/lib/python3.10/site-packages/distributed/nanny.py", line 853, in kill
    await process.join(max(0, deadline - time()))
  File "/opt/conda/envs/rapids/lib/python3.10/site-packages/distributed/process.py", line 330, in join
    await wait_for(asyncio.shield(self._exit_future), timeout)
  File "/opt/conda/envs/rapids/lib/python3.10/site-packages/distributed/utils.py", line 1919, in wait_for
    return await asyncio.wait_for(fut, timeout)
  File "/opt/conda/envs/rapids/lib/python3.10/asyncio/tasks.py", line 458, in wait_for
    raise exceptions.TimeoutError() from exc
asyncio.exceptions.TimeoutError
2023-06-26 18:18:08,166 - distributed.nanny - ERROR - Error in Nanny killing Worker subprocess
Traceback (most recent call last):
  File "/opt/conda/envs/rapids/lib/python3.10/asyncio/tasks.py", line 456, in wait_for
    return fut.result()
asyncio.exceptions.CancelledError

The above exception was the direct cause of the following exception:

Traceback (most recent call last):
  File "/opt/conda/envs/rapids/lib/python3.10/site-packages/distributed/nanny.py", line 597, in close
    await self.kill(timeout=timeout, reason=reason)
  File "/opt/conda/envs/rapids/lib/python3.10/site-packages/distributed/nanny.py", line 380, in kill
    await self.process.kill(reason=reason, timeout=0.8 * (deadline - time()))
  File "/opt/conda/envs/rapids/lib/python3.10/site-packages/distributed/nanny.py", line 853, in kill
    await process.join(max(0, deadline - time()))
  File "/opt/conda/envs/rapids/lib/python3.10/site-packages/distributed/process.py", line 330, in join
    await wait_for(asyncio.shield(self._exit_future), timeout)
  File "/opt/conda/envs/rapids/lib/python3.10/site-packages/distributed/utils.py", line 1919, in wait_for
    return await asyncio.wait_for(fut, timeout)
  File "/opt/conda/envs/rapids/lib/python3.10/asyncio/tasks.py", line 458, in wait_for
    raise exceptions.TimeoutError() from exc
asyncio.exceptions.TimeoutError
2023-06-26 18:18:08,166 - distributed.nanny - ERROR - Error in Nanny killing Worker subprocess
Traceback (most recent call last):
  File "/opt/conda/envs/rapids/lib/python3.10/asyncio/tasks.py", line 456, in wait_for
    return fut.result()
asyncio.exceptions.CancelledError

The above exception was the direct cause of the following exception:

Traceback (most recent call last):
  File "/opt/conda/envs/rapids/lib/python3.10/site-packages/distributed/nanny.py", line 597, in close
    await self.kill(timeout=timeout, reason=reason)
  File "/opt/conda/envs/rapids/lib/python3.10/site-packages/distributed/nanny.py", line 380, in kill
    await self.process.kill(reason=reason, timeout=0.8 * (deadline - time()))
  File "/opt/conda/envs/rapids/lib/python3.10/site-packages/distributed/nanny.py", line 853, in kill
    await process.join(max(0, deadline - time()))
  File "/opt/conda/envs/rapids/lib/python3.10/site-packages/distributed/process.py", line 330, in join
    await wait_for(asyncio.shield(self._exit_future), timeout)
  File "/opt/conda/envs/rapids/lib/python3.10/site-packages/distributed/utils.py", line 1919, in wait_for
    return await asyncio.wait_for(fut, timeout)
  File "/opt/conda/envs/rapids/lib/python3.10/asyncio/tasks.py", line 458, in wait_for
    raise exceptions.TimeoutError() from exc
asyncio.exceptions.TimeoutError
2023-06-26 18:18:08,166 - distributed.nanny - ERROR - Error in Nanny killing Worker subprocess
Traceback (most recent call last):
  File "/opt/conda/envs/rapids/lib/python3.10/asyncio/tasks.py", line 456, in wait_for
    return fut.result()
asyncio.exceptions.CancelledError

The above exception was the direct cause of the following exception:

Traceback (most recent call last):
  File "/opt/conda/envs/rapids/lib/python3.10/site-packages/distributed/nanny.py", line 597, in close
    await self.kill(timeout=timeout, reason=reason)
  File "/opt/conda/envs/rapids/lib/python3.10/site-packages/distributed/nanny.py", line 380, in kill
    await self.process.kill(reason=reason, timeout=0.8 * (deadline - time()))
  File "/opt/conda/envs/rapids/lib/python3.10/site-packages/distributed/nanny.py", line 853, in kill
    await process.join(max(0, deadline - time()))
  File "/opt/conda/envs/rapids/lib/python3.10/site-packages/distributed/process.py", line 330, in join
    await wait_for(asyncio.shield(self._exit_future), timeout)
  File "/opt/conda/envs/rapids/lib/python3.10/site-packages/distributed/utils.py", line 1919, in wait_for
    return await asyncio.wait_for(fut, timeout)
  File "/opt/conda/envs/rapids/lib/python3.10/asyncio/tasks.py", line 458, in wait_for
    raise exceptions.TimeoutError() from exc
asyncio.exceptions.TimeoutError
2023-06-26 18:18:08,166 - distributed.nanny - ERROR - Error in Nanny killing Worker subprocess
Traceback (most recent call last):
  File "/opt/conda/envs/rapids/lib/python3.10/asyncio/tasks.py", line 456, in wait_for
    return fut.result()
asyncio.exceptions.CancelledError

The above exception was the direct cause of the following exception:

Traceback (most recent call last):
  File "/opt/conda/envs/rapids/lib/python3.10/site-packages/distributed/nanny.py", line 597, in close
    await self.kill(timeout=timeout, reason=reason)
  File "/opt/conda/envs/rapids/lib/python3.10/site-packages/distributed/nanny.py", line 380, in kill
    await self.process.kill(reason=reason, timeout=0.8 * (deadline - time()))
  File "/opt/conda/envs/rapids/lib/python3.10/site-packages/distributed/nanny.py", line 853, in kill
    await process.join(max(0, deadline - time()))
  File "/opt/conda/envs/rapids/lib/python3.10/site-packages/distributed/process.py", line 330, in join
    await wait_for(asyncio.shield(self._exit_future), timeout)
  File "/opt/conda/envs/rapids/lib/python3.10/site-packages/distributed/utils.py", line 1919, in wait_for
    return await asyncio.wait_for(fut, timeout)
  File "/opt/conda/envs/rapids/lib/python3.10/asyncio/tasks.py", line 458, in wait_for
    raise exceptions.TimeoutError() from exc
asyncio.exceptions.TimeoutError
2023-06-26 18:18:08,166 - distributed.nanny - ERROR - Error in Nanny killing Worker subprocess
Traceback (most recent call last):
  File "/opt/conda/envs/rapids/lib/python3.10/asyncio/tasks.py", line 456, in wait_for
    return fut.result()
asyncio.exceptions.CancelledError

The above exception was the direct cause of the following exception:

Traceback (most recent call last):
  File "/opt/conda/envs/rapids/lib/python3.10/site-packages/distributed/nanny.py", line 597, in close
    await self.kill(timeout=timeout, reason=reason)
  File "/opt/conda/envs/rapids/lib/python3.10/site-packages/distributed/nanny.py", line 380, in kill
    await self.process.kill(reason=reason, timeout=0.8 * (deadline - time()))
  File "/opt/conda/envs/rapids/lib/python3.10/site-packages/distributed/nanny.py", line 853, in kill
    await process.join(max(0, deadline - time()))
  File "/opt/conda/envs/rapids/lib/python3.10/site-packages/distributed/process.py", line 330, in join
    await wait_for(asyncio.shield(self._exit_future), timeout)
  File "/opt/conda/envs/rapids/lib/python3.10/site-packages/distributed/utils.py", line 1919, in wait_for
    return await asyncio.wait_for(fut, timeout)
  File "/opt/conda/envs/rapids/lib/python3.10/asyncio/tasks.py", line 458, in wait_for
    raise exceptions.TimeoutError() from exc
asyncio.exceptions.TimeoutError
2023-06-26 18:18:08,167 - distributed.nanny - ERROR - Error in Nanny killing Worker subprocess
Traceback (most recent call last):
  File "/opt/conda/envs/rapids/lib/python3.10/asyncio/tasks.py", line 456, in wait_for
    return fut.result()
asyncio.exceptions.CancelledError

The above exception was the direct cause of the following exception:

Traceback (most recent call last):
  File "/opt/conda/envs/rapids/lib/python3.10/site-packages/distributed/nanny.py", line 597, in close
    await self.kill(timeout=timeout, reason=reason)
  File "/opt/conda/envs/rapids/lib/python3.10/site-packages/distributed/nanny.py", line 380, in kill
    await self.process.kill(reason=reason, timeout=0.8 * (deadline - time()))
  File "/opt/conda/envs/rapids/lib/python3.10/site-packages/distributed/nanny.py", line 853, in kill
    await process.join(max(0, deadline - time()))
  File "/opt/conda/envs/rapids/lib/python3.10/site-packages/distributed/process.py", line 330, in join
    await wait_for(asyncio.shield(self._exit_future), timeout)
  File "/opt/conda/envs/rapids/lib/python3.10/site-packages/distributed/utils.py", line 1919, in wait_for
    return await asyncio.wait_for(fut, timeout)
  File "/opt/conda/envs/rapids/lib/python3.10/asyncio/tasks.py", line 458, in wait_for
    raise exceptions.TimeoutError() from exc
asyncio.exceptions.TimeoutError
2023-06-26 18:18:08,167 - distributed.nanny - ERROR - Error in Nanny killing Worker subprocess
Traceback (most recent call last):
  File "/opt/conda/envs/rapids/lib/python3.10/asyncio/tasks.py", line 456, in wait_for
    return fut.result()
asyncio.exceptions.CancelledError

The above exception was the direct cause of the following exception:

Traceback (most recent call last):
  File "/opt/conda/envs/rapids/lib/python3.10/site-packages/distributed/nanny.py", line 597, in close
    await self.kill(timeout=timeout, reason=reason)
  File "/opt/conda/envs/rapids/lib/python3.10/site-packages/distributed/nanny.py", line 380, in kill
    await self.process.kill(reason=reason, timeout=0.8 * (deadline - time()))
  File "/opt/conda/envs/rapids/lib/python3.10/site-packages/distributed/nanny.py", line 853, in kill
    await process.join(max(0, deadline - time()))
  File "/opt/conda/envs/rapids/lib/python3.10/site-packages/distributed/process.py", line 330, in join
    await wait_for(asyncio.shield(self._exit_future), timeout)
  File "/opt/conda/envs/rapids/lib/python3.10/site-packages/distributed/utils.py", line 1919, in wait_for
    return await asyncio.wait_for(fut, timeout)
  File "/opt/conda/envs/rapids/lib/python3.10/asyncio/tasks.py", line 458, in wait_for
    raise exceptions.TimeoutError() from exc
asyncio.exceptions.TimeoutError
2023-06-26 18:18:08,167 - distributed.nanny - ERROR - Error in Nanny killing Worker subprocess
Traceback (most recent call last):
  File "/opt/conda/envs/rapids/lib/python3.10/asyncio/tasks.py", line 456, in wait_for
    return fut.result()
asyncio.exceptions.CancelledError

The above exception was the direct cause of the following exception:

Traceback (most recent call last):
  File "/opt/conda/envs/rapids/lib/python3.10/site-packages/distributed/nanny.py", line 597, in close
    await self.kill(timeout=timeout, reason=reason)
  File "/opt/conda/envs/rapids/lib/python3.10/site-packages/distributed/nanny.py", line 380, in kill
    await self.process.kill(reason=reason, timeout=0.8 * (deadline - time()))
  File "/opt/conda/envs/rapids/lib/python3.10/site-packages/distributed/nanny.py", line 853, in kill
    await process.join(max(0, deadline - time()))
  File "/opt/conda/envs/rapids/lib/python3.10/site-packages/distributed/process.py", line 330, in join
    await wait_for(asyncio.shield(self._exit_future), timeout)
  File "/opt/conda/envs/rapids/lib/python3.10/site-packages/distributed/utils.py", line 1919, in wait_for
    return await asyncio.wait_for(fut, timeout)
  File "/opt/conda/envs/rapids/lib/python3.10/asyncio/tasks.py", line 458, in wait_for
    raise exceptions.TimeoutError() from exc
asyncio.exceptions.TimeoutError
2023-06-26 18:18:08,167 - distributed.nanny - ERROR - Error in Nanny killing Worker subprocess
Traceback (most recent call last):
  File "/opt/conda/envs/rapids/lib/python3.10/asyncio/tasks.py", line 456, in wait_for
    return fut.result()
asyncio.exceptions.CancelledError

The above exception was the direct cause of the following exception:

Traceback (most recent call last):
  File "/opt/conda/envs/rapids/lib/python3.10/site-packages/distributed/nanny.py", line 597, in close
    await self.kill(timeout=timeout, reason=reason)
  File "/opt/conda/envs/rapids/lib/python3.10/site-packages/distributed/nanny.py", line 380, in kill
    await self.process.kill(reason=reason, timeout=0.8 * (deadline - time()))
  File "/opt/conda/envs/rapids/lib/python3.10/site-packages/distributed/nanny.py", line 853, in kill
    await process.join(max(0, deadline - time()))
  File "/opt/conda/envs/rapids/lib/python3.10/site-packages/distributed/process.py", line 330, in join
    await wait_for(asyncio.shield(self._exit_future), timeout)
  File "/opt/conda/envs/rapids/lib/python3.10/site-packages/distributed/utils.py", line 1919, in wait_for
    return await asyncio.wait_for(fut, timeout)
  File "/opt/conda/envs/rapids/lib/python3.10/asyncio/tasks.py", line 458, in wait_for
    raise exceptions.TimeoutError() from exc
asyncio.exceptions.TimeoutError
2023-06-26 18:18:08,167 - distributed.nanny - ERROR - Error in Nanny killing Worker subprocess
Traceback (most recent call last):
  File "/opt/conda/envs/rapids/lib/python3.10/asyncio/tasks.py", line 456, in wait_for
    return fut.result()
asyncio.exceptions.CancelledError

The above exception was the direct cause of the following exception:

Traceback (most recent call last):
  File "/opt/conda/envs/rapids/lib/python3.10/site-packages/distributed/nanny.py", line 597, in close
    await self.kill(timeout=timeout, reason=reason)
  File "/opt/conda/envs/rapids/lib/python3.10/site-packages/distributed/nanny.py", line 380, in kill
    await self.process.kill(reason=reason, timeout=0.8 * (deadline - time()))
  File "/opt/conda/envs/rapids/lib/python3.10/site-packages/distributed/nanny.py", line 853, in kill
    await process.join(max(0, deadline - time()))
  File "/opt/conda/envs/rapids/lib/python3.10/site-packages/distributed/process.py", line 330, in join
    await wait_for(asyncio.shield(self._exit_future), timeout)
  File "/opt/conda/envs/rapids/lib/python3.10/site-packages/distributed/utils.py", line 1919, in wait_for
    return await asyncio.wait_for(fut, timeout)
  File "/opt/conda/envs/rapids/lib/python3.10/asyncio/tasks.py", line 458, in wait_for
    raise exceptions.TimeoutError() from exc
asyncio.exceptions.TimeoutError
2023-06-26 18:18:08,167 - distributed.nanny - ERROR - Error in Nanny killing Worker subprocess
Traceback (most recent call last):
  File "/opt/conda/envs/rapids/lib/python3.10/asyncio/tasks.py", line 456, in wait_for
    return fut.result()
asyncio.exceptions.CancelledError

The above exception was the direct cause of the following exception:

Traceback (most recent call last):
  File "/opt/conda/envs/rapids/lib/python3.10/site-packages/distributed/nanny.py", line 597, in close
    await self.kill(timeout=timeout, reason=reason)
  File "/opt/conda/envs/rapids/lib/python3.10/site-packages/distributed/nanny.py", line 380, in kill
    await self.process.kill(reason=reason, timeout=0.8 * (deadline - time()))
  File "/opt/conda/envs/rapids/lib/python3.10/site-packages/distributed/nanny.py", line 853, in kill
    await process.join(max(0, deadline - time()))
  File "/opt/conda/envs/rapids/lib/python3.10/site-packages/distributed/process.py", line 330, in join
    await wait_for(asyncio.shield(self._exit_future), timeout)
  File "/opt/conda/envs/rapids/lib/python3.10/site-packages/distributed/utils.py", line 1919, in wait_for
    return await asyncio.wait_for(fut, timeout)
  File "/opt/conda/envs/rapids/lib/python3.10/asyncio/tasks.py", line 458, in wait_for
    raise exceptions.TimeoutError() from exc
asyncio.exceptions.TimeoutError
2023-06-26 18:18:08,168 - distributed.nanny - ERROR - Error in Nanny killing Worker subprocess
Traceback (most recent call last):
  File "/opt/conda/envs/rapids/lib/python3.10/asyncio/tasks.py", line 456, in wait_for
    return fut.result()
asyncio.exceptions.CancelledError

The above exception was the direct cause of the following exception:

Traceback (most recent call last):
  File "/opt/conda/envs/rapids/lib/python3.10/site-packages/distributed/nanny.py", line 597, in close
    await self.kill(timeout=timeout, reason=reason)
  File "/opt/conda/envs/rapids/lib/python3.10/site-packages/distributed/nanny.py", line 380, in kill
    await self.process.kill(reason=reason, timeout=0.8 * (deadline - time()))
  File "/opt/conda/envs/rapids/lib/python3.10/site-packages/distributed/nanny.py", line 853, in kill
    await process.join(max(0, deadline - time()))
  File "/opt/conda/envs/rapids/lib/python3.10/site-packages/distributed/process.py", line 330, in join
    await wait_for(asyncio.shield(self._exit_future), timeout)
  File "/opt/conda/envs/rapids/lib/python3.10/site-packages/distributed/utils.py", line 1919, in wait_for
    return await asyncio.wait_for(fut, timeout)
  File "/opt/conda/envs/rapids/lib/python3.10/asyncio/tasks.py", line 458, in wait_for
    raise exceptions.TimeoutError() from exc
asyncio.exceptions.TimeoutError
2023-06-26 18:18:08,170 - distributed.process - INFO - reaping stray process <SpawnProcess name='Dask Worker process (from Nanny)' pid=358913 parent=358836 started daemon>
2023-06-26 18:18:08,170 - distributed.process - INFO - reaping stray process <SpawnProcess name='Dask Worker process (from Nanny)' pid=358910 parent=358836 started daemon>
2023-06-26 18:18:08,170 - distributed.process - INFO - reaping stray process <SpawnProcess name='Dask Worker process (from Nanny)' pid=358908 parent=358836 started daemon>
2023-06-26 18:18:08,170 - distributed.process - INFO - reaping stray process <SpawnProcess name='Dask Worker process (from Nanny)' pid=358905 parent=358836 started daemon>
2023-06-26 18:18:08,170 - distributed.process - INFO - reaping stray process <SpawnProcess name='Dask Worker process (from Nanny)' pid=358901 parent=358836 started daemon>
2023-06-26 18:18:08,170 - distributed.process - INFO - reaping stray process <SpawnProcess name='Dask Worker process (from Nanny)' pid=358897 parent=358836 started daemon>
2023-06-26 18:18:08,170 - distributed.process - INFO - reaping stray process <SpawnProcess name='Dask Worker process (from Nanny)' pid=358896 parent=358836 started daemon>
2023-06-26 18:18:08,170 - distributed.process - INFO - reaping stray process <SpawnProcess name='Dask Worker process (from Nanny)' pid=358893 parent=358836 started daemon>
2023-06-26 18:18:08,171 - distributed.process - INFO - reaping stray process <SpawnProcess name='Dask Worker process (from Nanny)' pid=358889 parent=358836 started daemon>
2023-06-26 18:18:08,171 - distributed.process - INFO - reaping stray process <SpawnProcess name='Dask Worker process (from Nanny)' pid=358887 parent=358836 started daemon>
2023-06-26 18:18:08,171 - distributed.process - INFO - reaping stray process <SpawnProcess name='Dask Worker process (from Nanny)' pid=358884 parent=358836 started daemon>
2023-06-26 18:18:08,171 - distributed.process - INFO - reaping stray process <SpawnProcess name='Dask Worker process (from Nanny)' pid=358880 parent=358836 started daemon>
2023-06-26 18:18:08,171 - distributed.process - INFO - reaping stray process <SpawnProcess name='Dask Worker process (from Nanny)' pid=358877 parent=358836 started daemon>
2023-06-26 18:18:08,171 - distributed.process - INFO - reaping stray process <SpawnProcess name='Dask Worker process (from Nanny)' pid=358874 parent=358836 started daemon>
2023-06-26 18:18:08,171 - distributed.process - INFO - reaping stray process <SpawnProcess name='Dask Worker process (from Nanny)' pid=358871 parent=358836 started daemon>
2023-06-26 18:18:08,171 - distributed.process - INFO - reaping stray process <SpawnProcess name='Dask Worker process (from Nanny)' pid=358868 parent=358836 started daemon>
2023-06-26 18:18:10,558 - distributed.process - WARNING - [<AsyncProcess Dask Worker process (from Nanny)>] process 358874 exit status was already read will report exitcode 255
2023-06-26 18:18:10,896 - distributed.process - WARNING - [<AsyncProcess Dask Worker process (from Nanny)>] process 358893 exit status was already read will report exitcode 255
2023-06-26 18:18:11,198 - distributed.process - WARNING - [<AsyncProcess Dask Worker process (from Nanny)>] process 358897 exit status was already read will report exitcode 255
2023-06-26 18:18:11,354 - distributed.process - WARNING - [<AsyncProcess Dask Worker process (from Nanny)>] process 358913 exit status was already read will report exitcode 255
2023-06-26 18:18:11,511 - distributed.process - WARNING - [<AsyncProcess Dask Worker process (from Nanny)>] process 358901 exit status was already read will report exitcode 255
2023-06-26 18:18:12,313 - distributed.process - WARNING - [<AsyncProcess Dask Worker process (from Nanny)>] process 358868 exit status was already read will report exitcode 255
