RUNNING: "python -m dask_cuda.cli.dask_cuda_worker --rmm-pool-size=12G
             --local-directory=/tmp/
             --scheduler-file=/root/work/cugraph/mg_utils/dask-scheduler.json
             --memory-limit=auto
             --device-memory-limit=auto
            "
2023-06-22 22:38:58,237 - distributed.nanny - INFO -         Start Nanny at: 'tcp://10.33.227.169:38437'
2023-06-22 22:38:58,242 - distributed.nanny - INFO -         Start Nanny at: 'tcp://10.33.227.169:44235'
2023-06-22 22:38:58,244 - distributed.nanny - INFO -         Start Nanny at: 'tcp://10.33.227.169:37075'
2023-06-22 22:38:58,247 - distributed.nanny - INFO -         Start Nanny at: 'tcp://10.33.227.169:37607'
2023-06-22 22:38:58,249 - distributed.nanny - INFO -         Start Nanny at: 'tcp://10.33.227.169:35333'
2023-06-22 22:38:58,253 - distributed.nanny - INFO -         Start Nanny at: 'tcp://10.33.227.169:41197'
2023-06-22 22:38:58,254 - distributed.nanny - INFO -         Start Nanny at: 'tcp://10.33.227.169:32867'
2023-06-22 22:38:58,257 - distributed.nanny - INFO -         Start Nanny at: 'tcp://10.33.227.169:36435'
2023-06-22 22:38:59,680 - distributed.preloading - INFO - Creating preload: dask_cuda.initialize
2023-06-22 22:38:59,680 - distributed.preloading - INFO - Import preload module: dask_cuda.initialize
2023-06-22 22:38:59,764 - distributed.preloading - INFO - Creating preload: dask_cuda.initialize
2023-06-22 22:38:59,764 - distributed.preloading - INFO - Import preload module: dask_cuda.initialize
2023-06-22 22:38:59,765 - distributed.preloading - INFO - Creating preload: dask_cuda.initialize
2023-06-22 22:38:59,765 - distributed.preloading - INFO - Import preload module: dask_cuda.initialize
2023-06-22 22:38:59,775 - distributed.preloading - INFO - Creating preload: dask_cuda.initialize
2023-06-22 22:38:59,775 - distributed.preloading - INFO - Import preload module: dask_cuda.initialize
2023-06-22 22:38:59,777 - distributed.preloading - INFO - Creating preload: dask_cuda.initialize
2023-06-22 22:38:59,777 - distributed.preloading - INFO - Import preload module: dask_cuda.initialize
2023-06-22 22:38:59,778 - distributed.preloading - INFO - Creating preload: dask_cuda.initialize
2023-06-22 22:38:59,778 - distributed.preloading - INFO - Import preload module: dask_cuda.initialize
2023-06-22 22:38:59,790 - distributed.preloading - INFO - Creating preload: dask_cuda.initialize
2023-06-22 22:38:59,790 - distributed.preloading - INFO - Import preload module: dask_cuda.initialize
2023-06-22 22:38:59,795 - distributed.preloading - INFO - Creating preload: dask_cuda.initialize
2023-06-22 22:38:59,795 - distributed.preloading - INFO - Import preload module: dask_cuda.initialize
2023-06-22 22:39:00,114 - distributed.preloading - INFO - Run preload setup: dask_cuda.initialize
2023-06-22 22:39:00,211 - distributed.preloading - INFO - Run preload setup: dask_cuda.initialize
2023-06-22 22:39:00,211 - distributed.preloading - INFO - Run preload setup: dask_cuda.initialize
2023-06-22 22:39:00,223 - distributed.preloading - INFO - Run preload setup: dask_cuda.initialize
2023-06-22 22:39:00,227 - distributed.preloading - INFO - Run preload setup: dask_cuda.initialize
2023-06-22 22:39:00,230 - distributed.preloading - INFO - Run preload setup: dask_cuda.initialize
2023-06-22 22:39:00,232 - distributed.preloading - INFO - Run preload setup: dask_cuda.initialize
2023-06-22 22:39:00,232 - distributed.preloading - INFO - Run preload setup: dask_cuda.initialize
2023-06-22 22:39:01,515 - distributed.worker - INFO -       Start worker at:  tcp://10.33.227.169:41655
2023-06-22 22:39:01,515 - distributed.worker - INFO -          Listening to:  tcp://10.33.227.169:41655
2023-06-22 22:39:01,515 - distributed.worker - INFO -          dashboard at:        10.33.227.169:43007
2023-06-22 22:39:01,515 - distributed.worker - INFO - Waiting to connect to:   tcp://10.33.227.169:8786
2023-06-22 22:39:01,515 - distributed.worker - INFO - -------------------------------------------------
2023-06-22 22:39:01,515 - distributed.worker - INFO -               Threads:                          1
2023-06-22 22:39:01,515 - distributed.worker - INFO -                Memory:                  62.97 GiB
2023-06-22 22:39:01,516 - distributed.worker - INFO -       Local Directory: /tmp/dask-scratch-space/worker-q4ynrdsk
2023-06-22 22:39:01,516 - distributed.worker - INFO - Starting Worker plugin PreImport-b760a89c-e3e9-461a-8337-979179732bf2
2023-06-22 22:39:01,516 - distributed.worker - INFO - Starting Worker plugin CPUAffinity-b7f093bf-a10a-42f9-9c20-245fdbc8c3ee
2023-06-22 22:39:01,517 - distributed.worker - INFO - Starting Worker plugin RMMSetup-71a64a3d-011f-4f0c-bf5e-d04fc266c89f
2023-06-22 22:39:01,739 - distributed.worker - INFO - -------------------------------------------------
2023-06-22 22:39:02,019 - distributed.worker - INFO -         Registered to:   tcp://10.33.227.169:8786
2023-06-22 22:39:02,019 - distributed.worker - INFO - -------------------------------------------------
2023-06-22 22:39:02,022 - distributed.core - INFO - Starting established connection to tcp://10.33.227.169:8786
2023-06-22 22:39:02,567 - distributed.worker - INFO -       Start worker at:  tcp://10.33.227.169:36837
2023-06-22 22:39:02,568 - distributed.worker - INFO -          Listening to:  tcp://10.33.227.169:36837
2023-06-22 22:39:02,568 - distributed.worker - INFO -          dashboard at:        10.33.227.169:35695
2023-06-22 22:39:02,568 - distributed.worker - INFO - Waiting to connect to:   tcp://10.33.227.169:8786
2023-06-22 22:39:02,568 - distributed.worker - INFO - -------------------------------------------------
2023-06-22 22:39:02,568 - distributed.worker - INFO -               Threads:                          1
2023-06-22 22:39:02,568 - distributed.worker - INFO -                Memory:                  62.97 GiB
2023-06-22 22:39:02,568 - distributed.worker - INFO -       Local Directory: /tmp/dask-scratch-space/worker-0d2u_aa8
2023-06-22 22:39:02,568 - distributed.worker - INFO - Starting Worker plugin RMMSetup-e49053d5-b56e-4f33-8e08-3daf643be2a6
2023-06-22 22:39:02,575 - distributed.worker - INFO -       Start worker at:  tcp://10.33.227.169:45291
2023-06-22 22:39:02,575 - distributed.worker - INFO -          Listening to:  tcp://10.33.227.169:45291
2023-06-22 22:39:02,575 - distributed.worker - INFO -          dashboard at:        10.33.227.169:45977
2023-06-22 22:39:02,575 - distributed.worker - INFO - Waiting to connect to:   tcp://10.33.227.169:8786
2023-06-22 22:39:02,575 - distributed.worker - INFO - -------------------------------------------------
2023-06-22 22:39:02,575 - distributed.worker - INFO -               Threads:                          1
2023-06-22 22:39:02,575 - distributed.worker - INFO -                Memory:                  62.97 GiB
2023-06-22 22:39:02,575 - distributed.worker - INFO -       Local Directory: /tmp/dask-scratch-space/worker-ftgfz8yh
2023-06-22 22:39:02,576 - distributed.worker - INFO - Starting Worker plugin PreImport-05ef2ecf-afbb-434e-9e80-a8b82f1e7178
2023-06-22 22:39:02,576 - distributed.worker - INFO - Starting Worker plugin CPUAffinity-3db01ed5-b9ee-49d0-a394-5b7d79295768
2023-06-22 22:39:02,576 - distributed.worker - INFO - Starting Worker plugin RMMSetup-fe91bcb0-e14e-4c0d-9e0d-ab09666ad69c
2023-06-22 22:39:02,577 - distributed.worker - INFO -       Start worker at:  tcp://10.33.227.169:40447
2023-06-22 22:39:02,577 - distributed.worker - INFO -          Listening to:  tcp://10.33.227.169:40447
2023-06-22 22:39:02,577 - distributed.worker - INFO -          dashboard at:        10.33.227.169:35803
2023-06-22 22:39:02,578 - distributed.worker - INFO - Waiting to connect to:   tcp://10.33.227.169:8786
2023-06-22 22:39:02,578 - distributed.worker - INFO - -------------------------------------------------
2023-06-22 22:39:02,578 - distributed.worker - INFO -               Threads:                          1
2023-06-22 22:39:02,578 - distributed.worker - INFO -                Memory:                  62.97 GiB
2023-06-22 22:39:02,578 - distributed.worker - INFO -       Local Directory: /tmp/dask-scratch-space/worker-zvesuwg9
2023-06-22 22:39:02,578 - distributed.worker - INFO - Starting Worker plugin PreImport-5ea79da8-cc0a-4156-8398-90f2ba6e5915
2023-06-22 22:39:02,578 - distributed.worker - INFO -       Start worker at:  tcp://10.33.227.169:37635
2023-06-22 22:39:02,578 - distributed.worker - INFO - Starting Worker plugin CPUAffinity-e6950b19-09bb-4c7c-bc27-c3b91b709aea
2023-06-22 22:39:02,578 - distributed.worker - INFO -          Listening to:  tcp://10.33.227.169:37635
2023-06-22 22:39:02,579 - distributed.worker - INFO -          dashboard at:        10.33.227.169:33445
2023-06-22 22:39:02,579 - distributed.worker - INFO - Waiting to connect to:   tcp://10.33.227.169:8786
2023-06-22 22:39:02,579 - distributed.worker - INFO - -------------------------------------------------
2023-06-22 22:39:02,579 - distributed.worker - INFO - Starting Worker plugin RMMSetup-526cf2f8-625b-4826-aa12-084d6b6639d3
2023-06-22 22:39:02,579 - distributed.worker - INFO -               Threads:                          1
2023-06-22 22:39:02,579 - distributed.worker - INFO -                Memory:                  62.97 GiB
2023-06-22 22:39:02,579 - distributed.worker - INFO -       Local Directory: /tmp/dask-scratch-space/worker-cw9dgv_1
2023-06-22 22:39:02,580 - distributed.worker - INFO - Starting Worker plugin PreImport-c60f7298-6c96-493e-9079-b28e7cdb4f50
2023-06-22 22:39:02,580 - distributed.worker - INFO - Starting Worker plugin CPUAffinity-354e8380-6d39-42bc-a5fc-0ae06506ddf6
2023-06-22 22:39:02,580 - distributed.worker - INFO - Starting Worker plugin RMMSetup-fe1ef7b1-5846-49a2-923b-32d32396ea50
2023-06-22 22:39:02,583 - distributed.worker - INFO -       Start worker at:  tcp://10.33.227.169:39515
2023-06-22 22:39:02,583 - distributed.worker - INFO -          Listening to:  tcp://10.33.227.169:39515
2023-06-22 22:39:02,583 - distributed.worker - INFO -          dashboard at:        10.33.227.169:36563
2023-06-22 22:39:02,583 - distributed.worker - INFO - Waiting to connect to:   tcp://10.33.227.169:8786
2023-06-22 22:39:02,583 - distributed.worker - INFO - -------------------------------------------------
2023-06-22 22:39:02,583 - distributed.worker - INFO -               Threads:                          1
2023-06-22 22:39:02,584 - distributed.worker - INFO -                Memory:                  62.97 GiB
2023-06-22 22:39:02,584 - distributed.worker - INFO -       Local Directory: /tmp/dask-scratch-space/worker-neob8xd0
2023-06-22 22:39:02,584 - distributed.worker - INFO - Starting Worker plugin RMMSetup-d510ba7b-1f4c-4d4e-b5a3-b50cb67e644d
2023-06-22 22:39:02,585 - distributed.worker - INFO -       Start worker at:  tcp://10.33.227.169:34397
2023-06-22 22:39:02,585 - distributed.worker - INFO -          Listening to:  tcp://10.33.227.169:34397
2023-06-22 22:39:02,585 - distributed.worker - INFO -          dashboard at:        10.33.227.169:46829
2023-06-22 22:39:02,585 - distributed.worker - INFO - Waiting to connect to:   tcp://10.33.227.169:8786
2023-06-22 22:39:02,585 - distributed.worker - INFO - -------------------------------------------------
2023-06-22 22:39:02,585 - distributed.worker - INFO -               Threads:                          1
2023-06-22 22:39:02,585 - distributed.worker - INFO -                Memory:                  62.97 GiB
2023-06-22 22:39:02,585 - distributed.worker - INFO -       Local Directory: /tmp/dask-scratch-space/worker-fw55cnw9
2023-06-22 22:39:02,586 - distributed.worker - INFO - Starting Worker plugin PreImport-3236d67c-a906-4acc-a381-7b29956a4997
2023-06-22 22:39:02,586 - distributed.worker - INFO - Starting Worker plugin CPUAffinity-f2a27818-e5a2-4a29-8212-e97848d28f8b
2023-06-22 22:39:02,586 - distributed.worker - INFO - Starting Worker plugin RMMSetup-776df425-c8ae-4f05-9604-d6dc19d4641c
2023-06-22 22:39:02,593 - distributed.worker - INFO -       Start worker at:  tcp://10.33.227.169:40099
2023-06-22 22:39:02,594 - distributed.worker - INFO -          Listening to:  tcp://10.33.227.169:40099
2023-06-22 22:39:02,594 - distributed.worker - INFO -          dashboard at:        10.33.227.169:41897
2023-06-22 22:39:02,594 - distributed.worker - INFO - Waiting to connect to:   tcp://10.33.227.169:8786
2023-06-22 22:39:02,594 - distributed.worker - INFO - -------------------------------------------------
2023-06-22 22:39:02,594 - distributed.worker - INFO -               Threads:                          1
2023-06-22 22:39:02,594 - distributed.worker - INFO -                Memory:                  62.97 GiB
2023-06-22 22:39:02,594 - distributed.worker - INFO -       Local Directory: /tmp/dask-scratch-space/worker-x_bncqda
2023-06-22 22:39:02,595 - distributed.worker - INFO - Starting Worker plugin RMMSetup-d1ec2e3a-a9f2-46a1-8ef7-3c55578ee355
2023-06-22 22:39:02,780 - distributed.worker - INFO - Starting Worker plugin PreImport-d51dff85-8142-4183-bb61-dbb0ec942995
2023-06-22 22:39:02,781 - distributed.worker - INFO - Starting Worker plugin CPUAffinity-c06d1b54-18cb-484d-98ed-0448389be1da
2023-06-22 22:39:02,781 - distributed.worker - INFO - Starting Worker plugin CPUAffinity-fc0a3b4c-c22d-4a7f-9edd-8cc073e96b03
2023-06-22 22:39:02,781 - distributed.worker - INFO - Starting Worker plugin PreImport-218c7f77-a9ca-48b5-aab8-abcda4ed0f22
2023-06-22 22:39:02,781 - distributed.worker - INFO - Starting Worker plugin PreImport-dc5991e0-e08f-4122-9e44-b73350fe79ed
2023-06-22 22:39:02,781 - distributed.worker - INFO - -------------------------------------------------
2023-06-22 22:39:02,781 - distributed.worker - INFO - Starting Worker plugin CPUAffinity-4945a6a7-9c46-4737-bb88-e6d6ed0df513
2023-06-22 22:39:02,781 - distributed.worker - INFO - -------------------------------------------------
2023-06-22 22:39:02,782 - distributed.worker - INFO - -------------------------------------------------
2023-06-22 22:39:02,782 - distributed.worker - INFO - -------------------------------------------------
2023-06-22 22:39:02,782 - distributed.worker - INFO - -------------------------------------------------
2023-06-22 22:39:02,782 - distributed.worker - INFO - -------------------------------------------------
2023-06-22 22:39:02,782 - distributed.worker - INFO - -------------------------------------------------
2023-06-22 22:39:02,791 - distributed.worker - INFO -         Registered to:   tcp://10.33.227.169:8786
2023-06-22 22:39:02,791 - distributed.worker - INFO - -------------------------------------------------
2023-06-22 22:39:02,792 - distributed.core - INFO - Starting established connection to tcp://10.33.227.169:8786
2023-06-22 22:39:02,792 - distributed.worker - INFO -         Registered to:   tcp://10.33.227.169:8786
2023-06-22 22:39:02,792 - distributed.worker - INFO - -------------------------------------------------
2023-06-22 22:39:02,794 - distributed.core - INFO - Starting established connection to tcp://10.33.227.169:8786
2023-06-22 22:39:02,794 - distributed.worker - INFO -         Registered to:   tcp://10.33.227.169:8786
2023-06-22 22:39:02,794 - distributed.worker - INFO - -------------------------------------------------
2023-06-22 22:39:02,795 - distributed.core - INFO - Starting established connection to tcp://10.33.227.169:8786
2023-06-22 22:39:02,796 - distributed.worker - INFO -         Registered to:   tcp://10.33.227.169:8786
2023-06-22 22:39:02,796 - distributed.worker - INFO - -------------------------------------------------
2023-06-22 22:39:02,798 - distributed.worker - INFO -         Registered to:   tcp://10.33.227.169:8786
2023-06-22 22:39:02,798 - distributed.worker - INFO - -------------------------------------------------
2023-06-22 22:39:02,798 - distributed.core - INFO - Starting established connection to tcp://10.33.227.169:8786
2023-06-22 22:39:02,800 - distributed.worker - INFO -         Registered to:   tcp://10.33.227.169:8786
2023-06-22 22:39:02,800 - distributed.worker - INFO - -------------------------------------------------
2023-06-22 22:39:02,801 - distributed.core - INFO - Starting established connection to tcp://10.33.227.169:8786
2023-06-22 22:39:02,801 - distributed.worker - INFO -         Registered to:   tcp://10.33.227.169:8786
2023-06-22 22:39:02,801 - distributed.worker - INFO - -------------------------------------------------
2023-06-22 22:39:02,802 - distributed.core - INFO - Starting established connection to tcp://10.33.227.169:8786
2023-06-22 22:39:02,804 - distributed.core - INFO - Starting established connection to tcp://10.33.227.169:8786
2023-06-22 22:39:05,185 - distributed.worker - INFO - Run out-of-band function '_func_ucp_listener_port'
2023-06-22 22:39:05,185 - distributed.worker - INFO - Run out-of-band function '_func_ucp_listener_port'
2023-06-22 22:39:05,185 - distributed.worker - INFO - Run out-of-band function '_func_ucp_listener_port'
2023-06-22 22:39:05,186 - distributed.worker - INFO - Run out-of-band function '_func_ucp_listener_port'
2023-06-22 22:39:05,186 - distributed.worker - INFO - Run out-of-band function '_func_ucp_listener_port'
2023-06-22 22:39:05,186 - distributed.worker - INFO - Run out-of-band function '_func_ucp_listener_port'
2023-06-22 22:39:05,186 - distributed.worker - INFO - Run out-of-band function '_func_ucp_listener_port'
2023-06-22 22:39:05,187 - distributed.worker - INFO - Run out-of-band function '_func_ucp_listener_port'
2023-06-22 22:39:05,262 - distributed.worker - INFO - Run out-of-band function '_func_init_all'
2023-06-22 22:39:05,262 - distributed.worker - INFO - Run out-of-band function '_func_init_all'
2023-06-22 22:39:05,262 - distributed.worker - INFO - Run out-of-band function '_func_init_all'
2023-06-22 22:39:05,262 - distributed.worker - INFO - Run out-of-band function '_func_init_all'
2023-06-22 22:39:05,262 - distributed.worker - INFO - Run out-of-band function '_func_init_all'
2023-06-22 22:39:05,262 - distributed.worker - INFO - Run out-of-band function '_func_init_all'
2023-06-22 22:39:05,263 - distributed.worker - INFO - Run out-of-band function '_func_init_all'
2023-06-22 22:39:05,263 - distributed.worker - INFO - Run out-of-band function '_func_init_all'
2023-06-22 22:39:16,297 - distributed.worker - INFO - Run out-of-band function '_subcomm_init'
2023-06-22 22:39:16,298 - distributed.worker - INFO - Run out-of-band function '_subcomm_init'
2023-06-22 22:39:16,452 - distributed.worker - INFO - Run out-of-band function '_subcomm_init'
2023-06-22 22:39:16,473 - distributed.worker - INFO - Run out-of-band function '_subcomm_init'
2023-06-22 22:39:16,481 - distributed.worker - INFO - Run out-of-band function '_subcomm_init'
2023-06-22 22:39:16,561 - distributed.worker - INFO - Run out-of-band function '_subcomm_init'
2023-06-22 22:39:16,693 - distributed.worker - INFO - Run out-of-band function '_subcomm_init'
2023-06-22 22:39:16,848 - distributed.worker - INFO - Run out-of-band function '_subcomm_init'
2023-06-22 22:39:22,945 - distributed.core - INFO - Event loop was unresponsive in Worker for 16.00s.  This is often caused by long-running GIL-holding functions or moving large chunks of data. This can cause timeouts and instability.
2023-06-22 22:39:22,946 - distributed.core - INFO - Event loop was unresponsive in Worker for 16.01s.  This is often caused by long-running GIL-holding functions or moving large chunks of data. This can cause timeouts and instability.
2023-06-22 22:39:22,946 - distributed.core - INFO - Event loop was unresponsive in Worker for 16.01s.  This is often caused by long-running GIL-holding functions or moving large chunks of data. This can cause timeouts and instability.
2023-06-22 22:39:22,946 - distributed.core - INFO - Event loop was unresponsive in Worker for 16.01s.  This is often caused by long-running GIL-holding functions or moving large chunks of data. This can cause timeouts and instability.
2023-06-22 22:39:22,965 - distributed.core - INFO - Event loop was unresponsive in Worker for 16.02s.  This is often caused by long-running GIL-holding functions or moving large chunks of data. This can cause timeouts and instability.
2023-06-22 22:39:22,966 - distributed.core - INFO - Event loop was unresponsive in Worker for 16.02s.  This is often caused by long-running GIL-holding functions or moving large chunks of data. This can cause timeouts and instability.
2023-06-22 22:39:22,966 - distributed.core - INFO - Event loop was unresponsive in Worker for 16.03s.  This is often caused by long-running GIL-holding functions or moving large chunks of data. This can cause timeouts and instability.
2023-06-22 22:39:22,966 - distributed.core - INFO - Event loop was unresponsive in Worker for 16.03s.  This is often caused by long-running GIL-holding functions or moving large chunks of data. This can cause timeouts and instability.
2023-06-22 22:39:32,389 - distributed.worker - INFO - Stopping worker at tcp://10.33.227.169:41655. Reason: worker-close
2023-06-22 22:39:32,389 - distributed.worker - INFO - Stopping worker at tcp://10.33.227.169:34397. Reason: worker-close
2023-06-22 22:39:32,389 - distributed.worker - INFO - Stopping worker at tcp://10.33.227.169:36837. Reason: worker-close
2023-06-22 22:39:32,389 - distributed.worker - INFO - Stopping worker at tcp://10.33.227.169:40447. Reason: worker-handle-scheduler-connection-broken
2023-06-22 22:39:32,389 - distributed.worker - INFO - Stopping worker at tcp://10.33.227.169:37635. Reason: worker-handle-scheduler-connection-broken
2023-06-22 22:39:32,389 - distributed.worker - INFO - Stopping worker at tcp://10.33.227.169:40099. Reason: worker-handle-scheduler-connection-broken
2023-06-22 22:39:32,389 - distributed.worker - INFO - Stopping worker at tcp://10.33.227.169:45291. Reason: worker-handle-scheduler-connection-broken
2023-06-22 22:39:32,389 - distributed.worker - INFO - Stopping worker at tcp://10.33.227.169:39515. Reason: worker-handle-scheduler-connection-broken
2023-06-22 22:39:32,390 - distributed.nanny - INFO - Closing Nanny at 'tcp://10.33.227.169:38437'. Reason: nanny-close
2023-06-22 22:39:32,392 - distributed.nanny - INFO - Nanny asking worker to close. Reason: nanny-close
2023-06-22 22:39:32,390 - distributed.batched - INFO - Batched Comm Closed <TCP (closed) Worker->Scheduler local=tcp://10.33.227.169:43628 remote=tcp://10.33.227.169:8786>
Traceback (most recent call last):
  File "/opt/conda/envs/rapids/lib/python3.10/asyncio/runners.py", line 44, in run
    return loop.run_until_complete(main)
  File "/opt/conda/envs/rapids/lib/python3.10/asyncio/base_events.py", line 636, in run_until_complete
    self.run_forever()
  File "/opt/conda/envs/rapids/lib/python3.10/asyncio/base_events.py", line 603, in run_forever
    self._run_once()
  File "/opt/conda/envs/rapids/lib/python3.10/asyncio/base_events.py", line 1871, in _run_once
    event_list = self._selector.select(timeout)
  File "/opt/conda/envs/rapids/lib/python3.10/selectors.py", line 469, in select
    fd_event_list = self._selector.poll(timeout, max_ev)
KeyboardInterrupt

During handling of the above exception, another exception occurred:

Traceback (most recent call last):
  File "/opt/conda/envs/rapids/lib/python3.10/site-packages/distributed/batched.py", line 115, in _background_send
    nbytes = yield coro
  File "/opt/conda/envs/rapids/lib/python3.10/site-packages/tornado/gen.py", line 767, in run
    value = future.result()
  File "/opt/conda/envs/rapids/lib/python3.10/site-packages/distributed/comm/tcp.py", line 269, in write
    raise CommClosedError()
distributed.comm.core.CommClosedError
2023-06-22 22:39:32,393 - distributed.nanny - INFO - Closing Nanny at 'tcp://10.33.227.169:44235'. Reason: nanny-close
2023-06-22 22:39:32,391 - distributed.batched - INFO - Batched Comm Closed <TCP (closed) Worker->Scheduler local=tcp://10.33.227.169:43642 remote=tcp://10.33.227.169:8786>
Traceback (most recent call last):
  File "/opt/conda/envs/rapids/lib/python3.10/asyncio/runners.py", line 44, in run
    return loop.run_until_complete(main)
  File "/opt/conda/envs/rapids/lib/python3.10/asyncio/base_events.py", line 636, in run_until_complete
    self.run_forever()
  File "/opt/conda/envs/rapids/lib/python3.10/asyncio/base_events.py", line 603, in run_forever
    self._run_once()
  File "/opt/conda/envs/rapids/lib/python3.10/asyncio/base_events.py", line 1871, in _run_once
    event_list = self._selector.select(timeout)
  File "/opt/conda/envs/rapids/lib/python3.10/selectors.py", line 469, in select
    fd_event_list = self._selector.poll(timeout, max_ev)
KeyboardInterrupt

During handling of the above exception, another exception occurred:

Traceback (most recent call last):
  File "/opt/conda/envs/rapids/lib/python3.10/site-packages/distributed/batched.py", line 115, in _background_send
    nbytes = yield coro
  File "/opt/conda/envs/rapids/lib/python3.10/site-packages/tornado/gen.py", line 767, in run
    value = future.result()
  File "/opt/conda/envs/rapids/lib/python3.10/site-packages/distributed/comm/tcp.py", line 269, in write
    raise CommClosedError()
distributed.comm.core.CommClosedError
2023-06-22 22:39:32,391 - distributed.batched - INFO - Batched Comm Closed <TCP (closed) Worker->Scheduler local=tcp://10.33.227.169:43658 remote=tcp://10.33.227.169:8786>
Traceback (most recent call last):
  File "/opt/conda/envs/rapids/lib/python3.10/asyncio/runners.py", line 44, in run
    return loop.run_until_complete(main)
  File "/opt/conda/envs/rapids/lib/python3.10/asyncio/base_events.py", line 636, in run_until_complete
    self.run_forever()
  File "/opt/conda/envs/rapids/lib/python3.10/asyncio/base_events.py", line 603, in run_forever
    self._run_once()
  File "/opt/conda/envs/rapids/lib/python3.10/asyncio/base_events.py", line 1871, in _run_once
    event_list = self._selector.select(timeout)
  File "/opt/conda/envs/rapids/lib/python3.10/selectors.py", line 469, in select
    fd_event_list = self._selector.poll(timeout, max_ev)
KeyboardInterrupt

During handling of the above exception, another exception occurred:

Traceback (most recent call last):
  File "/opt/conda/envs/rapids/lib/python3.10/site-packages/distributed/batched.py", line 115, in _background_send
    nbytes = yield coro
  File "/opt/conda/envs/rapids/lib/python3.10/site-packages/tornado/gen.py", line 767, in run
    value = future.result()
  File "/opt/conda/envs/rapids/lib/python3.10/site-packages/distributed/comm/tcp.py", line 269, in write
    raise CommClosedError()
distributed.comm.core.CommClosedError
2023-06-22 22:39:32,395 - distributed.nanny - INFO - Nanny asking worker to close. Reason: nanny-close
2023-06-22 22:39:32,395 - distributed.nanny - INFO - Closing Nanny at 'tcp://10.33.227.169:37075'. Reason: nanny-close
2023-06-22 22:39:32,396 - distributed.nanny - INFO - Nanny asking worker to close. Reason: nanny-close
2023-06-22 22:39:32,396 - distributed.nanny - INFO - Closing Nanny at 'tcp://10.33.227.169:35333'. Reason: nanny-close
2023-06-22 22:39:32,396 - distributed.nanny - INFO - Nanny asking worker to close. Reason: nanny-close
2023-06-22 22:39:32,397 - distributed.nanny - INFO - Closing Nanny at 'tcp://10.33.227.169:37607'. Reason: nanny-close
2023-06-22 22:39:32,397 - distributed.nanny - INFO - Nanny asking worker to close. Reason: nanny-close
2023-06-22 22:39:32,398 - distributed.nanny - INFO - Closing Nanny at 'tcp://10.33.227.169:32867'. Reason: nanny-close
2023-06-22 22:39:32,398 - distributed.nanny - INFO - Nanny asking worker to close. Reason: nanny-close
2023-06-22 22:39:32,398 - distributed.nanny - INFO - Closing Nanny at 'tcp://10.33.227.169:36435'. Reason: nanny-close
2023-06-22 22:39:32,399 - distributed.nanny - INFO - Nanny asking worker to close. Reason: nanny-close
2023-06-22 22:39:32,399 - distributed.nanny - INFO - Closing Nanny at 'tcp://10.33.227.169:41197'. Reason: nanny-close
2023-06-22 22:39:32,400 - distributed.nanny - INFO - Nanny asking worker to close. Reason: nanny-close
2023-06-22 22:39:32,413 - distributed.worker - ERROR - Timed out during handshake while connecting to tcp://10.33.227.169:38437 after 100 s
Traceback (most recent call last):
  File "/opt/conda/envs/rapids/lib/python3.10/asyncio/runners.py", line 44, in run
    return loop.run_until_complete(main)
  File "/opt/conda/envs/rapids/lib/python3.10/asyncio/base_events.py", line 636, in run_until_complete
    self.run_forever()
  File "/opt/conda/envs/rapids/lib/python3.10/asyncio/base_events.py", line 603, in run_forever
    self._run_once()
  File "/opt/conda/envs/rapids/lib/python3.10/asyncio/base_events.py", line 1871, in _run_once
    event_list = self._selector.select(timeout)
  File "/opt/conda/envs/rapids/lib/python3.10/selectors.py", line 469, in select
    fd_event_list = self._selector.poll(timeout, max_ev)
KeyboardInterrupt

During handling of the above exception, another exception occurred:

Traceback (most recent call last):
  File "/opt/conda/envs/rapids/lib/python3.10/site-packages/tornado/iostream.py", line 861, in _read_to_buffer
    bytes_read = self.read_from_fd(buf)
  File "/opt/conda/envs/rapids/lib/python3.10/site-packages/tornado/iostream.py", line 1116, in read_from_fd
    return self.socket.recv_into(buf, len(buf))
ConnectionResetError: [Errno 104] Connection reset by peer

The above exception was the direct cause of the following exception:

Traceback (most recent call last):
  File "/opt/conda/envs/rapids/lib/python3.10/site-packages/distributed/comm/core.py", line 373, in connect
    handshake = await wait_for(comm.read(), time_left())
  File "/opt/conda/envs/rapids/lib/python3.10/site-packages/distributed/utils.py", line 1878, in wait_for
    return await asyncio.wait_for(fut, timeout)
  File "/opt/conda/envs/rapids/lib/python3.10/asyncio/tasks.py", line 445, in wait_for
    return fut.result()
  File "/opt/conda/envs/rapids/lib/python3.10/site-packages/distributed/comm/tcp.py", line 241, in read
    convert_stream_closed_error(self, e)
  File "/opt/conda/envs/rapids/lib/python3.10/site-packages/distributed/comm/tcp.py", line 142, in convert_stream_closed_error
    raise CommClosedError(f"in {obj}: {exc.__class__.__name__}: {exc}") from exc
distributed.comm.core.CommClosedError: in <TCP (closed)  local=tcp://10.33.227.169:45000 remote=tcp://10.33.227.169:38437>: ConnectionResetError: [Errno 104] Connection reset by peer

The above exception was the direct cause of the following exception:

Traceback (most recent call last):
  File "/opt/conda/envs/rapids/lib/python3.10/site-packages/distributed/utils.py", line 754, in wrapper
    return await func(*args, **kwargs)
  File "/opt/conda/envs/rapids/lib/python3.10/site-packages/distributed/worker.py", line 1540, in close
    await r.close_gracefully(reason=reason)
  File "/opt/conda/envs/rapids/lib/python3.10/site-packages/distributed/core.py", line 1362, in send_recv_from_rpc
    comm = await self.pool.connect(self.addr)
  File "/opt/conda/envs/rapids/lib/python3.10/site-packages/distributed/core.py", line 1606, in connect
    return await connect_attempt
  File "/opt/conda/envs/rapids/lib/python3.10/site-packages/distributed/core.py", line 1527, in _connect
    comm = await connect(
  File "/opt/conda/envs/rapids/lib/python3.10/site-packages/distributed/comm/core.py", line 378, in connect
    raise OSError(
OSError: Timed out during handshake while connecting to tcp://10.33.227.169:38437 after 100 s
2023-06-22 22:39:32,414 - distributed.core - ERROR - Timed out during handshake while connecting to tcp://10.33.227.169:36435 after 100 s
Traceback (most recent call last):
  File "/opt/conda/envs/rapids/lib/python3.10/asyncio/runners.py", line 44, in run
    return loop.run_until_complete(main)
  File "/opt/conda/envs/rapids/lib/python3.10/asyncio/base_events.py", line 636, in run_until_complete
    self.run_forever()
  File "/opt/conda/envs/rapids/lib/python3.10/asyncio/base_events.py", line 603, in run_forever
    self._run_once()
  File "/opt/conda/envs/rapids/lib/python3.10/asyncio/base_events.py", line 1871, in _run_once
    event_list = self._selector.select(timeout)
  File "/opt/conda/envs/rapids/lib/python3.10/selectors.py", line 469, in select
    fd_event_list = self._selector.poll(timeout, max_ev)
KeyboardInterrupt

During handling of the above exception, another exception occurred:

Traceback (most recent call last):
  File "/opt/conda/envs/rapids/lib/python3.10/site-packages/tornado/iostream.py", line 861, in _read_to_buffer
    bytes_read = self.read_from_fd(buf)
  File "/opt/conda/envs/rapids/lib/python3.10/site-packages/tornado/iostream.py", line 1116, in read_from_fd
    return self.socket.recv_into(buf, len(buf))
ConnectionResetError: [Errno 104] Connection reset by peer

The above exception was the direct cause of the following exception:

Traceback (most recent call last):
  File "/opt/conda/envs/rapids/lib/python3.10/site-packages/distributed/comm/core.py", line 373, in connect
    handshake = await wait_for(comm.read(), time_left())
  File "/opt/conda/envs/rapids/lib/python3.10/site-packages/distributed/utils.py", line 1878, in wait_for
    return await asyncio.wait_for(fut, timeout)
  File "/opt/conda/envs/rapids/lib/python3.10/asyncio/tasks.py", line 445, in wait_for
    return fut.result()
  File "/opt/conda/envs/rapids/lib/python3.10/site-packages/distributed/comm/tcp.py", line 241, in read
    convert_stream_closed_error(self, e)
  File "/opt/conda/envs/rapids/lib/python3.10/site-packages/distributed/comm/tcp.py", line 142, in convert_stream_closed_error
    raise CommClosedError(f"in {obj}: {exc.__class__.__name__}: {exc}") from exc
distributed.comm.core.CommClosedError: in <TCP (closed)  local=tcp://10.33.227.169:45280 remote=tcp://10.33.227.169:36435>: ConnectionResetError: [Errno 104] Connection reset by peer

The above exception was the direct cause of the following exception:

Traceback (most recent call last):
  File "/opt/conda/envs/rapids/lib/python3.10/site-packages/distributed/utils.py", line 754, in wrapper
    return await func(*args, **kwargs)
  File "/opt/conda/envs/rapids/lib/python3.10/site-packages/distributed/worker.py", line 1540, in close
    await r.close_gracefully(reason=reason)
  File "/opt/conda/envs/rapids/lib/python3.10/site-packages/distributed/core.py", line 1362, in send_recv_from_rpc
    comm = await self.pool.connect(self.addr)
  File "/opt/conda/envs/rapids/lib/python3.10/site-packages/distributed/core.py", line 1606, in connect
    return await connect_attempt
  File "/opt/conda/envs/rapids/lib/python3.10/site-packages/distributed/core.py", line 1527, in _connect
    comm = await connect(
  File "/opt/conda/envs/rapids/lib/python3.10/site-packages/distributed/comm/core.py", line 378, in connect
    raise OSError(
OSError: Timed out during handshake while connecting to tcp://10.33.227.169:36435 after 100 s
2023-06-22 22:39:32,415 - distributed.worker - ERROR - Timed out during handshake while connecting to tcp://10.33.227.169:32867 after 100 s
Traceback (most recent call last):
  File "/opt/conda/envs/rapids/lib/python3.10/asyncio/runners.py", line 44, in run
    return loop.run_until_complete(main)
  File "/opt/conda/envs/rapids/lib/python3.10/asyncio/base_events.py", line 636, in run_until_complete
    self.run_forever()
  File "/opt/conda/envs/rapids/lib/python3.10/asyncio/base_events.py", line 603, in run_forever
    self._run_once()
  File "/opt/conda/envs/rapids/lib/python3.10/asyncio/base_events.py", line 1871, in _run_once
    event_list = self._selector.select(timeout)
  File "/opt/conda/envs/rapids/lib/python3.10/selectors.py", line 469, in select
    fd_event_list = self._selector.poll(timeout, max_ev)
KeyboardInterrupt

During handling of the above exception, another exception occurred:

Traceback (most recent call last):
  File "/opt/conda/envs/rapids/lib/python3.10/site-packages/tornado/iostream.py", line 861, in _read_to_buffer
    bytes_read = self.read_from_fd(buf)
  File "/opt/conda/envs/rapids/lib/python3.10/site-packages/tornado/iostream.py", line 1116, in read_from_fd
    return self.socket.recv_into(buf, len(buf))
ConnectionResetError: [Errno 104] Connection reset by peer

The above exception was the direct cause of the following exception:

Traceback (most recent call last):
  File "/opt/conda/envs/rapids/lib/python3.10/site-packages/distributed/comm/core.py", line 373, in connect
    handshake = await wait_for(comm.read(), time_left())
  File "/opt/conda/envs/rapids/lib/python3.10/site-packages/distributed/utils.py", line 1878, in wait_for
    return await asyncio.wait_for(fut, timeout)
  File "/opt/conda/envs/rapids/lib/python3.10/asyncio/tasks.py", line 445, in wait_for
    return fut.result()
  File "/opt/conda/envs/rapids/lib/python3.10/site-packages/distributed/comm/tcp.py", line 241, in read
    convert_stream_closed_error(self, e)
  File "/opt/conda/envs/rapids/lib/python3.10/site-packages/distributed/comm/tcp.py", line 142, in convert_stream_closed_error
    raise CommClosedError(f"in {obj}: {exc.__class__.__name__}: {exc}") from exc
distributed.comm.core.CommClosedError: in <TCP (closed)  local=tcp://10.33.227.169:46366 remote=tcp://10.33.227.169:32867>: ConnectionResetError: [Errno 104] Connection reset by peer

The above exception was the direct cause of the following exception:

Traceback (most recent call last):
  File "/opt/conda/envs/rapids/lib/python3.10/site-packages/distributed/utils.py", line 754, in wrapper
    return await func(*args, **kwargs)
  File "/opt/conda/envs/rapids/lib/python3.10/site-packages/distributed/worker.py", line 1540, in close
    await r.close_gracefully(reason=reason)
  File "/opt/conda/envs/rapids/lib/python3.10/site-packages/distributed/core.py", line 1362, in send_recv_from_rpc
    comm = await self.pool.connect(self.addr)
  File "/opt/conda/envs/rapids/lib/python3.10/site-packages/distributed/core.py", line 1606, in connect
    return await connect_attempt
  File "/opt/conda/envs/rapids/lib/python3.10/site-packages/distributed/core.py", line 1527, in _connect
    comm = await connect(
  File "/opt/conda/envs/rapids/lib/python3.10/site-packages/distributed/comm/core.py", line 378, in connect
    raise OSError(
OSError: Timed out during handshake while connecting to tcp://10.33.227.169:32867 after 100 s
2023-06-22 22:39:32,416 - distributed.worker - ERROR - Timed out during handshake while connecting to tcp://10.33.227.169:44235 after 100 s
Traceback (most recent call last):
  File "/opt/conda/envs/rapids/lib/python3.10/asyncio/runners.py", line 44, in run
    return loop.run_until_complete(main)
  File "/opt/conda/envs/rapids/lib/python3.10/asyncio/base_events.py", line 636, in run_until_complete
    self.run_forever()
  File "/opt/conda/envs/rapids/lib/python3.10/asyncio/base_events.py", line 603, in run_forever
    self._run_once()
  File "/opt/conda/envs/rapids/lib/python3.10/asyncio/base_events.py", line 1871, in _run_once
    event_list = self._selector.select(timeout)
  File "/opt/conda/envs/rapids/lib/python3.10/selectors.py", line 469, in select
    fd_event_list = self._selector.poll(timeout, max_ev)
KeyboardInterrupt

During handling of the above exception, another exception occurred:

Traceback (most recent call last):
  File "/opt/conda/envs/rapids/lib/python3.10/site-packages/tornado/iostream.py", line 861, in _read_to_buffer
    bytes_read = self.read_from_fd(buf)
  File "/opt/conda/envs/rapids/lib/python3.10/site-packages/tornado/iostream.py", line 1116, in read_from_fd
    return self.socket.recv_into(buf, len(buf))
ConnectionResetError: [Errno 104] Connection reset by peer

The above exception was the direct cause of the following exception:

Traceback (most recent call last):
  File "/opt/conda/envs/rapids/lib/python3.10/site-packages/distributed/comm/core.py", line 373, in connect
    handshake = await wait_for(comm.read(), time_left())
  File "/opt/conda/envs/rapids/lib/python3.10/site-packages/distributed/utils.py", line 1878, in wait_for
    return await asyncio.wait_for(fut, timeout)
  File "/opt/conda/envs/rapids/lib/python3.10/asyncio/tasks.py", line 445, in wait_for
    return fut.result()
  File "/opt/conda/envs/rapids/lib/python3.10/site-packages/distributed/comm/tcp.py", line 241, in read
    convert_stream_closed_error(self, e)
  File "/opt/conda/envs/rapids/lib/python3.10/site-packages/distributed/comm/tcp.py", line 142, in convert_stream_closed_error
    raise CommClosedError(f"in {obj}: {exc.__class__.__name__}: {exc}") from exc
distributed.comm.core.CommClosedError: in <TCP (closed)  local=tcp://10.33.227.169:55278 remote=tcp://10.33.227.169:44235>: ConnectionResetError: [Errno 104] Connection reset by peer

The above exception was the direct cause of the following exception:

Traceback (most recent call last):
  File "/opt/conda/envs/rapids/lib/python3.10/site-packages/distributed/utils.py", line 754, in wrapper
    return await func(*args, **kwargs)
  File "/opt/conda/envs/rapids/lib/python3.10/site-packages/distributed/worker.py", line 1540, in close
    await r.close_gracefully(reason=reason)
  File "/opt/conda/envs/rapids/lib/python3.10/site-packages/distributed/core.py", line 1362, in send_recv_from_rpc
    comm = await self.pool.connect(self.addr)
  File "/opt/conda/envs/rapids/lib/python3.10/site-packages/distributed/core.py", line 1606, in connect
    return await connect_attempt
  File "/opt/conda/envs/rapids/lib/python3.10/site-packages/distributed/core.py", line 1527, in _connect
    comm = await connect(
  File "/opt/conda/envs/rapids/lib/python3.10/site-packages/distributed/comm/core.py", line 378, in connect
    raise OSError(
OSError: Timed out during handshake while connecting to tcp://10.33.227.169:44235 after 100 s
2023-06-22 22:39:32,417 - distributed.core - ERROR - Timed out during handshake while connecting to tcp://10.33.227.169:37075 after 100 s
Traceback (most recent call last):
  File "/opt/conda/envs/rapids/lib/python3.10/asyncio/runners.py", line 44, in run
    return loop.run_until_complete(main)
  File "/opt/conda/envs/rapids/lib/python3.10/asyncio/base_events.py", line 636, in run_until_complete
    self.run_forever()
  File "/opt/conda/envs/rapids/lib/python3.10/asyncio/base_events.py", line 603, in run_forever
    self._run_once()
  File "/opt/conda/envs/rapids/lib/python3.10/asyncio/base_events.py", line 1871, in _run_once
    event_list = self._selector.select(timeout)
  File "/opt/conda/envs/rapids/lib/python3.10/selectors.py", line 469, in select
    fd_event_list = self._selector.poll(timeout, max_ev)
KeyboardInterrupt

During handling of the above exception, another exception occurred:

Traceback (most recent call last):
  File "/opt/conda/envs/rapids/lib/python3.10/site-packages/tornado/iostream.py", line 861, in _read_to_buffer
    bytes_read = self.read_from_fd(buf)
  File "/opt/conda/envs/rapids/lib/python3.10/site-packages/tornado/iostream.py", line 1116, in read_from_fd
    return self.socket.recv_into(buf, len(buf))
ConnectionResetError: [Errno 104] Connection reset by peer

The above exception was the direct cause of the following exception:

Traceback (most recent call last):
  File "/opt/conda/envs/rapids/lib/python3.10/site-packages/distributed/comm/core.py", line 373, in connect
    handshake = await wait_for(comm.read(), time_left())
  File "/opt/conda/envs/rapids/lib/python3.10/site-packages/distributed/utils.py", line 1878, in wait_for
    return await asyncio.wait_for(fut, timeout)
  File "/opt/conda/envs/rapids/lib/python3.10/asyncio/tasks.py", line 445, in wait_for
    return fut.result()
  File "/opt/conda/envs/rapids/lib/python3.10/site-packages/distributed/comm/tcp.py", line 241, in read
    convert_stream_closed_error(self, e)
  File "/opt/conda/envs/rapids/lib/python3.10/site-packages/distributed/comm/tcp.py", line 142, in convert_stream_closed_error
    raise CommClosedError(f"in {obj}: {exc.__class__.__name__}: {exc}") from exc
distributed.comm.core.CommClosedError: in <TCP (closed)  local=tcp://10.33.227.169:34590 remote=tcp://10.33.227.169:37075>: ConnectionResetError: [Errno 104] Connection reset by peer

The above exception was the direct cause of the following exception:

Traceback (most recent call last):
  File "/opt/conda/envs/rapids/lib/python3.10/site-packages/distributed/utils.py", line 754, in wrapper
    return await func(*args, **kwargs)
  File "/opt/conda/envs/rapids/lib/python3.10/site-packages/distributed/worker.py", line 1540, in close
    await r.close_gracefully(reason=reason)
  File "/opt/conda/envs/rapids/lib/python3.10/site-packages/distributed/core.py", line 1362, in send_recv_from_rpc
    comm = await self.pool.connect(self.addr)
  File "/opt/conda/envs/rapids/lib/python3.10/site-packages/distributed/core.py", line 1606, in connect
    return await connect_attempt
  File "/opt/conda/envs/rapids/lib/python3.10/site-packages/distributed/core.py", line 1527, in _connect
    comm = await connect(
  File "/opt/conda/envs/rapids/lib/python3.10/site-packages/distributed/comm/core.py", line 378, in connect
    raise OSError(
OSError: Timed out during handshake while connecting to tcp://10.33.227.169:37075 after 100 s
2023-06-22 22:39:32,417 - distributed.worker - ERROR - Timed out during handshake while connecting to tcp://10.33.227.169:37607 after 100 s
Traceback (most recent call last):
  File "/opt/conda/envs/rapids/lib/python3.10/asyncio/runners.py", line 44, in run
    return loop.run_until_complete(main)
  File "/opt/conda/envs/rapids/lib/python3.10/asyncio/base_events.py", line 636, in run_until_complete
    self.run_forever()
  File "/opt/conda/envs/rapids/lib/python3.10/asyncio/base_events.py", line 603, in run_forever
    self._run_once()
  File "/opt/conda/envs/rapids/lib/python3.10/asyncio/base_events.py", line 1871, in _run_once
    event_list = self._selector.select(timeout)
  File "/opt/conda/envs/rapids/lib/python3.10/selectors.py", line 469, in select
    fd_event_list = self._selector.poll(timeout, max_ev)
KeyboardInterrupt

During handling of the above exception, another exception occurred:

Traceback (most recent call last):
  File "/opt/conda/envs/rapids/lib/python3.10/site-packages/tornado/iostream.py", line 861, in _read_to_buffer
    bytes_read = self.read_from_fd(buf)
  File "/opt/conda/envs/rapids/lib/python3.10/site-packages/tornado/iostream.py", line 1116, in read_from_fd
    return self.socket.recv_into(buf, len(buf))
ConnectionResetError: [Errno 104] Connection reset by peer

The above exception was the direct cause of the following exception:

Traceback (most recent call last):
  File "/opt/conda/envs/rapids/lib/python3.10/site-packages/distributed/comm/core.py", line 373, in connect
    handshake = await wait_for(comm.read(), time_left())
  File "/opt/conda/envs/rapids/lib/python3.10/site-packages/distributed/utils.py", line 1878, in wait_for
    return await asyncio.wait_for(fut, timeout)
  File "/opt/conda/envs/rapids/lib/python3.10/asyncio/tasks.py", line 445, in wait_for
    return fut.result()
  File "/opt/conda/envs/rapids/lib/python3.10/site-packages/distributed/comm/tcp.py", line 241, in read
    convert_stream_closed_error(self, e)
  File "/opt/conda/envs/rapids/lib/python3.10/site-packages/distributed/comm/tcp.py", line 142, in convert_stream_closed_error
    raise CommClosedError(f"in {obj}: {exc.__class__.__name__}: {exc}") from exc
distributed.comm.core.CommClosedError: in <TCP (closed)  local=tcp://10.33.227.169:34278 remote=tcp://10.33.227.169:37607>: ConnectionResetError: [Errno 104] Connection reset by peer

The above exception was the direct cause of the following exception:

Traceback (most recent call last):
  File "/opt/conda/envs/rapids/lib/python3.10/site-packages/distributed/utils.py", line 754, in wrapper
    return await func(*args, **kwargs)
  File "/opt/conda/envs/rapids/lib/python3.10/site-packages/distributed/worker.py", line 1540, in close
    await r.close_gracefully(reason=reason)
  File "/opt/conda/envs/rapids/lib/python3.10/site-packages/distributed/core.py", line 1362, in send_recv_from_rpc
    comm = await self.pool.connect(self.addr)
  File "/opt/conda/envs/rapids/lib/python3.10/site-packages/distributed/core.py", line 1606, in connect
    return await connect_attempt
  File "/opt/conda/envs/rapids/lib/python3.10/site-packages/distributed/core.py", line 1527, in _connect
    comm = await connect(
  File "/opt/conda/envs/rapids/lib/python3.10/site-packages/distributed/comm/core.py", line 378, in connect
    raise OSError(
OSError: Timed out during handshake while connecting to tcp://10.33.227.169:37607 after 100 s
2023-06-22 22:39:32,419 - distributed.core - ERROR - Timed out during handshake while connecting to tcp://10.33.227.169:35333 after 100 s
Traceback (most recent call last):
  File "/opt/conda/envs/rapids/lib/python3.10/asyncio/runners.py", line 44, in run
    return loop.run_until_complete(main)
  File "/opt/conda/envs/rapids/lib/python3.10/asyncio/base_events.py", line 636, in run_until_complete
    self.run_forever()
  File "/opt/conda/envs/rapids/lib/python3.10/asyncio/base_events.py", line 603, in run_forever
    self._run_once()
  File "/opt/conda/envs/rapids/lib/python3.10/asyncio/base_events.py", line 1871, in _run_once
    event_list = self._selector.select(timeout)
  File "/opt/conda/envs/rapids/lib/python3.10/selectors.py", line 469, in select
    fd_event_list = self._selector.poll(timeout, max_ev)
KeyboardInterrupt

During handling of the above exception, another exception occurred:

Traceback (most recent call last):
  File "/opt/conda/envs/rapids/lib/python3.10/site-packages/tornado/iostream.py", line 861, in _read_to_buffer
    bytes_read = self.read_from_fd(buf)
  File "/opt/conda/envs/rapids/lib/python3.10/site-packages/tornado/iostream.py", line 1116, in read_from_fd
    return self.socket.recv_into(buf, len(buf))
ConnectionResetError: [Errno 104] Connection reset by peer

The above exception was the direct cause of the following exception:

Traceback (most recent call last):
  File "/opt/conda/envs/rapids/lib/python3.10/site-packages/distributed/comm/core.py", line 373, in connect
    handshake = await wait_for(comm.read(), time_left())
  File "/opt/conda/envs/rapids/lib/python3.10/site-packages/distributed/utils.py", line 1878, in wait_for
    return await asyncio.wait_for(fut, timeout)
  File "/opt/conda/envs/rapids/lib/python3.10/asyncio/tasks.py", line 445, in wait_for
    return fut.result()
  File "/opt/conda/envs/rapids/lib/python3.10/site-packages/distributed/comm/tcp.py", line 241, in read
    convert_stream_closed_error(self, e)
  File "/opt/conda/envs/rapids/lib/python3.10/site-packages/distributed/comm/tcp.py", line 142, in convert_stream_closed_error
    raise CommClosedError(f"in {obj}: {exc.__class__.__name__}: {exc}") from exc
distributed.comm.core.CommClosedError: in <TCP (closed)  local=tcp://10.33.227.169:42826 remote=tcp://10.33.227.169:35333>: ConnectionResetError: [Errno 104] Connection reset by peer

The above exception was the direct cause of the following exception:

Traceback (most recent call last):
  File "/opt/conda/envs/rapids/lib/python3.10/site-packages/distributed/utils.py", line 754, in wrapper
    return await func(*args, **kwargs)
  File "/opt/conda/envs/rapids/lib/python3.10/site-packages/distributed/worker.py", line 1540, in close
    await r.close_gracefully(reason=reason)
  File "/opt/conda/envs/rapids/lib/python3.10/site-packages/distributed/core.py", line 1362, in send_recv_from_rpc
    comm = await self.pool.connect(self.addr)
  File "/opt/conda/envs/rapids/lib/python3.10/site-packages/distributed/core.py", line 1606, in connect
    return await connect_attempt
  File "/opt/conda/envs/rapids/lib/python3.10/site-packages/distributed/core.py", line 1527, in _connect
    comm = await connect(
  File "/opt/conda/envs/rapids/lib/python3.10/site-packages/distributed/comm/core.py", line 378, in connect
    raise OSError(
OSError: Timed out during handshake while connecting to tcp://10.33.227.169:35333 after 100 s
2023-06-22 22:39:32,421 - distributed.worker - ERROR - Timed out during handshake while connecting to tcp://10.33.227.169:41197 after 100 s
Traceback (most recent call last):
  File "/opt/conda/envs/rapids/lib/python3.10/asyncio/runners.py", line 44, in run
    return loop.run_until_complete(main)
  File "/opt/conda/envs/rapids/lib/python3.10/asyncio/base_events.py", line 636, in run_until_complete
    self.run_forever()
  File "/opt/conda/envs/rapids/lib/python3.10/asyncio/base_events.py", line 603, in run_forever
    self._run_once()
  File "/opt/conda/envs/rapids/lib/python3.10/asyncio/base_events.py", line 1871, in _run_once
    event_list = self._selector.select(timeout)
  File "/opt/conda/envs/rapids/lib/python3.10/selectors.py", line 469, in select
    fd_event_list = self._selector.poll(timeout, max_ev)
KeyboardInterrupt

During handling of the above exception, another exception occurred:

Traceback (most recent call last):
  File "/opt/conda/envs/rapids/lib/python3.10/site-packages/tornado/iostream.py", line 861, in _read_to_buffer
    bytes_read = self.read_from_fd(buf)
  File "/opt/conda/envs/rapids/lib/python3.10/site-packages/tornado/iostream.py", line 1116, in read_from_fd
    return self.socket.recv_into(buf, len(buf))
ConnectionResetError: [Errno 104] Connection reset by peer

The above exception was the direct cause of the following exception:

Traceback (most recent call last):
  File "/opt/conda/envs/rapids/lib/python3.10/site-packages/distributed/comm/core.py", line 373, in connect
    handshake = await wait_for(comm.read(), time_left())
  File "/opt/conda/envs/rapids/lib/python3.10/site-packages/distributed/utils.py", line 1878, in wait_for
    return await asyncio.wait_for(fut, timeout)
  File "/opt/conda/envs/rapids/lib/python3.10/asyncio/tasks.py", line 445, in wait_for
    return fut.result()
  File "/opt/conda/envs/rapids/lib/python3.10/site-packages/distributed/comm/tcp.py", line 241, in read
    convert_stream_closed_error(self, e)
  File "/opt/conda/envs/rapids/lib/python3.10/site-packages/distributed/comm/tcp.py", line 142, in convert_stream_closed_error
    raise CommClosedError(f"in {obj}: {exc.__class__.__name__}: {exc}") from exc
distributed.comm.core.CommClosedError: in <TCP (closed)  local=tcp://10.33.227.169:53886 remote=tcp://10.33.227.169:41197>: ConnectionResetError: [Errno 104] Connection reset by peer

The above exception was the direct cause of the following exception:

Traceback (most recent call last):
  File "/opt/conda/envs/rapids/lib/python3.10/site-packages/distributed/utils.py", line 754, in wrapper
    return await func(*args, **kwargs)
  File "/opt/conda/envs/rapids/lib/python3.10/site-packages/distributed/worker.py", line 1540, in close
    await r.close_gracefully(reason=reason)
  File "/opt/conda/envs/rapids/lib/python3.10/site-packages/distributed/core.py", line 1362, in send_recv_from_rpc
    comm = await self.pool.connect(self.addr)
  File "/opt/conda/envs/rapids/lib/python3.10/site-packages/distributed/core.py", line 1606, in connect
    return await connect_attempt
  File "/opt/conda/envs/rapids/lib/python3.10/site-packages/distributed/core.py", line 1527, in _connect
    comm = await connect(
  File "/opt/conda/envs/rapids/lib/python3.10/site-packages/distributed/comm/core.py", line 378, in connect
    raise OSError(
OSError: Timed out during handshake while connecting to tcp://10.33.227.169:41197 after 100 s
2023-06-22 22:39:35,602 - distributed.nanny - WARNING - Worker process still alive after 3.1999726867675786 seconds, killing
2023-06-22 22:39:35,602 - distributed.nanny - WARNING - Worker process still alive after 3.1999989318847657 seconds, killing
2023-06-22 22:39:35,603 - distributed.nanny - WARNING - Worker process still alive after 3.199999389648438 seconds, killing
2023-06-22 22:39:35,604 - distributed.nanny - WARNING - Worker process still alive after 3.199999389648438 seconds, killing
2023-06-22 22:39:35,605 - distributed.nanny - WARNING - Worker process still alive after 3.1999992370605472 seconds, killing
2023-06-22 22:39:35,606 - distributed.nanny - WARNING - Worker process still alive after 3.1999992370605472 seconds, killing
2023-06-22 22:39:35,606 - distributed.nanny - WARNING - Worker process still alive after 3.1999989318847657 seconds, killing
2023-06-22 22:39:35,607 - distributed.nanny - WARNING - Worker process still alive after 3.1999992370605472 seconds, killing
2023-06-22 22:39:36,393 - distributed.nanny - ERROR - Error in Nanny killing Worker subprocess
Traceback (most recent call last):
  File "/opt/conda/envs/rapids/lib/python3.10/asyncio/tasks.py", line 456, in wait_for
    return fut.result()
asyncio.exceptions.CancelledError

The above exception was the direct cause of the following exception:

Traceback (most recent call last):
  File "/opt/conda/envs/rapids/lib/python3.10/site-packages/distributed/nanny.py", line 597, in close
    await self.kill(timeout=timeout, reason=reason)
  File "/opt/conda/envs/rapids/lib/python3.10/site-packages/distributed/nanny.py", line 380, in kill
    await self.process.kill(reason=reason, timeout=0.8 * (deadline - time()))
  File "/opt/conda/envs/rapids/lib/python3.10/site-packages/distributed/nanny.py", line 853, in kill
    await process.join(max(0, deadline - time()))
  File "/opt/conda/envs/rapids/lib/python3.10/site-packages/distributed/process.py", line 330, in join
    await wait_for(asyncio.shield(self._exit_future), timeout)
  File "/opt/conda/envs/rapids/lib/python3.10/site-packages/distributed/utils.py", line 1878, in wait_for
    return await asyncio.wait_for(fut, timeout)
  File "/opt/conda/envs/rapids/lib/python3.10/asyncio/tasks.py", line 458, in wait_for
    raise exceptions.TimeoutError() from exc
asyncio.exceptions.TimeoutError
2023-06-22 22:39:36,395 - distributed.nanny - ERROR - Error in Nanny killing Worker subprocess
Traceback (most recent call last):
  File "/opt/conda/envs/rapids/lib/python3.10/asyncio/tasks.py", line 456, in wait_for
    return fut.result()
asyncio.exceptions.CancelledError

The above exception was the direct cause of the following exception:

Traceback (most recent call last):
  File "/opt/conda/envs/rapids/lib/python3.10/site-packages/distributed/nanny.py", line 597, in close
    await self.kill(timeout=timeout, reason=reason)
  File "/opt/conda/envs/rapids/lib/python3.10/site-packages/distributed/nanny.py", line 380, in kill
    await self.process.kill(reason=reason, timeout=0.8 * (deadline - time()))
  File "/opt/conda/envs/rapids/lib/python3.10/site-packages/distributed/nanny.py", line 853, in kill
    await process.join(max(0, deadline - time()))
  File "/opt/conda/envs/rapids/lib/python3.10/site-packages/distributed/process.py", line 330, in join
    await wait_for(asyncio.shield(self._exit_future), timeout)
  File "/opt/conda/envs/rapids/lib/python3.10/site-packages/distributed/utils.py", line 1878, in wait_for
    return await asyncio.wait_for(fut, timeout)
  File "/opt/conda/envs/rapids/lib/python3.10/asyncio/tasks.py", line 458, in wait_for
    raise exceptions.TimeoutError() from exc
asyncio.exceptions.TimeoutError
2023-06-22 22:39:36,396 - distributed.nanny - ERROR - Error in Nanny killing Worker subprocess
Traceback (most recent call last):
  File "/opt/conda/envs/rapids/lib/python3.10/asyncio/tasks.py", line 456, in wait_for
    return fut.result()
asyncio.exceptions.CancelledError

The above exception was the direct cause of the following exception:

Traceback (most recent call last):
  File "/opt/conda/envs/rapids/lib/python3.10/site-packages/distributed/nanny.py", line 597, in close
    await self.kill(timeout=timeout, reason=reason)
  File "/opt/conda/envs/rapids/lib/python3.10/site-packages/distributed/nanny.py", line 380, in kill
    await self.process.kill(reason=reason, timeout=0.8 * (deadline - time()))
  File "/opt/conda/envs/rapids/lib/python3.10/site-packages/distributed/nanny.py", line 853, in kill
    await process.join(max(0, deadline - time()))
  File "/opt/conda/envs/rapids/lib/python3.10/site-packages/distributed/process.py", line 330, in join
    await wait_for(asyncio.shield(self._exit_future), timeout)
  File "/opt/conda/envs/rapids/lib/python3.10/site-packages/distributed/utils.py", line 1878, in wait_for
    return await asyncio.wait_for(fut, timeout)
  File "/opt/conda/envs/rapids/lib/python3.10/asyncio/tasks.py", line 458, in wait_for
    raise exceptions.TimeoutError() from exc
asyncio.exceptions.TimeoutError
2023-06-22 22:39:36,397 - distributed.nanny - ERROR - Error in Nanny killing Worker subprocess
Traceback (most recent call last):
  File "/opt/conda/envs/rapids/lib/python3.10/asyncio/tasks.py", line 456, in wait_for
    return fut.result()
asyncio.exceptions.CancelledError

The above exception was the direct cause of the following exception:

Traceback (most recent call last):
  File "/opt/conda/envs/rapids/lib/python3.10/site-packages/distributed/nanny.py", line 597, in close
    await self.kill(timeout=timeout, reason=reason)
  File "/opt/conda/envs/rapids/lib/python3.10/site-packages/distributed/nanny.py", line 380, in kill
    await self.process.kill(reason=reason, timeout=0.8 * (deadline - time()))
  File "/opt/conda/envs/rapids/lib/python3.10/site-packages/distributed/nanny.py", line 853, in kill
    await process.join(max(0, deadline - time()))
  File "/opt/conda/envs/rapids/lib/python3.10/site-packages/distributed/process.py", line 330, in join
    await wait_for(asyncio.shield(self._exit_future), timeout)
  File "/opt/conda/envs/rapids/lib/python3.10/site-packages/distributed/utils.py", line 1878, in wait_for
    return await asyncio.wait_for(fut, timeout)
  File "/opt/conda/envs/rapids/lib/python3.10/asyncio/tasks.py", line 458, in wait_for
    raise exceptions.TimeoutError() from exc
asyncio.exceptions.TimeoutError
2023-06-22 22:39:36,398 - distributed.nanny - ERROR - Error in Nanny killing Worker subprocess
Traceback (most recent call last):
  File "/opt/conda/envs/rapids/lib/python3.10/asyncio/tasks.py", line 456, in wait_for
    return fut.result()
asyncio.exceptions.CancelledError

The above exception was the direct cause of the following exception:

Traceback (most recent call last):
  File "/opt/conda/envs/rapids/lib/python3.10/site-packages/distributed/nanny.py", line 597, in close
    await self.kill(timeout=timeout, reason=reason)
  File "/opt/conda/envs/rapids/lib/python3.10/site-packages/distributed/nanny.py", line 380, in kill
    await self.process.kill(reason=reason, timeout=0.8 * (deadline - time()))
  File "/opt/conda/envs/rapids/lib/python3.10/site-packages/distributed/nanny.py", line 853, in kill
    await process.join(max(0, deadline - time()))
  File "/opt/conda/envs/rapids/lib/python3.10/site-packages/distributed/process.py", line 330, in join
    await wait_for(asyncio.shield(self._exit_future), timeout)
  File "/opt/conda/envs/rapids/lib/python3.10/site-packages/distributed/utils.py", line 1878, in wait_for
    return await asyncio.wait_for(fut, timeout)
  File "/opt/conda/envs/rapids/lib/python3.10/asyncio/tasks.py", line 458, in wait_for
    raise exceptions.TimeoutError() from exc
asyncio.exceptions.TimeoutError
2023-06-22 22:39:36,399 - distributed.nanny - ERROR - Error in Nanny killing Worker subprocess
Traceback (most recent call last):
  File "/opt/conda/envs/rapids/lib/python3.10/asyncio/tasks.py", line 456, in wait_for
    return fut.result()
asyncio.exceptions.CancelledError

The above exception was the direct cause of the following exception:

Traceback (most recent call last):
  File "/opt/conda/envs/rapids/lib/python3.10/site-packages/distributed/nanny.py", line 597, in close
    await self.kill(timeout=timeout, reason=reason)
  File "/opt/conda/envs/rapids/lib/python3.10/site-packages/distributed/nanny.py", line 380, in kill
    await self.process.kill(reason=reason, timeout=0.8 * (deadline - time()))
  File "/opt/conda/envs/rapids/lib/python3.10/site-packages/distributed/nanny.py", line 853, in kill
    await process.join(max(0, deadline - time()))
  File "/opt/conda/envs/rapids/lib/python3.10/site-packages/distributed/process.py", line 330, in join
    await wait_for(asyncio.shield(self._exit_future), timeout)
  File "/opt/conda/envs/rapids/lib/python3.10/site-packages/distributed/utils.py", line 1878, in wait_for
    return await asyncio.wait_for(fut, timeout)
  File "/opt/conda/envs/rapids/lib/python3.10/asyncio/tasks.py", line 458, in wait_for
    raise exceptions.TimeoutError() from exc
asyncio.exceptions.TimeoutError
2023-06-22 22:39:36,399 - distributed.nanny - ERROR - Error in Nanny killing Worker subprocess
Traceback (most recent call last):
  File "/opt/conda/envs/rapids/lib/python3.10/asyncio/tasks.py", line 456, in wait_for
    return fut.result()
asyncio.exceptions.CancelledError

The above exception was the direct cause of the following exception:

Traceback (most recent call last):
  File "/opt/conda/envs/rapids/lib/python3.10/site-packages/distributed/nanny.py", line 597, in close
    await self.kill(timeout=timeout, reason=reason)
  File "/opt/conda/envs/rapids/lib/python3.10/site-packages/distributed/nanny.py", line 380, in kill
    await self.process.kill(reason=reason, timeout=0.8 * (deadline - time()))
  File "/opt/conda/envs/rapids/lib/python3.10/site-packages/distributed/nanny.py", line 853, in kill
    await process.join(max(0, deadline - time()))
  File "/opt/conda/envs/rapids/lib/python3.10/site-packages/distributed/process.py", line 330, in join
    await wait_for(asyncio.shield(self._exit_future), timeout)
  File "/opt/conda/envs/rapids/lib/python3.10/site-packages/distributed/utils.py", line 1878, in wait_for
    return await asyncio.wait_for(fut, timeout)
  File "/opt/conda/envs/rapids/lib/python3.10/asyncio/tasks.py", line 458, in wait_for
    raise exceptions.TimeoutError() from exc
asyncio.exceptions.TimeoutError
2023-06-22 22:39:36,401 - distributed.nanny - ERROR - Error in Nanny killing Worker subprocess
Traceback (most recent call last):
  File "/opt/conda/envs/rapids/lib/python3.10/asyncio/tasks.py", line 456, in wait_for
    return fut.result()
asyncio.exceptions.CancelledError

The above exception was the direct cause of the following exception:

Traceback (most recent call last):
  File "/opt/conda/envs/rapids/lib/python3.10/site-packages/distributed/nanny.py", line 597, in close
    await self.kill(timeout=timeout, reason=reason)
  File "/opt/conda/envs/rapids/lib/python3.10/site-packages/distributed/nanny.py", line 380, in kill
    await self.process.kill(reason=reason, timeout=0.8 * (deadline - time()))
  File "/opt/conda/envs/rapids/lib/python3.10/site-packages/distributed/nanny.py", line 853, in kill
    await process.join(max(0, deadline - time()))
  File "/opt/conda/envs/rapids/lib/python3.10/site-packages/distributed/process.py", line 330, in join
    await wait_for(asyncio.shield(self._exit_future), timeout)
  File "/opt/conda/envs/rapids/lib/python3.10/site-packages/distributed/utils.py", line 1878, in wait_for
    return await asyncio.wait_for(fut, timeout)
  File "/opt/conda/envs/rapids/lib/python3.10/asyncio/tasks.py", line 458, in wait_for
    raise exceptions.TimeoutError() from exc
asyncio.exceptions.TimeoutError
2023-06-22 22:39:36,402 - distributed.process - INFO - reaping stray process <SpawnProcess name='Dask Worker process (from Nanny)' pid=1476601 parent=1476531 started daemon>
2023-06-22 22:39:36,402 - distributed.process - INFO - reaping stray process <SpawnProcess name='Dask Worker process (from Nanny)' pid=1476598 parent=1476531 started daemon>
2023-06-22 22:39:36,402 - distributed.process - INFO - reaping stray process <SpawnProcess name='Dask Worker process (from Nanny)' pid=1476595 parent=1476531 started daemon>
2023-06-22 22:39:36,402 - distributed.process - INFO - reaping stray process <SpawnProcess name='Dask Worker process (from Nanny)' pid=1476592 parent=1476531 started daemon>
2023-06-22 22:39:36,402 - distributed.process - INFO - reaping stray process <SpawnProcess name='Dask Worker process (from Nanny)' pid=1476589 parent=1476531 started daemon>
2023-06-22 22:39:36,402 - distributed.process - INFO - reaping stray process <SpawnProcess name='Dask Worker process (from Nanny)' pid=1476586 parent=1476531 started daemon>
2023-06-22 22:39:36,402 - distributed.process - INFO - reaping stray process <SpawnProcess name='Dask Worker process (from Nanny)' pid=1476583 parent=1476531 started daemon>
2023-06-22 22:39:36,402 - distributed.process - INFO - reaping stray process <SpawnProcess name='Dask Worker process (from Nanny)' pid=1476580 parent=1476531 started daemon>
2023-06-22 22:39:36,688 - distributed.process - WARNING - [<AsyncProcess Dask Worker process (from Nanny)>] process 1476598 exit status was already read will report exitcode 255
2023-06-22 22:39:36,958 - distributed.process - WARNING - [<AsyncProcess Dask Worker process (from Nanny)>] process 1476601 exit status was already read will report exitcode 255
2023-06-22 22:39:37,331 - distributed.process - WARNING - [<AsyncProcess Dask Worker process (from Nanny)>] process 1476586 exit status was already read will report exitcode 255
